Workbook

Sheet Tracker
A1: MPE PACOM TO 32 Bridge – Deliverable Tracker
A2: PWS: Mission Partner Environment (MPE) Engineering Services for USPACOM | Contract 47QTCK-18-D-0017 | SOS International LLC | Follow-on to HC1047-18-D-0002 / HC1047-23-F0032
A3: Government POCs | C3: COR / Alternate COR / Property Administrator: see DITCO Additional Text G1 (not in this file). Acceptors below are carried over from the Thunderdome tracker – edit the lists on the Tracker tab.
A5: At a glance | C5: Overdue | D5: Due within 7 days | E5: Awaiting COR / J698 | F5: Fully accepted | G5: Returned: resubmit | H5: PWS paragraphs with no deliverable
C6: =COUNTIF('Daily Agenda'!$M$5:$M$231,"OVERDUE") -> 0 | D6: =COUNTIF('Daily Agenda'!$M$5:$M$231,"Due within 7 days") -> 0 | E6: =COUNTIF('Daily Agenda'!$M$5:$M$231,"Awaiting*") -> 0 | F6: =COUNTIF('Daily Agenda'!$M$5:$M$231,"Done") -> 0 | G6: =COUNTIF('Daily Agenda'!$M$5:$M$231,"Returned: resubmit") -> 0 | H6: =COUNTIF($I$9:$M$48,"None named*") -> 2
AB7: Lists (dropdown sources). Names you type into an Accepted By cell do not have to be on a list.
A8: Month | B8: Sub Task Number | C8: Paragraph / Section | D8: Frequency | E8: Category | F8: Primary POC | G8: Secondary POC | H8: Format of Deliverable | I8: Deliverable 1 | J8: Deliverable 2 | K8: Deliverable 3 | L8: Deliverable 4 | M8: Deliverable 5 | N8: Status Flow 1 | O8: Status Flow 2 | P8: Status Flow 3 | Q8: COR Accepted By | R8: COR Date Accepted | S8: J698 Accepted By | T8: J698 Date Accepted | AB8: Category | AC8: Status Flow 1 | AD8: Status Flow 2 | AE8: Status Flow 3 | AF8: Frequency | AG8: Month | AH8: COR Acceptors | AI8: J698 Acceptors
A9: Nov | B9: 6.1.1 | C9: Monthly Progress Report | D9: Monthly | E9: Program Mgmt | F9: Christine Y. Shigeta | G9: Brian Abrigo | H9: Mixed (see deliverables) | I9: B01 Monthly Progress Report (MPR) | J9: B02 90-Day Action Plan | K9: B03 Contractor Performance Report (CPR) | N9: Not Received | O9: Not Reviewed | AB9: Engineering | AC9: Received | AD9: Reviewed | AE9: Accepted | AF9: Weekly | AG9: Jan | AH9: Christine Y. Shigeta | AI9: J698
H10: Due / Frequency (per document) | I10: Due: 10th day of each month; if the 10th day falls on a weekend or holiday, submit on the first business day following Freq: Monthly, on 10th workday | J10: Due: 3 business days prior to the CPR meeting Freq: Final – 60 business days after award, and monthly updates thereafter Final plan: 60 business days after award (see Daily Agenda) Flag: CPR meeting date is not fixed in the PWS; 15th of the month assumed (settings). | K10: Due: Within 5 business days of a CPR meeting Freq: Monthly, within 5 business days after CPR Flag: Assumes CPR meeting on the day set in settings. | AB10: Operations | AC10: Not Received | AD10: Not Reviewed | AE10: Returned | AF10: Monthly | AG10: Feb | AH10: Brian Abrigo
A11: Nov | B11: 6.1.2 | C11: Weekly Activity Report | D11: Weekly | E11: Program Mgmt | F11: Christine Y. Shigeta | G11: Brian Abrigo | H11: MS Word | I11: B04 Weekly Activity Report (WAR) | N11: Not Received | O11: Not Reviewed | AB11: Program Mgmt | AD11: Demonstrated | AE11: Returned, but Fixed | AF11: Quarterly | AG11: Mar | AH11: Primary COR (DITCO G1)
H12: Due / Frequency (per document) | I12: Due: COB every Friday Freq: Friday Recurring weekly | AD12: Not Demonstrated | AF12: Annual | AG12: Apr | AH12: Alternate COR (DITCO G1)
A13: Nov | B13: 6.1.3 | C13: Transition-out Plan and Task Order Close Out | D13: One-Time | E13: Program Mgmt | F13: Christine Y. Shigeta | G13: Brian Abrigo | H13: MS Office Suite of Products | I13: B05 Transition- out Plan | N13: Not Received | O13: Not Reviewed | AF13: Daily (standing) | AG13: May
H14: Due / Frequency (per document) | I14: Due: 120 calendar days prior to the end of this task order Freq: 120 calendar days prior to the end of a Task Order Dates: see Daily Agenda (120 days before end) | AF14: One-Time | AG14: Jun
A15: Nov | B15: 6.2.1 | C15: System Engineering and Development Support | D15: As Needed | E15: Engineering | F15: Christine Y. Shigeta | G15: Brian Abrigo | H15: Mixed (see deliverables) | I15: B06 Technical Reports | J15: B07 Technical Presentations | K15: B08 Design Documentation | L15: B09 Software Documentation | M15: B10 Engineering Notes | N15: Not Received | O15: Not Reviewed | AF15: One-Time + Updates | AG15: Jul
H16: Due / Frequency (per document) | I16: Due: As specified in 90-day Action Plan Freq: As required by the COR and Government Project Lead | J16: Due: Drafts within three (3) business days of government requirement; Finals within three (3) business days of receipt of approved draft, with any markups, from Government Freq: Drafts within three (3) business days of Government requirement; Finals within three (3) business days of receipt of approved draft, with any markups, from Government | K16: Due: As specified in 90-day Action Plan Freq: As required by the COR and Government Project Lead | L16: Due: As specified in 90-day Action Plan Freq: As required by the COR and Government Project Lead | M16: Due: As specified in 90-day Action Plan Freq: As required by the COR and Government Project Lead | AF16: As Needed | AG16: Aug
A17: Nov | B17: 6.2.2 | C17: Installation and Operations Testing | D17: As Needed | E17: Operations | F17: Christine Y. Shigeta | G17: Brian Abrigo | H17: MS Office Suite of Products | I17: B11 Test Script | J17: B12 Test Report | K17: B13 COTS and GOTS Cost/Benefit Analysis | N17: Not Received | O17: Not Reviewed | AF17: Mixed (see due row) | AG17: Sep
H18: Due / Frequency (per document) | I18: Due: 30 business days before testing Freq: As required by the COR and Government Project Lead | J18: Due: 20 business days after testing is completed Freq: As required by the COR and Government Project Lead | K18: Due: As specified in 90 business days Action Plan Freq: As required by the COR and Government Project Lead | AF18: None named | AG18: Oct
A19: Nov | B19: 6.2.3 | C19: New System Capabilities Implementation and Support | D19: As Needed | E19: Engineering | F19: Christine Y. Shigeta | G19: Brian Abrigo | H19: MS Office Suite of Products | I19: B14 New Capabilities Demonstration Technical Report | N19: Not Received | O19: Not Reviewed | AG19: Nov
H20: Due / Frequency (per document) | I20: Due: 20 business days after demonstration is completed Freq: As required by the COR and Government Project Lead | AG20: Dec
A21: Nov | B21: 6.2.4 | C21: Technical System Software and Training Support | D21: As Needed | E21: Operations | F21: Christine Y. Shigeta | G21: Brian Abrigo | H21: MS Office Suite of Products | I21: B15 Training Materials | N21: Not Received | O21: Not Reviewed
H22: Due / Frequency (per document) | I22: Due: 30 business days before training delivery Freq: 30 days prior to any on- site, schoolhouse, or CBT
A23: Nov | B23: 6.2.5 | C23: Technical Documentation and Meeting Support | D23: Mixed (see due row) | E23: Engineering | F23: Christine Y. Shigeta | G23: Brian Abrigo | H23: MS Office Suite of Products | I23: B16 Technical Library Documentation Report | J23: B17 Technical Briefing/ Presentation | N23: Not Received | O23: Not Reviewed
H24: Due / Frequency (per document) | I24: Due: 10th day of each month; if the 10th day falls on a weekend or holiday, submit on the first business day following Freq: 10th day of each month | J24: Due: Drafts within three (3) business days of government requirement; Finals within three (3) business days of receipt of approved draft, with any markups, from Government Freq: Drafts within three (3) business days of Government requirement; Finals within three (3) business days of receipt of approved draft, with any markups, from Government
A25: Nov | B25: 6.2.6 | C25: Test and Evaluation / Verify and Validate | D25: As Needed | E25: Program Mgmt | F25: Christine Y. Shigeta | G25: Brian Abrigo | H25: Mixed (see deliverables) | I25: B18 Test and Evaluation V&V Report | J25: B19 Technical Procedures Documentation | K25: B20 Engineering Change Proposals (ECP) | L25: B21 Test Scenarios | M25: B22 Test Results | N25: Not Received | O25: Not Reviewed
H26: Due / Frequency (per document) | I26: Due: As specified in 90-day Action Plan Freq: As required by the COR and Government Project Lead | J26: Due: As specified in 90-day Action Plan Freq: As required by the COR and Government Project Lead | K26: Due: Within ten (10) business days of identified need as a result of testing or operational shortfalls Freq: Within ten (10) business days of identified need as a result of testing or operational shortfalls | L26: Due: 30 business days prior to a test event Freq: 30 business days prior to a test event | M26: Due: Within five (5) business days after a test event Freq: Within five (5) business days after a test event
A27: Nov | B27: 6.2.7 | C27: System and Software / Hardware Interface Req | D27: As Needed | E27: Engineering | F27: Christine Y. Shigeta | G27: Brian Abrigo | H27: Government format | I27: B23 Interface Control Document (ICD) | N27: Not Received | O27: Not Reviewed
H28: Due / Frequency (per document) | I28: Due: As specified in 90-day Action Plan Freq: As required by the COR and Government Project Lead
A29: Nov | B29: 6.2.8 | C29: Network Management | D29: As Needed | E29: Operations | F29: Christine Y. Shigeta | G29: Brian Abrigo | H29: Vendor format | I29: B24 Network Management. Technical Report | N29: Not Received | O29: Not Reviewed
H30: Due / Frequency (per document) | I30: Due: As specified in 90-day Action Plan Freq: As required by the COR and Government Project Lead
A31: Nov | B31: 6.2.9 | C31: Knowledge Management | D31: As Needed | E31: Program Mgmt | F31: Christine Y. Shigeta | G31: Brian Abrigo | H31: Vendor format | I31: B25 Knowledge Management Artifacts | N31: Not Received | O31: Not Reviewed
H32: Due / Frequency (per document) | I32: Due: Within five (5) business days of event Freq: Within five (5) business days of event
A33: Nov | B33: 6.2.10 | C33: Remote Field Services | D33: None named | E33: Program Mgmt | F33: Christine Y. Shigeta | G33: Brian Abrigo | H33: n/a | I33: None named in PWS
H34: Due / Frequency (per document) | I34: PWS requires Field Service Engineer management, operations and maintenance at theater bases (Hawaii, Japan, Guam, Korea, Alaska, Australia, CONUS). No deliverable in Section 11.
A35: Nov | B35: 6.3.1 | C35: Network Security Management | D35: Mixed (see due row) | E35: Engineering | F35: Christine Y. Shigeta | G35: Brian Abrigo | H35: Government format | I35: B26 Authorization and Accreditation (A&A) Packages | J35: B27 Network Security Test Procedures | K35: B28 Information Assurance Compliance Report | N35: Not Received | O35: Not Reviewed
H36: Due / Frequency (per document) | I36: Due: As required by the COR Freq: Monthly, if required by the COR and Government Project Lead Flag: Monthly only if the COR requires it. Mark N/A in months it is not required. | J36: Due: As specified in 90-day Action Plan Freq: As required by the COR and Government Project Lead | K36: Due: As specified in 90-day Action Plan Freq: As required by the COR and Government Project Lead
A37: Nov | B37: 6.3.2 | C37: Connections to Network | D37: Monthly | E37: Operations | F37: Christine Y. Shigeta | G37: Brian Abrigo | H37: MS Office Suite of Products | I37: B29 Network Installation / De-installation Report | N37: Not Received | O37: Not Reviewed
H38: Due / Frequency (per document) | I38: Due: As required by the COR Freq: Monthly, if required by the COR and Government Project Lead Flag: Monthly only if the COR requires it. Mark N/A in months it is not required.
A39: Nov | B39: 6.3.3 | C39: Touch Labor Services | D39: Monthly | E39: Operations | F39: Christine Y. Shigeta | G39: Brian Abrigo | H39: MS Office Suite of Products | I39: B30 IAVA Compliance Report | J39: B31 COMSEC Management Procedures Report | N39: Not Received | O39: Not Reviewed
H40: Due / Frequency (per document) | I40: Due: As part of the MPR Freq: Monthly | J40: Due: As required by the COR Freq: Monthly, if required by the COR Flag: Monthly only if the COR requires it. Mark N/A in months it is not required.
A41: Nov | B41: 6.3.4 | C41: Handling of Non-Public Information | D41: None named | E41: Operations | F41: Christine Y. Shigeta | G41: Brian Abrigo | H41: n/a | I41: None named in PWS
...

Sheet Weekly
A1: Weekly Deliverables – due every Friday (COB)
A2: PWS: Mission Partner Environment (MPE) Engineering Services for USPACOM | Contract 47QTCK-18-D-0017 | SOS International LLC | Follow-on to HC1047-18-D-0002 / HC1047-23-F0032
A4: ID | B4: Deliverable | C4: PWS ¶ | D4: Primary POC | E4: Secondary POC | F4: Record | G4: Fully accepted | H4: Overdue | I4: Wk 1 | J4: Wk 2 | K4: Wk 3 | L4: Wk 4 | M4: Wk 5 | N4: Wk 6 | O4: Wk 7 | P4: Wk 8 | Q4: Wk 9 | R4: Wk 10 | S4: Wk 11 | T4: Wk 12 | U4: Wk 13 | V4: Wk 14 | W4: Wk 15 | X4: Wk 16 | Y4: Wk 17 | Z4: Wk 18 | AA4: Wk 19 | AB4: Wk 20 | AC4: Wk 21 | AD4: Wk 22 | AE4: Wk 23 | AF4: Wk 24 | AG4: Wk 25 | AH4: Wk 26 | AI4: Wk 27 | AJ4: Wk 28 | AK4: Wk 29 | AL4: Wk 30 | AM4: Wk 31 | AN4: Wk 32 | AO4: Wk 33 | AP4: Wk 34 | AQ4: Wk 35 | AR4: Wk 36 | AS4: Wk 37 | AT4: Wk 38 | AU4: Wk 39 | AV4: Wk 40 | AW4: Wk 41 | AX4: Wk 42 | AY4: Wk 43 | AZ4: Wk 44 | BA4: Wk 45 | BB4: Wk 46 | BC4: Wk 47 | BD4: Wk 48 | BE4: Wk 49 | BF4: Wk 50 | BG4: Wk 51 | BH4: Wk 52
A5: B04 | B5: Weekly Activity Report (WAR) | C5: 6.1.2 | D5: Christine Y. Shigeta | E5: Brian Abrigo | F5: Due date | G5: =SUMPRODUCT((I8:BH8<>"")*(I10:BH10<>"")) -> 0 | H5: =SUMPRODUCT((I5:BH5<TODAY())*(((I6:BH6="")+(I6:BH6="In Progress"))>0)*(((I8:BH8="")+(I10:BH10=""))>0)) -> 0 | I5: =ClockStart+MOD(6-WEEKDAY(ClockStart),7)+0 -> 46332 | J5: =ClockStart+MOD(6-WEEKDAY(ClockStart),7)+7 -> 46339 | K5: =ClockStart+MOD(6-WEEKDAY(ClockStart),7)+14 -> 46346 | L5: =ClockStart+MOD(6-WEEKDAY(ClockStart),7)+21 -> 46353 | M5: =ClockStart+MOD(6-WEEKDAY(ClockStart),7)+28 -> 46360 | N5: =ClockStart+MOD(6-WEEKDAY(ClockStart),7)+35 -> 46367 | O5: =ClockStart+MOD(6-WEEKDAY(ClockStart),7)+42 -> 46374 | P5: =ClockStart+MOD(6-WEEKDAY(ClockStart),7)+49 -> 46381 | Q5: =ClockStart+MOD(6-WEEKDAY(ClockStart),7)+56 -> 46388 | R5: =ClockStart+MOD(6-WEEKDAY(ClockStart),7)+63 -> 46395 | S5: =ClockStart+MOD(6-WEEKDAY(ClockStart),7)+70 -> 46402 | T5: =ClockStart+MOD(6-WEEKDAY(ClockStart),7)+77 -> 46409 | U5: =ClockStart+MOD(6-WEEKDAY(ClockStart),7)+84 -> 46416 | V5: =ClockStart+MOD(6-WEEKDAY(ClockStart),7)+91 -> 46423 | W5: =ClockStart+MOD(6-WEEKDAY(ClockStart),7)+98 -> 46430 | X5: =ClockStart+MOD(6-WEEKDAY(ClockStart),7)+105 -> 46437 | Y5: =ClockStart+MOD(6-WEEKDAY(ClockStart),7)+112 -> 46444 | Z5: =ClockStart+MOD(6-WEEKDAY(ClockStart),7)+119 -> 46451 | AA5: =ClockStart+MOD(6-WEEKDAY(ClockStart),7)+126 -> 46458 | AB5: =ClockStart+MOD(6-WEEKDAY(ClockStart),7)+133 -> 46465 | AC5: =ClockStart+MOD(6-WEEKDAY(ClockStart),7)+140 -> 46472 | AD5: =ClockStart+MOD(6-WEEKDAY(ClockStart),7)+147 -> 46479 | AE5: =ClockStart+MOD(6-WEEKDAY(ClockStart),7)+154 -> 46486 | AF5: =ClockStart+MOD(6-WEEKDAY(ClockStart),7)+161 -> 46493 | AG5: =ClockStart+MOD(6-WEEKDAY(ClockStart),7)+168 -> 46500 | AH5: =ClockStart+MOD(6-WEEKDAY(ClockStart),7)+175 -> 46507 | AI5: =ClockStart+MOD(6-WEEKDAY(ClockStart),7)+182 -> 46514 | AJ5: =ClockStart+MOD(6-WEEKDAY(ClockStart),7)+189 -> 46521 | AK5: =ClockStart+MOD(6-WEEKDAY(ClockStart),7)+196 -> 46528 | AL5: =ClockStart+MOD(6-WEEKDAY(ClockStart),7)+203 -> 46535 | AM5: =ClockStart+MOD(6-WEEKDAY(ClockStart),7)+210 -> 46542 | AN5: =ClockStart+MOD(6-WEEKDAY(ClockStart),7)+217 -> 46549 | AO5: =ClockStart+MOD(6-WEEKDAY(ClockStart),7)+224 -> 46556 | AP5: =ClockStart+MOD(6-WEEKDAY(ClockStart),7)+231 -> 46563 | AQ5: =ClockStart+MOD(6-WEEKDAY(ClockStart),7)+238 -> 46570 | AR5: =ClockStart+MOD(6-WEEKDAY(ClockStart),7)+245 -> 46577 | AS5: =ClockStart+MOD(6-WEEKDAY(ClockStart),7)+252 -> 46584 | AT5: =ClockStart+MOD(6-WEEKDAY(ClockStart),7)+259 -> 46591 | AU5: =ClockStart+MOD(6-WEEKDAY(ClockStart),7)+266 -> 46598 | AV5: =ClockStart+MOD(6-WEEKDAY(ClockStart),7)+273 -> 46605 | AW5: =ClockStart+MOD(6-WEEKDAY(ClockStart),7)+280 -> 46612 | AX5: =ClockStart+MOD(6-WEEKDAY(ClockStart),7)+287 -> 46619 | AY5: =ClockStart+MOD(6-WEEKDAY(ClockStart),7)+294 -> 46626 | AZ5: =ClockStart+MOD(6-WEEKDAY(ClockStart),7)+301 -> 46633 | BA5: =ClockStart+MOD(6-WEEKDAY(ClockStart),7)+308 -> 46640 | BB5: =ClockStart+MOD(6-WEEKDAY(ClockStart),7)+315 -> 46647 | BC5: =ClockStart+MOD(6-WEEKDAY(ClockStart),7)+322 -> 46654 | BD5: =ClockStart+MOD(6-WEEKDAY(ClockStart),7)+329 -> 46661 | BE5: =ClockStart+MOD(6-WEEKDAY(ClockStart),7)+336 -> 46668 | BF5: =ClockStart+MOD(6-WEEKDAY(ClockStart),7)+343 -> 46675 | BG5: =ClockStart+MOD(6-WEEKDAY(ClockStart),7)+350 -> 46682 | BH5: =ClockStart+MOD(6-WEEKDAY(ClockStart),7)+357 -> 46689
F6: Status
F7: COR accepted by
F8: COR date accepted
F9: J698 accepted by
F10: J698 date accepted
F11: Result | I11: =IF(AND(I8<>"",I10<>""),"Fully accepted",IF(I8<>"","COR only",IF(I10<>"","J698 only",""))) | J11: =IF(AND(J8<>"",J10<>""),"Fully accepted",IF(J8<>"","COR only",IF(J10<>"","J698 only",""))) | K11: =IF(AND(K8<>"",K10<>""),"Fully accepted",IF(K8<>"","COR only",IF(K10<>"","J698 only",""))) | L11: =IF(AND(L8<>"",L10<>""),"Fully accepted",IF(L8<>"","COR only",IF(L10<>"","J698 only",""))) | M11: =IF(AND(M8<>"",M10<>""),"Fully accepted",IF(M8<>"","COR only",IF(M10<>"","J698 only",""))) | N11: =IF(AND(N8<>"",N10<>""),"Fully accepted",IF(N8<>"","COR only",IF(N10<>"","J698 only",""))) | O11: =IF(AND(O8<>"",O10<>""),"Fully accepted",IF(O8<>"","COR only",IF(O10<>"","J698 only",""))) | P11: =IF(AND(P8<>"",P10<>""),"Fully accepted",IF(P8<>"","COR only",IF(P10<>"","J698 only",""))) | ... BH11: =IF(AND(BH8<>"",BH10<>""),"Fully accepted",IF(BH8<>"","COR only",IF(BH10<>"","J698 only","")))
A12: B34 | B12: Weekly Activity Report (WAR) | C12: 6.5.1 | D12: Christine Y. Shigeta | E12: Brian Abrigo | F12: Due date | G12: =SUMPRODUCT((I15:BH15<>"")*(I17:BH17<>"")) -> 0 | H12: =SUMPRODUCT((I12:BH12<TODAY())*(((I13:BH13="")+(I13:BH13="In Progress"))>0)*(((I15:BH15="")+(I17:BH17=""))>0)) -> 0 | I12: =ClockStart+MOD(6-WEEKDAY(ClockStart),7)+0 -> 46332 | J12: =ClockStart+MOD(6-WEEKDAY(ClockStart),7)+7 -> 46339 | K12: =ClockStart+MOD(6-WEEKDAY(ClockStart),7)+14 -> 46346 | L12: =ClockStart+MOD(6-WEEKDAY(ClockStart),7)+21 -> 46353 | M12: =ClockStart+MOD(6-WEEKDAY(ClockStart),7)+28 -> 46360 | N12: =ClockStart+MOD(6-WEEKDAY(ClockStart),7)+35 -> 46367 | O12: =ClockStart+MOD(6-WEEKDAY(ClockStart),7)+42 -> 46374 | P12: =ClockStart+MOD(6-WEEKDAY(ClockStart),7)+49 -> 46381 | Q12: =ClockStart+MOD(6-WEEKDAY(ClockStart),7)+56 -> 46388 | R12: =ClockStart+MOD(6-WEEKDAY(ClockStart),7)+63 -> 46395 | S12: =ClockStart+MOD(6-WEEKDAY(ClockStart),7)+70 -> 46402 | T12: =ClockStart+MOD(6-WEEKDAY(ClockStart),7)+77 -> 46409 | U12: =ClockStart+MOD(6-WEEKDAY(ClockStart),7)+84 -> 46416 | V12: =ClockStart+MOD(6-WEEKDAY(ClockStart),7)+91 -> 46423 | W12: =ClockStart+MOD(6-WEEKDAY(ClockStart),7)+98 -> 46430 | X12: =ClockStart+MOD(6-WEEKDAY(ClockStart),7)+105 -> 46437 | Y12: =ClockStart+MOD(6-WEEKDAY(ClockStart),7)+112 -> 46444 | Z12: =ClockStart+MOD(6-WEEKDAY(ClockStart),7)+119 -> 46451 | AA12: =ClockStart+MOD(6-WEEKDAY(ClockStart),7)+126 -> 46458 | AB12: =ClockStart+MOD(6-WEEKDAY(ClockStart),7)+133 -> 46465 | AC12: =ClockStart+MOD(6-WEEKDAY(ClockStart),7)+140 -> 46472 | AD12: =ClockStart+MOD(6-WEEKDAY(ClockStart),7)+147 -> 46479 | AE12: =ClockStart+MOD(6-WEEKDAY(ClockStart),7)+154 -> 46486 | AF12: =ClockStart+MOD(6-WEEKDAY(ClockStart),7)+161 -> 46493 | AG12: =ClockStart+MOD(6-WEEKDAY(ClockStart),7)+168 -> 46500 | AH12: =ClockStart+MOD(6-WEEKDAY(ClockStart),7)+175 -> 46507 | AI12: =ClockStart+MOD(6-WEEKDAY(ClockStart),7)+182 -> 46514 | AJ12: =ClockStart+MOD(6-WEEKDAY(ClockStart),7)+189 -> 46521 | AK12: =ClockStart+MOD(6-WEEKDAY(ClockStart),7)+196 -> 46528 | AL12: =ClockStart+MOD(6-WEEKDAY(ClockStart),7)+203 -> 46535 | AM12: =ClockStart+MOD(6-WEEKDAY(ClockStart),7)+210 -> 46542 | AN12: =ClockStart+MOD(6-WEEKDAY(ClockStart),7)+217 -> 46549 | AO12: =ClockStart+MOD(6-WEEKDAY(ClockStart),7)+224 -> 46556 | AP12: =ClockStart+MOD(6-WEEKDAY(ClockStart),7)+231 -> 46563 | AQ12: =ClockStart+MOD(6-WEEKDAY(ClockStart),7)+238 -> 46570 | AR12: =ClockStart+MOD(6-WEEKDAY(ClockStart),7)+245 -> 46577 | AS12: =ClockStart+MOD(6-WEEKDAY(ClockStart),7)+252 -> 46584 | AT12: =ClockStart+MOD(6-WEEKDAY(ClockStart),7)+259 -> 46591 | AU12: =ClockStart+MOD(6-WEEKDAY(ClockStart),7)+266 -> 46598 | AV12: =ClockStart+MOD(6-WEEKDAY(ClockStart),7)+273 -> 46605 | AW12: =ClockStart+MOD(6-WEEKDAY(ClockStart),7)+280 -> 46612 | AX12: =ClockStart+MOD(6-WEEKDAY(ClockStart),7)+287 -> 46619 | AY12: =ClockStart+MOD(6-WEEKDAY(ClockStart),7)+294 -> 46626 | AZ12: =ClockStart+MOD(6-WEEKDAY(ClockStart),7)+301 -> 46633 | BA12: =ClockStart+MOD(6-WEEKDAY(ClockStart),7)+308 -> 46640 | BB12: =ClockStart+MOD(6-WEEKDAY(ClockStart),7)+315 -> 46647 | BC12: =ClockStart+MOD(6-WEEKDAY(ClockStart),7)+322 -> 46654 | BD12: =ClockStart+MOD(6-WEEKDAY(ClockStart),7)+329 -> 46661 | BE12: =ClockStart+MOD(6-WEEKDAY(ClockStart),7)+336 -> 46668 | BF12: =ClockStart+MOD(6-WEEKDAY(ClockStart),7)+343 -> 46675 | BG12: =ClockStart+MOD(6-WEEKDAY(ClockStart),7)+350 -> 46682 | BH12: =ClockStart+MOD(6-WEEKDAY(ClockStart),7)+357 -> 46689
F13: Status
F14: COR accepted by
F15: COR date accepted
F16: J698 accepted by
F17: J698 date accepted
F18: Result | I18: =IF(AND(I15<>"",I17<>""),"Fully accepted",IF(I15<>"","COR only",IF(I17<>"","J698 only",""))) | J18: =IF(AND(J15<>"",J17<>""),"Fully accepted",IF(J15<>"","COR only",IF(J17<>"","J698 only",""))) | K18: =IF(AND(K15<>"",K17<>""),"Fully accepted",IF(K15<>"","COR only",IF(K17<>"","J698 only",""))) | L18: =IF(AND(L15<>"",L17<>""),"Fully accepted",IF(L15<>"","COR only",IF(L17<>"","J698 only",""))) | M18: =IF(AND(M15<>"",M17<>""),"Fully accepted",IF(M15<>"","COR only",IF(M17<>"","J698 only",""))) | N18: =IF(AND(N15<>"",N17<>""),"Fully accepted",IF(N15<>"","COR only",IF(N17<>"","J698 only",""))) | O18: =IF(AND(O15<>"",O17<>""),"Fully accepted",IF(O15<>"","COR only",IF(O17<>"","J698 only",""))) | P18: =IF(AND(P15<>"",P17<>""),"Fully accepted",IF(P15<>"","COR only",IF(P17<>"","J698 only",""))) | ... BH18: =IF(AND(BH15<>"",BH17<>""),"Fully accepted",IF(BH15<>"","COR only",IF(BH17<>"","J698 only","")))
B20: Set Status, then record who accepted it and when. Friday COB is explicit in the PWS (Section 11).

Sheet Monthly
A1: Monthly Deliverables – MPR and companion items
A2: PWS: Mission Partner Environment (MPE) Engineering Services for USPACOM | Contract 47QTCK-18-D-0017 | SOS International LLC | Follow-on to HC1047-18-D-0002 / HC1047-23-F0032
A4: ID | B4: Deliverable | C4: PWS ¶ | D4: Primary POC | E4: Secondary POC | F4: Record | G4: Fully accepted | H4: Overdue | I4: =EDATE(DATE(YEAR(ClockStart),MONTH(ClockStart),1),0) -> 46327 | J4: =EDATE(DATE(YEAR(ClockStart),MONTH(ClockStart),1),1) -> 46357 | K4: =EDATE(DATE(YEAR(ClockStart),MONTH(ClockStart),1),2) -> 46388 | L4: =EDATE(DATE(YEAR(ClockStart),MONTH(ClockStart),1),3) -> 46419 | M4: =EDATE(DATE(YEAR(ClockStart),MONTH(ClockStart),1),4) -> 46447 | N4: =EDATE(DATE(YEAR(ClockStart),MONTH(ClockStart),1),5) -> 46478 | O4: =EDATE(DATE(YEAR(ClockStart),MONTH(ClockStart),1),6) -> 46508 | P4: =EDATE(DATE(YEAR(ClockStart),MONTH(ClockStart),1),7) -> 46539 | Q4: =EDATE(DATE(YEAR(ClockStart),MONTH(ClockStart),1),8) -> 46569 | R4: =EDATE(DATE(YEAR(ClockStart),MONTH(ClockStart),1),9) -> 46600 | S4: =EDATE(DATE(YEAR(ClockStart),MONTH(ClockStart),1),10) -> 46631 | T4: =EDATE(DATE(YEAR(ClockStart),MONTH(ClockStart),1),11) -> 46661
A5: B01 | B5: Monthly Progress Report (MPR) | C5: 6.1.1 | D5: Christine Y. Shigeta | E5: Brian Abrigo | F5: Due date | G5: =SUMPRODUCT((I8:T8<>"")*(I10:T10<>"")) -> 0 | H5: =SUMPRODUCT((I5:T5<TODAY())*(((I6:T6="")+(I6:T6="In Progress"))>0)*(((I8:T8="")+(I10:T10=""))>0)) -> 0 | I5: =WORKDAY(DATE(YEAR(I$4),MONTH(I$4)+1,10)-1,1) -> 46366 | J5: =WORKDAY(DATE(YEAR(J$4),MONTH(J$4)+1,10)-1,1) -> 46398 | K5: =WORKDAY(DATE(YEAR(K$4),MONTH(K$4)+1,10)-1,1) -> 46428 | L5: =WORKDAY(DATE(YEAR(L$4),MONTH(L$4)+1,10)-1,1) -> 46456 | M5: =WORKDAY(DATE(YEAR(M$4),MONTH(M$4)+1,10)-1,1) -> 46489 | N5: =WORKDAY(DATE(YEAR(N$4),MONTH(N$4)+1,10)-1,1) -> 46517 | O5: =WORKDAY(DATE(YEAR(O$4),MONTH(O$4)+1,10)-1,1) -> 46548 | P5: =WORKDAY(DATE(YEAR(P$4),MONTH(P$4)+1,10)-1,1) -> 46580 | ... T5: =WORKDAY(DATE(YEAR(T$4),MONTH(T$4)+1,10)-1,1) -> 46701
F6: Status
F7: COR accepted by
F8: COR date accepted
F9: J698 accepted by
F10: J698 date accepted
F11: Result | I11: =IF(AND(I8<>"",I10<>""),"Fully accepted",IF(I8<>"","COR only",IF(I10<>"","J698 only",""))) | J11: =IF(AND(J8<>"",J10<>""),"Fully accepted",IF(J8<>"","COR only",IF(J10<>"","J698 only",""))) | K11: =IF(AND(K8<>"",K10<>""),"Fully accepted",IF(K8<>"","COR only",IF(K10<>"","J698 only",""))) | L11: =IF(AND(L8<>"",L10<>""),"Fully accepted",IF(L8<>"","COR only",IF(L10<>"","J698 only",""))) | M11: =IF(AND(M8<>"",M10<>""),"Fully accepted",IF(M8<>"","COR only",IF(M10<>"","J698 only",""))) | N11: =IF(AND(N8<>"",N10<>""),"Fully accepted",IF(N8<>"","COR only",IF(N10<>"","J698 only",""))) | O11: =IF(AND(O8<>"",O10<>""),"Fully accepted",IF(O8<>"","COR only",IF(O10<>"","J698 only",""))) | P11: =IF(AND(P8<>"",P10<>""),"Fully accepted",IF(P8<>"","COR only",IF(P10<>"","J698 only",""))) | ... T11: =IF(AND(T8<>"",T10<>""),"Fully accepted",IF(T8<>"","COR only",IF(T10<>"","J698 only","")))
A12: B02 | B12: 90-Day Action Plan | C12: 6.1.1 | D12: Christine Y. Shigeta | E12: Brian Abrigo | F12: Due date | G12: =SUMPRODUCT((I15:T15<>"")*(I17:T17<>"")) -> 0 | H12: =SUMPRODUCT((I12:T12<TODAY())*(((I13:T13="")+(I13:T13="In Progress"))>0)*(((I15:T15="")+(I17:T17=""))>0)) -> 0 | I12: =WORKDAY(DATE(YEAR(I$4),MONTH(I$4)+1,CPRDay),-3) -> 46366 | J12: =WORKDAY(DATE(YEAR(J$4),MONTH(J$4)+1,CPRDay),-3) -> 46399 | K12: =WORKDAY(DATE(YEAR(K$4),MONTH(K$4)+1,CPRDay),-3) -> 46428 | L12: =WORKDAY(DATE(YEAR(L$4),MONTH(L$4)+1,CPRDay),-3) -> 46456 | M12: =WORKDAY(DATE(YEAR(M$4),MONTH(M$4)+1,CPRDay),-3) -> 46489 | N12: =WORKDAY(DATE(YEAR(N$4),MONTH(N$4)+1,CPRDay),-3) -> 46519 | O12: =WORKDAY(DATE(YEAR(O$4),MONTH(O$4)+1,CPRDay),-3) -> 46548 | P12: =WORKDAY(DATE(YEAR(P$4),MONTH(P$4)+1,CPRDay),-3) -> 46580 | ... T12: =WORKDAY(DATE(YEAR(T$4),MONTH(T$4)+1,CPRDay),-3) -> 46701
F13: Status
F14: COR accepted by
F15: COR date accepted
F16: J698 accepted by
F17: J698 date accepted
F18: Result | I18: =IF(AND(I15<>"",I17<>""),"Fully accepted",IF(I15<>"","COR only",IF(I17<>"","J698 only",""))) | J18: =IF(AND(J15<>"",J17<>""),"Fully accepted",IF(J15<>"","COR only",IF(J17<>"","J698 only",""))) | K18: =IF(AND(K15<>"",K17<>""),"Fully accepted",IF(K15<>"","COR only",IF(K17<>"","J698 only",""))) | L18: =IF(AND(L15<>"",L17<>""),"Fully accepted",IF(L15<>"","COR only",IF(L17<>"","J698 only",""))) | M18: =IF(AND(M15<>"",M17<>""),"Fully accepted",IF(M15<>"","COR only",IF(M17<>"","J698 only",""))) | N18: =IF(AND(N15<>"",N17<>""),"Fully accepted",IF(N15<>"","COR only",IF(N17<>"","J698 only",""))) | O18: =IF(AND(O15<>"",O17<>""),"Fully accepted",IF(O15<>"","COR only",IF(O17<>"","J698 only",""))) | P18: =IF(AND(P15<>"",P17<>""),"Fully accepted",IF(P15<>"","COR only",IF(P17<>"","J698 only",""))) | ... T18: =IF(AND(T15<>"",T17<>""),"Fully accepted",IF(T15<>"","COR only",IF(T17<>"","J698 only","")))
A19: B03 | B19: Contractor Performance Report (CPR) | C19: 6.1.1 | D19: Christine Y. Shigeta | E19: Brian Abrigo | F19: Due date | G19: =SUMPRODUCT((I22:T22<>"")*(I24:T24<>"")) -> 0 | H19: =SUMPRODUCT((I19:T19<TODAY())*(((I20:T20="")+(I20:T20="In Progress"))>0)*(((I22:T22="")+(I24:T24=""))>0)) -> 0 | I19: =WORKDAY(DATE(YEAR(I$4),MONTH(I$4)+1,CPRDay),5) -> 46378 | J19: =WORKDAY(DATE(YEAR(J$4),MONTH(J$4)+1,CPRDay),5) -> 46409 | K19: =WORKDAY(DATE(YEAR(K$4),MONTH(K$4)+1,CPRDay),5) -> 46440 | L19: =WORKDAY(DATE(YEAR(L$4),MONTH(L$4)+1,CPRDay),5) -> 46468 | M19: =WORKDAY(DATE(YEAR(M$4),MONTH(M$4)+1,CPRDay),5) -> 46499 | N19: =WORKDAY(DATE(YEAR(N$4),MONTH(N$4)+1,CPRDay),5) -> 46528 | O19: =WORKDAY(DATE(YEAR(O$4),MONTH(O$4)+1,CPRDay),5) -> 46560 | P19: =WORKDAY(DATE(YEAR(P$4),MONTH(P$4)+1,CPRDay),5) -> 46590 | ... T19: =WORKDAY(DATE(YEAR(T$4),MONTH(T$4)+1,CPRDay),5) -> 46713
F20: Status
F21: COR accepted by
F22: COR date accepted
F23: J698 accepted by
F24: J698 date accepted
F25: Result | I25: =IF(AND(I22<>"",I24<>""),"Fully accepted",IF(I22<>"","COR only",IF(I24<>"","J698 only",""))) | J25: =IF(AND(J22<>"",J24<>""),"Fully accepted",IF(J22<>"","COR only",IF(J24<>"","J698 only",""))) | K25: =IF(AND(K22<>"",K24<>""),"Fully accepted",IF(K22<>"","COR only",IF(K24<>"","J698 only",""))) | L25: =IF(AND(L22<>"",L24<>""),"Fully accepted",IF(L22<>"","COR only",IF(L24<>"","J698 only",""))) | M25: =IF(AND(M22<>"",M24<>""),"Fully accepted",IF(M22<>"","COR only",IF(M24<>"","J698 only",""))) | N25: =IF(AND(N22<>"",N24<>""),"Fully accepted",IF(N22<>"","COR only",IF(N24<>"","J698 only",""))) | O25: =IF(AND(O22<>"",O24<>""),"Fully accepted",IF(O22<>"","COR only",IF(O24<>"","J698 only",""))) | P25: =IF(AND(P22<>"",P24<>""),"Fully accepted",IF(P22<>"","COR only",IF(P24<>"","J698 only",""))) | ... T25: =IF(AND(T22<>"",T24<>""),"Fully accepted",IF(T22<>"","COR only",IF(T24<>"","J698 only","")))
A26: B16 | B26: Technical Library Documentation Report | C26: 6.2.5 | D26: Christine Y. Shigeta | E26: Brian Abrigo | F26: Due date | G26: =SUMPRODUCT((I29:T29<>"")*(I31:T31<>"")) -> 0 | H26: =SUMPRODUCT((I26:T26<TODAY())*(((I27:T27="")+(I27:T27="In Progress"))>0)*(((I29:T29="")+(I31:T31=""))>0)) -> 0 | I26: =WORKDAY(DATE(YEAR(I$4),MONTH(I$4)+1,10)-1,1) -> 46366 | J26: =WORKDAY(DATE(YEAR(J$4),MONTH(J$4)+1,10)-1,1) -> 46398 | K26: =WORKDAY(DATE(YEAR(K$4),MONTH(K$4)+1,10)-1,1) -> 46428 | L26: =WORKDAY(DATE(YEAR(L$4),MONTH(L$4)+1,10)-1,1) -> 46456 | M26: =WORKDAY(DATE(YEAR(M$4),MONTH(M$4)+1,10)-1,1) -> 46489 | N26: =WORKDAY(DATE(YEAR(N$4),MONTH(N$4)+1,10)-1,1) -> 46517 | O26: =WORKDAY(DATE(YEAR(O$4),MONTH(O$4)+1,10)-1,1) -> 46548 | P26: =WORKDAY(DATE(YEAR(P$4),MONTH(P$4)+1,10)-1,1) -> 46580 | ... T26: =WORKDAY(DATE(YEAR(T$4),MONTH(T$4)+1,10)-1,1) -> 46701
F27: Status
F28: COR accepted by
F29: COR date accepted
F30: J698 accepted by
F31: J698 date accepted
F32: Result | I32: =IF(AND(I29<>"",I31<>""),"Fully accepted",IF(I29<>"","COR only",IF(I31<>"","J698 only",""))) | J32: =IF(AND(J29<>"",J31<>""),"Fully accepted",IF(J29<>"","COR only",IF(J31<>"","J698 only",""))) | K32: =IF(AND(K29<>"",K31<>""),"Fully accepted",IF(K29<>"","COR only",IF(K31<>"","J698 only",""))) | L32: =IF(AND(L29<>"",L31<>""),"Fully accepted",IF(L29<>"","COR only",IF(L31<>"","J698 only",""))) | M32: =IF(AND(M29<>"",M31<>""),"Fully accepted",IF(M29<>"","COR only",IF(M31<>"","J698 only",""))) | N32: =IF(AND(N29<>"",N31<>""),"Fully accepted",IF(N29<>"","COR only",IF(N31<>"","J698 only",""))) | O32: =IF(AND(O29<>"",O31<>""),"Fully accepted",IF(O29<>"","COR only",IF(O31<>"","J698 only",""))) | P32: =IF(AND(P29<>"",P31<>""),"Fully accepted",IF(P29<>"","COR only",IF(P31<>"","J698 only",""))) | ... T32: =IF(AND(T29<>"",T31<>""),"Fully accepted",IF(T29<>"","COR only",IF(T31<>"","J698 only","")))
A33: B26 | B33: Authorization and Accreditation (A&A) Packages | C33: 6.3.1 | D33: Christine Y. Shigeta | E33: Brian Abrigo | F33: Due date | G33: =SUMPRODUCT((I36:T36<>"")*(I38:T38<>"")) -> 0 | H33: =SUMPRODUCT((I33:T33<TODAY())*(((I34:T34="")+(I34:T34="In Progress"))>0)*(((I36:T36="")+(I38:T38=""))>0)) -> 0 | I33: =WORKDAY(DATE(YEAR(I$4),MONTH(I$4)+1,10)-1,1) -> 46366 | J33: =WORKDAY(DATE(YEAR(J$4),MONTH(J$4)+1,10)-1,1) -> 46398 | K33: =WORKDAY(DATE(YEAR(K$4),MONTH(K$4)+1,10)-1,1) -> 46428 | L33: =WORKDAY(DATE(YEAR(L$4),MONTH(L$4)+1,10)-1,1) -> 46456 | M33: =WORKDAY(DATE(YEAR(M$4),MONTH(M$4)+1,10)-1,1) -> 46489 | N33: =WORKDAY(DATE(YEAR(N$4),MONTH(N$4)+1,10)-1,1) -> 46517 | O33: =WORKDAY(DATE(YEAR(O$4),MONTH(O$4)+1,10)-1,1) -> 46548 | P33: =WORKDAY(DATE(YEAR(P$4),MONTH(P$4)+1,10)-1,1) -> 46580 | ... T33: =WORKDAY(DATE(YEAR(T$4),MONTH(T$4)+1,10)-1,1) -> 46701
F34: Status
F35: COR accepted by
F36: COR date accepted
F37: J698 accepted by
F38: J698 date accepted
F39: Result | I39: =IF(AND(I36<>"",I38<>""),"Fully accepted",IF(I36<>"","COR only",IF(I38<>"","J698 only",""))) | J39: =IF(AND(J36<>"",J38<>""),"Fully accepted",IF(J36<>"","COR only",IF(J38<>"","J698 only",""))) | K39: =IF(AND(K36<>"",K38<>""),"Fully accepted",IF(K36<>"","COR only",IF(K38<>"","J698 only",""))) | L39: =IF(AND(L36<>"",L38<>""),"Fully accepted",IF(L36<>"","COR only",IF(L38<>"","J698 only",""))) | M39: =IF(AND(M36<>"",M38<>""),"Fully accepted",IF(M36<>"","COR only",IF(M38<>"","J698 only",""))) | N39: =IF(AND(N36<>"",N38<>""),"Fully accepted",IF(N36<>"","COR only",IF(N38<>"","J698 only",""))) | O39: =IF(AND(O36<>"",O38<>""),"Fully accepted",IF(O36<>"","COR only",IF(O38<>"","J698 only",""))) | P39: =IF(AND(P36<>"",P38<>""),"Fully accepted",IF(P36<>"","COR only",IF(P38<>"","J698 only",""))) | ... T39: =IF(AND(T36<>"",T38<>""),"Fully accepted",IF(T36<>"","COR only",IF(T38<>"","J698 only","")))
A40: B29 | B40: Network Installation / De-installation Report | C40: 6.3.2 | D40: Christine Y. Shigeta | E40: Brian Abrigo | F40: Due date | G40: =SUMPRODUCT((I43:T43<>"")*(I45:T45<>"")) -> 0 | H40: =SUMPRODUCT((I40:T40<TODAY())*(((I41:T41="")+(I41:T41="In Progress"))>0)*(((I43:T43="")+(I45:T45=""))>0)) -> 0 | I40: =WORKDAY(DATE(YEAR(I$4),MONTH(I$4)+1,10)-1,1) -> 46366 | J40: =WORKDAY(DATE(YEAR(J$4),MONTH(J$4)+1,10)-1,1) -> 46398 | K40: =WORKDAY(DATE(YEAR(K$4),MONTH(K$4)+1,10)-1,1) -> 46428 | L40: =WORKDAY(DATE(YEAR(L$4),MONTH(L$4)+1,10)-1,1) -> 46456 | M40: =WORKDAY(DATE(YEAR(M$4),MONTH(M$4)+1,10)-1,1) -> 46489 | N40: =WORKDAY(DATE(YEAR(N$4),MONTH(N$4)+1,10)-1,1) -> 46517 | O40: =WORKDAY(DATE(YEAR(O$4),MONTH(O$4)+1,10)-1,1) -> 46548 | P40: =WORKDAY(DATE(YEAR(P$4),MONTH(P$4)+1,10)-1,1) -> 46580 | ... T40: =WORKDAY(DATE(YEAR(T$4),MONTH(T$4)+1,10)-1,1) -> 46701
F41: Status
...

Sheet Daily Agenda
A1: Daily Agenda – what is due, in date order
A2: PWS: Mission Partner Environment (MPE) Engineering Services for USPACOM | Contract 47QTCK-18-D-0017 | SOS International LLC | Follow-on to HC1047-18-D-0002 / HC1047-23-F0032
P3: Settings (edit the yellow cells)
A4: Due Date | B4: Day | C4: ID | D4: Deliverable | E4: Source | F4: Status | G4: COR Accepted By | H4: COR Date Accepted | I4: J698 Accepted By | J4: J698 Date Accepted | K4: Result | L4: Days Until Due | M4: Flag | N4: Notes | P4: Clock start (PLACEHOLDER – PoP not stated in this file) | Q4: 46327
A5: =Weekly!I5 -> 46332 | B5: =TEXT(A5,"ddd") -> Fri | C5: B04 | D5: Weekly Activity Report (WAR) – Wk 1 | E5: Weekly | F5: =IF(Weekly!I6="","",Weekly!I6) | G5: =IF(Weekly!I7="","",Weekly!I7) | H5: =IF(Weekly!I8="","",Weekly!I8) | I5: =IF(Weekly!I9="","",Weekly!I9) | J5: =IF(Weekly!I10="","",Weekly!I10) | K5: =IF(AND(H5<>"",J5<>""),"Fully accepted",IF(H5<>"","COR only",IF(J5<>"","J698 only",""))) | L5: =A5-TodayD -> 24 | M5: =IF(K5="Fully accepted","Done",IF(F5="N/A","N/A",IF(F5="Returned","Returned: resubmit",IF(K5="J698 only","Awaiting J698",IF(K5="COR only","Awaiting COR",IF(F5="Submitted","Awaiting COR + J698",IF(A5<TodayD,"OVERDUE",IF(A5-TodayD<=7,"Due within 7 days","")))))))) | P5: End of 12-month base period | Q5: =EDATE(ClockStart,12)-1 -> 46691
A6: =Weekly!I12 -> 46332 | B6: =TEXT(A6,"ddd") -> Fri | C6: B34 | D6: Weekly Activity Report (WAR) – Wk 1 | E6: Weekly | F6: =IF(Weekly!I13="","",Weekly!I13) | G6: =IF(Weekly!I14="","",Weekly!I14) | H6: =IF(Weekly!I15="","",Weekly!I15) | I6: =IF(Weekly!I16="","",Weekly!I16) | J6: =IF(Weekly!I17="","",Weekly!I17) | K6: =IF(AND(H6<>"",J6<>""),"Fully accepted",IF(H6<>"","COR only",IF(J6<>"","J698 only",""))) | L6: =A6-TodayD -> 24 | M6: =IF(K6="Fully accepted","Done",IF(F6="N/A","N/A",IF(F6="Returned","Returned: resubmit",IF(K6="J698 only","Awaiting J698",IF(K6="COR only","Awaiting COR",IF(F6="Submitted","Awaiting COR + J698",IF(A6<TodayD,"OVERDUE",IF(A6-TodayD<=7,"Due within 7 days","")))))))) | P6: End with 6-month extension (FAR 52.217-8) | Q6: =EDATE(ClockStart,18)-1 -> 46873
A7: =Weekly!J5 -> 46339 | B7: =TEXT(A7,"ddd") -> Fri | C7: B04 | D7: Weekly Activity Report (WAR) – Wk 2 | E7: Weekly | F7: =IF(Weekly!J6="","",Weekly!J6) | G7: =IF(Weekly!J7="","",Weekly!J7) | H7: =IF(Weekly!J8="","",Weekly!J8) | I7: =IF(Weekly!J9="","",Weekly!J9) | J7: =IF(Weekly!J10="","",Weekly!J10) | K7: =IF(AND(H7<>"",J7<>""),"Fully accepted",IF(H7<>"","COR only",IF(J7<>"","J698 only",""))) | L7: =A7-TodayD -> 31 | M7: =IF(K7="Fully accepted","Done",IF(F7="N/A","N/A",IF(F7="Returned","Returned: resubmit",IF(K7="J698 only","Awaiting J698",IF(K7="COR only","Awaiting COR",IF(F7="Submitted","Awaiting COR + J698",IF(A7<TodayD,"OVERDUE",IF(A7-TodayD<=7,"Due within 7 days","")))))))) | P7: CPR meeting day of month (ASSUMED) | Q7: 15
A8: =Weekly!J12 -> 46339 | B8: =TEXT(A8,"ddd") -> Fri | C8: B34 | D8: Weekly Activity Report (WAR) – Wk 2 | E8: Weekly | F8: =IF(Weekly!J13="","",Weekly!J13) | G8: =IF(Weekly!J14="","",Weekly!J14) | H8: =IF(Weekly!J15="","",Weekly!J15) | I8: =IF(Weekly!J16="","",Weekly!J16) | J8: =IF(Weekly!J17="","",Weekly!J17) | K8: =IF(AND(H8<>"",J8<>""),"Fully accepted",IF(H8<>"","COR only",IF(J8<>"","J698 only",""))) | L8: =A8-TodayD -> 31 | M8: =IF(K8="Fully accepted","Done",IF(F8="N/A","N/A",IF(F8="Returned","Returned: resubmit",IF(K8="J698 only","Awaiting J698",IF(K8="COR only","Awaiting COR",IF(F8="Submitted","Awaiting COR + J698",IF(A8<TodayD,"OVERDUE",IF(A8-TodayD<=7,"Due within 7 days","")))))))) | P8: Gov inspection window (business days) | Q8: 5
A9: =Weekly!K5 -> 46346 | B9: =TEXT(A9,"ddd") -> Fri | C9: B04 | D9: Weekly Activity Report (WAR) – Wk 3 | E9: Weekly | F9: =IF(Weekly!K6="","",Weekly!K6) | G9: =IF(Weekly!K7="","",Weekly!K7) | H9: =IF(Weekly!K8="","",Weekly!K8) | I9: =IF(Weekly!K9="","",Weekly!K9) | J9: =IF(Weekly!K10="","",Weekly!K10) | K9: =IF(AND(H9<>"",J9<>""),"Fully accepted",IF(H9<>"","COR only",IF(J9<>"","J698 only",""))) | L9: =A9-TodayD -> 38 | M9: =IF(K9="Fully accepted","Done",IF(F9="N/A","N/A",IF(F9="Returned","Returned: resubmit",IF(K9="J698 only","Awaiting J698",IF(K9="COR only","Awaiting COR",IF(F9="Submitted","Awaiting COR + J698",IF(A9<TodayD,"OVERDUE",IF(A9-TodayD<=7,"Due within 7 days","")))))))) | P9: Resubmission window (business days) | Q9: 10
A10: =Weekly!K12 -> 46346 | B10: =TEXT(A10,"ddd") -> Fri | C10: B34 | D10: Weekly Activity Report (WAR) – Wk 3 | E10: Weekly | F10: =IF(Weekly!K13="","",Weekly!K13) | G10: =IF(Weekly!K14="","",Weekly!K14) | H10: =IF(Weekly!K15="","",Weekly!K15) | I10: =IF(Weekly!K16="","",Weekly!K16) | J10: =IF(Weekly!K17="","",Weekly!K17) | K10: =IF(AND(H10<>"",J10<>""),"Fully accepted",IF(H10<>"","COR only",IF(J10<>"","J698 only",""))) | L10: =A10-TodayD -> 38 | M10: =IF(K10="Fully accepted","Done",IF(F10="N/A","N/A",IF(F10="Returned","Returned: resubmit",IF(K10="J698 only","Awaiting J698",IF(K10="COR only","Awaiting COR",IF(F10="Submitted","Awaiting COR + J698",IF(A10<TodayD,"OVERDUE",IF(A10-TodayD<=7,"Due within 7 days","")))))))) | P10: Today | Q10: =TODAY() -> 46308
A11: =Weekly!L5 -> 46353 | B11: =TEXT(A11,"ddd") -> Fri | C11: B04 | D11: Weekly Activity Report (WAR) – Wk 4 | E11: Weekly | F11: =IF(Weekly!L6="","",Weekly!L6) | G11: =IF(Weekly!L7="","",Weekly!L7) | H11: =IF(Weekly!L8="","",Weekly!L8) | I11: =IF(Weekly!L9="","",Weekly!L9) | J11: =IF(Weekly!L10="","",Weekly!L10) | K11: =IF(AND(H11<>"",J11<>""),"Fully accepted",IF(H11<>"","COR only",IF(J11<>"","J698 only",""))) | L11: =A11-TodayD -> 45 | M11: =IF(K11="Fully accepted","Done",IF(F11="N/A","N/A",IF(F11="Returned","Returned: resubmit",IF(K11="J698 only","Awaiting J698",IF(K11="COR only","Awaiting COR",IF(F11="Submitted","Awaiting COR + J698",IF(A11<TodayD,"OVERDUE",IF(A11-TodayD<=7,"Due within 7 days",""))))))))
A12: =Weekly!L12 -> 46353 | B12: =TEXT(A12,"ddd") -> Fri | C12: B34 | D12: Weekly Activity Report (WAR) – Wk 4 | E12: Weekly | F12: =IF(Weekly!L13="","",Weekly!L13) | G12: =IF(Weekly!L14="","",Weekly!L14) | H12: =IF(Weekly!L15="","",Weekly!L15) | I12: =IF(Weekly!L16="","",Weekly!L16) | J12: =IF(Weekly!L17="","",Weekly!L17) | K12: =IF(AND(H12<>"",J12<>""),"Fully accepted",IF(H12<>"","COR only",IF(J12<>"","J698 only",""))) | L12: =A12-TodayD -> 45 | M12: =IF(K12="Fully accepted","Done",IF(F12="N/A","N/A",IF(F12="Returned","Returned: resubmit",IF(K12="J698 only","Awaiting J698",IF(K12="COR only","Awaiting COR",IF(F12="Submitted","Awaiting COR + J698",IF(A12<TodayD,"OVERDUE",IF(A12-TodayD<=7,"Due within 7 days","")))))))) | P12: PoP is "completed at TO award" in this PWS: set the real start in cell Q4.
A13: =Weekly!M5 -> 46360 | B13: =TEXT(A13,"ddd") -> Fri | C13: B04 | D13: Weekly Activity Report (WAR) – Wk 5 | E13: Weekly | F13: =IF(Weekly!M6="","",Weekly!M6) | G13: =IF(Weekly!M7="","",Weekly!M7) | H13: =IF(Weekly!M8="","",Weekly!M8) | I13: =IF(Weekly!M9="","",Weekly!M9) | J13: =IF(Weekly!M10="","",Weekly!M10) | K13: =IF(AND(H13<>"",J13<>""),"Fully accepted",IF(H13<>"","COR only",IF(J13<>"","J698 only",""))) | L13: =A13-TodayD -> 52 | M13: =IF(K13="Fully accepted","Done",IF(F13="N/A","N/A",IF(F13="Returned","Returned: resubmit",IF(K13="J698 only","Awaiting J698",IF(K13="COR only","Awaiting COR",IF(F13="Submitted","Awaiting COR + J698",IF(A13<TodayD,"OVERDUE",IF(A13-TodayD<=7,"Due within 7 days","")))))))) | P13: Inspection and resubmission windows are not stated in this PWS; 5 and 10 business days are placeholders.
A14: =Weekly!M12 -> 46360 | B14: =TEXT(A14,"ddd") -> Fri | C14: B34 | D14: Weekly Activity Report (WAR) – Wk 5 | E14: Weekly | F14: =IF(Weekly!M13="","",Weekly!M13) | G14: =IF(Weekly!M14="","",Weekly!M14) | H14: =IF(Weekly!M15="","",Weekly!M15) | I14: =IF(Weekly!M16="","",Weekly!M16) | J14: =IF(Weekly!M17="","",Weekly!M17) | K14: =IF(AND(H14<>"",J14<>""),"Fully accepted",IF(H14<>"","COR only",IF(J14<>"","J698 only",""))) | L14: =A14-TodayD -> 52 | M14: =IF(K14="Fully accepted","Done",IF(F14="N/A","N/A",IF(F14="Returned","Returned: resubmit",IF(K14="J698 only","Awaiting J698",IF(K14="COR only","Awaiting COR",IF(F14="Submitted","Awaiting COR + J698",IF(A14<TodayD,"OVERDUE",IF(A14-TodayD<=7,"Due within 7 days","")))))))) | P14: Holidays are not excluded from business-day math.
A15: =Monthly!I5 -> 46366 | B15: =TEXT(A15,"ddd") -> Thu | C15: B01 | D15: Monthly Progress Report (MPR) – Nov 2026 | E15: Monthly | F15: =IF(Monthly!I6="","",Monthly!I6) | G15: =IF(Monthly!I7="","",Monthly!I7) | H15: =IF(Monthly!I8="","",Monthly!I8) | I15: =IF(Monthly!I9="","",Monthly!I9) | J15: =IF(Monthly!I10="","",Monthly!I10) | K15: =IF(AND(H15<>"",J15<>""),"Fully accepted",IF(H15<>"","COR only",IF(J15<>"","J698 only",""))) | L15: =A15-TodayD -> 58 | M15: =IF(K15="Fully accepted","Done",IF(F15="N/A","N/A",IF(F15="Returned","Returned: resubmit",IF(K15="J698 only","Awaiting J698",IF(K15="COR only","Awaiting COR",IF(F15="Submitted","Awaiting COR + J698",IF(A15<TodayD,"OVERDUE",IF(A15-TodayD<=7,"Due within 7 days",""))))))))
A16: =Monthly!I12 -> 46366 | B16: =TEXT(A16,"ddd") -> Thu | C16: B02 | D16: 90-Day Action Plan – Nov 2026 | E16: Monthly | F16: =IF(Monthly!I13="","",Monthly!I13) | G16: =IF(Monthly!I14="","",Monthly!I14) | H16: =IF(Monthly!I15="","",Monthly!I15) | I16: =IF(Monthly!I16="","",Monthly!I16) | J16: =IF(Monthly!I17="","",Monthly!I17) | K16: =IF(AND(H16<>"",J16<>""),"Fully accepted",IF(H16<>"","COR only",IF(J16<>"","J698 only",""))) | L16: =A16-TodayD -> 58 | M16: =IF(K16="Fully accepted","Done",IF(F16="N/A","N/A",IF(F16="Returned","Returned: resubmit",IF(K16="J698 only","Awaiting J698",IF(K16="COR only","Awaiting COR",IF(F16="Submitted","Awaiting COR + J698",IF(A16<TodayD,"OVERDUE",IF(A16-TodayD<=7,"Due within 7 days",""))))))))
A17: =Monthly!I26 -> 46366 | B17: =TEXT(A17,"ddd") -> Thu | C17: B16 | D17: Technical Library Documentation Report – Nov 2026 | E17: Monthly | F17: =IF(Monthly!I27="","",Monthly!I27) | G17: =IF(Monthly!I28="","",Monthly!I28) | H17: =IF(Monthly!I29="","",Monthly!I29) | I17: =IF(Monthly!I30="","",Monthly!I30) | J17: =IF(Monthly!I31="","",Monthly!I31) | K17: =IF(AND(H17<>"",J17<>""),"Fully accepted",IF(H17<>"","COR only",IF(J17<>"","J698 only",""))) | L17: =A17-TodayD -> 58 | M17: =IF(K17="Fully accepted","Done",IF(F17="N/A","N/A",IF(F17="Returned","Returned: resubmit",IF(K17="J698 only","Awaiting J698",IF(K17="COR only","Awaiting COR",IF(F17="Submitted","Awaiting COR + J698",IF(A17<TodayD,"OVERDUE",IF(A17-TodayD<=7,"Due within 7 days",""))))))))
A18: =Monthly!I33 -> 46366 | B18: =TEXT(A18,"ddd") -> Thu | C18: B26 | D18: Authorization and Accreditation (A&A) Packages – Nov 2026 | E18: Monthly | F18: =IF(Monthly!I34="","",Monthly!I34) | G18: =IF(Monthly!I35="","",Monthly!I35) | H18: =IF(Monthly!I36="","",Monthly!I36) | I18: =IF(Monthly!I37="","",Monthly!I37) | J18: =IF(Monthly!I38="","",Monthly!I38) | K18: =IF(AND(H18<>"",J18<>""),"Fully accepted",IF(H18<>"","COR only",IF(J18<>"","J698 only",""))) | L18: =A18-TodayD -> 58 | M18: =IF(K18="Fully accepted","Done",IF(F18="N/A","N/A",IF(F18="Returned","Returned: resubmit",IF(K18="J698 only","Awaiting J698",IF(K18="COR only","Awaiting COR",IF(F18="Submitted","Awaiting COR + J698",IF(A18<TodayD,"OVERDUE",IF(A18-TodayD<=7,"Due within 7 days",""))))))))
A19: =Monthly!I40 -> 46366 | B19: =TEXT(A19,"ddd") -> Thu | C19: B29 | D19: Network Installation / De-installation Report – Nov 2026 | E19: Monthly | F19: =IF(Monthly!I41="","",Monthly!I41) | G19: =IF(Monthly!I42="","",Monthly!I42) | H19: =IF(Monthly!I43="","",Monthly!I43) | I19: =IF(Monthly!I44="","",Monthly!I44) | J19: =IF(Monthly!I45="","",Monthly!I45) | K19: =IF(AND(H19<>"",J19<>""),"Fully accepted",IF(H19<>"","COR only",IF(J19<>"","J698 only",""))) | L19: =A19-TodayD -> 58 | M19: =IF(K19="Fully accepted","Done",IF(F19="N/A","N/A",IF(F19="Returned","Returned: resubmit",IF(K19="J698 only","Awaiting J698",IF(K19="COR only","Awaiting COR",IF(F19="Submitted","Awaiting COR + J698",IF(A19<TodayD,"OVERDUE",IF(A19-TodayD<=7,"Due within 7 days",""))))))))
A20: =Monthly!I47 -> 46366 | B20: =TEXT(A20,"ddd") -> Thu | C20: B30 | D20: IAVA Compliance Report – Nov 2026 | E20: Monthly | F20: =IF(Monthly!I48="","",Monthly!I48) | G20: =IF(Monthly!I49="","",Monthly!I49) | H20: =IF(Monthly!I50="","",Monthly!I50) | I20: =IF(Monthly!I51="","",Monthly!I51) | J20: =IF(Monthly!I52="","",Monthly!I52) | K20: =IF(AND(H20<>"",J20<>""),"Fully accepted",IF(H20<>"","COR only",IF(J20<>"","J698 only",""))) | L20: =A20-TodayD -> 58 | M20: =IF(K20="Fully accepted","Done",IF(F20="N/A","N/A",IF(F20="Returned","Returned: resubmit",IF(K20="J698 only","Awaiting J698",IF(K20="COR only","Awaiting COR",IF(F20="Submitted","Awaiting COR + J698",IF(A20<TodayD,"OVERDUE",IF(A20-TodayD<=7,"Due within 7 days",""))))))))
A21: =Monthly!I54 -> 46366 | B21: =TEXT(A21,"ddd") -> Thu | C21: B31 | D21: COMSEC Management Procedures Report – Nov 2026 | E21: Monthly | F21: =IF(Monthly!I55="","",Monthly!I55) | G21: =IF(Monthly!I56="","",Monthly!I56) | H21: =IF(Monthly!I57="","",Monthly!I57) | I21: =IF(Monthly!I58="","",Monthly!I58) | J21: =IF(Monthly!I59="","",Monthly!I59) | K21: =IF(AND(H21<>"",J21<>""),"Fully accepted",IF(H21<>"","COR only",IF(J21<>"","J698 only",""))) | L21: =A21-TodayD -> 58 | M21: =IF(K21="Fully accepted","Done",IF(F21="N/A","N/A",IF(F21="Returned","Returned: resubmit",IF(K21="J698 only","Awaiting J698",IF(K21="COR only","Awaiting COR",IF(F21="Submitted","Awaiting COR + J698",IF(A21<TodayD,"OVERDUE",IF(A21-TodayD<=7,"Due within 7 days",""))))))))
A22: =Monthly!I61 -> 46366 | B22: =TEXT(A22,"ddd") -> Thu | C22: B32 | D22: Technical Documentation & Report(s) – Nov 2026 | E22: Monthly | F22: =IF(Monthly!I62="","",Monthly!I62) | G22: =IF(Monthly!I63="","",Monthly!I63) | H22: =IF(Monthly!I64="","",Monthly!I64) | I22: =IF(Monthly!I65="","",Monthly!I65) | J22: =IF(Monthly!I66="","",Monthly!I66) | K22: =IF(AND(H22<>"",J22<>""),"Fully accepted",IF(H22<>"","COR only",IF(J22<>"","J698 only",""))) | L22: =A22-TodayD -> 58 | M22: =IF(K22="Fully accepted","Done",IF(F22="N/A","N/A",IF(F22="Returned","Returned: resubmit",IF(K22="J698 only","Awaiting J698",IF(K22="COR only","Awaiting COR",IF(F22="Submitted","Awaiting COR + J698",IF(A22<TodayD,"OVERDUE",IF(A22-TodayD<=7,"Due within 7 days",""))))))))
A23: =Monthly!I68 -> 46366 | B23: =TEXT(A23,"ddd") -> Thu | C23: B35 | D23: Non-Disclosure Agreement Report – Nov 2026 | E23: Monthly | F23: =IF(Monthly!I69="","",Monthly!I69) | G23: =IF(Monthly!I70="","",Monthly!I70) | H23: =IF(Monthly!I71="","",Monthly!I71) | I23: =IF(Monthly!I72="","",Monthly!I72) | J23: =IF(Monthly!I73="","",Monthly!I73) | K23: =IF(AND(H23<>"",J23<>""),"Fully accepted",IF(H23<>"","COR only",IF(J23<>"","J698 only",""))) | L23: =A23-TodayD -> 58 | M23: =IF(K23="Fully accepted","Done",IF(F23="N/A","N/A",IF(F23="Returned","Returned: resubmit",IF(K23="J698 only","Awaiting J698",IF(K23="COR only","Awaiting COR",IF(F23="Submitted","Awaiting COR + J698",IF(A23<TodayD,"OVERDUE",IF(A23-TodayD<=7,"Due within 7 days",""))))))))
A24: =Weekly!N5 -> 46367 | B24: =TEXT(A24,"ddd") -> Fri | C24: B04 | D24: Weekly Activity Report (WAR) – Wk 6 | E24: Weekly | F24: =IF(Weekly!N6="","",Weekly!N6) | G24: =IF(Weekly!N7="","",Weekly!N7) | H24: =IF(Weekly!N8="","",Weekly!N8) | I24: =IF(Weekly!N9="","",Weekly!N9) | J24: =IF(Weekly!N10="","",Weekly!N10) | K24: =IF(AND(H24<>"",J24<>""),"Fully accepted",IF(H24<>"","COR only",IF(J24<>"","J698 only",""))) | L24: =A24-TodayD -> 59 | M24: =IF(K24="Fully accepted","Done",IF(F24="N/A","N/A",IF(F24="Returned","Returned: resubmit",IF(K24="J698 only","Awaiting J698",IF(K24="COR only","Awaiting COR",IF(F24="Submitted","Awaiting COR + J698",IF(A24<TodayD,"OVERDUE",IF(A24-TodayD<=7,"Due within 7 days",""))))))))
A25: =Weekly!N12 -> 46367 | B25: =TEXT(A25,"ddd") -> Fri | C25: B34 | D25: Weekly Activity Report (WAR) – Wk 6 | E25: Weekly | F25: =IF(Weekly!N13="","",Weekly!N13) | G25: =IF(Weekly!N14="","",Weekly!N14) | H25: =IF(Weekly!N15="","",Weekly!N15) | I25: =IF(Weekly!N16="","",Weekly!N16) | J25: =IF(Weekly!N17="","",Weekly!N17) | K25: =IF(AND(H25<>"",J25<>""),"Fully accepted",IF(H25<>"","COR only",IF(J25<>"","J698 only",""))) | L25: =A25-TodayD -> 59 | M25: =IF(K25="Fully accepted","Done",IF(F25="N/A","N/A",IF(F25="Returned","Returned: resubmit",IF(K25="J698 only","Awaiting J698",IF(K25="COR only","Awaiting COR",IF(F25="Submitted","Awaiting COR + J698",IF(A25<TodayD,"OVERDUE",IF(A25-TodayD<=7,"Due within 7 days",""))))))))
A26: =Weekly!O5 -> 46374 | B26: =TEXT(A26,"ddd") -> Fri | C26: B04 | D26: Weekly Activity Report (WAR) – Wk 7 | E26: Weekly | F26: =IF(Weekly!O6="","",Weekly!O6) | G26: =IF(Weekly!O7="","",Weekly!O7) | H26: =IF(Weekly!O8="","",Weekly!O8) | I26: =IF(Weekly!O9="","",Weekly!O9) | J26: =IF(Weekly!O10="","",Weekly!O10) | K26: =IF(AND(H26<>"",J26<>""),"Fully accepted",IF(H26<>"","COR only",IF(J26<>"","J698 only",""))) | L26: =A26-TodayD -> 66 | M26: =IF(K26="Fully accepted","Done",IF(F26="N/A","N/A",IF(F26="Returned","Returned: resubmit",IF(K26="J698 only","Awaiting J698",IF(K26="COR only","Awaiting COR",IF(F26="Submitted","Awaiting COR + J698",IF(A26<TodayD,"OVERDUE",IF(A26-TodayD<=7,"Due within 7 days",""))))))))
A27: =Weekly!O12 -> 46374 | B27: =TEXT(A27,"ddd") -> Fri | C27: B34 | D27: Weekly Activity Report (WAR) – Wk 7 | E27: Weekly | F27: =IF(Weekly!O13="","",Weekly!O13) | G27: =IF(Weekly!O14="","",Weekly!O14) | H27: =IF(Weekly!O15="","",Weekly!O15) | I27: =IF(Weekly!O16="","",Weekly!O16) | J27: =IF(Weekly!O17="","",Weekly!O17) | K27: =IF(AND(H27<>"",J27<>""),"Fully accepted",IF(H27<>"","COR only",IF(J27<>"","J698 only",""))) | L27: =A27-TodayD -> 66 | M27: =IF(K27="Fully accepted","Done",IF(F27="N/A","N/A",IF(F27="Returned","Returned: resubmit",IF(K27="J698 only","Awaiting J698",IF(K27="COR only","Awaiting COR",IF(F27="Submitted","Awaiting COR + J698",IF(A27<TodayD,"OVERDUE",IF(A27-TodayD<=7,"Due within 7 days",""))))))))
A28: =Monthly!I19 -> 46378 | B28: =TEXT(A28,"ddd") -> Tue | C28: B03 | D28: Contractor Performance Report (CPR) – Nov 2026 | E28: Monthly | F28: =IF(Monthly!I20="","",Monthly!I20) | G28: =IF(Monthly!I21="","",Monthly!I21) | H28: =IF(Monthly!I22="","",Monthly!I22) | I28: =IF(Monthly!I23="","",Monthly!I23) | J28: =IF(Monthly!I24="","",Monthly!I24) | K28: =IF(AND(H28<>"",J28<>""),"Fully accepted",IF(H28<>"","COR only",IF(J28<>"","J698 only",""))) | L28: =A28-TodayD -> 70 | M28: =IF(K28="Fully accepted","Done",IF(F28="N/A","N/A",IF(F28="Returned","Returned: resubmit",IF(K28="J698 only","Awaiting J698",IF(K28="COR only","Awaiting COR",IF(F28="Submitted","Awaiting COR + J698",IF(A28<TodayD,"OVERDUE",IF(A28-TodayD<=7,"Due within 7 days",""))))))))
A29: =Weekly!P5 -> 46381 | B29: =TEXT(A29,"ddd") -> Fri | C29: B04 | D29: Weekly Activity Report (WAR) – Wk 8 | E29: Weekly | F29: =IF(Weekly!P6="","",Weekly!P6) | G29: =IF(Weekly!P7="","",Weekly!P7) | H29: =IF(Weekly!P8="","",Weekly!P8) | I29: =IF(Weekly!P9="","",Weekly!P9) | J29: =IF(Weekly!P10="","",Weekly!P10) | K29: =IF(AND(H29<>"",J29<>""),"Fully accepted",IF(H29<>"","COR only",IF(J29<>"","J698 only",""))) | L29: =A29-TodayD -> 73 | M29: =IF(K29="Fully accepted","Done",IF(F29="N/A","N/A",IF(F29="Returned","Returned: resubmit",IF(K29="J698 only","Awaiting J698",IF(K29="COR only","Awaiting COR",IF(F29="Submitted","Awaiting COR + J698",IF(A29<TodayD,"OVERDUE",IF(A29-TodayD<=7,"Due within 7 days",""))))))))
A30: =Weekly!P12 -> 46381 | B30: =TEXT(A30,"ddd") -> Fri | C30: B34 | D30: Weekly Activity Report (WAR) – Wk 8 | E30: Weekly | F30: =IF(Weekly!P13="","",Weekly!P13) | G30: =IF(Weekly!P14="","",Weekly!P14) | H30: =IF(Weekly!P15="","",Weekly!P15) | I30: =IF(Weekly!P16="","",Weekly!P16) | J30: =IF(Weekly!P17="","",Weekly!P17) | K30: =IF(AND(H30<>"",J30<>""),"Fully accepted",IF(H30<>"","COR only",IF(J30<>"","J698 only",""))) | L30: =A30-TodayD -> 73 | M30: =IF(K30="Fully accepted","Done",IF(F30="N/A","N/A",IF(F30="Returned","Returned: resubmit",IF(K30="J698 only","Awaiting J698",IF(K30="COR only","Awaiting COR",IF(F30="Submitted","Awaiting COR + J698",IF(A30<TodayD,"OVERDUE",IF(A30-TodayD<=7,"Due within 7 days",""))))))))
A31: =Weekly!Q5 -> 46388 | B31: =TEXT(A31,"ddd") -> Fri | C31: B04 | D31: Weekly Activity Report (WAR) – Wk 9 | E31: Weekly | F31: =IF(Weekly!Q6="","",Weekly!Q6) | G31: =IF(Weekly!Q7="","",Weekly!Q7) | H31: =IF(Weekly!Q8="","",Weekly!Q8) | I31: =IF(Weekly!Q9="","",Weekly!Q9) | J31: =IF(Weekly!Q10="","",Weekly!Q10) | K31: =IF(AND(H31<>"",J31<>""),"Fully accepted",IF(H31<>"","COR only",IF(J31<>"","J698 only",""))) | L31: =A31-TodayD -> 80 | M31: =IF(K31="Fully accepted","Done",IF(F31="N/A","N/A",IF(F31="Returned","Returned: resubmit",IF(K31="J698 only","Awaiting J698",IF(K31="COR only","Awaiting COR",IF(F31="Submitted","Awaiting COR + J698",IF(A31<TodayD,"OVERDUE",IF(A31-TodayD<=7,"Due within 7 days",""))))))))
A32: =Weekly!Q12 -> 46388 | B32: =TEXT(A32,"ddd") -> Fri | C32: B34 | D32: Weekly Activity Report (WAR) – Wk 9 | E32: Weekly | F32: =IF(Weekly!Q13="","",Weekly!Q13) | G32: =IF(Weekly!Q14="","",Weekly!Q14) | H32: =IF(Weekly!Q15="","",Weekly!Q15) | I32: =IF(Weekly!Q16="","",Weekly!Q16) | J32: =IF(Weekly!Q17="","",Weekly!Q17) | K32: =IF(AND(H32<>"",J32<>""),"Fully accepted",IF(H32<>"","COR only",IF(J32<>"","J698 only",""))) | L32: =A32-TodayD -> 80 | M32: =IF(K32="Fully accepted","Done",IF(F32="N/A","N/A",IF(F32="Returned","Returned: resubmit",IF(K32="J698 only","Awaiting J698",IF(K32="COR only","Awaiting COR",IF(F32="Submitted","Awaiting COR + J698",IF(A32<TodayD,"OVERDUE",IF(A32-TodayD<=7,"Due within 7 days",""))))))))
A33: =Weekly!R5 -> 46395 | B33: =TEXT(A33,"ddd") -> Fri | C33: B04 | D33: Weekly Activity Report (WAR) – Wk 10 | E33: Weekly | F33: =IF(Weekly!R6="","",Weekly!R6) | G33: =IF(Weekly!R7="","",Weekly!R7) | H33: =IF(Weekly!R8="","",Weekly!R8) | I33: =IF(Weekly!R9="","",Weekly!R9) | J33: =IF(Weekly!R10="","",Weekly!R10) | K33: =IF(AND(H33<>"",J33<>""),"Fully accepted",IF(H33<>"","COR only",IF(J33<>"","J698 only",""))) | L33: =A33-TodayD -> 87 | M33: =IF(K33="Fully accepted","Done",IF(F33="N/A","N/A",IF(F33="Returned","Returned: resubmit",IF(K33="J698 only","Awaiting J698",IF(K33="COR only","Awaiting COR",IF(F33="Submitted","Awaiting COR + J698",IF(A33<TodayD,"OVERDUE",IF(A33-TodayD<=7,"Due within 7 days",""))))))))
A34: =Weekly!R12 -> 46395 | B34: =TEXT(A34,"ddd") -> Fri | C34: B34 | D34: Weekly Activity Report (WAR) – Wk 10 | E34: Weekly | F34: =IF(Weekly!R13="","",Weekly!R13) | G34: =IF(Weekly!R14="","",Weekly!R14) | H34: =IF(Weekly!R15="","",Weekly!R15) | I34: =IF(Weekly!R16="","",Weekly!R16) | J34: =IF(Weekly!R17="","",Weekly!R17) | K34: =IF(AND(H34<>"",J34<>""),"Fully accepted",IF(H34<>"","COR only",IF(J34<>"","J698 only",""))) | L34: =A34-TodayD -> 87 | M34: =IF(K34="Fully accepted","Done",IF(F34="N/A","N/A",IF(F34="Returned","Returned: resubmit",IF(K34="J698 only","Awaiting J698",IF(K34="COR only","Awaiting COR",IF(F34="Submitted","Awaiting COR + J698",IF(A34<TodayD,"OVERDUE",IF(A34-TodayD<=7,"Due within 7 days",""))))))))
A35: =Monthly!J5 -> 46398 | B35: =TEXT(A35,"ddd") -> Mon | C35: B01 | D35: Monthly Progress Report (MPR) – Dec 2026 | E35: Monthly | F35: =IF(Monthly!J6="","",Monthly!J6) | G35: =IF(Monthly!J7="","",Monthly!J7) | H35: =IF(Monthly!J8="","",Monthly!J8) | I35: =IF(Monthly!J9="","",Monthly!J9) | J35: =IF(Monthly!J10="","",Monthly!J10) | K35: =IF(AND(H35<>"",J35<>""),"Fully accepted",IF(H35<>"","COR only",IF(J35<>"","J698 only",""))) | L35: =A35-TodayD -> 90 | M35: =IF(K35="Fully accepted","Done",IF(F35="N/A","N/A",IF(F35="Returned","Returned: resubmit",IF(K35="J698 only","Awaiting J698",IF(K35="COR only","Awaiting COR",IF(F35="Submitted","Awaiting COR + J698",IF(A35<TodayD,"OVERDUE",IF(A35-TodayD<=7,"Due within 7 days",""))))))))
A36: =Monthly!J26 -> 46398 | B36: =TEXT(A36,"ddd") -> Mon | C36: B16 | D36: Technical Library Documentation Report – Dec 2026 | E36: Monthly | F36: =IF(Monthly!J27="","",Monthly!J27) | G36: =IF(Monthly!J28="","",Monthly!J28) | H36: =IF(Monthly!J29="","",Monthly!J29) | I36: =IF(Monthly!J30="","",Monthly!J30) | J36: =IF(Monthly!J31="","",Monthly!J31) | K36: =IF(AND(H36<>"",J36<>""),"Fully accepted",IF(H36<>"","COR only",IF(J36<>"","J698 only",""))) | L36: =A36-TodayD -> 90 | M36: =IF(K36="Fully accepted","Done",IF(F36="N/A","N/A",IF(F36="Returned","Returned: resubmit",IF(K36="J698 only","Awaiting J698",IF(K36="COR only","Awaiting COR",IF(F36="Submitted","Awaiting COR + J698",IF(A36<TodayD,"OVERDUE",IF(A36-TodayD<=7,"Due within 7 days",""))))))))
A37: =Monthly!J33 -> 46398 | B37: =TEXT(A37,"ddd") -> Mon | C37: B26 | D37: Authorization and Accreditation (A&A) Packages – Dec 2026 | E37: Monthly | F37: =IF(Monthly!J34="","",Monthly!J34) | G37: =IF(Monthly!J35="","",Monthly!J35) | H37: =IF(Monthly!J36="","",Monthly!J36) | I37: =IF(Monthly!J37="","",Monthly!J37) | J37: =IF(Monthly!J38="","",Monthly!J38) | K37: =IF(AND(H37<>"",J37<>""),"Fully accepted",IF(H37<>"","COR only",IF(J37<>"","J698 only",""))) | L37: =A37-TodayD -> 90 | M37: =IF(K37="Fully accepted","Done",IF(F37="N/A","N/A",IF(F37="Returned","Returned: resubmit",IF(K37="J698 only","Awaiting J698",IF(K37="COR only","Awaiting COR",IF(F37="Submitted","Awaiting COR + J698",IF(A37<TodayD,"OVERDUE",IF(A37-TodayD<=7,"Due within 7 days",""))))))))
A38: =Monthly!J40 -> 46398 | B38: =TEXT(A38,"ddd") -> Mon | C38: B29 | D38: Network Installation / De-installation Report – Dec 2026 | E38: Monthly | F38: =IF(Monthly!J41="","",Monthly!J41) | G38: =IF(Monthly!J42="","",Monthly!J42) | H38: =IF(Monthly!J43="","",Monthly!J43) | I38: =IF(Monthly!J44="","",Monthly!J44) | J38: =IF(Monthly!J45="","",Monthly!J45) | K38: =IF(AND(H38<>"",J38<>""),"Fully accepted",IF(H38<>"","COR only",IF(J38<>"","J698 only",""))) | L38: =A38-TodayD -> 90 | M38: =IF(K38="Fully accepted","Done",IF(F38="N/A","N/A",IF(F38="Returned","Returned: resubmit",IF(K38="J698 only","Awaiting J698",IF(K38="COR only","Awaiting COR",IF(F38="Submitted","Awaiting COR + J698",IF(A38<TodayD,"OVERDUE",IF(A38-TodayD<=7,"Due within 7 days",""))))))))
