Workbook

Sheet Tracker
A1: ITS2 (IT Service Support) – Deliverable Tracker
A2: PWS as of 29 Sep 2023 | USINDOPACOM J6 | Tracking No. 712367735 | Follow-on to CS2 (GS00Q17GWD2133 / HC1019-19-F-0015) | Transition-in Jan 2024; Base Feb 2024 – Jan 2025; Option Years 1–4 to Jan 2029
A3: Government POCs | C3: Primary COR and Alternate COR are blank in the PWS. Acceptors below are carried over from the Thunderdome tracker – edit the lists on the Tracker tab.
A5: At a glance | C5: Overdue | D5: Due within 7 days | E5: Awaiting COR / J698 | F5: Fully accepted | G5: Returned: resubmit | H5: PWS paragraphs with no deliverable
C6: =COUNTIF('Daily Agenda'!$M$5:$M$434,"OVERDUE") -> 24 | D6: =COUNTIF('Daily Agenda'!$M$5:$M$434,"Due within 7 days") -> 8 | E6: =COUNTIF('Daily Agenda'!$M$5:$M$434,"Awaiting*") -> 0 | F6: =COUNTIF('Daily Agenda'!$M$5:$M$434,"Done") -> 0 | G6: =COUNTIF('Daily Agenda'!$M$5:$M$434,"Returned: resubmit") -> 0 | H6: =COUNTIF($I$9:$M$114,"None named*") -> 0
AB7: Lists (dropdown sources). Names you type into an Accepted By cell do not have to be on a list.
A8: Month | B8: Sub Task Number | C8: Paragraph / Section | D8: Frequency | E8: Category | F8: Primary POC | G8: Secondary POC | H8: Format of Deliverable | I8: Deliverable 1 | J8: Deliverable 2 | K8: Deliverable 3 | L8: Deliverable 4 | M8: Deliverable 5 | N8: Status Flow 1 | O8: Status Flow 2 | P8: Status Flow 3 | Q8: COR Accepted By | R8: COR Date Accepted | S8: J698 Accepted By | T8: J698 Date Accepted | AB8: Category | AC8: Status Flow 1 | AD8: Status Flow 2 | AE8: Status Flow 3 | AF8: Frequency | AG8: Month | AH8: COR Acceptors | AI8: J698 Acceptors
A9: Oct | B9: 6.1.1 | C9: Enterprise Architecture Support | D9: Mixed (see due row) | E9: Program Mgmt | F9: Christine Y. Shigeta | G9: Brian Abrigo | H9: Distribute to TA | I9: 6.1.1-01 Architecture Recommendations | J9: 6.1.1-02 Architecture Implementation Plans | K9: 6.1.1-03 MSR | N9: Not Received | O9: Not Reviewed | AB9: Cybersecurity | AC9: Received | AD9: Reviewed | AE9: Accepted | AF9: Weekly | AG9: Jan | AH9: Christine Y. Shigeta | AI9: J698
H10: Due / Frequency (per document) | I10: Due: NLT 5 business days from assignment Freq: As Required | J10: Due: NLT 15 business days from assignment Freq: As Required | K10: Due: NLT 5th business day of the succeeding month Freq: Monthly | AB10: Engineering | AC10: Not Received | AD10: Not Reviewed | AE10: Returned | AF10: Monthly | AG10: Feb | AH10: Brian Abrigo
A11: Oct | B11: 6.1.2 | C11: Project Management Support | D11: Not required (suspended) | E11: Program Mgmt | F11: Christine Y. Shigeta | G11: Brian Abrigo | H11: Distribute to TA | I11: 6.1.2-01 Project POAM | J11: 6.1.2-02 Project Risk Plan | K11: 6.1.2-03 Decision Brief {POAM Deviation} | L11: 6.1.2-04 MSR | AB11: Operations | AD11: Demonstrated | AE11: Returned, but Fixed | AF11: Quarterly | AG11: Mar
H12: Due / Frequency (per document) | I12: Due: Initial: NLT 3 weeks of project assignment Updates: NLT the last duty day of the week Freq: As Required Flag: Subtask not required effective 1 Jun 2022, until further notice (PWS Section 11). | J12: Due: Initial: NLT 3 weeks of project assignment Maintenance: NLT 3 weeks of identified change Freq: As Required Flag: Subtask not required effective 1 Jun 2022, until further notice (PWS Section 11). | K12: Due: NLT 3 weeks of identified requirement Freq: As Required Flag: Subtask not required effective 1 Jun 2022, until further notice (PWS Section 11). | L12: Due: NLT 5th business day of the succeeding month Freq: Monthly Flag: Subtask not required effective 1 Jun 2022, until further notice (PWS Section 11). | AB12: Program Mgmt | AD12: Not Demonstrated | AF12: Annual | AG12: Apr
A13: Oct | B13: 6.1.3 | C13: Business Process Analyst Support | D13: Mixed (see due row) | E13: Program Mgmt | F13: Christine Y. Shigeta | G13: Brian Abrigo | H13: Distribute to TA | I13: 6.1.3-01 Story Board Recommendations and Plans | J13: 6.1.3-02 Story Board Implementations | K13: 6.1.3-03 MSR | N13: Not Received | O13: Not Reviewed | AF13: Daily (standing) | AG13: May
H14: Due / Frequency (per document) | I14: Due: Initial: NLT 3 weeks of assignment Maintenance: NLT 3 weeks of identified change Freq: As Required | J14: Due: Initial: NLT 3 weeks of assignment Maintenance: NLT 3 weeks of identified change Freq: As Required | K14: Due: NLT 5th business day of the succeeding month Freq: Monthly | AF14: One-Time | AG14: Jun
A15: Oct | B15: 6.2.1 | C15: Audio Visual Systems Engineering Support | D15: Mixed (see due row) | E15: Engineering | F15: Christine Y. Shigeta | G15: Brian Abrigo | H15: Distribute to TA | I15: 6.2.1-01 AV Recommendations | J15: 6.2.1-02 AV Documentation | K15: 6.2.1-03 AV Audits | L15: 6.2.1-04 AV POAM | M15: 6.2.1-05 MSR | N15: Not Received | O15: Not Reviewed | AF15: One-Time + Updates | AG15: Jul
H16: Due / Frequency (per document) | I16: Due: NLT 5th business day of the 1st month of the quarter Freq: Quarterly | J16: Due: NLT 5 business days after the activity completion Freq: As Required | K16: Due: NLT 5th business day of the 1st month of the quarter Freq: Quarterly | L16: Due: NLT 3 weeks of project assignment Freq: As Required | M16: Due: NLT 5th business day of the succeeding month Freq: Monthly | AF16: As Needed | AG16: Aug
A17: Oct | B17: 6.2.2 | C17: Video Teleconferencing (VTC) Scheduling Support | D17: Mixed (see due row) | E17: Engineering | F17: Christine Y. Shigeta | G17: Brian Abrigo | H17: Distribute to TA | I17: 6.2.2-01 Technology Evaluation & Recommendations | J17: 6.2.2-02 Standard Operating Procedures (SOP) & Training | K17: 6.2.2-03 VTC Scheduling & Operations | L17: 6.2.2-04 MSR | N17: Not Received | O17: Not Reviewed | AF17: Not required (suspended) | AG17: Sep
H18: Due / Frequency (per document) | I18: Due: NLT 15 days from assignment Freq: As Required | J18: Due: NLT 15 days from assignment Freq: As Required | K18: Due: Short Notice / Emergent: NLT 1 hour of notification Standard: NLT 1 day of notification Freq: As Required | L18: Due: NLT 5th business day of the succeeding month Freq: Monthly | AF18: Mixed (see due row) | AG18: Oct
A19: Oct | B19: 6.2.3 | C19: Video Teleconferencing (VTC) Network Engineering Support | D19: Mixed (see due row) | E19: Engineering | F19: Christine Y. Shigeta | G19: Brian Abrigo | H19: Distribute to TA | I19: 6.2.3-01 VTC Recommendations | J19: 6.2.3-02 MSR | N19: Not Received | O19: Not Reviewed | AF19: None named | AG19: Nov
H20: Due / Frequency (per document) | I20: Due: NLT 5th business day of the 1st month of the quarter Freq: Quarterly | J20: Due: NLT 5th business day of the succeeding month Freq: Monthly | AG20: Dec
A21: Oct | B21: 6.2.4 | C21: Senior Cisco Networking Engineering Support (1 of 2) | D21: Mixed (see due row) | E21: Engineering | F21: Christine Y. Shigeta | G21: Brian Abrigo | H21: Distribute to TA | I21: 6.2.4-01 Network Engineering Design & Implementation | J21: 6.2.4-02 Network Engineering Troubleshooting and Operations | K21: 6.2.4-03 Network ASIs | L21: 6.2.4-04 STIG Implementation & Reporting | M21: 6.2.4-05 Security Scans | N21: Not Received | O21: Not Reviewed
H22: Due / Frequency (per document) | I22: Due: NLT 15 business days after assignment of task Freq: As Required | J22: Due: On-going Freq: Daily | K22: Due: NLT 5 business days after assignment Freq: As Required | L22: Due: Monthly: NLT 5th business day of the succeeding month Quarterly: NLT 5th business day of the 1st month of the quarter Freq: Monthly & Quarterly Flag: Also reported quarterly (5th business day of the quarter's first month). | M22: Due: a) Documentation: NLT 1 business days after issue identification b) Resolution NLT 5 business days after issue identification Freq: Daily
A23: Oct | B23: 6.2.4 | C23: Senior Cisco Networking Engineering Support (2 of 2) | D23: Mixed (see due row) | E23: Engineering | F23: Christine Y. Shigeta | G23: Brian Abrigo | H23: Distribute to TA | I23: 6.2.4-06 Network Cabling | J23: 6.2.4-07 Architecture & Rack Diagrams | K23: 6.2.4-08 Standard Operating Procedures (SOP) | L23: 6.2.4-09 MSR | N23: Not Received | O23: Not Reviewed
H24: Due / Frequency (per document) | I24: Due: Maintenance complete NLT 5 business days assigned Freq: As Required | J24: Due: NLT 15 business days after assignment of task Freq: As Required | K24: Due: NLT 15 business days after assignment of task Freq: As Required | L24: Due: NLT 5th business day of the succeeding month Freq: Monthly
A25: Oct | B25: 6.2.5 | C25: Cisco Network Engineering Support (1 of 2) | D25: Mixed (see due row) | E25: Engineering | F25: Christine Y. Shigeta | G25: Brian Abrigo | H25: Distribute to TA | I25: 6.2.5-01 Network Engineering Design & Implementation | J25: 6.2.5-02 Network Engineering Troubleshooting and Operations | K25: 6.2.5-03 Network ASIs | L25: 6.2.5-04 STIG Implementation & Reporting | M25: 6.2.5-05 Security Scans | N25: Not Received | O25: Not Reviewed
H26: Due / Frequency (per document) | I26: Due: NLT 15 business days after assignment of task Freq: As Required | J26: Due: On-going Freq: Daily | K26: Due: NLT 5 business days after assignment Freq: As Required | L26: Due: Monthly: NLT 5th business day of the succeeding month Quarterly: NLT 5th business day of the 1st month of the quarter Freq: Monthly & Quarterly Flag: Also reported quarterly (5th business day of the quarter's first month). | M26: Due: a) Documentation: NLT 1 business days after issue identification b) Resolution NLT 5 business days after issue identification Freq: Daily
A27: Oct | B27: 6.2.5 | C27: Cisco Network Engineering Support (2 of 2) | D27: Mixed (see due row) | E27: Engineering | F27: Christine Y. Shigeta | G27: Brian Abrigo | H27: Distribute to TA | I27: 6.2.5-06 Network Cabling | J27: 6.2.5-07 Architecture & Rack Diagrams | K27: 6.2.5-08 Standard Operating Procedures (SOP) | L27: 6.2.5-09 MSR | N27: Not Received | O27: Not Reviewed
H28: Due / Frequency (per document) | I28: Due: Maintenance complete NLT 5 business days assigned Freq: As Required | J28: Due: NLT 15 business days after assignment of task Freq: As Required | K28: Due: NLT 15 business days after assignment of task Freq: As Required | L28: Due: NLT 5th business day of the succeeding month Freq: Monthly
A29: Oct | B29: 6.3.1 | C29: Linux System Administration Support (1 of 2) | D29: Daily (standing) | E29: Operations | F29: Christine Y. Shigeta | G29: Brian Abrigo | H29: Distribute to TA | I29: 6.3.1-01 System Administration {Operating Systems & Applications} | J29: 6.3.1-02 Patching | K29: 6.3.1-03 STIG Compliance | L29: 6.3.1-04 PKI Compliance | M29: 6.3.1-05 ESS Compliance | N29: Not Received | O29: Not Reviewed
H30: Due / Frequency (per document) | I30: Due: On-going Freq: Daily | J30: Due: a) NLT the patch IAVA compliance date b) All deficiencies documented with a POAM within 1 business day Freq: Daily | K30: Due: a) NLT 4 weeks of STIGS release b) NLT 5 business days of CAT I STIG release c) (STIG Status Report) NLT 5 business days after the start of the new quarter Freq: Daily | L30: Due: On-going Freq: Daily | M30: Due: On-going Freq: Daily
A31: Oct | B31: 6.3.1 | C31: Linux System Administration Support (2 of 2) | D31: Mixed (see due row) | E31: Operations | F31: Christine Y. Shigeta | G31: Brian Abrigo | H31: Distribute to TA | I31: 6.3.1-06 Security Scans | J31: 6.3.1-07 Backup / Restore | K31: 6.3.1-08 Standard Operating Procedures (SOP) | L31: 6.3.1-09 MSR | N31: Not Received | O31: Not Reviewed
H32: Due / Frequency (per document) | I32: Due: a) Documentation: NLT 1 business days after issue identification b) Resolution: NLT 5 business days after issue identification Freq: Daily | J32: Due: a) NLT COB every workday for backups b) NLT last workday of month for restore validation Freq: Daily for backups Monthly for restores Flag: Daily backups; monthly restore test (last workday of month). | K32: Due: a) Documentation: NLT 1 business days after issue identification b) Resolution: NLT 5 business days after issue identification Freq: Quarterly Flag: Due text repeats the Security Scans wording; quarterly review assumed due the 5th business day of the quarter's first month. | L32: Due: NLT 5th business day of the succeeding month Freq: Monthly
A33: Oct | B33: 6.3.2 | C33: Virtual Desktop Infrastructure (VDI) System Administration Support (1 of 2) | D33: Daily (standing) | E33: Operations | F33: Christine Y. Shigeta | G33: Brian Abrigo | H33: Distribute to TA | I33: 6.3.2-01 System Administration {Operating Systems & Applications} | J33: 6.3.2-02 STIG Compliance | K33: 6.3.2-03 PKI Compliance | L33: 6.3.2-04 HBSS Compliance | M33: 6.3.2-05 Security Scans | N33: Not Received | O33: Not Reviewed
H34: Due / Frequency (per document) | I34: Due: On-going Freq: Daily | J34: Due: a) NLT 4 weeks of STIGS release b) NLT 5 business days of CAT I STIG release c) (STIG Status Report) NLT 5 business days after the start of the new quarter Freq: Daily | K34: Due: On-going Freq: Daily | L34: Due: On-going Freq: Daily | M34: Due: a) Documentation: NLT 1 business days after issue identification b) Resolution NLT 5 business days after issue identification Freq: Daily
A35: Oct | B35: 6.3.2 | C35: Virtual Desktop Infrastructure (VDI) System Administration Support (2 of 2) | D35: Mixed (see due row) | E35: Operations | F35: Christine Y. Shigeta | G35: Brian Abrigo | H35: Distribute to TA | I35: 6.3.2-06 Backup / Restore | J35: 6.3.2-07 Standard Operating Procedures (SOP) | K35: 6.3.2-08 MSR | N35: Not Received | O35: Not Reviewed
H36: Due / Frequency (per document) | I36: Due: a) NLT COB every workday for backups b) NLT last workday of month for restore validation Freq: Daily for backups Monthly for restores Flag: Daily backups; monthly restore test (last workday of month). | J36: Due: a) Documentation: NLT 1 business days after issue identification b) Resolution NLT 5 business days after issue identification Freq: Quarterly Flag: Due text repeats the Security Scans wording; quarterly review assumed due the 5th business day of the quarter's first month. | K36: Due: NLT 5th business day of the succeeding month Freq: Monthly
A37: Oct | B37: 6.3.3 | C37: Virtual Infrastructure (VI) System Administration Support (1 of 2) | D37: Daily (standing) | E37: Operations | F37: Christine Y. Shigeta | G37: Brian Abrigo | H37: Distribute to TA | I37: 6.3.3-01 System Administration {Operating Systems & Applications} | J37: 6.3.3-02 Patching | K37: 6.3.3-03 STIG Compliance | L37: 6.3.3-04 PKI Compliance | M37: 6.3.3-05 ESS Compliance | N37: Not Received | O37: Not Reviewed
H38: Due / Frequency (per document) | I38: Due: On-going Freq: Daily | J38: Due: On-going Freq: Daily | K38: Due: a) NLT 4 weeks of STIGS release b) NLT 5 business days of CAT I STIG release c) (STIG Status Report) NLT 5 business days after the start of the new quarter Freq: Daily | L38: Due: On-going Freq: Daily | M38: Due: On-going Freq: Daily
A39: Oct | B39: 6.3.3 | C39: Virtual Infrastructure (VI) System Administration Support (2 of 2) | D39: Mixed (see due row) | E39: Operations | F39: Christine Y. Shigeta | G39: Brian Abrigo | H39: Distribute to TA | I39: 6.3.3-06 Security Scans | J39: 6.3.3-07 Backup / Restore | K39: 6.3.3-08 Continuity of Operations (COOP) | L39: 6.3.3-09 Standard Operating Procedures (SOP) | M39: 6.3.3-10 MSR | N39: Not Received | O39: Not Reviewed
H40: Due / Frequency (per document) | I40: Due: a) Documentation: NLT 1 business days after issue identification b) Resolution NLT 5 business days after issue identification Freq: Daily | J40: Due: a) NLT COB every workday for backups b) NLT last workday of month for restore validation Freq: Daily for backups Monthly for restores Flag: Daily backups; monthly restore test (last workday of month). | K40: Due: a) On-going b) bi-annual test/exercise based on USINDOPACOM operational schedule Freq: Daily & bi-annual Flag: Includes a bi-annual COOP test/exercise (no date anchor in the PWS). | L40: Due: a) Documentation: NLT 1 business days after issue identification b) Resolution NLT 5 business days after issue identification Freq: Quarterly Flag: Due text repeats the Security Scans wording; quarterly review assumed due the 5th business day of the quarter's first month. | M40: Due: NLT 5th business day of the succeeding month Freq: Monthly
A41: Oct | B41: 6.3.4 | C41: Senior Windows System Administration Support (1 of 3) | D41: Daily (standing) | E41: Operations | F41: Christine Y. Shigeta | G41: Brian Abrigo | H41: Distribute to TA | I41: 6.3.4-01 System Administration {Operating Systems & Applications} | J41: 6.3.4-02 Patching | K41: 6.3.4-03 STIG Compliance | L41: 6.3.4-04 PKI Compliance | M41: 6.3.4-05 ESS Compliance | N41: Not Received | O41: Not Reviewed
...

Sheet Weekly
A1: Weekly Deliverables – last duty day / 3rd business day of the following week
A2: PWS as of 29 Sep 2023 | USINDOPACOM J6 | Tracking No. 712367735 | Follow-on to CS2 (GS00Q17GWD2133 / HC1019-19-F-0015) | Transition-in Jan 2024; Base Feb 2024 – Jan 2025; Option Years 1–4 to Jan 2029
A4: ID | B4: Deliverable | C4: PWS ¶ | D4: Primary POC | E4: Secondary POC | F4: Record | G4: Fully accepted | H4: Overdue | I4: Wk 1 | J4: Wk 2 | K4: Wk 3 | L4: Wk 4 | M4: Wk 5 | N4: Wk 6 | O4: Wk 7 | P4: Wk 8 | Q4: Wk 9 | R4: Wk 10 | S4: Wk 11 | T4: Wk 12 | U4: Wk 13 | V4: Wk 14 | W4: Wk 15 | X4: Wk 16 | Y4: Wk 17 | Z4: Wk 18 | AA4: Wk 19 | AB4: Wk 20 | AC4: Wk 21 | AD4: Wk 22 | AE4: Wk 23 | AF4: Wk 24 | AG4: Wk 25 | AH4: Wk 26
A5: 6.3.4-08 | B5: Active Directory Management – 6.3.4 Senior Windows System Administration Support | C5: 6.3.4.p | D5: Christine Y. Shigeta | E5: Brian Abrigo | F5: Due date | G5: =SUMPRODUCT((I8:AH8<>"")*(I10:AH10<>"")) -> 0 | H5: =SUMPRODUCT((I5:AH5<TODAY())*(((I6:AH6="")+(I6:AH6="In Progress"))>0)*(((I8:AH8="")+(I10:AH10=""))>0)) -> 2 | I5: =ClockStart+MOD(6-WEEKDAY(ClockStart),7)+0 -> 46297 | J5: =ClockStart+MOD(6-WEEKDAY(ClockStart),7)+7 -> 46304 | K5: =ClockStart+MOD(6-WEEKDAY(ClockStart),7)+14 -> 46311 | L5: =ClockStart+MOD(6-WEEKDAY(ClockStart),7)+21 -> 46318 | M5: =ClockStart+MOD(6-WEEKDAY(ClockStart),7)+28 -> 46325 | N5: =ClockStart+MOD(6-WEEKDAY(ClockStart),7)+35 -> 46332 | O5: =ClockStart+MOD(6-WEEKDAY(ClockStart),7)+42 -> 46339 | P5: =ClockStart+MOD(6-WEEKDAY(ClockStart),7)+49 -> 46346 | Q5: =ClockStart+MOD(6-WEEKDAY(ClockStart),7)+56 -> 46353 | R5: =ClockStart+MOD(6-WEEKDAY(ClockStart),7)+63 -> 46360 | S5: =ClockStart+MOD(6-WEEKDAY(ClockStart),7)+70 -> 46367 | T5: =ClockStart+MOD(6-WEEKDAY(ClockStart),7)+77 -> 46374 | U5: =ClockStart+MOD(6-WEEKDAY(ClockStart),7)+84 -> 46381 | V5: =ClockStart+MOD(6-WEEKDAY(ClockStart),7)+91 -> 46388 | W5: =ClockStart+MOD(6-WEEKDAY(ClockStart),7)+98 -> 46395 | X5: =ClockStart+MOD(6-WEEKDAY(ClockStart),7)+105 -> 46402 | Y5: =ClockStart+MOD(6-WEEKDAY(ClockStart),7)+112 -> 46409 | Z5: =ClockStart+MOD(6-WEEKDAY(ClockStart),7)+119 -> 46416 | AA5: =ClockStart+MOD(6-WEEKDAY(ClockStart),7)+126 -> 46423 | AB5: =ClockStart+MOD(6-WEEKDAY(ClockStart),7)+133 -> 46430 | AC5: =ClockStart+MOD(6-WEEKDAY(ClockStart),7)+140 -> 46437 | AD5: =ClockStart+MOD(6-WEEKDAY(ClockStart),7)+147 -> 46444 | AE5: =ClockStart+MOD(6-WEEKDAY(ClockStart),7)+154 -> 46451 | AF5: =ClockStart+MOD(6-WEEKDAY(ClockStart),7)+161 -> 46458 | AG5: =ClockStart+MOD(6-WEEKDAY(ClockStart),7)+168 -> 46465 | AH5: =ClockStart+MOD(6-WEEKDAY(ClockStart),7)+175 -> 46472
F6: Status
F7: COR accepted by
F8: COR date accepted
F9: J698 accepted by
F10: J698 date accepted
F11: Result | I11: =IF(AND(I8<>"",I10<>""),"Fully accepted",IF(I8<>"","COR only",IF(I10<>"","J698 only",""))) | J11: =IF(AND(J8<>"",J10<>""),"Fully accepted",IF(J8<>"","COR only",IF(J10<>"","J698 only",""))) | K11: =IF(AND(K8<>"",K10<>""),"Fully accepted",IF(K8<>"","COR only",IF(K10<>"","J698 only",""))) | L11: =IF(AND(L8<>"",L10<>""),"Fully accepted",IF(L8<>"","COR only",IF(L10<>"","J698 only",""))) | M11: =IF(AND(M8<>"",M10<>""),"Fully accepted",IF(M8<>"","COR only",IF(M10<>"","J698 only",""))) | N11: =IF(AND(N8<>"",N10<>""),"Fully accepted",IF(N8<>"","COR only",IF(N10<>"","J698 only",""))) | O11: =IF(AND(O8<>"",O10<>""),"Fully accepted",IF(O8<>"","COR only",IF(O10<>"","J698 only",""))) | P11: =IF(AND(P8<>"",P10<>""),"Fully accepted",IF(P8<>"","COR only",IF(P10<>"","J698 only",""))) | ... AH11: =IF(AND(AH8<>"",AH10<>""),"Fully accepted",IF(AH8<>"","COR only",IF(AH10<>"","J698 only","")))
A12: 6.3.5-08 | B12: Active Directory Management – 6.3.5 Windows System Administration Support | C12: 6.3.5.p | D12: Christine Y. Shigeta | E12: Brian Abrigo | F12: Due date | G12: =SUMPRODUCT((I15:AH15<>"")*(I17:AH17<>"")) -> 0 | H12: =SUMPRODUCT((I12:AH12<TODAY())*(((I13:AH13="")+(I13:AH13="In Progress"))>0)*(((I15:AH15="")+(I17:AH17=""))>0)) -> 2 | I12: =ClockStart+MOD(6-WEEKDAY(ClockStart),7)+0 -> 46297 | J12: =ClockStart+MOD(6-WEEKDAY(ClockStart),7)+7 -> 46304 | K12: =ClockStart+MOD(6-WEEKDAY(ClockStart),7)+14 -> 46311 | L12: =ClockStart+MOD(6-WEEKDAY(ClockStart),7)+21 -> 46318 | M12: =ClockStart+MOD(6-WEEKDAY(ClockStart),7)+28 -> 46325 | N12: =ClockStart+MOD(6-WEEKDAY(ClockStart),7)+35 -> 46332 | O12: =ClockStart+MOD(6-WEEKDAY(ClockStart),7)+42 -> 46339 | P12: =ClockStart+MOD(6-WEEKDAY(ClockStart),7)+49 -> 46346 | Q12: =ClockStart+MOD(6-WEEKDAY(ClockStart),7)+56 -> 46353 | R12: =ClockStart+MOD(6-WEEKDAY(ClockStart),7)+63 -> 46360 | S12: =ClockStart+MOD(6-WEEKDAY(ClockStart),7)+70 -> 46367 | T12: =ClockStart+MOD(6-WEEKDAY(ClockStart),7)+77 -> 46374 | U12: =ClockStart+MOD(6-WEEKDAY(ClockStart),7)+84 -> 46381 | V12: =ClockStart+MOD(6-WEEKDAY(ClockStart),7)+91 -> 46388 | W12: =ClockStart+MOD(6-WEEKDAY(ClockStart),7)+98 -> 46395 | X12: =ClockStart+MOD(6-WEEKDAY(ClockStart),7)+105 -> 46402 | Y12: =ClockStart+MOD(6-WEEKDAY(ClockStart),7)+112 -> 46409 | Z12: =ClockStart+MOD(6-WEEKDAY(ClockStart),7)+119 -> 46416 | AA12: =ClockStart+MOD(6-WEEKDAY(ClockStart),7)+126 -> 46423 | AB12: =ClockStart+MOD(6-WEEKDAY(ClockStart),7)+133 -> 46430 | AC12: =ClockStart+MOD(6-WEEKDAY(ClockStart),7)+140 -> 46437 | AD12: =ClockStart+MOD(6-WEEKDAY(ClockStart),7)+147 -> 46444 | AE12: =ClockStart+MOD(6-WEEKDAY(ClockStart),7)+154 -> 46451 | AF12: =ClockStart+MOD(6-WEEKDAY(ClockStart),7)+161 -> 46458 | AG12: =ClockStart+MOD(6-WEEKDAY(ClockStart),7)+168 -> 46465 | AH12: =ClockStart+MOD(6-WEEKDAY(ClockStart),7)+175 -> 46472
F13: Status
F14: COR accepted by
F15: COR date accepted
F16: J698 accepted by
F17: J698 date accepted
F18: Result | I18: =IF(AND(I15<>"",I17<>""),"Fully accepted",IF(I15<>"","COR only",IF(I17<>"","J698 only",""))) | J18: =IF(AND(J15<>"",J17<>""),"Fully accepted",IF(J15<>"","COR only",IF(J17<>"","J698 only",""))) | K18: =IF(AND(K15<>"",K17<>""),"Fully accepted",IF(K15<>"","COR only",IF(K17<>"","J698 only",""))) | L18: =IF(AND(L15<>"",L17<>""),"Fully accepted",IF(L15<>"","COR only",IF(L17<>"","J698 only",""))) | M18: =IF(AND(M15<>"",M17<>""),"Fully accepted",IF(M15<>"","COR only",IF(M17<>"","J698 only",""))) | N18: =IF(AND(N15<>"",N17<>""),"Fully accepted",IF(N15<>"","COR only",IF(N17<>"","J698 only",""))) | O18: =IF(AND(O15<>"",O17<>""),"Fully accepted",IF(O15<>"","COR only",IF(O17<>"","J698 only",""))) | P18: =IF(AND(P15<>"",P17<>""),"Fully accepted",IF(P15<>"","COR only",IF(P17<>"","J698 only",""))) | ... AH18: =IF(AND(AH15<>"",AH17<>""),"Fully accepted",IF(AH15<>"","COR only",IF(AH17<>"","J698 only","")))
A19: 6.5.2-01 | B19: Compliance Tracking & Reporting – 6.5.2 Cybersecurity Compliance Support | C19: 6.5.2.a | D19: Christine Y. Shigeta | E19: Brian Abrigo | F19: Due date | G19: =SUMPRODUCT((I22:AH22<>"")*(I24:AH24<>"")) -> 0 | H19: =SUMPRODUCT((I19:AH19<TODAY())*(((I20:AH20="")+(I20:AH20="In Progress"))>0)*(((I22:AH22="")+(I24:AH24=""))>0)) -> 2 | I19: =ClockStart+MOD(6-WEEKDAY(ClockStart),7)+0 -> 46297 | J19: =ClockStart+MOD(6-WEEKDAY(ClockStart),7)+7 -> 46304 | K19: =ClockStart+MOD(6-WEEKDAY(ClockStart),7)+14 -> 46311 | L19: =ClockStart+MOD(6-WEEKDAY(ClockStart),7)+21 -> 46318 | M19: =ClockStart+MOD(6-WEEKDAY(ClockStart),7)+28 -> 46325 | N19: =ClockStart+MOD(6-WEEKDAY(ClockStart),7)+35 -> 46332 | O19: =ClockStart+MOD(6-WEEKDAY(ClockStart),7)+42 -> 46339 | P19: =ClockStart+MOD(6-WEEKDAY(ClockStart),7)+49 -> 46346 | Q19: =ClockStart+MOD(6-WEEKDAY(ClockStart),7)+56 -> 46353 | R19: =ClockStart+MOD(6-WEEKDAY(ClockStart),7)+63 -> 46360 | S19: =ClockStart+MOD(6-WEEKDAY(ClockStart),7)+70 -> 46367 | T19: =ClockStart+MOD(6-WEEKDAY(ClockStart),7)+77 -> 46374 | U19: =ClockStart+MOD(6-WEEKDAY(ClockStart),7)+84 -> 46381 | V19: =ClockStart+MOD(6-WEEKDAY(ClockStart),7)+91 -> 46388 | W19: =ClockStart+MOD(6-WEEKDAY(ClockStart),7)+98 -> 46395 | X19: =ClockStart+MOD(6-WEEKDAY(ClockStart),7)+105 -> 46402 | Y19: =ClockStart+MOD(6-WEEKDAY(ClockStart),7)+112 -> 46409 | Z19: =ClockStart+MOD(6-WEEKDAY(ClockStart),7)+119 -> 46416 | AA19: =ClockStart+MOD(6-WEEKDAY(ClockStart),7)+126 -> 46423 | AB19: =ClockStart+MOD(6-WEEKDAY(ClockStart),7)+133 -> 46430 | AC19: =ClockStart+MOD(6-WEEKDAY(ClockStart),7)+140 -> 46437 | AD19: =ClockStart+MOD(6-WEEKDAY(ClockStart),7)+147 -> 46444 | AE19: =ClockStart+MOD(6-WEEKDAY(ClockStart),7)+154 -> 46451 | AF19: =ClockStart+MOD(6-WEEKDAY(ClockStart),7)+161 -> 46458 | AG19: =ClockStart+MOD(6-WEEKDAY(ClockStart),7)+168 -> 46465 | AH19: =ClockStart+MOD(6-WEEKDAY(ClockStart),7)+175 -> 46472
F20: Status
F21: COR accepted by
F22: COR date accepted
F23: J698 accepted by
F24: J698 date accepted
F25: Result | I25: =IF(AND(I22<>"",I24<>""),"Fully accepted",IF(I22<>"","COR only",IF(I24<>"","J698 only",""))) | J25: =IF(AND(J22<>"",J24<>""),"Fully accepted",IF(J22<>"","COR only",IF(J24<>"","J698 only",""))) | K25: =IF(AND(K22<>"",K24<>""),"Fully accepted",IF(K22<>"","COR only",IF(K24<>"","J698 only",""))) | L25: =IF(AND(L22<>"",L24<>""),"Fully accepted",IF(L22<>"","COR only",IF(L24<>"","J698 only",""))) | M25: =IF(AND(M22<>"",M24<>""),"Fully accepted",IF(M22<>"","COR only",IF(M24<>"","J698 only",""))) | N25: =IF(AND(N22<>"",N24<>""),"Fully accepted",IF(N22<>"","COR only",IF(N24<>"","J698 only",""))) | O25: =IF(AND(O22<>"",O24<>""),"Fully accepted",IF(O22<>"","COR only",IF(O24<>"","J698 only",""))) | P25: =IF(AND(P22<>"",P24<>""),"Fully accepted",IF(P22<>"","COR only",IF(P24<>"","J698 only",""))) | ... AH25: =IF(AND(AH22<>"",AH24<>""),"Fully accepted",IF(AH22<>"","COR only",IF(AH24<>"","J698 only","")))
A26: 6.5.2-02 | B26: Risk Analysis – 6.5.2 Cybersecurity Compliance Support | C26: 6.5.2.b | D26: Christine Y. Shigeta | E26: Brian Abrigo | F26: Due date | G26: =SUMPRODUCT((I29:AH29<>"")*(I31:AH31<>"")) -> 0 | H26: =SUMPRODUCT((I26:AH26<TODAY())*(((I27:AH27="")+(I27:AH27="In Progress"))>0)*(((I29:AH29="")+(I31:AH31=""))>0)) -> 2 | I26: =ClockStart+MOD(6-WEEKDAY(ClockStart),7)+0 -> 46297 | J26: =ClockStart+MOD(6-WEEKDAY(ClockStart),7)+7 -> 46304 | K26: =ClockStart+MOD(6-WEEKDAY(ClockStart),7)+14 -> 46311 | L26: =ClockStart+MOD(6-WEEKDAY(ClockStart),7)+21 -> 46318 | M26: =ClockStart+MOD(6-WEEKDAY(ClockStart),7)+28 -> 46325 | N26: =ClockStart+MOD(6-WEEKDAY(ClockStart),7)+35 -> 46332 | O26: =ClockStart+MOD(6-WEEKDAY(ClockStart),7)+42 -> 46339 | P26: =ClockStart+MOD(6-WEEKDAY(ClockStart),7)+49 -> 46346 | Q26: =ClockStart+MOD(6-WEEKDAY(ClockStart),7)+56 -> 46353 | R26: =ClockStart+MOD(6-WEEKDAY(ClockStart),7)+63 -> 46360 | S26: =ClockStart+MOD(6-WEEKDAY(ClockStart),7)+70 -> 46367 | T26: =ClockStart+MOD(6-WEEKDAY(ClockStart),7)+77 -> 46374 | U26: =ClockStart+MOD(6-WEEKDAY(ClockStart),7)+84 -> 46381 | V26: =ClockStart+MOD(6-WEEKDAY(ClockStart),7)+91 -> 46388 | W26: =ClockStart+MOD(6-WEEKDAY(ClockStart),7)+98 -> 46395 | X26: =ClockStart+MOD(6-WEEKDAY(ClockStart),7)+105 -> 46402 | Y26: =ClockStart+MOD(6-WEEKDAY(ClockStart),7)+112 -> 46409 | Z26: =ClockStart+MOD(6-WEEKDAY(ClockStart),7)+119 -> 46416 | AA26: =ClockStart+MOD(6-WEEKDAY(ClockStart),7)+126 -> 46423 | AB26: =ClockStart+MOD(6-WEEKDAY(ClockStart),7)+133 -> 46430 | AC26: =ClockStart+MOD(6-WEEKDAY(ClockStart),7)+140 -> 46437 | AD26: =ClockStart+MOD(6-WEEKDAY(ClockStart),7)+147 -> 46444 | AE26: =ClockStart+MOD(6-WEEKDAY(ClockStart),7)+154 -> 46451 | AF26: =ClockStart+MOD(6-WEEKDAY(ClockStart),7)+161 -> 46458 | AG26: =ClockStart+MOD(6-WEEKDAY(ClockStart),7)+168 -> 46465 | AH26: =ClockStart+MOD(6-WEEKDAY(ClockStart),7)+175 -> 46472
F27: Status
F28: COR accepted by
F29: COR date accepted
F30: J698 accepted by
F31: J698 date accepted
F32: Result | I32: =IF(AND(I29<>"",I31<>""),"Fully accepted",IF(I29<>"","COR only",IF(I31<>"","J698 only",""))) | J32: =IF(AND(J29<>"",J31<>""),"Fully accepted",IF(J29<>"","COR only",IF(J31<>"","J698 only",""))) | K32: =IF(AND(K29<>"",K31<>""),"Fully accepted",IF(K29<>"","COR only",IF(K31<>"","J698 only",""))) | L32: =IF(AND(L29<>"",L31<>""),"Fully accepted",IF(L29<>"","COR only",IF(L31<>"","J698 only",""))) | M32: =IF(AND(M29<>"",M31<>""),"Fully accepted",IF(M29<>"","COR only",IF(M31<>"","J698 only",""))) | N32: =IF(AND(N29<>"",N31<>""),"Fully accepted",IF(N29<>"","COR only",IF(N31<>"","J698 only",""))) | O32: =IF(AND(O29<>"",O31<>""),"Fully accepted",IF(O29<>"","COR only",IF(O31<>"","J698 only",""))) | P32: =IF(AND(P29<>"",P31<>""),"Fully accepted",IF(P29<>"","COR only",IF(P31<>"","J698 only",""))) | ... AH32: =IF(AND(AH29<>"",AH31<>""),"Fully accepted",IF(AH29<>"","COR only",IF(AH31<>"","J698 only","")))
A33: 6.5.4-04 | B33: Configuration Management Summary of Changes – 6.5.4 Network Defense Administrator Support | C33: 6.5.4.d | D33: Christine Y. Shigeta | E33: Brian Abrigo | F33: Due date | G33: =SUMPRODUCT((I36:AH36<>"")*(I38:AH38<>"")) -> 0 | H33: =SUMPRODUCT((I33:AH33<TODAY())*(((I34:AH34="")+(I34:AH34="In Progress"))>0)*(((I36:AH36="")+(I38:AH38=""))>0)) -> 1 | I33: =ClockStart+MOD(4-WEEKDAY(ClockStart),7)+0 -> 46302 | J33: =ClockStart+MOD(4-WEEKDAY(ClockStart),7)+7 -> 46309 | K33: =ClockStart+MOD(4-WEEKDAY(ClockStart),7)+14 -> 46316 | L33: =ClockStart+MOD(4-WEEKDAY(ClockStart),7)+21 -> 46323 | M33: =ClockStart+MOD(4-WEEKDAY(ClockStart),7)+28 -> 46330 | N33: =ClockStart+MOD(4-WEEKDAY(ClockStart),7)+35 -> 46337 | O33: =ClockStart+MOD(4-WEEKDAY(ClockStart),7)+42 -> 46344 | P33: =ClockStart+MOD(4-WEEKDAY(ClockStart),7)+49 -> 46351 | Q33: =ClockStart+MOD(4-WEEKDAY(ClockStart),7)+56 -> 46358 | R33: =ClockStart+MOD(4-WEEKDAY(ClockStart),7)+63 -> 46365 | S33: =ClockStart+MOD(4-WEEKDAY(ClockStart),7)+70 -> 46372 | T33: =ClockStart+MOD(4-WEEKDAY(ClockStart),7)+77 -> 46379 | U33: =ClockStart+MOD(4-WEEKDAY(ClockStart),7)+84 -> 46386 | V33: =ClockStart+MOD(4-WEEKDAY(ClockStart),7)+91 -> 46393 | W33: =ClockStart+MOD(4-WEEKDAY(ClockStart),7)+98 -> 46400 | X33: =ClockStart+MOD(4-WEEKDAY(ClockStart),7)+105 -> 46407 | Y33: =ClockStart+MOD(4-WEEKDAY(ClockStart),7)+112 -> 46414 | Z33: =ClockStart+MOD(4-WEEKDAY(ClockStart),7)+119 -> 46421 | AA33: =ClockStart+MOD(4-WEEKDAY(ClockStart),7)+126 -> 46428 | AB33: =ClockStart+MOD(4-WEEKDAY(ClockStart),7)+133 -> 46435 | AC33: =ClockStart+MOD(4-WEEKDAY(ClockStart),7)+140 -> 46442 | AD33: =ClockStart+MOD(4-WEEKDAY(ClockStart),7)+147 -> 46449 | AE33: =ClockStart+MOD(4-WEEKDAY(ClockStart),7)+154 -> 46456 | AF33: =ClockStart+MOD(4-WEEKDAY(ClockStart),7)+161 -> 46463 | AG33: =ClockStart+MOD(4-WEEKDAY(ClockStart),7)+168 -> 46470 | AH33: =ClockStart+MOD(4-WEEKDAY(ClockStart),7)+175 -> 46477
F34: Status
F35: COR accepted by
F36: COR date accepted
F37: J698 accepted by
F38: J698 date accepted
F39: Result | I39: =IF(AND(I36<>"",I38<>""),"Fully accepted",IF(I36<>"","COR only",IF(I38<>"","J698 only",""))) | J39: =IF(AND(J36<>"",J38<>""),"Fully accepted",IF(J36<>"","COR only",IF(J38<>"","J698 only",""))) | K39: =IF(AND(K36<>"",K38<>""),"Fully accepted",IF(K36<>"","COR only",IF(K38<>"","J698 only",""))) | L39: =IF(AND(L36<>"",L38<>""),"Fully accepted",IF(L36<>"","COR only",IF(L38<>"","J698 only",""))) | M39: =IF(AND(M36<>"",M38<>""),"Fully accepted",IF(M36<>"","COR only",IF(M38<>"","J698 only",""))) | N39: =IF(AND(N36<>"",N38<>""),"Fully accepted",IF(N36<>"","COR only",IF(N38<>"","J698 only",""))) | O39: =IF(AND(O36<>"",O38<>""),"Fully accepted",IF(O36<>"","COR only",IF(O38<>"","J698 only",""))) | P39: =IF(AND(P36<>"",P38<>""),"Fully accepted",IF(P36<>"","COR only",IF(P38<>"","J698 only",""))) | ... AH39: =IF(AND(AH36<>"",AH38<>""),"Fully accepted",IF(AH36<>"","COR only",IF(AH38<>"","J698 only","")))
A40: 6.5.4-05 | B40: Cyber Threat Summaries – 6.5.4 Network Defense Administrator Support | C40: 6.5.4.e | D40: Christine Y. Shigeta | E40: Brian Abrigo | F40: Due date | G40: =SUMPRODUCT((I43:AH43<>"")*(I45:AH45<>"")) -> 0 | H40: =SUMPRODUCT((I40:AH40<TODAY())*(((I41:AH41="")+(I41:AH41="In Progress"))>0)*(((I43:AH43="")+(I45:AH45=""))>0)) -> 1 | I40: =ClockStart+MOD(4-WEEKDAY(ClockStart),7)+0 -> 46302 | J40: =ClockStart+MOD(4-WEEKDAY(ClockStart),7)+7 -> 46309 | K40: =ClockStart+MOD(4-WEEKDAY(ClockStart),7)+14 -> 46316 | L40: =ClockStart+MOD(4-WEEKDAY(ClockStart),7)+21 -> 46323 | M40: =ClockStart+MOD(4-WEEKDAY(ClockStart),7)+28 -> 46330 | N40: =ClockStart+MOD(4-WEEKDAY(ClockStart),7)+35 -> 46337 | O40: =ClockStart+MOD(4-WEEKDAY(ClockStart),7)+42 -> 46344 | P40: =ClockStart+MOD(4-WEEKDAY(ClockStart),7)+49 -> 46351 | Q40: =ClockStart+MOD(4-WEEKDAY(ClockStart),7)+56 -> 46358 | R40: =ClockStart+MOD(4-WEEKDAY(ClockStart),7)+63 -> 46365 | S40: =ClockStart+MOD(4-WEEKDAY(ClockStart),7)+70 -> 46372 | T40: =ClockStart+MOD(4-WEEKDAY(ClockStart),7)+77 -> 46379 | U40: =ClockStart+MOD(4-WEEKDAY(ClockStart),7)+84 -> 46386 | V40: =ClockStart+MOD(4-WEEKDAY(ClockStart),7)+91 -> 46393 | W40: =ClockStart+MOD(4-WEEKDAY(ClockStart),7)+98 -> 46400 | X40: =ClockStart+MOD(4-WEEKDAY(ClockStart),7)+105 -> 46407 | Y40: =ClockStart+MOD(4-WEEKDAY(ClockStart),7)+112 -> 46414 | Z40: =ClockStart+MOD(4-WEEKDAY(ClockStart),7)+119 -> 46421 | AA40: =ClockStart+MOD(4-WEEKDAY(ClockStart),7)+126 -> 46428 | AB40: =ClockStart+MOD(4-WEEKDAY(ClockStart),7)+133 -> 46435 | AC40: =ClockStart+MOD(4-WEEKDAY(ClockStart),7)+140 -> 46442 | AD40: =ClockStart+MOD(4-WEEKDAY(ClockStart),7)+147 -> 46449 | AE40: =ClockStart+MOD(4-WEEKDAY(ClockStart),7)+154 -> 46456 | AF40: =ClockStart+MOD(4-WEEKDAY(ClockStart),7)+161 -> 46463 | AG40: =ClockStart+MOD(4-WEEKDAY(ClockStart),7)+168 -> 46470 | AH40: =ClockStart+MOD(4-WEEKDAY(ClockStart),7)+175 -> 46477
F41: Status
...

Sheet Monthly
A1: Monthly Deliverables – MSRs and monthly reports (5th business day of the succeeding month)
A2: PWS as of 29 Sep 2023 | USINDOPACOM J6 | Tracking No. 712367735 | Follow-on to CS2 (GS00Q17GWD2133 / HC1019-19-F-0015) | Transition-in Jan 2024; Base Feb 2024 – Jan 2025; Option Years 1–4 to Jan 2029
A4: ID | B4: Deliverable | C4: PWS ¶ | D4: Primary POC | E4: Secondary POC | F4: Record | G4: Fully accepted | H4: Overdue | I4: =EDATE(DATE(YEAR(ClockStart),MONTH(ClockStart),1),0) -> 46296 | J4: =EDATE(DATE(YEAR(ClockStart),MONTH(ClockStart),1),1) -> 46327 | K4: =EDATE(DATE(YEAR(ClockStart),MONTH(ClockStart),1),2) -> 46357 | L4: =EDATE(DATE(YEAR(ClockStart),MONTH(ClockStart),1),3) -> 46388 | M4: =EDATE(DATE(YEAR(ClockStart),MONTH(ClockStart),1),4) -> 46419 | N4: =EDATE(DATE(YEAR(ClockStart),MONTH(ClockStart),1),5) -> 46447
A5: 6.1.1-03 | B5: MSR – 6.1.1 Enterprise Architecture Support | C5: 6.1.1.c | D5: Christine Y. Shigeta | E5: Brian Abrigo | F5: Due date | G5: =SUMPRODUCT((I8:N8<>"")*(I10:N10<>"")) -> 0 | H5: =SUMPRODUCT((I5:N5<TODAY())*(((I6:N6="")+(I6:N6="In Progress"))>0)*(((I8:N8="")+(I10:N10=""))>0)) -> 0 | I5: =WORKDAY(EOMONTH(I$4,0),5) -> 46332 | J5: =WORKDAY(EOMONTH(J$4,0),5) -> 46363 | K5: =WORKDAY(EOMONTH(K$4,0),5) -> 46394 | L5: =WORKDAY(EOMONTH(L$4,0),5) -> 46423 | M5: =WORKDAY(EOMONTH(M$4,0),5) -> 46451 | N5: =WORKDAY(EOMONTH(N$4,0),5) -> 46484
F6: Status
F7: COR accepted by
F8: COR date accepted
F9: J698 accepted by
F10: J698 date accepted
F11: Result | I11: =IF(AND(I8<>"",I10<>""),"Fully accepted",IF(I8<>"","COR only",IF(I10<>"","J698 only",""))) | J11: =IF(AND(J8<>"",J10<>""),"Fully accepted",IF(J8<>"","COR only",IF(J10<>"","J698 only",""))) | K11: =IF(AND(K8<>"",K10<>""),"Fully accepted",IF(K8<>"","COR only",IF(K10<>"","J698 only",""))) | L11: =IF(AND(L8<>"",L10<>""),"Fully accepted",IF(L8<>"","COR only",IF(L10<>"","J698 only",""))) | M11: =IF(AND(M8<>"",M10<>""),"Fully accepted",IF(M8<>"","COR only",IF(M10<>"","J698 only",""))) | N11: =IF(AND(N8<>"",N10<>""),"Fully accepted",IF(N8<>"","COR only",IF(N10<>"","J698 only","")))
A12: 6.1.3-03 | B12: MSR – 6.1.3 Business Process Analyst Support | C12: 6.1.3.f | D12: Christine Y. Shigeta | E12: Brian Abrigo | F12: Due date | G12: =SUMPRODUCT((I15:N15<>"")*(I17:N17<>"")) -> 0 | H12: =SUMPRODUCT((I12:N12<TODAY())*(((I13:N13="")+(I13:N13="In Progress"))>0)*(((I15:N15="")+(I17:N17=""))>0)) -> 0 | I12: =WORKDAY(EOMONTH(I$4,0),5) -> 46332 | J12: =WORKDAY(EOMONTH(J$4,0),5) -> 46363 | K12: =WORKDAY(EOMONTH(K$4,0),5) -> 46394 | L12: =WORKDAY(EOMONTH(L$4,0),5) -> 46423 | M12: =WORKDAY(EOMONTH(M$4,0),5) -> 46451 | N12: =WORKDAY(EOMONTH(N$4,0),5) -> 46484
F13: Status
F14: COR accepted by
F15: COR date accepted
F16: J698 accepted by
F17: J698 date accepted
F18: Result | I18: =IF(AND(I15<>"",I17<>""),"Fully accepted",IF(I15<>"","COR only",IF(I17<>"","J698 only",""))) | J18: =IF(AND(J15<>"",J17<>""),"Fully accepted",IF(J15<>"","COR only",IF(J17<>"","J698 only",""))) | K18: =IF(AND(K15<>"",K17<>""),"Fully accepted",IF(K15<>"","COR only",IF(K17<>"","J698 only",""))) | L18: =IF(AND(L15<>"",L17<>""),"Fully accepted",IF(L15<>"","COR only",IF(L17<>"","J698 only",""))) | M18: =IF(AND(M15<>"",M17<>""),"Fully accepted",IF(M15<>"","COR only",IF(M17<>"","J698 only",""))) | N18: =IF(AND(N15<>"",N17<>""),"Fully accepted",IF(N15<>"","COR only",IF(N17<>"","J698 only","")))
A19: 6.2.1-05 | B19: MSR – 6.2.1 Audio Visual Systems Engineering Support | C19: 6.2.1.o | D19: Christine Y. Shigeta | E19: Brian Abrigo | F19: Due date | G19: =SUMPRODUCT((I22:N22<>"")*(I24:N24<>"")) -> 0 | H19: =SUMPRODUCT((I19:N19<TODAY())*(((I20:N20="")+(I20:N20="In Progress"))>0)*(((I22:N22="")+(I24:N24=""))>0)) -> 0 | I19: =WORKDAY(EOMONTH(I$4,0),5) -> 46332 | J19: =WORKDAY(EOMONTH(J$4,0),5) -> 46363 | K19: =WORKDAY(EOMONTH(K$4,0),5) -> 46394 | L19: =WORKDAY(EOMONTH(L$4,0),5) -> 46423 | M19: =WORKDAY(EOMONTH(M$4,0),5) -> 46451 | N19: =WORKDAY(EOMONTH(N$4,0),5) -> 46484
F20: Status
F21: COR accepted by
F22: COR date accepted
F23: J698 accepted by
F24: J698 date accepted
F25: Result | I25: =IF(AND(I22<>"",I24<>""),"Fully accepted",IF(I22<>"","COR only",IF(I24<>"","J698 only",""))) | J25: =IF(AND(J22<>"",J24<>""),"Fully accepted",IF(J22<>"","COR only",IF(J24<>"","J698 only",""))) | K25: =IF(AND(K22<>"",K24<>""),"Fully accepted",IF(K22<>"","COR only",IF(K24<>"","J698 only",""))) | L25: =IF(AND(L22<>"",L24<>""),"Fully accepted",IF(L22<>"","COR only",IF(L24<>"","J698 only",""))) | M25: =IF(AND(M22<>"",M24<>""),"Fully accepted",IF(M22<>"","COR only",IF(M24<>"","J698 only",""))) | N25: =IF(AND(N22<>"",N24<>""),"Fully accepted",IF(N22<>"","COR only",IF(N24<>"","J698 only","")))
A26: 6.2.2-04 | B26: MSR – 6.2.2 Video Teleconferencing (VTC) Scheduling Support | C26: 6.2.2.e | D26: Christine Y. Shigeta | E26: Brian Abrigo | F26: Due date | G26: =SUMPRODUCT((I29:N29<>"")*(I31:N31<>"")) -> 0 | H26: =SUMPRODUCT((I26:N26<TODAY())*(((I27:N27="")+(I27:N27="In Progress"))>0)*(((I29:N29="")+(I31:N31=""))>0)) -> 0 | I26: =WORKDAY(EOMONTH(I$4,0),5) -> 46332 | J26: =WORKDAY(EOMONTH(J$4,0),5) -> 46363 | K26: =WORKDAY(EOMONTH(K$4,0),5) -> 46394 | L26: =WORKDAY(EOMONTH(L$4,0),5) -> 46423 | M26: =WORKDAY(EOMONTH(M$4,0),5) -> 46451 | N26: =WORKDAY(EOMONTH(N$4,0),5) -> 46484
F27: Status
F28: COR accepted by
F29: COR date accepted
F30: J698 accepted by
F31: J698 date accepted
F32: Result | I32: =IF(AND(I29<>"",I31<>""),"Fully accepted",IF(I29<>"","COR only",IF(I31<>"","J698 only",""))) | J32: =IF(AND(J29<>"",J31<>""),"Fully accepted",IF(J29<>"","COR only",IF(J31<>"","J698 only",""))) | K32: =IF(AND(K29<>"",K31<>""),"Fully accepted",IF(K29<>"","COR only",IF(K31<>"","J698 only",""))) | L32: =IF(AND(L29<>"",L31<>""),"Fully accepted",IF(L29<>"","COR only",IF(L31<>"","J698 only",""))) | M32: =IF(AND(M29<>"",M31<>""),"Fully accepted",IF(M29<>"","COR only",IF(M31<>"","J698 only",""))) | N32: =IF(AND(N29<>"",N31<>""),"Fully accepted",IF(N29<>"","COR only",IF(N31<>"","J698 only","")))
A33: 6.2.3-02 | B33: MSR – 6.2.3 Video Teleconferencing (VTC) Network Engineering Support | C33: 6.2.3.p | D33: Christine Y. Shigeta | E33: Brian Abrigo | F33: Due date | G33: =SUMPRODUCT((I36:N36<>"")*(I38:N38<>"")) -> 0 | H33: =SUMPRODUCT((I33:N33<TODAY())*(((I34:N34="")+(I34:N34="In Progress"))>0)*(((I36:N36="")+(I38:N38=""))>0)) -> 0 | I33: =WORKDAY(EOMONTH(I$4,0),5) -> 46332 | J33: =WORKDAY(EOMONTH(J$4,0),5) -> 46363 | K33: =WORKDAY(EOMONTH(K$4,0),5) -> 46394 | L33: =WORKDAY(EOMONTH(L$4,0),5) -> 46423 | M33: =WORKDAY(EOMONTH(M$4,0),5) -> 46451 | N33: =WORKDAY(EOMONTH(N$4,0),5) -> 46484
F34: Status
F35: COR accepted by
F36: COR date accepted
F37: J698 accepted by
F38: J698 date accepted
F39: Result | I39: =IF(AND(I36<>"",I38<>""),"Fully accepted",IF(I36<>"","COR only",IF(I38<>"","J698 only",""))) | J39: =IF(AND(J36<>"",J38<>""),"Fully accepted",IF(J36<>"","COR only",IF(J38<>"","J698 only",""))) | K39: =IF(AND(K36<>"",K38<>""),"Fully accepted",IF(K36<>"","COR only",IF(K38<>"","J698 only",""))) | L39: =IF(AND(L36<>"",L38<>""),"Fully accepted",IF(L36<>"","COR only",IF(L38<>"","J698 only",""))) | M39: =IF(AND(M36<>"",M38<>""),"Fully accepted",IF(M36<>"","COR only",IF(M38<>"","J698 only",""))) | N39: =IF(AND(N36<>"",N38<>""),"Fully accepted",IF(N36<>"","COR only",IF(N38<>"","J698 only","")))
A40: 6.2.4-04 | B40: STIG Implementation & Reporting – 6.2.4 Senior Cisco Networking Engineering Support | C40: 6.2.4.e | D40: Christine Y. Shigeta | E40: Brian Abrigo | F40: Due date | G40: =SUMPRODUCT((I43:N43<>"")*(I45:N45<>"")) -> 0 | H40: =SUMPRODUCT((I40:N40<TODAY())*(((I41:N41="")+(I41:N41="In Progress"))>0)*(((I43:N43="")+(I45:N45=""))>0)) -> 0 | I40: =WORKDAY(EOMONTH(I$4,0),5) -> 46332 | J40: =WORKDAY(EOMONTH(J$4,0),5) -> 46363 | K40: =WORKDAY(EOMONTH(K$4,0),5) -> 46394 | L40: =WORKDAY(EOMONTH(L$4,0),5) -> 46423 | M40: =WORKDAY(EOMONTH(M$4,0),5) -> 46451 | N40: =WORKDAY(EOMONTH(N$4,0),5) -> 46484
F41: Status
...

Sheet Quarterly
A1: Quarterly Deliverables – 5th business day of the quarter's first month
A2: PWS as of 29 Sep 2023 | USINDOPACOM J6 | Tracking No. 712367735 | Follow-on to CS2 (GS00Q17GWD2133 / HC1019-19-F-0015) | Transition-in Jan 2024; Base Feb 2024 – Jan 2025; Option Years 1–4 to Jan 2029
A4: ID | B4: Deliverable | C4: PWS ¶ | D4: Primary POC | E4: Secondary POC | F4: Record | G4: Fully accepted | H4: Overdue | I4: =EDATE(DATE(YEAR(ClockStart),MONTH(ClockStart)-MOD(MONTH(ClockStart)-1,3),1),0) -> 46296 | J4: =EDATE(DATE(YEAR(ClockStart),MONTH(ClockStart)-MOD(MONTH(ClockStart)-1,3),1),3) -> 46388 | K4: =EDATE(DATE(YEAR(ClockStart),MONTH(ClockStart)-MOD(MONTH(ClockStart)-1,3),1),6) -> 46478
A5: 6.2.1-01 | B5: AV Recommendations – 6.2.1 Audio Visual Systems Engineering Support | C5: 6.2.1.d & 6.2.1.l | D5: Christine Y. Shigeta | E5: Brian Abrigo | F5: Due date | G5: =SUMPRODUCT((I8:K8<>"")*(I10:K10<>"")) -> 0 | H5: =SUMPRODUCT((I5:K5<TODAY())*(((I6:K6="")+(I6:K6="In Progress"))>0)*(((I8:K8="")+(I10:K10=""))>0)) -> 1 | I5: =WORKDAY(I$4-1,5) -> 46302 | J5: =WORKDAY(J$4-1,5) -> 46394 | K5: =WORKDAY(K$4-1,5) -> 46484
F6: Status
F7: COR accepted by
F8: COR date accepted
F9: J698 accepted by
F10: J698 date accepted
F11: Result | I11: =IF(AND(I8<>"",I10<>""),"Fully accepted",IF(I8<>"","COR only",IF(I10<>"","J698 only",""))) | J11: =IF(AND(J8<>"",J10<>""),"Fully accepted",IF(J8<>"","COR only",IF(J10<>"","J698 only",""))) | K11: =IF(AND(K8<>"",K10<>""),"Fully accepted",IF(K8<>"","COR only",IF(K10<>"","J698 only","")))
A12: 6.2.1-03 | B12: AV Audits – 6.2.1 Audio Visual Systems Engineering Support | C12: 6.2.1.k | D12: Christine Y. Shigeta | E12: Brian Abrigo | F12: Due date | G12: =SUMPRODUCT((I15:K15<>"")*(I17:K17<>"")) -> 0 | H12: =SUMPRODUCT((I12:K12<TODAY())*(((I13:K13="")+(I13:K13="In Progress"))>0)*(((I15:K15="")+(I17:K17=""))>0)) -> 1 | I12: =WORKDAY(I$4-1,5) -> 46302 | J12: =WORKDAY(J$4-1,5) -> 46394 | K12: =WORKDAY(K$4-1,5) -> 46484
F13: Status
F14: COR accepted by
F15: COR date accepted
F16: J698 accepted by
F17: J698 date accepted
F18: Result | I18: =IF(AND(I15<>"",I17<>""),"Fully accepted",IF(I15<>"","COR only",IF(I17<>"","J698 only",""))) | J18: =IF(AND(J15<>"",J17<>""),"Fully accepted",IF(J15<>"","COR only",IF(J17<>"","J698 only",""))) | K18: =IF(AND(K15<>"",K17<>""),"Fully accepted",IF(K15<>"","COR only",IF(K17<>"","J698 only","")))
A19: 6.2.3-01 | B19: VTC Recommendations – 6.2.3 Video Teleconferencing (VTC) Network Engineering Support | C19: 6.2.3.d & 6.2.3.g & 6.2.3.m | D19: Christine Y. Shigeta | E19: Brian Abrigo | F19: Due date | G19: =SUMPRODUCT((I22:K22<>"")*(I24:K24<>"")) -> 0 | H19: =SUMPRODUCT((I19:K19<TODAY())*(((I20:K20="")+(I20:K20="In Progress"))>0)*(((I22:K22="")+(I24:K24=""))>0)) -> 1 | I19: =WORKDAY(I$4-1,5) -> 46302 | J19: =WORKDAY(J$4-1,5) -> 46394 | K19: =WORKDAY(K$4-1,5) -> 46484
F20: Status
F21: COR accepted by
F22: COR date accepted
F23: J698 accepted by
F24: J698 date accepted
F25: Result | I25: =IF(AND(I22<>"",I24<>""),"Fully accepted",IF(I22<>"","COR only",IF(I24<>"","J698 only",""))) | J25: =IF(AND(J22<>"",J24<>""),"Fully accepted",IF(J22<>"","COR only",IF(J24<>"","J698 only",""))) | K25: =IF(AND(K22<>"",K24<>""),"Fully accepted",IF(K22<>"","COR only",IF(K24<>"","J698 only","")))
A26: 6.3.1-08 | B26: Standard Operating Procedures (SOP) – 6.3.1 Linux System Administration Support | C26: 6.3.1.p | D26: Christine Y. Shigeta | E26: Brian Abrigo | F26: Due date | G26: =SUMPRODUCT((I29:K29<>"")*(I31:K31<>"")) -> 0 | H26: =SUMPRODUCT((I26:K26<TODAY())*(((I27:K27="")+(I27:K27="In Progress"))>0)*(((I29:K29="")+(I31:K31=""))>0)) -> 1 | I26: =WORKDAY(I$4-1,5) -> 46302 | J26: =WORKDAY(J$4-1,5) -> 46394 | K26: =WORKDAY(K$4-1,5) -> 46484
F27: Status
F28: COR accepted by
F29: COR date accepted
F30: J698 accepted by
F31: J698 date accepted
F32: Result | I32: =IF(AND(I29<>"",I31<>""),"Fully accepted",IF(I29<>"","COR only",IF(I31<>"","J698 only",""))) | J32: =IF(AND(J29<>"",J31<>""),"Fully accepted",IF(J29<>"","COR only",IF(J31<>"","J698 only",""))) | K32: =IF(AND(K29<>"",K31<>""),"Fully accepted",IF(K29<>"","COR only",IF(K31<>"","J698 only","")))
A33: 6.3.2-07 | B33: Standard Operating Procedures (SOP) – 6.3.2 Virtual Desktop Infrastructure (VDI) System Administration Support | C33: 6.3.2.m | D33: Christine Y. Shigeta | E33: Brian Abrigo | F33: Due date | G33: =SUMPRODUCT((I36:K36<>"")*(I38:K38<>"")) -> 0 | H33: =SUMPRODUCT((I33:K33<TODAY())*(((I34:K34="")+(I34:K34="In Progress"))>0)*(((I36:K36="")+(I38:K38=""))>0)) -> 1 | I33: =WORKDAY(I$4-1,5) -> 46302 | J33: =WORKDAY(J$4-1,5) -> 46394 | K33: =WORKDAY(K$4-1,5) -> 46484
F34: Status
F35: COR accepted by
F36: COR date accepted
F37: J698 accepted by
F38: J698 date accepted
F39: Result | I39: =IF(AND(I36<>"",I38<>""),"Fully accepted",IF(I36<>"","COR only",IF(I38<>"","J698 only",""))) | J39: =IF(AND(J36<>"",J38<>""),"Fully accepted",IF(J36<>"","COR only",IF(J38<>"","J698 only",""))) | K39: =IF(AND(K36<>"",K38<>""),"Fully accepted",IF(K36<>"","COR only",IF(K38<>"","J698 only","")))
A40: 6.3.3-09 | B40: Standard Operating Procedures (SOP) – 6.3.3 Virtual Infrastructure (VI) System Administration Support | C40: 6.3.3.n | D40: Christine Y. Shigeta | E40: Brian Abrigo | F40: Due date | G40: =SUMPRODUCT((I43:K43<>"")*(I45:K45<>"")) -> 0 | H40: =SUMPRODUCT((I40:K40<TODAY())*(((I41:K41="")+(I41:K41="In Progress"))>0)*(((I43:K43="")+(I45:K45=""))>0)) -> 1 | I40: =WORKDAY(I$4-1,5) -> 46302 | J40: =WORKDAY(J$4-1,5) -> 46394 | K40: =WORKDAY(K$4-1,5) -> 46484
F41: Status
...

Sheet Daily Duties
A1: Daily Duties – standing requirements, confirmed monthly
A2: PWS as of 29 Sep 2023 | USINDOPACOM J6 | Tracking No. 712367735 | Follow-on to CS2 (GS00Q17GWD2133 / HC1019-19-F-0015) | Transition-in Jan 2024; Base Feb 2024 – Jan 2025; Option Years 1–4 to Jan 2029
A4: ID | B4: Deliverable | C4: PWS ¶ | D4: Primary POC | E4: Secondary POC | F4: Record | G4: Fully accepted | H4: Overdue | I4: =EDATE(DATE(YEAR(ClockStart),MONTH(ClockStart),1),0) -> 46296 | J4: =EDATE(DATE(YEAR(ClockStart),MONTH(ClockStart),1),1) -> 46327 | K4: =EDATE(DATE(YEAR(ClockStart),MONTH(ClockStart),1),2) -> 46357 | L4: =EDATE(DATE(YEAR(ClockStart),MONTH(ClockStart),1),3) -> 46388 | M4: =EDATE(DATE(YEAR(ClockStart),MONTH(ClockStart),1),4) -> 46419 | N4: =EDATE(DATE(YEAR(ClockStart),MONTH(ClockStart),1),5) -> 46447
A5: 6.2.4-02 | B5: Network Engineering Troubleshooting and Operations – 6.2.4 Senior Cisco Networking Engineering Support | C5: 6.2.4.a 6.2.4.g 6.2.4.h 6.2.4.i 6.2.4.j 6.2.4.k 6.2.4.l 6.2.4.m | D5: Christine Y. Shigeta | E5: Brian Abrigo | F5: Due date | G5: =SUMPRODUCT((I8:N8<>"")*(I10:N10<>"")) -> 0 | H5: =SUMPRODUCT((I5:N5<TODAY())*(((I6:N6="")+(I6:N6="In Progress"))>0)*(((I8:N8="")+(I10:N10=""))>0)) -> 0 | I5: =WORKDAY(EOMONTH(I$4,0),5) -> 46332 | J5: =WORKDAY(EOMONTH(J$4,0),5) -> 46363 | K5: =WORKDAY(EOMONTH(K$4,0),5) -> 46394 | L5: =WORKDAY(EOMONTH(L$4,0),5) -> 46423 | M5: =WORKDAY(EOMONTH(M$4,0),5) -> 46451 | N5: =WORKDAY(EOMONTH(N$4,0),5) -> 46484
F6: Status
F7: COR accepted by
F8: COR date accepted
F9: J698 accepted by
F10: J698 date accepted
F11: Result | I11: =IF(AND(I8<>"",I10<>""),"Fully accepted",IF(I8<>"","COR only",IF(I10<>"","J698 only",""))) | J11: =IF(AND(J8<>"",J10<>""),"Fully accepted",IF(J8<>"","COR only",IF(J10<>"","J698 only",""))) | K11: =IF(AND(K8<>"",K10<>""),"Fully accepted",IF(K8<>"","COR only",IF(K10<>"","J698 only",""))) | L11: =IF(AND(L8<>"",L10<>""),"Fully accepted",IF(L8<>"","COR only",IF(L10<>"","J698 only",""))) | M11: =IF(AND(M8<>"",M10<>""),"Fully accepted",IF(M8<>"","COR only",IF(M10<>"","J698 only",""))) | N11: =IF(AND(N8<>"",N10<>""),"Fully accepted",IF(N8<>"","COR only",IF(N10<>"","J698 only","")))
A12: 6.2.4-05 | B12: Security Scans – 6.2.4 Senior Cisco Networking Engineering Support | C12: 6.2.4.h | D12: Christine Y. Shigeta | E12: Brian Abrigo | F12: Due date | G12: =SUMPRODUCT((I15:N15<>"")*(I17:N17<>"")) -> 0 | H12: =SUMPRODUCT((I12:N12<TODAY())*(((I13:N13="")+(I13:N13="In Progress"))>0)*(((I15:N15="")+(I17:N17=""))>0)) -> 0 | I12: =WORKDAY(EOMONTH(I$4,0),5) -> 46332 | J12: =WORKDAY(EOMONTH(J$4,0),5) -> 46363 | K12: =WORKDAY(EOMONTH(K$4,0),5) -> 46394 | L12: =WORKDAY(EOMONTH(L$4,0),5) -> 46423 | M12: =WORKDAY(EOMONTH(M$4,0),5) -> 46451 | N12: =WORKDAY(EOMONTH(N$4,0),5) -> 46484
F13: Status
F14: COR accepted by
F15: COR date accepted
F16: J698 accepted by
F17: J698 date accepted
F18: Result | I18: =IF(AND(I15<>"",I17<>""),"Fully accepted",IF(I15<>"","COR only",IF(I17<>"","J698 only",""))) | J18: =IF(AND(J15<>"",J17<>""),"Fully accepted",IF(J15<>"","COR only",IF(J17<>"","J698 only",""))) | K18: =IF(AND(K15<>"",K17<>""),"Fully accepted",IF(K15<>"","COR only",IF(K17<>"","J698 only",""))) | L18: =IF(AND(L15<>"",L17<>""),"Fully accepted",IF(L15<>"","COR only",IF(L17<>"","J698 only",""))) | M18: =IF(AND(M15<>"",M17<>""),"Fully accepted",IF(M15<>"","COR only",IF(M17<>"","J698 only",""))) | N18: =IF(AND(N15<>"",N17<>""),"Fully accepted",IF(N15<>"","COR only",IF(N17<>"","J698 only","")))
A19: 6.2.5-02 | B19: Network Engineering Troubleshooting and Operations – 6.2.5 Cisco Network Engineering Support | C19: 6.2.5.a 6.2.5.g 6.2.5.h 6.2.5.i 6.2.5.j 6.2.5.k 6.2.5.l 6.2.5.m | D19: Christine Y. Shigeta | E19: Brian Abrigo | F19: Due date | G19: =SUMPRODUCT((I22:N22<>"")*(I24:N24<>"")) -> 0 | H19: =SUMPRODUCT((I19:N19<TODAY())*(((I20:N20="")+(I20:N20="In Progress"))>0)*(((I22:N22="")+(I24:N24=""))>0)) -> 0 | I19: =WORKDAY(EOMONTH(I$4,0),5) -> 46332 | J19: =WORKDAY(EOMONTH(J$4,0),5) -> 46363 | K19: =WORKDAY(EOMONTH(K$4,0),5) -> 46394 | L19: =WORKDAY(EOMONTH(L$4,0),5) -> 46423 | M19: =WORKDAY(EOMONTH(M$4,0),5) -> 46451 | N19: =WORKDAY(EOMONTH(N$4,0),5) -> 46484
F20: Status
F21: COR accepted by
F22: COR date accepted
F23: J698 accepted by
F24: J698 date accepted
F25: Result | I25: =IF(AND(I22<>"",I24<>""),"Fully accepted",IF(I22<>"","COR only",IF(I24<>"","J698 only",""))) | J25: =IF(AND(J22<>"",J24<>""),"Fully accepted",IF(J22<>"","COR only",IF(J24<>"","J698 only",""))) | K25: =IF(AND(K22<>"",K24<>""),"Fully accepted",IF(K22<>"","COR only",IF(K24<>"","J698 only",""))) | L25: =IF(AND(L22<>"",L24<>""),"Fully accepted",IF(L22<>"","COR only",IF(L24<>"","J698 only",""))) | M25: =IF(AND(M22<>"",M24<>""),"Fully accepted",IF(M22<>"","COR only",IF(M24<>"","J698 only",""))) | N25: =IF(AND(N22<>"",N24<>""),"Fully accepted",IF(N22<>"","COR only",IF(N24<>"","J698 only","")))
A26: 6.2.5-05 | B26: Security Scans – 6.2.5 Cisco Network Engineering Support | C26: 6.2.5.h | D26: Christine Y. Shigeta | E26: Brian Abrigo | F26: Due date | G26: =SUMPRODUCT((I29:N29<>"")*(I31:N31<>"")) -> 0 | H26: =SUMPRODUCT((I26:N26<TODAY())*(((I27:N27="")+(I27:N27="In Progress"))>0)*(((I29:N29="")+(I31:N31=""))>0)) -> 0 | I26: =WORKDAY(EOMONTH(I$4,0),5) -> 46332 | J26: =WORKDAY(EOMONTH(J$4,0),5) -> 46363 | K26: =WORKDAY(EOMONTH(K$4,0),5) -> 46394 | L26: =WORKDAY(EOMONTH(L$4,0),5) -> 46423 | M26: =WORKDAY(EOMONTH(M$4,0),5) -> 46451 | N26: =WORKDAY(EOMONTH(N$4,0),5) -> 46484
F27: Status
F28: COR accepted by
F29: COR date accepted
F30: J698 accepted by
F31: J698 date accepted
F32: Result | I32: =IF(AND(I29<>"",I31<>""),"Fully accepted",IF(I29<>"","COR only",IF(I31<>"","J698 only",""))) | J32: =IF(AND(J29<>"",J31<>""),"Fully accepted",IF(J29<>"","COR only",IF(J31<>"","J698 only",""))) | K32: =IF(AND(K29<>"",K31<>""),"Fully accepted",IF(K29<>"","COR only",IF(K31<>"","J698 only",""))) | L32: =IF(AND(L29<>"",L31<>""),"Fully accepted",IF(L29<>"","COR only",IF(L31<>"","J698 only",""))) | M32: =IF(AND(M29<>"",M31<>""),"Fully accepted",IF(M29<>"","COR only",IF(M31<>"","J698 only",""))) | N32: =IF(AND(N29<>"",N31<>""),"Fully accepted",IF(N29<>"","COR only",IF(N31<>"","J698 only","")))
A33: 6.3.1-01 | B33: System Administration {Operating Systems & Applications} – 6.3.1 Linux System Administration Support | C33: 6.3.1.a 6.3.1.e 6.3.1.f 6.3.1.h 6.3.1.i 6.3.1.j 6.3.1.k 6.3.1.n 6.3.1.o | D33: Christine Y. Shigeta | E33: Brian Abrigo | F33: Due date | G33: =SUMPRODUCT((I36:N36<>"")*(I38:N38<>"")) -> 0 | H33: =SUMPRODUCT((I33:N33<TODAY())*(((I34:N34="")+(I34:N34="In Progress"))>0)*(((I36:N36="")+(I38:N38=""))>0)) -> 0 | I33: =WORKDAY(EOMONTH(I$4,0),5) -> 46332 | J33: =WORKDAY(EOMONTH(J$4,0),5) -> 46363 | K33: =WORKDAY(EOMONTH(K$4,0),5) -> 46394 | L33: =WORKDAY(EOMONTH(L$4,0),5) -> 46423 | M33: =WORKDAY(EOMONTH(M$4,0),5) -> 46451 | N33: =WORKDAY(EOMONTH(N$4,0),5) -> 46484
F34: Status
F35: COR accepted by
F36: COR date accepted
F37: J698 accepted by
F38: J698 date accepted
F39: Result | I39: =IF(AND(I36<>"",I38<>""),"Fully accepted",IF(I36<>"","COR only",IF(I38<>"","J698 only",""))) | J39: =IF(AND(J36<>"",J38<>""),"Fully accepted",IF(J36<>"","COR only",IF(J38<>"","J698 only",""))) | K39: =IF(AND(K36<>"",K38<>""),"Fully accepted",IF(K36<>"","COR only",IF(K38<>"","J698 only",""))) | L39: =IF(AND(L36<>"",L38<>""),"Fully accepted",IF(L36<>"","COR only",IF(L38<>"","J698 only",""))) | M39: =IF(AND(M36<>"",M38<>""),"Fully accepted",IF(M36<>"","COR only",IF(M38<>"","J698 only",""))) | N39: =IF(AND(N36<>"",N38<>""),"Fully accepted",IF(N36<>"","COR only",IF(N38<>"","J698 only","")))
A40: 6.3.1-02 | B40: Patching – 6.3.1 Linux System Administration Support | C40: 6.3.1.b | D40: Christine Y. Shigeta | E40: Brian Abrigo | F40: Due date | G40: =SUMPRODUCT((I43:N43<>"")*(I45:N45<>"")) -> 0 | H40: =SUMPRODUCT((I40:N40<TODAY())*(((I41:N41="")+(I41:N41="In Progress"))>0)*(((I43:N43="")+(I45:N45=""))>0)) -> 0 | I40: =WORKDAY(EOMONTH(I$4,0),5) -> 46332 | J40: =WORKDAY(EOMONTH(J$4,0),5) -> 46363 | K40: =WORKDAY(EOMONTH(K$4,0),5) -> 46394 | L40: =WORKDAY(EOMONTH(L$4,0),5) -> 46423 | M40: =WORKDAY(EOMONTH(M$4,0),5) -> 46451 | N40: =WORKDAY(EOMONTH(N$4,0),5) -> 46484
F41: Status
...

Sheet Daily Agenda
A1: Daily Agenda – what is due, in date order
A2: PWS as of 29 Sep 2023 | USINDOPACOM J6 | Tracking No. 712367735 | Follow-on to CS2 (GS00Q17GWD2133 / HC1019-19-F-0015) | Transition-in Jan 2024; Base Feb 2024 – Jan 2025; Option Years 1–4 to Jan 2029
P3: Settings (edit the yellow cells)
A4: Due Date | B4: Day | C4: ID | D4: Deliverable | E4: Source | F4: Status | G4: COR Accepted By | H4: COR Date Accepted | I4: J698 Accepted By | J4: J698 Date Accepted | K4: Result | L4: Days Until Due | M4: Flag | N4: Notes | P4: Clock start (tracking window; current option year is OY2) | Q4: 46296
A5: =Weekly!I5 -> 46297 | B5: =TEXT(A5,"ddd") -> Fri | C5: 6.3.4-08 | D5: Active Directory Management – 6.3.4 Senior Windows System Administration Support – Wk 1 | E5: Weekly | F5: =IF(Weekly!I6="","",Weekly!I6) | G5: =IF(Weekly!I7="","",Weekly!I7) | H5: =IF(Weekly!I8="","",Weekly!I8) | I5: =IF(Weekly!I9="","",Weekly!I9) | J5: =IF(Weekly!I10="","",Weekly!I10) | K5: =IF(AND(H5<>"",J5<>""),"Fully accepted",IF(H5<>"","COR only",IF(J5<>"","J698 only",""))) | L5: =A5-TodayD -> -11 | M5: =IF(K5="Fully accepted","Done",IF(F5="N/A","N/A",IF(F5="Returned","Returned: resubmit",IF(K5="J698 only","Awaiting J698",IF(K5="COR only","Awaiting COR",IF(F5="Submitted","Awaiting COR + J698",IF(A5<TodayD,"OVERDUE",IF(A5-TodayD<=7,"Due within 7 days","")))))))) -> OVERDUE | P5: End of current option year (OY2) | Q5: 46418
A6: =Weekly!I12 -> 46297 | B6: =TEXT(A6,"ddd") -> Fri | C6: 6.3.5-08 | D6: Active Directory Management – 6.3.5 Windows System Administration Support – Wk 1 | E6: Weekly | F6: =IF(Weekly!I13="","",Weekly!I13) | G6: =IF(Weekly!I14="","",Weekly!I14) | H6: =IF(Weekly!I15="","",Weekly!I15) | I6: =IF(Weekly!I16="","",Weekly!I16) | J6: =IF(Weekly!I17="","",Weekly!I17) | K6: =IF(AND(H6<>"",J6<>""),"Fully accepted",IF(H6<>"","COR only",IF(J6<>"","J698 only",""))) | L6: =A6-TodayD -> -11 | M6: =IF(K6="Fully accepted","Done",IF(F6="N/A","N/A",IF(F6="Returned","Returned: resubmit",IF(K6="J698 only","Awaiting J698",IF(K6="COR only","Awaiting COR",IF(F6="Submitted","Awaiting COR + J698",IF(A6<TodayD,"OVERDUE",IF(A6-TodayD<=7,"Due within 7 days","")))))))) -> OVERDUE | P6: End of final option year (OY4) | Q6: 47149
A7: =Weekly!I19 -> 46297 | B7: =TEXT(A7,"ddd") -> Fri | C7: 6.5.2-01 | D7: Compliance Tracking & Reporting – 6.5.2 Cybersecurity Compliance Support – Wk 1 | E7: Weekly | F7: =IF(Weekly!I20="","",Weekly!I20) | G7: =IF(Weekly!I21="","",Weekly!I21) | H7: =IF(Weekly!I22="","",Weekly!I22) | I7: =IF(Weekly!I23="","",Weekly!I23) | J7: =IF(Weekly!I24="","",Weekly!I24) | K7: =IF(AND(H7<>"",J7<>""),"Fully accepted",IF(H7<>"","COR only",IF(J7<>"","J698 only",""))) | L7: =A7-TodayD -> -11 | M7: =IF(K7="Fully accepted","Done",IF(F7="N/A","N/A",IF(F7="Returned","Returned: resubmit",IF(K7="J698 only","Awaiting J698",IF(K7="COR only","Awaiting COR",IF(F7="Submitted","Awaiting COR + J698",IF(A7<TodayD,"OVERDUE",IF(A7-TodayD<=7,"Due within 7 days","")))))))) -> OVERDUE | P7: Gov inspection window (business days) | Q7: 5
A8: =Weekly!I26 -> 46297 | B8: =TEXT(A8,"ddd") -> Fri | C8: 6.5.2-02 | D8: Risk Analysis – 6.5.2 Cybersecurity Compliance Support – Wk 1 | E8: Weekly | F8: =IF(Weekly!I27="","",Weekly!I27) | G8: =IF(Weekly!I28="","",Weekly!I28) | H8: =IF(Weekly!I29="","",Weekly!I29) | I8: =IF(Weekly!I30="","",Weekly!I30) | J8: =IF(Weekly!I31="","",Weekly!I31) | K8: =IF(AND(H8<>"",J8<>""),"Fully accepted",IF(H8<>"","COR only",IF(J8<>"","J698 only",""))) | L8: =A8-TodayD -> -11 | M8: =IF(K8="Fully accepted","Done",IF(F8="N/A","N/A",IF(F8="Returned","Returned: resubmit",IF(K8="J698 only","Awaiting J698",IF(K8="COR only","Awaiting COR",IF(F8="Submitted","Awaiting COR + J698",IF(A8<TodayD,"OVERDUE",IF(A8-TodayD<=7,"Due within 7 days","")))))))) -> OVERDUE | P8: Resubmission window (business days) | Q8: 10
