Workbook

Sheet Tracker
A1: LEIA Task Order – Deliverable Tracker
A2: TO 47QFCA24F0049 | Contract 47QFCA22D0032 | Smartronix, LLC | GSA AAS-Defense | for SOCPAC | Awarded 25 Sep 2024, Mod P00008 (29 May 2025) | Base + 7 options to 24 Sep 2031
A3: Government POCs | C3: AAS CO: Steve Madsen | AAS COR: Alexandria Williams | ACORs: Donald Shevlin, Crystal Miller | TO TPOC: Keith Stilwell (per Project Plan P018) | Acceptance by AAS COR and designated TPOC (E.1)
A5: At a glance | C5: Overdue | D5: Due within 7 days | E5: Awaiting AAS COR / TPOC | F5: Fully accepted | G5: Returned: resubmit | H5: PWS paragraphs with no deliverable
C6: =COUNTIF('Daily Agenda'!$M$5:$M$49,"OVERDUE") -> 8 | D6: =COUNTIF('Daily Agenda'!$M$5:$M$49,"Due within 7 days") -> 0 | E6: =COUNTIF('Daily Agenda'!$M$5:$M$49,"Awaiting*") -> 0 | F6: =COUNTIF('Daily Agenda'!$M$5:$M$49,"Done") -> 0 | G6: =COUNTIF('Daily Agenda'!$M$5:$M$49,"Returned: resubmit") -> 0 | H6: =COUNTIF($I$9:$M$52,"None named*") -> 0
AB7: Lists (dropdown sources). Names you type into an Accepted By cell do not have to be on a list.
A8: Month | B8: Sub Task Number | C8: Paragraph / Section | D8: Frequency | E8: Category | F8: Primary POC | G8: Secondary POC | H8: Format of Deliverable | I8: Deliverable 1 | J8: Deliverable 2 | K8: Deliverable 3 | L8: Deliverable 4 | M8: Deliverable 5 | N8: Status Flow 1 | O8: Status Flow 2 | P8: Status Flow 3 | Q8: AAS COR Accepted By | R8: AAS COR Date Accepted | S8: TPOC Accepted By | T8: TPOC Date Accepted | AB8: Category | AC8: Status Flow 1 | AD8: Status Flow 2 | AE8: Status Flow 3 | AF8: Frequency | AG8: Month | AH8: AAS COR Acceptors | AI8: TPOC Acceptors
A9: Oct | B9: C.5.1 | C9: Task 1 – Program Management | D9: Mixed (see due row) | E9: Program Mgmt | F9: Alexandria Williams (AAS COR) | G9: Keith Stilwell (TPOC) | H9: Contractor format | I9: D01 Monthly Status of GFP and CAP | J9: D02 Program Management Deliverables | N9: Not Received | O9: Not Reviewed | AB9: Cybersecurity | AC9: Received | AD9: Reviewed | AE9: Accepted | AF9: Weekly | AG9: Jan | AH9: Alexandria Williams (AAS COR) | AI9: Keith Stilwell (TO TPOC)
H10: Due / Frequency (per document) | I10: Due: Monthly Freq: Monthly (C.5.1) Flag: F.3 gives no day. The 1st calendar day (per Project Plan P018 F01) is assumed; due the next workday if it falls on a weekend or holiday. | J10: Due: IAW Project Plan (PP) Freq: As needed | AB10: Intelligence | AC10: Not Received | AD10: Not Reviewed | AE10: Returned | AF10: Monthly | AG10: Feb | AH10: Foster Folger (AAS PM / COR per P018) | AI10: Dr. Marvina Harring (Requirement Owner)
A11: Oct | B11: C.5.1.1 | C11: Subtask 1.1 – Service Contract Reporting | D11: Annual | E11: Program Mgmt | F11: Alexandria Williams (AAS COR) | G11: Keith Stilwell (TPOC) | H11: Contractor format | I11: C1.1 SAM.gov Service Contract Reporting (labor hours) | N11: Not Received | O11: Not Reviewed | AB11: Logistics | AD11: Demonstrated | AE11: Returned, but Fixed | AF11: Quarterly | AG11: Mar | AH11: Donald Shevlin (AAS ACOR)
H12: Due / Frequency (per document) | I12: Due: NLT 31 Oct each year Freq: Annual Date: Sat 31 Oct 2026 (NLT) | AB12: Operations | AD12: Not Demonstrated | AF12: Annual | AG12: Apr | AH12: Crystal Miller (AAS ACOR)
A13: Oct | B13: C.5.1.2 | C13: Subtask 1.2 – TO Kick-Off Meeting | D13: One-Time | E13: Program Mgmt | F13: Alexandria Williams (AAS COR) | G13: Keith Stilwell (TPOC) | H13: Contractor format | I13: C1.2a TO Kick-Off Meeting Agenda | J13: C1.2b TO Kick-Off Meeting Minutes Report | N13: Not Received | O13: Not Reviewed | AB13: Program Mgmt | AF13: Daily (standing) | AG13: May
H14: Due / Frequency (per document) | I14: Due: Before the kick-off (kick-off NLT 5 workdays after TO start) Freq: One-time Historical (TO start 25 Sep 2024) | J14: Due: After the kick-off Freq: One-time Historical (TO start 25 Sep 2024) | AB14: Solutions | AF14: One-Time | AG14: Jun
A15: Oct | B15: C.5.1.3 | C15: Subtask 1.3 – Monthly Status Report (MSR) | D15: Monthly | E15: Program Mgmt | F15: Alexandria Williams (AAS COR) | G15: Keith Stilwell (TPOC) | H15: Contractor format | I15: C1.3 Monthly Status Report (MSR) | N15: Not Received | O15: Not Reviewed | AB15: Training | AF15: One-Time + Updates | AG15: Jul
H16: Due / Frequency (per document) | I16: Due: Monthly (no day in the TO) Freq: Monthly Also: 60 days before each option period ends, identify recurring requirements that could transition to another contract type. Flag: The TO gives no due day. Project Plan P018 sets the 1st calendar day of each month; used here. | AF16: As Needed | AG16: Aug
A17: Oct | B17: C.5.1.4 | C17: Subtask 1.4 – Technical Status Meetings | D17: Monthly | E17: Program Mgmt | F17: Alexandria Williams (AAS COR) | G17: Keith Stilwell (TPOC) | H17: Contractor format | I17: C1.4 Technical Status Meeting Minutes | N17: Not Received | O17: Not Reviewed | AF17: Not required (suspended) | AG17: Sep
H18: Due / Frequency (per document) | I18: Due: Monthly meeting; minutes to the AAS COR (no day stated) Freq: Monthly Flag: No due day stated; due with the MSR (assumed). | AF18: Mixed (see due row) | AG18: Oct
A19: Oct | B19: C.5.1.5 | C19: Subtask 1.5 – Program Management Plan (PMP) | D19: Quarterly | E19: Program Mgmt | F19: Alexandria Williams (AAS COR) | G19: Keith Stilwell (TPOC) | H19: Contractor format | I19: D03 Program Management Plan (PMP) | N19: Not Received | O19: Not Reviewed | AF19: None named | AG19: Nov
H20: Due / Frequency (per document) | I20: Due: At Kick-Off Meeting; quarterly updates unless there is a significant project change Freq: Quarterly updates Flag: C.5.1.5 says update annually at minimum; F.3 says quarterly. Quarterly assumed, due 5 business days after quarter end. | AG20: Dec
A21: Oct | B21: C.5.1.6 | C21: Subtask 1.6 – Project Plan (PP) | D21: As Needed | E21: Program Mgmt | F21: Alexandria Williams (AAS COR) | G21: Keith Stilwell (TPOC) | H21: Contractor format | I21: D04 Project Plan (PP) | N21: Not Received | O21: Not Reviewed
H22: Due / Frequency (per document) | I22: Due: NLT 5 workdays following the technical exchange meeting with the Government Freq: Each project
A23: Oct | B23: C.5.1.7 | C23: Subtask 1.7 – Project Trip Reports | D23: As Needed | E23: Program Mgmt | F23: Alexandria Williams (AAS COR) | G23: Keith Stilwell (TPOC) | H23: Contractor format | I23: D05 Trip Report(s) | N23: Not Received | O23: Not Reviewed
H24: Due / Frequency (per document) | I24: Due: Within 10 workdays following completion of each trip Freq: Each trip Flag: F.3 cites C.5.1.6; the trip-report paragraph is C.5.1.7.
A25: Oct | B25: C.5.1.8 | C25: Subtask 1.8 – Transition-In | D25: One-Time | E25: Program Mgmt | F25: Alexandria Williams (AAS COR) | G25: Keith Stilwell (TPOC) | H25: Contractor format | I25: D06 Transition-In Plan | N25: Not Received | O25: Not Reviewed
H26: Due / Frequency (per document) | I26: Due: At Kick-Off Meeting start Freq: One-time Historical (TO start 25 Sep 2024)
A27: Oct | B27: C.5.1.9 | C27: Subtask 1.9 – Transition-Out | D27: One-Time + Updates | E27: Program Mgmt | F27: Alexandria Williams (AAS COR) | G27: Keith Stilwell (TPOC) | H27: Contractor format | I27: D07 Transition-Out Plan | N27: Not Received | O27: Not Reviewed
H28: Due / Frequency (per document) | I28: Due: Within six months of TO start; update annually, then quarterly in the final option period Freq: One-time + updates Annual update: Fri 25 Sep 2026. Implement NLT 6 months before TO expiry: Mon 24 Mar 2031. Flag: Annual updates run each 25 Sep (TO start anniversary); quarterly updates start in the final option period.
A29: Oct | B29: C.5.1.10 | C29: Subtask 1.10 – TO Management Portal | D29: One-Time | E29: Program Mgmt | F29: Alexandria Williams (AAS COR) | G29: Keith Stilwell (TPOC) | H29: Contractor format | I29: D08 Task Order (TO) Management Portal Strategy | N29: Not Received | O29: Not Reviewed
H30: Due / Frequency (per document) | I30: Due: At Kick-Off Meeting start; portal operational within 90 days of approval Freq: One-time Historical (TO start 25 Sep 2024)
A31: Oct | B31: C.5.2 | C31: Task 2 – C6ISR Operations (Subtasks 2.1–2.4) | D31: As Needed | E31: Operations | F31: Alexandria Williams (AAS COR) | G31: Keith Stilwell (TPOC) | H31: Contractor format | I31: D09 Operations Deliverables (C6ISR Operations, Subtasks 2.1–2.4) | N31: Not Received | O31: Not Reviewed
H32: Due / Frequency (per document) | I32: Due: IAW Project Plan (PP) Freq: Each project
A33: Oct | B33: C.5.3 | C33: Task 3 – C6ISR Solutions | D33: As Needed | E33: Solutions | F33: Alexandria Williams (AAS COR) | G33: Keith Stilwell (TPOC) | H33: Contractor format | I33: D10 C6ISR Deliverables (Solutions) | N33: Not Received | O33: Not Reviewed
H34: Due / Frequency (per document) | I34: Due: IAW Project Plan (PP) Freq: Each project
A35: Oct | B35: C.5.4 | C35: Task 4 – Intelligence Operations (Subtasks 4.1–4.2) | D35: As Needed | E35: Intelligence | F35: Alexandria Williams (AAS COR) | G35: Keith Stilwell (TPOC) | H35: Contractor format | I35: D11 Intelligence Analysis and Assessment Deliverables | N35: Not Received | O35: Not Reviewed
H36: Due / Frequency (per document) | I36: Due: IAW Project Plan (PP) Freq: Each project Flag: F.3 cites C.5.4.1 only; Subtask 4.2 (PED) also lists no separate deliverable.
A37: Oct | B37: C.5.5 | C37: Task 5 – C6ISR Training | D37: As Needed | E37: Training | F37: Alexandria Williams (AAS COR) | G37: Keith Stilwell (TPOC) | H37: Contractor format | I37: D12 Training Deliverables | N37: Not Received | O37: Not Reviewed
H38: Due / Frequency (per document) | I38: Due: IAW Project Plan (PP) Freq: Each project
A39: Oct | B39: C.5.6 | C39: Task 6 – Cybersecurity and IA | D39: As Needed | E39: Cybersecurity | F39: Alexandria Williams (AAS COR) | G39: Keith Stilwell (TPOC) | H39: Contractor format | I39: D13 Cyber and IA Deliverables | N39: Not Received | O39: Not Reviewed
H40: Due / Frequency (per document) | I40: Due: IAW Project Plan (PP) Freq: Each project
A41: Oct | B41: C.5.7 | C41: Task 7 – Logistics | D41: As Needed | E41: Logistics | F41: Alexandria Williams (AAS COR) | G41: Keith Stilwell (TPOC) | H41: Contractor format | I41: D14 Logistics Deliverables | N41: Not Received | O41: Not Reviewed
...

Sheet Monthly
A1: Monthly Deliverables – GFP/CAP status, MSR, Technical Status Meeting minutes
A2: TO 47QFCA24F0049 | Contract 47QFCA22D0032 | Smartronix, LLC | GSA AAS-Defense | for SOCPAC | Awarded 25 Sep 2024, Mod P00008 (29 May 2025) | Base + 7 options to 24 Sep 2031
A4: ID | B4: Deliverable | C4: PWS ¶ | D4: Primary POC | E4: Secondary POC | F4: Record | G4: Fully accepted | H4: Overdue | I4: =EDATE(DATE(YEAR(ClockStart),MONTH(ClockStart),1),0) -> 46235 | J4: =EDATE(DATE(YEAR(ClockStart),MONTH(ClockStart),1),1) -> 46266 | K4: =EDATE(DATE(YEAR(ClockStart),MONTH(ClockStart),1),2) -> 46296 | L4: =EDATE(DATE(YEAR(ClockStart),MONTH(ClockStart),1),3) -> 46327 | M4: =EDATE(DATE(YEAR(ClockStart),MONTH(ClockStart),1),4) -> 46357 | N4: =EDATE(DATE(YEAR(ClockStart),MONTH(ClockStart),1),5) -> 46388 | O4: =EDATE(DATE(YEAR(ClockStart),MONTH(ClockStart),1),6) -> 46419 | P4: =EDATE(DATE(YEAR(ClockStart),MONTH(ClockStart),1),7) -> 46447 | Q4: =EDATE(DATE(YEAR(ClockStart),MONTH(ClockStart),1),8) -> 46478 | R4: =EDATE(DATE(YEAR(ClockStart),MONTH(ClockStart),1),9) -> 46508 | S4: =EDATE(DATE(YEAR(ClockStart),MONTH(ClockStart),1),10) -> 46539 | T4: =EDATE(DATE(YEAR(ClockStart),MONTH(ClockStart),1),11) -> 46569
A5: D01 | B5: Monthly Status of GFP and CAP | C5: C.5.1 | D5: Alexandria Williams (AAS COR) | E5: Keith Stilwell (TPOC) | F5: Due date | G5: =SUMPRODUCT((I8:T8<>"")*(I10:T10<>"")) -> 0 | H5: =SUMPRODUCT((I5:T5<TODAY())*(((I6:T6="")+(I6:T6="In Progress"))>0)*(((I8:T8="")+(I10:T10=""))>0)) -> 2 | I5: =WORKDAY(DATE(YEAR(I$4),MONTH(I$4)+1,1)-1,1) -> 46266 | J5: =WORKDAY(DATE(YEAR(J$4),MONTH(J$4)+1,1)-1,1) -> 46296 | K5: =WORKDAY(DATE(YEAR(K$4),MONTH(K$4)+1,1)-1,1) -> 46328 | L5: =WORKDAY(DATE(YEAR(L$4),MONTH(L$4)+1,1)-1,1) -> 46357 | M5: =WORKDAY(DATE(YEAR(M$4),MONTH(M$4)+1,1)-1,1) -> 46388 | N5: =WORKDAY(DATE(YEAR(N$4),MONTH(N$4)+1,1)-1,1) -> 46419 | O5: =WORKDAY(DATE(YEAR(O$4),MONTH(O$4)+1,1)-1,1) -> 46447 | P5: =WORKDAY(DATE(YEAR(P$4),MONTH(P$4)+1,1)-1,1) -> 46478 | ... T5: =WORKDAY(DATE(YEAR(T$4),MONTH(T$4)+1,1)-1,1) -> 46601
F6: Status
F7: AAS COR accepted by
F8: AAS COR date accepted
F9: TPOC accepted by
F10: TPOC date accepted
F11: Result | I11: =IF(AND(I8<>"",I10<>""),"Fully accepted",IF(I8<>"","AAS COR only",IF(I10<>"","TPOC only",""))) | J11: =IF(AND(J8<>"",J10<>""),"Fully accepted",IF(J8<>"","AAS COR only",IF(J10<>"","TPOC only",""))) | K11: =IF(AND(K8<>"",K10<>""),"Fully accepted",IF(K8<>"","AAS COR only",IF(K10<>"","TPOC only",""))) | L11: =IF(AND(L8<>"",L10<>""),"Fully accepted",IF(L8<>"","AAS COR only",IF(L10<>"","TPOC only",""))) | M11: =IF(AND(M8<>"",M10<>""),"Fully accepted",IF(M8<>"","AAS COR only",IF(M10<>"","TPOC only",""))) | N11: =IF(AND(N8<>"",N10<>""),"Fully accepted",IF(N8<>"","AAS COR only",IF(N10<>"","TPOC only",""))) | O11: =IF(AND(O8<>"",O10<>""),"Fully accepted",IF(O8<>"","AAS COR only",IF(O10<>"","TPOC only",""))) | P11: =IF(AND(P8<>"",P10<>""),"Fully accepted",IF(P8<>"","AAS COR only",IF(P10<>"","TPOC only",""))) | ... T11: =IF(AND(T8<>"",T10<>""),"Fully accepted",IF(T8<>"","AAS COR only",IF(T10<>"","TPOC only","")))
A12: C1.3 | B12: Monthly Status Report (MSR) | C12: C.5.1.3 | D12: Alexandria Williams (AAS COR) | E12: Keith Stilwell (TPOC) | F12: Due date | G12: =SUMPRODUCT((I15:T15<>"")*(I17:T17<>"")) -> 0 | H12: =SUMPRODUCT((I12:T12<TODAY())*(((I13:T13="")+(I13:T13="In Progress"))>0)*(((I15:T15="")+(I17:T17=""))>0)) -> 2 | I12: =WORKDAY(DATE(YEAR(I$4),MONTH(I$4)+1,1)-1,1) -> 46266 | J12: =WORKDAY(DATE(YEAR(J$4),MONTH(J$4)+1,1)-1,1) -> 46296 | K12: =WORKDAY(DATE(YEAR(K$4),MONTH(K$4)+1,1)-1,1) -> 46328 | L12: =WORKDAY(DATE(YEAR(L$4),MONTH(L$4)+1,1)-1,1) -> 46357 | M12: =WORKDAY(DATE(YEAR(M$4),MONTH(M$4)+1,1)-1,1) -> 46388 | N12: =WORKDAY(DATE(YEAR(N$4),MONTH(N$4)+1,1)-1,1) -> 46419 | O12: =WORKDAY(DATE(YEAR(O$4),MONTH(O$4)+1,1)-1,1) -> 46447 | P12: =WORKDAY(DATE(YEAR(P$4),MONTH(P$4)+1,1)-1,1) -> 46478 | ... T12: =WORKDAY(DATE(YEAR(T$4),MONTH(T$4)+1,1)-1,1) -> 46601
F13: Status
F14: AAS COR accepted by
F15: AAS COR date accepted
F16: TPOC accepted by
F17: TPOC date accepted
F18: Result | I18: =IF(AND(I15<>"",I17<>""),"Fully accepted",IF(I15<>"","AAS COR only",IF(I17<>"","TPOC only",""))) | J18: =IF(AND(J15<>"",J17<>""),"Fully accepted",IF(J15<>"","AAS COR only",IF(J17<>"","TPOC only",""))) | K18: =IF(AND(K15<>"",K17<>""),"Fully accepted",IF(K15<>"","AAS COR only",IF(K17<>"","TPOC only",""))) | L18: =IF(AND(L15<>"",L17<>""),"Fully accepted",IF(L15<>"","AAS COR only",IF(L17<>"","TPOC only",""))) | M18: =IF(AND(M15<>"",M17<>""),"Fully accepted",IF(M15<>"","AAS COR only",IF(M17<>"","TPOC only",""))) | N18: =IF(AND(N15<>"",N17<>""),"Fully accepted",IF(N15<>"","AAS COR only",IF(N17<>"","TPOC only",""))) | O18: =IF(AND(O15<>"",O17<>""),"Fully accepted",IF(O15<>"","AAS COR only",IF(O17<>"","TPOC only",""))) | P18: =IF(AND(P15<>"",P17<>""),"Fully accepted",IF(P15<>"","AAS COR only",IF(P17<>"","TPOC only",""))) | ... T18: =IF(AND(T15<>"",T17<>""),"Fully accepted",IF(T15<>"","AAS COR only",IF(T17<>"","TPOC only","")))
A19: C1.4 | B19: Technical Status Meeting Minutes | C19: C.5.1.4 | D19: Alexandria Williams (AAS COR) | E19: Keith Stilwell (TPOC) | F19: Due date | G19: =SUMPRODUCT((I22:T22<>"")*(I24:T24<>"")) -> 0 | H19: =SUMPRODUCT((I19:T19<TODAY())*(((I20:T20="")+(I20:T20="In Progress"))>0)*(((I22:T22="")+(I24:T24=""))>0)) -> 2 | I19: =WORKDAY(DATE(YEAR(I$4),MONTH(I$4)+1,1)-1,1) -> 46266 | J19: =WORKDAY(DATE(YEAR(J$4),MONTH(J$4)+1,1)-1,1) -> 46296 | K19: =WORKDAY(DATE(YEAR(K$4),MONTH(K$4)+1,1)-1,1) -> 46328 | L19: =WORKDAY(DATE(YEAR(L$4),MONTH(L$4)+1,1)-1,1) -> 46357 | M19: =WORKDAY(DATE(YEAR(M$4),MONTH(M$4)+1,1)-1,1) -> 46388 | N19: =WORKDAY(DATE(YEAR(N$4),MONTH(N$4)+1,1)-1,1) -> 46419 | O19: =WORKDAY(DATE(YEAR(O$4),MONTH(O$4)+1,1)-1,1) -> 46447 | P19: =WORKDAY(DATE(YEAR(P$4),MONTH(P$4)+1,1)-1,1) -> 46478 | ... T19: =WORKDAY(DATE(YEAR(T$4),MONTH(T$4)+1,1)-1,1) -> 46601
F20: Status
F21: AAS COR accepted by
F22: AAS COR date accepted
F23: TPOC accepted by
F24: TPOC date accepted
F25: Result | I25: =IF(AND(I22<>"",I24<>""),"Fully accepted",IF(I22<>"","AAS COR only",IF(I24<>"","TPOC only",""))) | J25: =IF(AND(J22<>"",J24<>""),"Fully accepted",IF(J22<>"","AAS COR only",IF(J24<>"","TPOC only",""))) | K25: =IF(AND(K22<>"",K24<>""),"Fully accepted",IF(K22<>"","AAS COR only",IF(K24<>"","TPOC only",""))) | L25: =IF(AND(L22<>"",L24<>""),"Fully accepted",IF(L22<>"","AAS COR only",IF(L24<>"","TPOC only",""))) | M25: =IF(AND(M22<>"",M24<>""),"Fully accepted",IF(M22<>"","AAS COR only",IF(M24<>"","TPOC only",""))) | N25: =IF(AND(N22<>"",N24<>""),"Fully accepted",IF(N22<>"","AAS COR only",IF(N24<>"","TPOC only",""))) | O25: =IF(AND(O22<>"",O24<>""),"Fully accepted",IF(O22<>"","AAS COR only",IF(O24<>"","TPOC only",""))) | P25: =IF(AND(P22<>"",P24<>""),"Fully accepted",IF(P22<>"","AAS COR only",IF(P24<>"","TPOC only",""))) | ... T25: =IF(AND(T22<>"",T24<>""),"Fully accepted",IF(T22<>"","AAS COR only",IF(T24<>"","TPOC only","")))
B27: Set Status, then record who accepted it and when. The TO does not give a monthly due day; the 1st calendar day (Project Plan P018 F01), rolled to the next workday per F.3, is assumed.

Sheet Quarterly
A1: Quarterly Deliverables – Program Management Plan updates
A2: TO 47QFCA24F0049 | Contract 47QFCA22D0032 | Smartronix, LLC | GSA AAS-Defense | for SOCPAC | Awarded 25 Sep 2024, Mod P00008 (29 May 2025) | Base + 7 options to 24 Sep 2031
A4: ID | B4: Deliverable | C4: PWS ¶ | D4: Primary POC | E4: Secondary POC | F4: Record | G4: Fully accepted | H4: Overdue | I4: =EDATE(DATE(YEAR(ClockStart),MONTH(ClockStart)-MOD(MONTH(ClockStart)-1,3),1),0) -> 46204 | J4: =EDATE(DATE(YEAR(ClockStart),MONTH(ClockStart)-MOD(MONTH(ClockStart)-1,3),1),3) -> 46296 | K4: =EDATE(DATE(YEAR(ClockStart),MONTH(ClockStart)-MOD(MONTH(ClockStart)-1,3),1),6) -> 46388 | L4: =EDATE(DATE(YEAR(ClockStart),MONTH(ClockStart)-MOD(MONTH(ClockStart)-1,3),1),9) -> 46478
A5: D03 | B5: Program Management Plan (PMP) | C5: C.5.1.5; H.13 | D5: Alexandria Williams (AAS COR) | E5: Keith Stilwell (TPOC) | F5: Due date | G5: =SUMPRODUCT((I8:L8<>"")*(I10:L10<>"")) -> 0 | H5: =SUMPRODUCT((I5:L5<TODAY())*(((I6:L6="")+(I6:L6="In Progress"))>0)*(((I8:L8="")+(I10:L10=""))>0)) -> 1 | I5: =WORKDAY(EOMONTH(I$4,2),5) -> 46302 | J5: =WORKDAY(EOMONTH(J$4,2),5) -> 46394 | K5: =WORKDAY(EOMONTH(K$4,2),5) -> 46484 | L5: =WORKDAY(EOMONTH(L$4,2),5) -> 46575
F6: Status
F7: AAS COR accepted by
F8: AAS COR date accepted
F9: TPOC accepted by
F10: TPOC date accepted
F11: Result | I11: =IF(AND(I8<>"",I10<>""),"Fully accepted",IF(I8<>"","AAS COR only",IF(I10<>"","TPOC only",""))) | J11: =IF(AND(J8<>"",J10<>""),"Fully accepted",IF(J8<>"","AAS COR only",IF(J10<>"","TPOC only",""))) | K11: =IF(AND(K8<>"",K10<>""),"Fully accepted",IF(K8<>"","AAS COR only",IF(K10<>"","TPOC only",""))) | L11: =IF(AND(L8<>"",L10<>""),"Fully accepted",IF(L8<>"","AAS COR only",IF(L10<>"","TPOC only","")))
B13: Set Status, then record who accepted it and when. F.3 calls for quarterly PMP updates; C.5.1.5 says annual. 5 business days after quarter end is assumed.

Sheet Daily Agenda
A1: Daily Agenda – what is due, in date order
A2: TO 47QFCA24F0049 | Contract 47QFCA22D0032 | Smartronix, LLC | GSA AAS-Defense | for SOCPAC | Awarded 25 Sep 2024, Mod P00008 (29 May 2025) | Base + 7 options to 24 Sep 2031
P3: Settings (edit the yellow cells)
A4: Due Date | B4: Day | C4: ID | D4: Deliverable | E4: Source | F4: Status | G4: AAS COR Accepted By | H4: AAS COR Date Accepted | I4: TPOC Accepted By | J4: TPOC Date Accepted | K4: Result | L4: Days Until Due | M4: Flag | N4: Notes | P4: Clock start (tracking window = Option Period 2 start) | Q4: 46235
A5: =Monthly!I12 -> 46266 | B5: =TEXT(A5,"ddd") -> Tue | C5: C1.3 | D5: Monthly Status Report (MSR) – Aug 2026 | E5: Monthly | F5: =IF(Monthly!I13="","",Monthly!I13) | G5: =IF(Monthly!I14="","",Monthly!I14) | H5: =IF(Monthly!I15="","",Monthly!I15) | I5: =IF(Monthly!I16="","",Monthly!I16) | J5: =IF(Monthly!I17="","",Monthly!I17) | K5: =IF(AND(H5<>"",J5<>""),"Fully accepted",IF(H5<>"","AAS COR only",IF(J5<>"","TPOC only",""))) | L5: =A5-TodayD -> -42 | M5: =IF(K5="Fully accepted","Done",IF(F5="N/A","N/A",IF(F5="Returned","Returned: resubmit",IF(K5="TPOC only","Awaiting TPOC",IF(K5="AAS COR only","Awaiting AAS COR",IF(F5="Submitted","Awaiting AAS COR + TPOC",IF(A5<TodayD,"OVERDUE",IF(A5-TodayD<=7,"Due within 7 days","")))))))) -> OVERDUE | P5: TO start (award period start) | Q5: 45560
A6: =Monthly!I19 -> 46266 | B6: =TEXT(A6,"ddd") -> Tue | C6: C1.4 | D6: Technical Status Meeting Minutes – Aug 2026 | E6: Monthly | F6: =IF(Monthly!I20="","",Monthly!I20) | G6: =IF(Monthly!I21="","",Monthly!I21) | H6: =IF(Monthly!I22="","",Monthly!I22) | I6: =IF(Monthly!I23="","",Monthly!I23) | J6: =IF(Monthly!I24="","",Monthly!I24) | K6: =IF(AND(H6<>"",J6<>""),"Fully accepted",IF(H6<>"","AAS COR only",IF(J6<>"","TPOC only",""))) | L6: =A6-TodayD -> -42 | M6: =IF(K6="Fully accepted","Done",IF(F6="N/A","N/A",IF(F6="Returned","Returned: resubmit",IF(K6="TPOC only","Awaiting TPOC",IF(K6="AAS COR only","Awaiting AAS COR",IF(F6="Submitted","Awaiting AAS COR + TPOC",IF(A6<TodayD,"OVERDUE",IF(A6-TodayD<=7,"Due within 7 days","")))))))) -> OVERDUE | P6: End of current option period (Option 2) | Q6: 46599
A7: =Monthly!I5 -> 46266 | B7: =TEXT(A7,"ddd") -> Tue | C7: D01 | D7: Monthly Status of GFP and CAP – Aug 2026 | E7: Monthly | F7: =IF(Monthly!I6="","",Monthly!I6) | G7: =IF(Monthly!I7="","",Monthly!I7) | H7: =IF(Monthly!I8="","",Monthly!I8) | I7: =IF(Monthly!I9="","",Monthly!I9) | J7: =IF(Monthly!I10="","",Monthly!I10) | K7: =IF(AND(H7<>"",J7<>""),"Fully accepted",IF(H7<>"","AAS COR only",IF(J7<>"","TPOC only",""))) | L7: =A7-TodayD -> -42 | M7: =IF(K7="Fully accepted","Done",IF(F7="N/A","N/A",IF(F7="Returned","Returned: resubmit",IF(K7="TPOC only","Awaiting TPOC",IF(K7="AAS COR only","Awaiting AAS COR",IF(F7="Submitted","Awaiting AAS COR + TPOC",IF(A7<TodayD,"OVERDUE",IF(A7-TodayD<=7,"Due within 7 days","")))))))) -> OVERDUE | P7: End of final option (Option 7) | Q7: 48115
A8: =DATE(YEAR(ClockStart),MONTH(TOStart),DAY(TOStart)) -> 46290 | B8: =TEXT(A8,"ddd") -> Fri | C8: D07 | D8: D07 – Transition-Out Plan, annual update (TO start anniversary) | E8: One-time | K8: =IF(AND(H8<>"",J8<>""),"Fully accepted",IF(H8<>"","AAS COR only",IF(J8<>"","TPOC only",""))) | L8: =A8-TodayD -> -18 | M8: =IF(K8="Fully accepted","Done",IF(F8="N/A","N/A",IF(F8="Returned","Returned: resubmit",IF(K8="TPOC only","Awaiting TPOC",IF(K8="AAS COR only","Awaiting AAS COR",IF(F8="Submitted","Awaiting AAS COR + TPOC",IF(A8<TodayD,"OVERDUE",IF(A8-TodayD<=7,"Due within 7 days","")))))))) -> OVERDUE | N8: Updates annually; quarterly in the final option period. | P8: Gov inspection window (workdays, E.2) | Q8: 15
A9: =Monthly!J12 -> 46296 | B9: =TEXT(A9,"ddd") -> Thu | C9: C1.3 | D9: Monthly Status Report (MSR) – Sep 2026 | E9: Monthly | F9: =IF(Monthly!J13="","",Monthly!J13) | G9: =IF(Monthly!J14="","",Monthly!J14) | H9: =IF(Monthly!J15="","",Monthly!J15) | I9: =IF(Monthly!J16="","",Monthly!J16) | J9: =IF(Monthly!J17="","",Monthly!J17) | K9: =IF(AND(H9<>"",J9<>""),"Fully accepted",IF(H9<>"","AAS COR only",IF(J9<>"","TPOC only",""))) | L9: =A9-TodayD -> -12 | M9: =IF(K9="Fully accepted","Done",IF(F9="N/A","N/A",IF(F9="Returned","Returned: resubmit",IF(K9="TPOC only","Awaiting TPOC",IF(K9="AAS COR only","Awaiting AAS COR",IF(F9="Submitted","Awaiting AAS COR + TPOC",IF(A9<TodayD,"OVERDUE",IF(A9-TodayD<=7,"Due within 7 days","")))))))) -> OVERDUE | P9: Resubmission window (workdays, E.4) | Q9: 10
A10: =Monthly!J19 -> 46296 | B10: =TEXT(A10,"ddd") -> Thu | C10: C1.4 | D10: Technical Status Meeting Minutes – Sep 2026 | E10: Monthly | F10: =IF(Monthly!J20="","",Monthly!J20) | G10: =IF(Monthly!J21="","",Monthly!J21) | H10: =IF(Monthly!J22="","",Monthly!J22) | I10: =IF(Monthly!J23="","",Monthly!J23) | J10: =IF(Monthly!J24="","",Monthly!J24) | K10: =IF(AND(H10<>"",J10<>""),"Fully accepted",IF(H10<>"","AAS COR only",IF(J10<>"","TPOC only",""))) | L10: =A10-TodayD -> -12 | M10: =IF(K10="Fully accepted","Done",IF(F10="N/A","N/A",IF(F10="Returned","Returned: resubmit",IF(K10="TPOC only","Awaiting TPOC",IF(K10="AAS COR only","Awaiting AAS COR",IF(F10="Submitted","Awaiting AAS COR + TPOC",IF(A10<TodayD,"OVERDUE",IF(A10-TodayD<=7,"Due within 7 days","")))))))) -> OVERDUE | P10: Today | Q10: =TODAY() -> 46308
A11: =Monthly!J5 -> 46296 | B11: =TEXT(A11,"ddd") -> Thu | C11: D01 | D11: Monthly Status of GFP and CAP – Sep 2026 | E11: Monthly | F11: =IF(Monthly!J6="","",Monthly!J6) | G11: =IF(Monthly!J7="","",Monthly!J7) | H11: =IF(Monthly!J8="","",Monthly!J8) | I11: =IF(Monthly!J9="","",Monthly!J9) | J11: =IF(Monthly!J10="","",Monthly!J10) | K11: =IF(AND(H11<>"",J11<>""),"Fully accepted",IF(H11<>"","AAS COR only",IF(J11<>"","TPOC only",""))) | L11: =A11-TodayD -> -12 | M11: =IF(K11="Fully accepted","Done",IF(F11="N/A","N/A",IF(F11="Returned","Returned: resubmit",IF(K11="TPOC only","Awaiting TPOC",IF(K11="AAS COR only","Awaiting AAS COR",IF(F11="Submitted","Awaiting AAS COR + TPOC",IF(A11<TodayD,"OVERDUE",IF(A11-TodayD<=7,"Due within 7 days","")))))))) -> OVERDUE
A12: =Quarterly!I5 -> 46302 | B12: =TEXT(A12,"ddd") -> Wed | C12: D03 | D12: Program Management Plan (PMP) – Qtr from 01 Jul 2026 | E12: Quarterly | F12: =IF(Quarterly!I6="","",Quarterly!I6) | G12: =IF(Quarterly!I7="","",Quarterly!I7) | H12: =IF(Quarterly!I8="","",Quarterly!I8) | I12: =IF(Quarterly!I9="","",Quarterly!I9) | J12: =IF(Quarterly!I10="","",Quarterly!I10) | K12: =IF(AND(H12<>"",J12<>""),"Fully accepted",IF(H12<>"","AAS COR only",IF(J12<>"","TPOC only",""))) | L12: =A12-TodayD -> -6 | M12: =IF(K12="Fully accepted","Done",IF(F12="N/A","N/A",IF(F12="Returned","Returned: resubmit",IF(K12="TPOC only","Awaiting TPOC",IF(K12="AAS COR only","Awaiting AAS COR",IF(F12="Submitted","Awaiting AAS COR + TPOC",IF(A12<TodayD,"OVERDUE",IF(A12-TodayD<=7,"Due within 7 days","")))))))) -> OVERDUE | P12: Per F.3, deliverables are due the next Government workday if the date falls on a weekend or holiday.
A13: =DATE(YEAR(ClockStart),10,31) -> 46326 | B13: =TEXT(A13,"ddd") -> Sat | C13: C1.1 | D13: C1.1 – SAM.gov Service Contract Reporting (NLT 31 Oct) | E13: One-time | K13: =IF(AND(H13<>"",J13<>""),"Fully accepted",IF(H13<>"","AAS COR only",IF(J13<>"","TPOC only",""))) | L13: =A13-TodayD -> 18 | M13: =IF(K13="Fully accepted","Done",IF(F13="N/A","N/A",IF(F13="Returned","Returned: resubmit",IF(K13="TPOC only","Awaiting TPOC",IF(K13="AAS COR only","Awaiting AAS COR",IF(F13="Submitted","Awaiting AAS COR + TPOC",IF(A13<TodayD,"OVERDUE",IF(A13-TodayD<=7,"Due within 7 days","")))))))) | N13: All labor hours for the government fiscal year. | P13: Late delivery: file a Problem Notification Report (F.6).
A14: =Monthly!K12 -> 46328 | B14: =TEXT(A14,"ddd") -> Mon | C14: C1.3 | D14: Monthly Status Report (MSR) – Oct 2026 | E14: Monthly | F14: =IF(Monthly!K13="","",Monthly!K13) | G14: =IF(Monthly!K14="","",Monthly!K14) | H14: =IF(Monthly!K15="","",Monthly!K15) | I14: =IF(Monthly!K16="","",Monthly!K16) | J14: =IF(Monthly!K17="","",Monthly!K17) | K14: =IF(AND(H14<>"",J14<>""),"Fully accepted",IF(H14<>"","AAS COR only",IF(J14<>"","TPOC only",""))) | L14: =A14-TodayD -> 20 | M14: =IF(K14="Fully accepted","Done",IF(F14="N/A","N/A",IF(F14="Returned","Returned: resubmit",IF(K14="TPOC only","Awaiting TPOC",IF(K14="AAS COR only","Awaiting AAS COR",IF(F14="Submitted","Awaiting AAS COR + TPOC",IF(A14<TodayD,"OVERDUE",IF(A14-TodayD<=7,"Due within 7 days","")))))))) | P14: Holidays are not excluded from business-day math here.
A15: =Monthly!K19 -> 46328 | B15: =TEXT(A15,"ddd") -> Mon | C15: C1.4 | D15: Technical Status Meeting Minutes – Oct 2026 | E15: Monthly | F15: =IF(Monthly!K20="","",Monthly!K20) | G15: =IF(Monthly!K21="","",Monthly!K21) | H15: =IF(Monthly!K22="","",Monthly!K22) | I15: =IF(Monthly!K23="","",Monthly!K23) | J15: =IF(Monthly!K24="","",Monthly!K24) | K15: =IF(AND(H15<>"",J15<>""),"Fully accepted",IF(H15<>"","AAS COR only",IF(J15<>"","TPOC only",""))) | L15: =A15-TodayD -> 20 | M15: =IF(K15="Fully accepted","Done",IF(F15="N/A","N/A",IF(F15="Returned","Returned: resubmit",IF(K15="TPOC only","Awaiting TPOC",IF(K15="AAS COR only","Awaiting AAS COR",IF(F15="Submitted","Awaiting AAS COR + TPOC",IF(A15<TodayD,"OVERDUE",IF(A15-TodayD<=7,"Due within 7 days",""))))))))
A16: =Monthly!K5 -> 46328 | B16: =TEXT(A16,"ddd") -> Mon | C16: D01 | D16: Monthly Status of GFP and CAP – Oct 2026 | E16: Monthly | F16: =IF(Monthly!K6="","",Monthly!K6) | G16: =IF(Monthly!K7="","",Monthly!K7) | H16: =IF(Monthly!K8="","",Monthly!K8) | I16: =IF(Monthly!K9="","",Monthly!K9) | J16: =IF(Monthly!K10="","",Monthly!K10) | K16: =IF(AND(H16<>"",J16<>""),"Fully accepted",IF(H16<>"","AAS COR only",IF(J16<>"","TPOC only",""))) | L16: =A16-TodayD -> 20 | M16: =IF(K16="Fully accepted","Done",IF(F16="N/A","N/A",IF(F16="Returned","Returned: resubmit",IF(K16="TPOC only","Awaiting TPOC",IF(K16="AAS COR only","Awaiting AAS COR",IF(F16="Submitted","Awaiting AAS COR + TPOC",IF(A16<TodayD,"OVERDUE",IF(A16-TodayD<=7,"Due within 7 days",""))))))))
A17: =Monthly!L12 -> 46357 | B17: =TEXT(A17,"ddd") -> Tue | C17: C1.3 | D17: Monthly Status Report (MSR) – Nov 2026 | E17: Monthly | F17: =IF(Monthly!L13="","",Monthly!L13) | G17: =IF(Monthly!L14="","",Monthly!L14) | H17: =IF(Monthly!L15="","",Monthly!L15) | I17: =IF(Monthly!L16="","",Monthly!L16) | J17: =IF(Monthly!L17="","",Monthly!L17) | K17: =IF(AND(H17<>"",J17<>""),"Fully accepted",IF(H17<>"","AAS COR only",IF(J17<>"","TPOC only",""))) | L17: =A17-TodayD -> 49 | M17: =IF(K17="Fully accepted","Done",IF(F17="N/A","N/A",IF(F17="Returned","Returned: resubmit",IF(K17="TPOC only","Awaiting TPOC",IF(K17="AAS COR only","Awaiting AAS COR",IF(F17="Submitted","Awaiting AAS COR + TPOC",IF(A17<TodayD,"OVERDUE",IF(A17-TodayD<=7,"Due within 7 days",""))))))))
A18: =Monthly!L19 -> 46357 | B18: =TEXT(A18,"ddd") -> Tue | C18: C1.4 | D18: Technical Status Meeting Minutes – Nov 2026 | E18: Monthly | F18: =IF(Monthly!L20="","",Monthly!L20) | G18: =IF(Monthly!L21="","",Monthly!L21) | H18: =IF(Monthly!L22="","",Monthly!L22) | I18: =IF(Monthly!L23="","",Monthly!L23) | J18: =IF(Monthly!L24="","",Monthly!L24) | K18: =IF(AND(H18<>"",J18<>""),"Fully accepted",IF(H18<>"","AAS COR only",IF(J18<>"","TPOC only",""))) | L18: =A18-TodayD -> 49 | M18: =IF(K18="Fully accepted","Done",IF(F18="N/A","N/A",IF(F18="Returned","Returned: resubmit",IF(K18="TPOC only","Awaiting TPOC",IF(K18="AAS COR only","Awaiting AAS COR",IF(F18="Submitted","Awaiting AAS COR + TPOC",IF(A18<TodayD,"OVERDUE",IF(A18-TodayD<=7,"Due within 7 days",""))))))))
A19: =Monthly!L5 -> 46357 | B19: =TEXT(A19,"ddd") -> Tue | C19: D01 | D19: Monthly Status of GFP and CAP – Nov 2026 | E19: Monthly | F19: =IF(Monthly!L6="","",Monthly!L6) | G19: =IF(Monthly!L7="","",Monthly!L7) | H19: =IF(Monthly!L8="","",Monthly!L8) | I19: =IF(Monthly!L9="","",Monthly!L9) | J19: =IF(Monthly!L10="","",Monthly!L10) | K19: =IF(AND(H19<>"",J19<>""),"Fully accepted",IF(H19<>"","AAS COR only",IF(J19<>"","TPOC only",""))) | L19: =A19-TodayD -> 49 | M19: =IF(K19="Fully accepted","Done",IF(F19="N/A","N/A",IF(F19="Returned","Returned: resubmit",IF(K19="TPOC only","Awaiting TPOC",IF(K19="AAS COR only","Awaiting AAS COR",IF(F19="Submitted","Awaiting AAS COR + TPOC",IF(A19<TodayD,"OVERDUE",IF(A19-TodayD<=7,"Due within 7 days",""))))))))
A20: =Monthly!M12 -> 46388 | B20: =TEXT(A20,"ddd") -> Fri | C20: C1.3 | D20: Monthly Status Report (MSR) – Dec 2026 | E20: Monthly | F20: =IF(Monthly!M13="","",Monthly!M13) | G20: =IF(Monthly!M14="","",Monthly!M14) | H20: =IF(Monthly!M15="","",Monthly!M15) | I20: =IF(Monthly!M16="","",Monthly!M16) | J20: =IF(Monthly!M17="","",Monthly!M17) | K20: =IF(AND(H20<>"",J20<>""),"Fully accepted",IF(H20<>"","AAS COR only",IF(J20<>"","TPOC only",""))) | L20: =A20-TodayD -> 80 | M20: =IF(K20="Fully accepted","Done",IF(F20="N/A","N/A",IF(F20="Returned","Returned: resubmit",IF(K20="TPOC only","Awaiting TPOC",IF(K20="AAS COR only","Awaiting AAS COR",IF(F20="Submitted","Awaiting AAS COR + TPOC",IF(A20<TodayD,"OVERDUE",IF(A20-TodayD<=7,"Due within 7 days",""))))))))
A21: =Monthly!M19 -> 46388 | B21: =TEXT(A21,"ddd") -> Fri | C21: C1.4 | D21: Technical Status Meeting Minutes – Dec 2026 | E21: Monthly | F21: =IF(Monthly!M20="","",Monthly!M20) | G21: =IF(Monthly!M21="","",Monthly!M21) | H21: =IF(Monthly!M22="","",Monthly!M22) | I21: =IF(Monthly!M23="","",Monthly!M23) | J21: =IF(Monthly!M24="","",Monthly!M24) | K21: =IF(AND(H21<>"",J21<>""),"Fully accepted",IF(H21<>"","AAS COR only",IF(J21<>"","TPOC only",""))) | L21: =A21-TodayD -> 80 | M21: =IF(K21="Fully accepted","Done",IF(F21="N/A","N/A",IF(F21="Returned","Returned: resubmit",IF(K21="TPOC only","Awaiting TPOC",IF(K21="AAS COR only","Awaiting AAS COR",IF(F21="Submitted","Awaiting AAS COR + TPOC",IF(A21<TodayD,"OVERDUE",IF(A21-TodayD<=7,"Due within 7 days",""))))))))
A22: =Monthly!M5 -> 46388 | B22: =TEXT(A22,"ddd") -> Fri | C22: D01 | D22: Monthly Status of GFP and CAP – Dec 2026 | E22: Monthly | F22: =IF(Monthly!M6="","",Monthly!M6) | G22: =IF(Monthly!M7="","",Monthly!M7) | H22: =IF(Monthly!M8="","",Monthly!M8) | I22: =IF(Monthly!M9="","",Monthly!M9) | J22: =IF(Monthly!M10="","",Monthly!M10) | K22: =IF(AND(H22<>"",J22<>""),"Fully accepted",IF(H22<>"","AAS COR only",IF(J22<>"","TPOC only",""))) | L22: =A22-TodayD -> 80 | M22: =IF(K22="Fully accepted","Done",IF(F22="N/A","N/A",IF(F22="Returned","Returned: resubmit",IF(K22="TPOC only","Awaiting TPOC",IF(K22="AAS COR only","Awaiting AAS COR",IF(F22="Submitted","Awaiting AAS COR + TPOC",IF(A22<TodayD,"OVERDUE",IF(A22-TodayD<=7,"Due within 7 days",""))))))))
A23: =Quarterly!J5 -> 46394 | B23: =TEXT(A23,"ddd") -> Thu | C23: D03 | D23: Program Management Plan (PMP) – Qtr from 01 Oct 2026 | E23: Quarterly | F23: =IF(Quarterly!J6="","",Quarterly!J6) | G23: =IF(Quarterly!J7="","",Quarterly!J7) | H23: =IF(Quarterly!J8="","",Quarterly!J8) | I23: =IF(Quarterly!J9="","",Quarterly!J9) | J23: =IF(Quarterly!J10="","",Quarterly!J10) | K23: =IF(AND(H23<>"",J23<>""),"Fully accepted",IF(H23<>"","AAS COR only",IF(J23<>"","TPOC only",""))) | L23: =A23-TodayD -> 86 | M23: =IF(K23="Fully accepted","Done",IF(F23="N/A","N/A",IF(F23="Returned","Returned: resubmit",IF(K23="TPOC only","Awaiting TPOC",IF(K23="AAS COR only","Awaiting AAS COR",IF(F23="Submitted","Awaiting AAS COR + TPOC",IF(A23<TodayD,"OVERDUE",IF(A23-TodayD<=7,"Due within 7 days",""))))))))
A24: =Monthly!N12 -> 46419 | B24: =TEXT(A24,"ddd") -> Mon | C24: C1.3 | D24: Monthly Status Report (MSR) – Jan 2027 | E24: Monthly | F24: =IF(Monthly!N13="","",Monthly!N13) | G24: =IF(Monthly!N14="","",Monthly!N14) | H24: =IF(Monthly!N15="","",Monthly!N15) | I24: =IF(Monthly!N16="","",Monthly!N16) | J24: =IF(Monthly!N17="","",Monthly!N17) | K24: =IF(AND(H24<>"",J24<>""),"Fully accepted",IF(H24<>"","AAS COR only",IF(J24<>"","TPOC only",""))) | L24: =A24-TodayD -> 111 | M24: =IF(K24="Fully accepted","Done",IF(F24="N/A","N/A",IF(F24="Returned","Returned: resubmit",IF(K24="TPOC only","Awaiting TPOC",IF(K24="AAS COR only","Awaiting AAS COR",IF(F24="Submitted","Awaiting AAS COR + TPOC",IF(A24<TodayD,"OVERDUE",IF(A24-TodayD<=7,"Due within 7 days",""))))))))
A25: =Monthly!N19 -> 46419 | B25: =TEXT(A25,"ddd") -> Mon | C25: C1.4 | D25: Technical Status Meeting Minutes – Jan 2027 | E25: Monthly | F25: =IF(Monthly!N20="","",Monthly!N20) | G25: =IF(Monthly!N21="","",Monthly!N21) | H25: =IF(Monthly!N22="","",Monthly!N22) | I25: =IF(Monthly!N23="","",Monthly!N23) | J25: =IF(Monthly!N24="","",Monthly!N24) | K25: =IF(AND(H25<>"",J25<>""),"Fully accepted",IF(H25<>"","AAS COR only",IF(J25<>"","TPOC only",""))) | L25: =A25-TodayD -> 111 | M25: =IF(K25="Fully accepted","Done",IF(F25="N/A","N/A",IF(F25="Returned","Returned: resubmit",IF(K25="TPOC only","Awaiting TPOC",IF(K25="AAS COR only","Awaiting AAS COR",IF(F25="Submitted","Awaiting AAS COR + TPOC",IF(A25<TodayD,"OVERDUE",IF(A25-TodayD<=7,"Due within 7 days",""))))))))
A26: =Monthly!N5 -> 46419 | B26: =TEXT(A26,"ddd") -> Mon | C26: D01 | D26: Monthly Status of GFP and CAP – Jan 2027 | E26: Monthly | F26: =IF(Monthly!N6="","",Monthly!N6) | G26: =IF(Monthly!N7="","",Monthly!N7) | H26: =IF(Monthly!N8="","",Monthly!N8) | I26: =IF(Monthly!N9="","",Monthly!N9) | J26: =IF(Monthly!N10="","",Monthly!N10) | K26: =IF(AND(H26<>"",J26<>""),"Fully accepted",IF(H26<>"","AAS COR only",IF(J26<>"","TPOC only",""))) | L26: =A26-TodayD -> 111 | M26: =IF(K26="Fully accepted","Done",IF(F26="N/A","N/A",IF(F26="Returned","Returned: resubmit",IF(K26="TPOC only","Awaiting TPOC",IF(K26="AAS COR only","Awaiting AAS COR",IF(F26="Submitted","Awaiting AAS COR + TPOC",IF(A26<TodayD,"OVERDUE",IF(A26-TodayD<=7,"Due within 7 days",""))))))))
A27: =Monthly!O12 -> 46447 | B27: =TEXT(A27,"ddd") -> Mon | C27: C1.3 | D27: Monthly Status Report (MSR) – Feb 2027 | E27: Monthly | F27: =IF(Monthly!O13="","",Monthly!O13) | G27: =IF(Monthly!O14="","",Monthly!O14) | H27: =IF(Monthly!O15="","",Monthly!O15) | I27: =IF(Monthly!O16="","",Monthly!O16) | J27: =IF(Monthly!O17="","",Monthly!O17) | K27: =IF(AND(H27<>"",J27<>""),"Fully accepted",IF(H27<>"","AAS COR only",IF(J27<>"","TPOC only",""))) | L27: =A27-TodayD -> 139 | M27: =IF(K27="Fully accepted","Done",IF(F27="N/A","N/A",IF(F27="Returned","Returned: resubmit",IF(K27="TPOC only","Awaiting TPOC",IF(K27="AAS COR only","Awaiting AAS COR",IF(F27="Submitted","Awaiting AAS COR + TPOC",IF(A27<TodayD,"OVERDUE",IF(A27-TodayD<=7,"Due within 7 days",""))))))))
A28: =Monthly!O19 -> 46447 | B28: =TEXT(A28,"ddd") -> Mon | C28: C1.4 | D28: Technical Status Meeting Minutes – Feb 2027 | E28: Monthly | F28: =IF(Monthly!O20="","",Monthly!O20) | G28: =IF(Monthly!O21="","",Monthly!O21) | H28: =IF(Monthly!O22="","",Monthly!O22) | I28: =IF(Monthly!O23="","",Monthly!O23) | J28: =IF(Monthly!O24="","",Monthly!O24) | K28: =IF(AND(H28<>"",J28<>""),"Fully accepted",IF(H28<>"","AAS COR only",IF(J28<>"","TPOC only",""))) | L28: =A28-TodayD -> 139 | M28: =IF(K28="Fully accepted","Done",IF(F28="N/A","N/A",IF(F28="Returned","Returned: resubmit",IF(K28="TPOC only","Awaiting TPOC",IF(K28="AAS COR only","Awaiting AAS COR",IF(F28="Submitted","Awaiting AAS COR + TPOC",IF(A28<TodayD,"OVERDUE",IF(A28-TodayD<=7,"Due within 7 days",""))))))))
A29: =Monthly!O5 -> 46447 | B29: =TEXT(A29,"ddd") -> Mon | C29: D01 | D29: Monthly Status of GFP and CAP – Feb 2027 | E29: Monthly | F29: =IF(Monthly!O6="","",Monthly!O6) | G29: =IF(Monthly!O7="","",Monthly!O7) | H29: =IF(Monthly!O8="","",Monthly!O8) | I29: =IF(Monthly!O9="","",Monthly!O9) | J29: =IF(Monthly!O10="","",Monthly!O10) | K29: =IF(AND(H29<>"",J29<>""),"Fully accepted",IF(H29<>"","AAS COR only",IF(J29<>"","TPOC only",""))) | L29: =A29-TodayD -> 139 | M29: =IF(K29="Fully accepted","Done",IF(F29="N/A","N/A",IF(F29="Returned","Returned: resubmit",IF(K29="TPOC only","Awaiting TPOC",IF(K29="AAS COR only","Awaiting AAS COR",IF(F29="Submitted","Awaiting AAS COR + TPOC",IF(A29<TodayD,"OVERDUE",IF(A29-TodayD<=7,"Due within 7 days",""))))))))
A30: =Monthly!P12 -> 46478 | B30: =TEXT(A30,"ddd") -> Thu | C30: C1.3 | D30: Monthly Status Report (MSR) – Mar 2027 | E30: Monthly | F30: =IF(Monthly!P13="","",Monthly!P13) | G30: =IF(Monthly!P14="","",Monthly!P14) | H30: =IF(Monthly!P15="","",Monthly!P15) | I30: =IF(Monthly!P16="","",Monthly!P16) | J30: =IF(Monthly!P17="","",Monthly!P17) | K30: =IF(AND(H30<>"",J30<>""),"Fully accepted",IF(H30<>"","AAS COR only",IF(J30<>"","TPOC only",""))) | L30: =A30-TodayD -> 170 | M30: =IF(K30="Fully accepted","Done",IF(F30="N/A","N/A",IF(F30="Returned","Returned: resubmit",IF(K30="TPOC only","Awaiting TPOC",IF(K30="AAS COR only","Awaiting AAS COR",IF(F30="Submitted","Awaiting AAS COR + TPOC",IF(A30<TodayD,"OVERDUE",IF(A30-TodayD<=7,"Due within 7 days",""))))))))
A31: =Monthly!P19 -> 46478 | B31: =TEXT(A31,"ddd") -> Thu | C31: C1.4 | D31: Technical Status Meeting Minutes – Mar 2027 | E31: Monthly | F31: =IF(Monthly!P20="","",Monthly!P20) | G31: =IF(Monthly!P21="","",Monthly!P21) | H31: =IF(Monthly!P22="","",Monthly!P22) | I31: =IF(Monthly!P23="","",Monthly!P23) | J31: =IF(Monthly!P24="","",Monthly!P24) | K31: =IF(AND(H31<>"",J31<>""),"Fully accepted",IF(H31<>"","AAS COR only",IF(J31<>"","TPOC only",""))) | L31: =A31-TodayD -> 170 | M31: =IF(K31="Fully accepted","Done",IF(F31="N/A","N/A",IF(F31="Returned","Returned: resubmit",IF(K31="TPOC only","Awaiting TPOC",IF(K31="AAS COR only","Awaiting AAS COR",IF(F31="Submitted","Awaiting AAS COR + TPOC",IF(A31<TodayD,"OVERDUE",IF(A31-TodayD<=7,"Due within 7 days",""))))))))
A32: =Monthly!P5 -> 46478 | B32: =TEXT(A32,"ddd") -> Thu | C32: D01 | D32: Monthly Status of GFP and CAP – Mar 2027 | E32: Monthly | F32: =IF(Monthly!P6="","",Monthly!P6) | G32: =IF(Monthly!P7="","",Monthly!P7) | H32: =IF(Monthly!P8="","",Monthly!P8) | I32: =IF(Monthly!P9="","",Monthly!P9) | J32: =IF(Monthly!P10="","",Monthly!P10) | K32: =IF(AND(H32<>"",J32<>""),"Fully accepted",IF(H32<>"","AAS COR only",IF(J32<>"","TPOC only",""))) | L32: =A32-TodayD -> 170 | M32: =IF(K32="Fully accepted","Done",IF(F32="N/A","N/A",IF(F32="Returned","Returned: resubmit",IF(K32="TPOC only","Awaiting TPOC",IF(K32="AAS COR only","Awaiting AAS COR",IF(F32="Submitted","Awaiting AAS COR + TPOC",IF(A32<TodayD,"OVERDUE",IF(A32-TodayD<=7,"Due within 7 days",""))))))))
A33: =Quarterly!K5 -> 46484 | B33: =TEXT(A33,"ddd") -> Wed | C33: D03 | D33: Program Management Plan (PMP) – Qtr from 01 Jan 2027 | E33: Quarterly | F33: =IF(Quarterly!K6="","",Quarterly!K6) | G33: =IF(Quarterly!K7="","",Quarterly!K7) | H33: =IF(Quarterly!K8="","",Quarterly!K8) | I33: =IF(Quarterly!K9="","",Quarterly!K9) | J33: =IF(Quarterly!K10="","",Quarterly!K10) | K33: =IF(AND(H33<>"",J33<>""),"Fully accepted",IF(H33<>"","AAS COR only",IF(J33<>"","TPOC only",""))) | L33: =A33-TodayD -> 176 | M33: =IF(K33="Fully accepted","Done",IF(F33="N/A","N/A",IF(F33="Returned","Returned: resubmit",IF(K33="TPOC only","Awaiting TPOC",IF(K33="AAS COR only","Awaiting AAS COR",IF(F33="Submitted","Awaiting AAS COR + TPOC",IF(A33<TodayD,"OVERDUE",IF(A33-TodayD<=7,"Due within 7 days",""))))))))
A34: =Monthly!Q12 -> 46510 | B34: =TEXT(A34,"ddd") -> Mon | C34: C1.3 | D34: Monthly Status Report (MSR) – Apr 2027 | E34: Monthly | F34: =IF(Monthly!Q13="","",Monthly!Q13) | G34: =IF(Monthly!Q14="","",Monthly!Q14) | H34: =IF(Monthly!Q15="","",Monthly!Q15) | I34: =IF(Monthly!Q16="","",Monthly!Q16) | J34: =IF(Monthly!Q17="","",Monthly!Q17) | K34: =IF(AND(H34<>"",J34<>""),"Fully accepted",IF(H34<>"","AAS COR only",IF(J34<>"","TPOC only",""))) | L34: =A34-TodayD -> 202 | M34: =IF(K34="Fully accepted","Done",IF(F34="N/A","N/A",IF(F34="Returned","Returned: resubmit",IF(K34="TPOC only","Awaiting TPOC",IF(K34="AAS COR only","Awaiting AAS COR",IF(F34="Submitted","Awaiting AAS COR + TPOC",IF(A34<TodayD,"OVERDUE",IF(A34-TodayD<=7,"Due within 7 days",""))))))))
A35: =Monthly!Q19 -> 46510 | B35: =TEXT(A35,"ddd") -> Mon | C35: C1.4 | D35: Technical Status Meeting Minutes – Apr 2027 | E35: Monthly | F35: =IF(Monthly!Q20="","",Monthly!Q20) | G35: =IF(Monthly!Q21="","",Monthly!Q21) | H35: =IF(Monthly!Q22="","",Monthly!Q22) | I35: =IF(Monthly!Q23="","",Monthly!Q23) | J35: =IF(Monthly!Q24="","",Monthly!Q24) | K35: =IF(AND(H35<>"",J35<>""),"Fully accepted",IF(H35<>"","AAS COR only",IF(J35<>"","TPOC only",""))) | L35: =A35-TodayD -> 202 | M35: =IF(K35="Fully accepted","Done",IF(F35="N/A","N/A",IF(F35="Returned","Returned: resubmit",IF(K35="TPOC only","Awaiting TPOC",IF(K35="AAS COR only","Awaiting AAS COR",IF(F35="Submitted","Awaiting AAS COR + TPOC",IF(A35<TodayD,"OVERDUE",IF(A35-TodayD<=7,"Due within 7 days",""))))))))
A36: =Monthly!Q5 -> 46510 | B36: =TEXT(A36,"ddd") -> Mon | C36: D01 | D36: Monthly Status of GFP and CAP – Apr 2027 | E36: Monthly | F36: =IF(Monthly!Q6="","",Monthly!Q6) | G36: =IF(Monthly!Q7="","",Monthly!Q7) | H36: =IF(Monthly!Q8="","",Monthly!Q8) | I36: =IF(Monthly!Q9="","",Monthly!Q9) | J36: =IF(Monthly!Q10="","",Monthly!Q10) | K36: =IF(AND(H36<>"",J36<>""),"Fully accepted",IF(H36<>"","AAS COR only",IF(J36<>"","TPOC only",""))) | L36: =A36-TodayD -> 202 | M36: =IF(K36="Fully accepted","Done",IF(F36="N/A","N/A",IF(F36="Returned","Returned: resubmit",IF(K36="TPOC only","Awaiting TPOC",IF(K36="AAS COR only","Awaiting AAS COR",IF(F36="Submitted","Awaiting AAS COR + TPOC",IF(A36<TodayD,"OVERDUE",IF(A36-TodayD<=7,"Due within 7 days",""))))))))
A37: =Monthly!R12 -> 46539 | B37: =TEXT(A37,"ddd") -> Tue | C37: C1.3 | D37: Monthly Status Report (MSR) – May 2027 | E37: Monthly | F37: =IF(Monthly!R13="","",Monthly!R13) | G37: =IF(Monthly!R14="","",Monthly!R14) | H37: =IF(Monthly!R15="","",Monthly!R15) | I37: =IF(Monthly!R16="","",Monthly!R16) | J37: =IF(Monthly!R17="","",Monthly!R17) | K37: =IF(AND(H37<>"",J37<>""),"Fully accepted",IF(H37<>"","AAS COR only",IF(J37<>"","TPOC only",""))) | L37: =A37-TodayD -> 231 | M37: =IF(K37="Fully accepted","Done",IF(F37="N/A","N/A",IF(F37="Returned","Returned: resubmit",IF(K37="TPOC only","Awaiting TPOC",IF(K37="AAS COR only","Awaiting AAS COR",IF(F37="Submitted","Awaiting AAS COR + TPOC",IF(A37<TodayD,"OVERDUE",IF(A37-TodayD<=7,"Due within 7 days",""))))))))
A38: =PeriodEnd-60 -> 46539 | B38: =TEXT(A38,"ddd") -> Tue | C38: C1.3 | D38: C1.3 – MSR content: identify recurring requirements eligible to transition (60 days before option period ends) | E38: One-time | K38: =IF(AND(H38<>"",J38<>""),"Fully accepted",IF(H38<>"","AAS COR only",IF(J38<>"","TPOC only",""))) | L38: =A38-TodayD -> 231 | M38: =IF(K38="Fully accepted","Done",IF(F38="N/A","N/A",IF(F38="Returned","Returned: resubmit",IF(K38="TPOC only","Awaiting TPOC",IF(K38="AAS COR only","Awaiting AAS COR",IF(F38="Submitted","Awaiting AAS COR + TPOC",IF(A38<TodayD,"OVERDUE",IF(A38-TodayD<=7,"Due within 7 days","")))))))) | N38: C.5.1.3.
A39: =Monthly!R19 -> 46539 | B39: =TEXT(A39,"ddd") -> Tue | C39: C1.4 | D39: Technical Status Meeting Minutes – May 2027 | E39: Monthly | F39: =IF(Monthly!R20="","",Monthly!R20) | G39: =IF(Monthly!R21="","",Monthly!R21) | H39: =IF(Monthly!R22="","",Monthly!R22) | I39: =IF(Monthly!R23="","",Monthly!R23) | J39: =IF(Monthly!R24="","",Monthly!R24) | K39: =IF(AND(H39<>"",J39<>""),"Fully accepted",IF(H39<>"","AAS COR only",IF(J39<>"","TPOC only",""))) | L39: =A39-TodayD -> 231 | M39: =IF(K39="Fully accepted","Done",IF(F39="N/A","N/A",IF(F39="Returned","Returned: resubmit",IF(K39="TPOC only","Awaiting TPOC",IF(K39="AAS COR only","Awaiting AAS COR",IF(F39="Submitted","Awaiting AAS COR + TPOC",IF(A39<TodayD,"OVERDUE",IF(A39-TodayD<=7,"Due within 7 days",""))))))))
A40: =Monthly!R5 -> 46539 | B40: =TEXT(A40,"ddd") -> Tue | C40: D01 | D40: Monthly Status of GFP and CAP – May 2027 | E40: Monthly | F40: =IF(Monthly!R6="","",Monthly!R6) | G40: =IF(Monthly!R7="","",Monthly!R7) | H40: =IF(Monthly!R8="","",Monthly!R8) | I40: =IF(Monthly!R9="","",Monthly!R9) | J40: =IF(Monthly!R10="","",Monthly!R10) | K40: =IF(AND(H40<>"",J40<>""),"Fully accepted",IF(H40<>"","AAS COR only",IF(J40<>"","TPOC only",""))) | L40: =A40-TodayD -> 231 | M40: =IF(K40="Fully accepted","Done",IF(F40="N/A","N/A",IF(F40="Returned","Returned: resubmit",IF(K40="TPOC only","Awaiting TPOC",IF(K40="AAS COR only","Awaiting AAS COR",IF(F40="Submitted","Awaiting AAS COR + TPOC",IF(A40<TodayD,"OVERDUE",IF(A40-TodayD<=7,"Due within 7 days",""))))))))
...
