Workbook

Sheet Tracker
A1: Project Plan P018 (J6 Comm Support) – Deliverable Tracker
A2: Project Plan # P018 (Deliverable 04) | TO 47QFCA24F0049 LEIA | Contract 47QFCA22D0032 | INDOPACOM J6 | 7600A 47QFCA24S0224 | Signed 31 Mar 2025 | PoP stated as 20MAR24 [sic] – 31JUL25
A3: Government POCs | C3: Req. Owner: Dr. Marvina Harring | AAS COR/PM: Foster Folger | AAS ACOR: Donald Shevlin | TO TPOC: Keith Stilwell | SMX Project Lead: Darren Conrad
A5: At a glance | C5: Overdue | D5: Due within 7 days | E5: Awaiting AAS COR / TPOC / Req Owner | F5: Fully accepted | G5: Returned: resubmit | H5: PWS paragraphs with no deliverable
C6: =COUNTIF('Daily Agenda'!$M$5:$M$44,"OVERDUE") -> 40 | D6: =COUNTIF('Daily Agenda'!$M$5:$M$44,"Due within 7 days") -> 0 | E6: =COUNTIF('Daily Agenda'!$M$5:$M$44,"Awaiting*") -> 0 | F6: =COUNTIF('Daily Agenda'!$M$5:$M$44,"Done") -> 0 | G6: =COUNTIF('Daily Agenda'!$M$5:$M$44,"Returned: resubmit") -> 0 | H6: =COUNTIF($I$9:$M$30,"None named*") -> 0
AB7: Lists (dropdown sources). Names you type into an Accepted By cell do not have to be on a list.
A8: Month | B8: Sub Task Number | C8: Paragraph / Section | D8: Frequency | E8: Category | F8: Primary POC | G8: Secondary POC | H8: Format of Deliverable | I8: Deliverable 1 | J8: Deliverable 2 | K8: Deliverable 3 | L8: Deliverable 4 | M8: Deliverable 5 | N8: Status Flow 1 | O8: Status Flow 2 | P8: Status Flow 3 | Q8: AAS COR Accepted By | R8: AAS COR Date Accepted | S8: TPOC / Req Owner Accepted By | T8: TPOC / Req Owner Date Accepted | AB8: Category | AC8: Status Flow 1 | AD8: Status Flow 2 | AE8: Status Flow 3 | AF8: Frequency | AG8: Month | AH8: AAS COR Acceptors | AI8: TPOC / Req Owner Acceptors
A9: Apr | B9: C.5.1.3 | C9: Monthly Status Report | D9: Monthly | E9: Program Mgmt | F9: Dr. Marvina Harring (Req. Owner) | G9: Keith Stilwell (TPOC) | H9: Contractor format | I9: F01 Monthly Status Report | N9: Not Received | O9: Not Reviewed | AB9: Cybersecurity | AC9: Received | AD9: Reviewed | AE9: Accepted | AF9: Weekly | AG9: Jan | AH9: Foster Folger (AAS COR / PM) | AI9: Keith Stilwell (TO TPOC)
H10: Due / Frequency (per document) | I10: Due: 1st calendar day of each month Freq: 5 copies (monthly) Flag: LEIA TO Deliverable 01 is the monthly GFP/CAP status; P018 labels F01 the Monthly Status Report. | AB10: Intelligence | AC10: Not Received | AD10: Not Reviewed | AE10: Returned | AF10: Monthly | AG10: Feb | AH10: Donald Shevlin (AAS ACOR) | AI10: Dr. Marvina Harring (Requirement Owner)
A11: Apr | B11: C.5.1.5 | C11: Project Plan (this document) | D11: One-Time | E11: Program Mgmt | F11: Dr. Marvina Harring (Req. Owner) | G11: Keith Stilwell (TPOC) | H11: Contractor format | I11: F04 Project Plan (this document) | N11: Not Received | O11: Not Reviewed | AB11: Logistics | AD11: Demonstrated | AE11: Returned, but Fixed | AF11: Quarterly | AG11: Mar
H12: Due / Frequency (per document) | I12: Due: At Project Kick-Off Meeting Freq: 1 Date: 20 Mar 2025 (signed 31 Mar 2025) Flag: P018 cites C.5.1.5 (the PMP paragraph); the Project Plan paragraph in the TO is C.5.1.6. | AB12: Operations | AD12: Not Demonstrated | AF12: Annual | AG12: Apr
A13: Apr | B13: C.5.2 | C13: Task 2 – C6ISR Operations | D13: Monthly | E13: Operations | F13: Dr. Marvina Harring (Req. Owner) | G13: Keith Stilwell (TPOC) | H13: Contractor format | I13: F09 C6ISR Operations Deliverables | N13: Not Received | O13: Not Reviewed | AB13: Program Mgmt | AF13: Daily (standing) | AG13: May
H14: Due / Frequency (per document) | I14: Due: ICW MSR (in concert with the Monthly Status Report) Freq: Number 02 Flag: "Number" column values are not explained in the Project Plan. | AB14: Solutions | AF14: One-Time | AG14: Jun
A15: Apr | B15: C.5.3 | C15: Task 3 – C6ISR Solutions | D15: Monthly | E15: Solutions | F15: Dr. Marvina Harring (Req. Owner) | G15: Keith Stilwell (TPOC) | H15: Contractor format | I15: F10 C6ISR Solutions Deliverables | N15: Not Received | O15: Not Reviewed | AB15: Training | AF15: One-Time + Updates | AG15: Jul
H16: Due / Frequency (per document) | I16: Due: ICW MSR (in concert with the Monthly Status Report) Freq: Number 03 | AF16: As Needed | AG16: Aug
A17: Apr | B17: C.5.4 | C17: Task 4 – Intelligence Operations | D17: Monthly | E17: Intelligence | F17: Dr. Marvina Harring (Req. Owner) | G17: Keith Stilwell (TPOC) | H17: Contractor format | I17: F11 Intelligence Operations Deliverables | N17: Not Received | O17: Not Reviewed | AF17: Not required (suspended) | AG17: Sep
H18: Due / Frequency (per document) | I18: Due: ICW MSR (in concert with the Monthly Status Report) Freq: Number 04 | AF18: Mixed (see due row) | AG18: Oct
A19: Apr | B19: C.5.5 | C19: Task 5 – Training | D19: Monthly | E19: Training | F19: Dr. Marvina Harring (Req. Owner) | G19: Keith Stilwell (TPOC) | H19: Contractor format | I19: F12 Training Deliverables | N19: Not Received | O19: Not Reviewed | AF19: None named | AG19: Nov
H20: Due / Frequency (per document) | I20: Due: ICW MSR (in concert with the Monthly Status Report) Freq: Number 05 | AG20: Dec
A21: Apr | B21: C.5.6 | C21: Task 6 – Cybersecurity and IA | D21: Monthly | E21: Cybersecurity | F21: Dr. Marvina Harring (Req. Owner) | G21: Keith Stilwell (TPOC) | H21: Contractor format | I21: F13 Cybersecurity and Information Assurance Deliverables | N21: Not Received | O21: Not Reviewed
H22: Due / Frequency (per document) | I22: Due: ICW MSR (in concert with the Monthly Status Report) Freq: Number 06
A23: Apr | B23: C.5.7 | C23: Task 7 – Logistics | D23: Monthly | E23: Logistics | F23: Dr. Marvina Harring (Req. Owner) | G23: Keith Stilwell (TPOC) | H23: Contractor format | I23: F14 Logistics Deliverables | N23: Not Received | O23: Not Reviewed
H24: Due / Frequency (per document) | I24: Due: ICW MSR (in concert with the Monthly Status Report) Freq: Number 07
A25: Apr | B25: Section 3 | C25: Project Milestones (1 of 2) | D25: One-Time | E25: Program Mgmt | F25: Dr. Marvina Harring (Req. Owner) | G25: Keith Stilwell (TPOC) | H25: n/a | I25: M01 Project Kick-Off Meeting Briefing | J25: M02 Project Plan | K25: M03 Project Initiation | L25: M04 Program Management Services initiation | M25: M05 C6ISR Operations Services initiation | N25: Not Received | O25: Not Reviewed
H26: Due / Frequency (per document) | I26: Due: O/A 20 Mar 2025 Freq: Milestone | J26: Due: O/A 20 Mar 2025 Freq: Milestone | K26: Due: O/A 01 Apr 2025 Freq: Milestone | L26: Due: O/A 01 Apr 2025 Freq: Milestone | M26: Due: O/A 01 Apr 2025 Freq: Milestone
A27: Apr | B27: Section 3 | C27: Project Milestones (2 of 2) | D27: One-Time | E27: Program Mgmt | F27: Dr. Marvina Harring (Req. Owner) | G27: Keith Stilwell (TPOC) | H27: n/a | I27: M06 C6ISR Solutions Services initiation | J27: M07 Training and Equipment Services initiation | K27: M08 Cybersecurity and IA Services initiation | L27: M09 Logistics Services initiation | N27: Not Received | O27: Not Reviewed
H28: Due / Frequency (per document) | I28: Due: O/A 01 Apr 2025 Freq: Milestone | J28: Due: O/A 01 Apr 2025 Freq: Milestone | K28: Due: O/A 01 Apr 2025 Freq: Milestone | L28: Due: O/A 01 Apr 2025 Freq: Milestone
A29: Apr | B29: Section 7 | C29: Project Management Plan and self-assessment | D29: As Needed | E29: Program Mgmt | F29: Dr. Marvina Harring (Req. Owner) | G29: Keith Stilwell (TPOC) | H29: Contractor format | I29: P71 PMP update (Project Plan 7.1) | J29: P72 Project Lead self-assessment (7.2) | N29: Not Received | O29: Not Reviewed
H30: Due / Frequency (per document) | I30: Due: Not stated Freq: As needed | J30: Due: Every six months Freq: Every 6 months Flag: Every six months from 20 Mar 2025 is 20 Sep 2025, after the 31 Jul 2025 end of Activity 1.
A32: Activity 1 ended 31 Jul 2025 unless extended by modification. Every date is in the past as of today, so items show OVERDUE until you back-fill who accepted them and when (or mark them N/A). Fully accepted = both dates filled in.

Sheet Monthly
A1: Monthly Deliverables – MSR and companion deliverables (due the 1st calendar day of each month)
A2: Project Plan # P018 (Deliverable 04) | TO 47QFCA24F0049 LEIA | Contract 47QFCA22D0032 | INDOPACOM J6 | 7600A 47QFCA24S0224 | Signed 31 Mar 2025 | PoP stated as 20MAR24 [sic] – 31JUL25
A4: ID | B4: Deliverable | C4: PWS ¶ | D4: Primary POC | E4: Secondary POC | F4: Record | G4: Fully accepted | H4: Overdue | I4: =EDATE(DATE(YEAR(ClockStart),MONTH(ClockStart),1),0) -> 45717 | J4: =EDATE(DATE(YEAR(ClockStart),MONTH(ClockStart),1),1) -> 45748 | K4: =EDATE(DATE(YEAR(ClockStart),MONTH(ClockStart),1),2) -> 45778 | L4: =EDATE(DATE(YEAR(ClockStart),MONTH(ClockStart),1),3) -> 45809 | M4: =EDATE(DATE(YEAR(ClockStart),MONTH(ClockStart),1),4) -> 45839
A5: F01 | B5: Monthly Status Report | C5: C.5.1.3 | D5: Dr. Marvina Harring (Req. Owner) | E5: Keith Stilwell (TPOC) | F5: Due date | G5: =SUMPRODUCT((I8:M8<>"")*(I10:M10<>"")) -> 0 | H5: =SUMPRODUCT((I5:M5<TODAY())*(((I6:M6="")+(I6:M6="In Progress"))>0)*(((I8:M8="")+(I10:M10=""))>0)) -> 5 | I5: =WORKDAY(DATE(YEAR(I$4),MONTH(I$4)+1,1)-1,1) -> 45748 | J5: =WORKDAY(DATE(YEAR(J$4),MONTH(J$4)+1,1)-1,1) -> 45778 | K5: =WORKDAY(DATE(YEAR(K$4),MONTH(K$4)+1,1)-1,1) -> 45810 | L5: =WORKDAY(DATE(YEAR(L$4),MONTH(L$4)+1,1)-1,1) -> 45839 | M5: =WORKDAY(DATE(YEAR(M$4),MONTH(M$4)+1,1)-1,1) -> 45870
F6: Status
F7: AAS COR accepted by
F8: AAS COR date accepted
F9: TPOC / Req Owner accepted by
F10: TPOC / Req Owner date accepted
F11: Result | I11: =IF(AND(I8<>"",I10<>""),"Fully accepted",IF(I8<>"","AAS COR only",IF(I10<>"","TPOC / Req Owner only",""))) | J11: =IF(AND(J8<>"",J10<>""),"Fully accepted",IF(J8<>"","AAS COR only",IF(J10<>"","TPOC / Req Owner only",""))) | K11: =IF(AND(K8<>"",K10<>""),"Fully accepted",IF(K8<>"","AAS COR only",IF(K10<>"","TPOC / Req Owner only",""))) | L11: =IF(AND(L8<>"",L10<>""),"Fully accepted",IF(L8<>"","AAS COR only",IF(L10<>"","TPOC / Req Owner only",""))) | M11: =IF(AND(M8<>"",M10<>""),"Fully accepted",IF(M8<>"","AAS COR only",IF(M10<>"","TPOC / Req Owner only","")))
A12: F09 | B12: C6ISR Operations Deliverables | C12: C.5.2 | D12: Dr. Marvina Harring (Req. Owner) | E12: Keith Stilwell (TPOC) | F12: Due date | G12: =SUMPRODUCT((I15:M15<>"")*(I17:M17<>"")) -> 0 | H12: =SUMPRODUCT((I12:M12<TODAY())*(((I13:M13="")+(I13:M13="In Progress"))>0)*(((I15:M15="")+(I17:M17=""))>0)) -> 5 | I12: =WORKDAY(DATE(YEAR(I$4),MONTH(I$4)+1,1)-1,1) -> 45748 | J12: =WORKDAY(DATE(YEAR(J$4),MONTH(J$4)+1,1)-1,1) -> 45778 | K12: =WORKDAY(DATE(YEAR(K$4),MONTH(K$4)+1,1)-1,1) -> 45810 | L12: =WORKDAY(DATE(YEAR(L$4),MONTH(L$4)+1,1)-1,1) -> 45839 | M12: =WORKDAY(DATE(YEAR(M$4),MONTH(M$4)+1,1)-1,1) -> 45870
F13: Status
F14: AAS COR accepted by
F15: AAS COR date accepted
F16: TPOC / Req Owner accepted by
F17: TPOC / Req Owner date accepted
F18: Result | I18: =IF(AND(I15<>"",I17<>""),"Fully accepted",IF(I15<>"","AAS COR only",IF(I17<>"","TPOC / Req Owner only",""))) | J18: =IF(AND(J15<>"",J17<>""),"Fully accepted",IF(J15<>"","AAS COR only",IF(J17<>"","TPOC / Req Owner only",""))) | K18: =IF(AND(K15<>"",K17<>""),"Fully accepted",IF(K15<>"","AAS COR only",IF(K17<>"","TPOC / Req Owner only",""))) | L18: =IF(AND(L15<>"",L17<>""),"Fully accepted",IF(L15<>"","AAS COR only",IF(L17<>"","TPOC / Req Owner only",""))) | M18: =IF(AND(M15<>"",M17<>""),"Fully accepted",IF(M15<>"","AAS COR only",IF(M17<>"","TPOC / Req Owner only","")))
A19: F10 | B19: C6ISR Solutions Deliverables | C19: C.5.3 | D19: Dr. Marvina Harring (Req. Owner) | E19: Keith Stilwell (TPOC) | F19: Due date | G19: =SUMPRODUCT((I22:M22<>"")*(I24:M24<>"")) -> 0 | H19: =SUMPRODUCT((I19:M19<TODAY())*(((I20:M20="")+(I20:M20="In Progress"))>0)*(((I22:M22="")+(I24:M24=""))>0)) -> 5 | I19: =WORKDAY(DATE(YEAR(I$4),MONTH(I$4)+1,1)-1,1) -> 45748 | J19: =WORKDAY(DATE(YEAR(J$4),MONTH(J$4)+1,1)-1,1) -> 45778 | K19: =WORKDAY(DATE(YEAR(K$4),MONTH(K$4)+1,1)-1,1) -> 45810 | L19: =WORKDAY(DATE(YEAR(L$4),MONTH(L$4)+1,1)-1,1) -> 45839 | M19: =WORKDAY(DATE(YEAR(M$4),MONTH(M$4)+1,1)-1,1) -> 45870
F20: Status
F21: AAS COR accepted by
F22: AAS COR date accepted
F23: TPOC / Req Owner accepted by
F24: TPOC / Req Owner date accepted
F25: Result | I25: =IF(AND(I22<>"",I24<>""),"Fully accepted",IF(I22<>"","AAS COR only",IF(I24<>"","TPOC / Req Owner only",""))) | J25: =IF(AND(J22<>"",J24<>""),"Fully accepted",IF(J22<>"","AAS COR only",IF(J24<>"","TPOC / Req Owner only",""))) | K25: =IF(AND(K22<>"",K24<>""),"Fully accepted",IF(K22<>"","AAS COR only",IF(K24<>"","TPOC / Req Owner only",""))) | L25: =IF(AND(L22<>"",L24<>""),"Fully accepted",IF(L22<>"","AAS COR only",IF(L24<>"","TPOC / Req Owner only",""))) | M25: =IF(AND(M22<>"",M24<>""),"Fully accepted",IF(M22<>"","AAS COR only",IF(M24<>"","TPOC / Req Owner only","")))
A26: F11 | B26: Intelligence Operations Deliverables | C26: C.5.4 | D26: Dr. Marvina Harring (Req. Owner) | E26: Keith Stilwell (TPOC) | F26: Due date | G26: =SUMPRODUCT((I29:M29<>"")*(I31:M31<>"")) -> 0 | H26: =SUMPRODUCT((I26:M26<TODAY())*(((I27:M27="")+(I27:M27="In Progress"))>0)*(((I29:M29="")+(I31:M31=""))>0)) -> 5 | I26: =WORKDAY(DATE(YEAR(I$4),MONTH(I$4)+1,1)-1,1) -> 45748 | J26: =WORKDAY(DATE(YEAR(J$4),MONTH(J$4)+1,1)-1,1) -> 45778 | K26: =WORKDAY(DATE(YEAR(K$4),MONTH(K$4)+1,1)-1,1) -> 45810 | L26: =WORKDAY(DATE(YEAR(L$4),MONTH(L$4)+1,1)-1,1) -> 45839 | M26: =WORKDAY(DATE(YEAR(M$4),MONTH(M$4)+1,1)-1,1) -> 45870
F27: Status
F28: AAS COR accepted by
F29: AAS COR date accepted
F30: TPOC / Req Owner accepted by
F31: TPOC / Req Owner date accepted
F32: Result | I32: =IF(AND(I29<>"",I31<>""),"Fully accepted",IF(I29<>"","AAS COR only",IF(I31<>"","TPOC / Req Owner only",""))) | J32: =IF(AND(J29<>"",J31<>""),"Fully accepted",IF(J29<>"","AAS COR only",IF(J31<>"","TPOC / Req Owner only",""))) | K32: =IF(AND(K29<>"",K31<>""),"Fully accepted",IF(K29<>"","AAS COR only",IF(K31<>"","TPOC / Req Owner only",""))) | L32: =IF(AND(L29<>"",L31<>""),"Fully accepted",IF(L29<>"","AAS COR only",IF(L31<>"","TPOC / Req Owner only",""))) | M32: =IF(AND(M29<>"",M31<>""),"Fully accepted",IF(M29<>"","AAS COR only",IF(M31<>"","TPOC / Req Owner only","")))
A33: F12 | B33: Training Deliverables | C33: C.5.5 | D33: Dr. Marvina Harring (Req. Owner) | E33: Keith Stilwell (TPOC) | F33: Due date | G33: =SUMPRODUCT((I36:M36<>"")*(I38:M38<>"")) -> 0 | H33: =SUMPRODUCT((I33:M33<TODAY())*(((I34:M34="")+(I34:M34="In Progress"))>0)*(((I36:M36="")+(I38:M38=""))>0)) -> 5 | I33: =WORKDAY(DATE(YEAR(I$4),MONTH(I$4)+1,1)-1,1) -> 45748 | J33: =WORKDAY(DATE(YEAR(J$4),MONTH(J$4)+1,1)-1,1) -> 45778 | K33: =WORKDAY(DATE(YEAR(K$4),MONTH(K$4)+1,1)-1,1) -> 45810 | L33: =WORKDAY(DATE(YEAR(L$4),MONTH(L$4)+1,1)-1,1) -> 45839 | M33: =WORKDAY(DATE(YEAR(M$4),MONTH(M$4)+1,1)-1,1) -> 45870
F34: Status
F35: AAS COR accepted by
F36: AAS COR date accepted
F37: TPOC / Req Owner accepted by
F38: TPOC / Req Owner date accepted
F39: Result | I39: =IF(AND(I36<>"",I38<>""),"Fully accepted",IF(I36<>"","AAS COR only",IF(I38<>"","TPOC / Req Owner only",""))) | J39: =IF(AND(J36<>"",J38<>""),"Fully accepted",IF(J36<>"","AAS COR only",IF(J38<>"","TPOC / Req Owner only",""))) | K39: =IF(AND(K36<>"",K38<>""),"Fully accepted",IF(K36<>"","AAS COR only",IF(K38<>"","TPOC / Req Owner only",""))) | L39: =IF(AND(L36<>"",L38<>""),"Fully accepted",IF(L36<>"","AAS COR only",IF(L38<>"","TPOC / Req Owner only",""))) | M39: =IF(AND(M36<>"",M38<>""),"Fully accepted",IF(M36<>"","AAS COR only",IF(M38<>"","TPOC / Req Owner only","")))
A40: F13 | B40: Cybersecurity and Information Assurance Deliverables | C40: C.5.6 | D40: Dr. Marvina Harring (Req. Owner) | E40: Keith Stilwell (TPOC) | F40: Due date | G40: =SUMPRODUCT((I43:M43<>"")*(I45:M45<>"")) -> 0 | H40: =SUMPRODUCT((I40:M40<TODAY())*(((I41:M41="")+(I41:M41="In Progress"))>0)*(((I43:M43="")+(I45:M45=""))>0)) -> 5 | I40: =WORKDAY(DATE(YEAR(I$4),MONTH(I$4)+1,1)-1,1) -> 45748 | J40: =WORKDAY(DATE(YEAR(J$4),MONTH(J$4)+1,1)-1,1) -> 45778 | K40: =WORKDAY(DATE(YEAR(K$4),MONTH(K$4)+1,1)-1,1) -> 45810 | L40: =WORKDAY(DATE(YEAR(L$4),MONTH(L$4)+1,1)-1,1) -> 45839 | M40: =WORKDAY(DATE(YEAR(M$4),MONTH(M$4)+1,1)-1,1) -> 45870
F41: Status
...

Sheet Daily Agenda
A1: Daily Agenda – what is due, in date order
A2: Project Plan # P018 (Deliverable 04) | TO 47QFCA24F0049 LEIA | Contract 47QFCA22D0032 | INDOPACOM J6 | 7600A 47QFCA24S0224 | Signed 31 Mar 2025 | PoP stated as 20MAR24 [sic] – 31JUL25
P3: Settings (edit the yellow cells)
A4: Due Date | B4: Day | C4: ID | D4: Deliverable | E4: Source | F4: Status | G4: AAS COR Accepted By | H4: AAS COR Date Accepted | I4: TPOC / Req Owner Accepted By | J4: TPOC / Req Owner Date Accepted | K4: Result | L4: Days Until Due | M4: Flag | N4: Notes | P4: Clock start (Project Kick-Off, per Section 3) | Q4: 45736
A5: =ClockStart -> 45736 | B5: =TEXT(A5,"ddd") -> Thu | C5: F04 | D5: F04 – Project Plan (this document), at kick-off | E5: One-time | K5: =IF(AND(H5<>"",J5<>""),"Fully accepted",IF(H5<>"","AAS COR only",IF(J5<>"","TPOC / Req Owner only",""))) | L5: =A5-TodayD -> -572 | M5: =IF(K5="Fully accepted","Done",IF(F5="N/A","N/A",IF(F5="Returned","Returned: resubmit",IF(K5="TPOC / Req Owner only","Awaiting TPOC / Req Owner",IF(K5="AAS COR only","Awaiting AAS COR",IF(F5="Submitted","Awaiting AAS COR + TPOC / Req Owner",IF(A5<TodayD,"OVERDUE",IF(A5-TodayD<=7,"Due within 7 days","")))))))) -> OVERDUE | P5: End of Activity 1 (31 Jul 2025) | Q5: 45869
A6: =ClockStart -> 45736 | B6: =TEXT(A6,"ddd") -> Thu | C6: M01 | D6: M01 – Project Kick-Off Meeting Briefing (O/A) | E6: One-time | K6: =IF(AND(H6<>"",J6<>""),"Fully accepted",IF(H6<>"","AAS COR only",IF(J6<>"","TPOC / Req Owner only",""))) | L6: =A6-TodayD -> -572 | M6: =IF(K6="Fully accepted","Done",IF(F6="N/A","N/A",IF(F6="Returned","Returned: resubmit",IF(K6="TPOC / Req Owner only","Awaiting TPOC / Req Owner",IF(K6="AAS COR only","Awaiting AAS COR",IF(F6="Submitted","Awaiting AAS COR + TPOC / Req Owner",IF(A6<TodayD,"OVERDUE",IF(A6-TodayD<=7,"Due within 7 days","")))))))) -> OVERDUE | P6: End of final period | Q6: =PeriodEnd -> 45869
A7: =ClockStart -> 45736 | B7: =TEXT(A7,"ddd") -> Thu | C7: M02 | D7: M02 – Project Plan (O/A); F04 at kick-off | E7: One-time | K7: =IF(AND(H7<>"",J7<>""),"Fully accepted",IF(H7<>"","AAS COR only",IF(J7<>"","TPOC / Req Owner only",""))) | L7: =A7-TodayD -> -572 | M7: =IF(K7="Fully accepted","Done",IF(F7="N/A","N/A",IF(F7="Returned","Returned: resubmit",IF(K7="TPOC / Req Owner only","Awaiting TPOC / Req Owner",IF(K7="AAS COR only","Awaiting AAS COR",IF(F7="Submitted","Awaiting AAS COR + TPOC / Req Owner",IF(A7<TodayD,"OVERDUE",IF(A7-TodayD<=7,"Due within 7 days","")))))))) -> OVERDUE | N7: Signed 31 Mar 2025. | P7: Gov inspection window (workdays, per parent TO E.2) | Q7: 15
A8: =Monthly!I5 -> 45748 | B8: =TEXT(A8,"ddd") -> Tue | C8: F01 | D8: Monthly Status Report – Mar 2025 | E8: Monthly | F8: =IF(Monthly!I6="","",Monthly!I6) | G8: =IF(Monthly!I7="","",Monthly!I7) | H8: =IF(Monthly!I8="","",Monthly!I8) | I8: =IF(Monthly!I9="","",Monthly!I9) | J8: =IF(Monthly!I10="","",Monthly!I10) | K8: =IF(AND(H8<>"",J8<>""),"Fully accepted",IF(H8<>"","AAS COR only",IF(J8<>"","TPOC / Req Owner only",""))) | L8: =A8-TodayD -> -560 | M8: =IF(K8="Fully accepted","Done",IF(F8="N/A","N/A",IF(F8="Returned","Returned: resubmit",IF(K8="TPOC / Req Owner only","Awaiting TPOC / Req Owner",IF(K8="AAS COR only","Awaiting AAS COR",IF(F8="Submitted","Awaiting AAS COR + TPOC / Req Owner",IF(A8<TodayD,"OVERDUE",IF(A8-TodayD<=7,"Due within 7 days","")))))))) -> OVERDUE | P8: Resubmission window (workdays, per parent TO E.4) | Q8: 10
A9: =Monthly!I12 -> 45748 | B9: =TEXT(A9,"ddd") -> Tue | C9: F09 | D9: C6ISR Operations Deliverables – Mar 2025 | E9: Monthly | F9: =IF(Monthly!I13="","",Monthly!I13) | G9: =IF(Monthly!I14="","",Monthly!I14) | H9: =IF(Monthly!I15="","",Monthly!I15) | I9: =IF(Monthly!I16="","",Monthly!I16) | J9: =IF(Monthly!I17="","",Monthly!I17) | K9: =IF(AND(H9<>"",J9<>""),"Fully accepted",IF(H9<>"","AAS COR only",IF(J9<>"","TPOC / Req Owner only",""))) | L9: =A9-TodayD -> -560 | M9: =IF(K9="Fully accepted","Done",IF(F9="N/A","N/A",IF(F9="Returned","Returned: resubmit",IF(K9="TPOC / Req Owner only","Awaiting TPOC / Req Owner",IF(K9="AAS COR only","Awaiting AAS COR",IF(F9="Submitted","Awaiting AAS COR + TPOC / Req Owner",IF(A9<TodayD,"OVERDUE",IF(A9-TodayD<=7,"Due within 7 days","")))))))) -> OVERDUE | P9: Today | Q9: =TODAY() -> 46308
A10: =Monthly!I19 -> 45748 | B10: =TEXT(A10,"ddd") -> Tue | C10: F10 | D10: C6ISR Solutions Deliverables – Mar 2025 | E10: Monthly | F10: =IF(Monthly!I20="","",Monthly!I20) | G10: =IF(Monthly!I21="","",Monthly!I21) | H10: =IF(Monthly!I22="","",Monthly!I22) | I10: =IF(Monthly!I23="","",Monthly!I23) | J10: =IF(Monthly!I24="","",Monthly!I24) | K10: =IF(AND(H10<>"",J10<>""),"Fully accepted",IF(H10<>"","AAS COR only",IF(J10<>"","TPOC / Req Owner only",""))) | L10: =A10-TodayD -> -560 | M10: =IF(K10="Fully accepted","Done",IF(F10="N/A","N/A",IF(F10="Returned","Returned: resubmit",IF(K10="TPOC / Req Owner only","Awaiting TPOC / Req Owner",IF(K10="AAS COR only","Awaiting AAS COR",IF(F10="Submitted","Awaiting AAS COR + TPOC / Req Owner",IF(A10<TodayD,"OVERDUE",IF(A10-TodayD<=7,"Due within 7 days","")))))))) -> OVERDUE
A11: =Monthly!I26 -> 45748 | B11: =TEXT(A11,"ddd") -> Tue | C11: F11 | D11: Intelligence Operations Deliverables – Mar 2025 | E11: Monthly | F11: =IF(Monthly!I27="","",Monthly!I27) | G11: =IF(Monthly!I28="","",Monthly!I28) | H11: =IF(Monthly!I29="","",Monthly!I29) | I11: =IF(Monthly!I30="","",Monthly!I30) | J11: =IF(Monthly!I31="","",Monthly!I31) | K11: =IF(AND(H11<>"",J11<>""),"Fully accepted",IF(H11<>"","AAS COR only",IF(J11<>"","TPOC / Req Owner only",""))) | L11: =A11-TodayD -> -560 | M11: =IF(K11="Fully accepted","Done",IF(F11="N/A","N/A",IF(F11="Returned","Returned: resubmit",IF(K11="TPOC / Req Owner only","Awaiting TPOC / Req Owner",IF(K11="AAS COR only","Awaiting AAS COR",IF(F11="Submitted","Awaiting AAS COR + TPOC / Req Owner",IF(A11<TodayD,"OVERDUE",IF(A11-TodayD<=7,"Due within 7 days","")))))))) -> OVERDUE | P11: The Project Plan gives the PoP as "20MAR24 – 31JUL25". The start year is likely 20 Mar 2025 (kick-off date); 2025 is used.
A12: =Monthly!I33 -> 45748 | B12: =TEXT(A12,"ddd") -> Tue | C12: F12 | D12: Training Deliverables – Mar 2025 | E12: Monthly | F12: =IF(Monthly!I34="","",Monthly!I34) | G12: =IF(Monthly!I35="","",Monthly!I35) | H12: =IF(Monthly!I36="","",Monthly!I36) | I12: =IF(Monthly!I37="","",Monthly!I37) | J12: =IF(Monthly!I38="","",Monthly!I38) | K12: =IF(AND(H12<>"",J12<>""),"Fully accepted",IF(H12<>"","AAS COR only",IF(J12<>"","TPOC / Req Owner only",""))) | L12: =A12-TodayD -> -560 | M12: =IF(K12="Fully accepted","Done",IF(F12="N/A","N/A",IF(F12="Returned","Returned: resubmit",IF(K12="TPOC / Req Owner only","Awaiting TPOC / Req Owner",IF(K12="AAS COR only","Awaiting AAS COR",IF(F12="Submitted","Awaiting AAS COR + TPOC / Req Owner",IF(A12<TodayD,"OVERDUE",IF(A12-TodayD<=7,"Due within 7 days","")))))))) -> OVERDUE | P12: Dates are estimates until funds are accepted by the AAS-D COR and a modification is awarded.
A13: =Monthly!I40 -> 45748 | B13: =TEXT(A13,"ddd") -> Tue | C13: F13 | D13: Cybersecurity and Information Assurance Deliverables – Mar 2025 | E13: Monthly | F13: =IF(Monthly!I41="","",Monthly!I41) | G13: =IF(Monthly!I42="","",Monthly!I42) | H13: =IF(Monthly!I43="","",Monthly!I43) | I13: =IF(Monthly!I44="","",Monthly!I44) | J13: =IF(Monthly!I45="","",Monthly!I45) | K13: =IF(AND(H13<>"",J13<>""),"Fully accepted",IF(H13<>"","AAS COR only",IF(J13<>"","TPOC / Req Owner only",""))) | L13: =A13-TodayD -> -560 | M13: =IF(K13="Fully accepted","Done",IF(F13="N/A","N/A",IF(F13="Returned","Returned: resubmit",IF(K13="TPOC / Req Owner only","Awaiting TPOC / Req Owner",IF(K13="AAS COR only","Awaiting AAS COR",IF(F13="Submitted","Awaiting AAS COR + TPOC / Req Owner",IF(A13<TodayD,"OVERDUE",IF(A13-TodayD<=7,"Due within 7 days","")))))))) -> OVERDUE | P13: Holidays are not excluded from business-day math.
A14: =Monthly!I47 -> 45748 | B14: =TEXT(A14,"ddd") -> Tue | C14: F14 | D14: Logistics Deliverables – Mar 2025 | E14: Monthly | F14: =IF(Monthly!I48="","",Monthly!I48) | G14: =IF(Monthly!I49="","",Monthly!I49) | H14: =IF(Monthly!I50="","",Monthly!I50) | I14: =IF(Monthly!I51="","",Monthly!I51) | J14: =IF(Monthly!I52="","",Monthly!I52) | K14: =IF(AND(H14<>"",J14<>""),"Fully accepted",IF(H14<>"","AAS COR only",IF(J14<>"","TPOC / Req Owner only",""))) | L14: =A14-TodayD -> -560 | M14: =IF(K14="Fully accepted","Done",IF(F14="N/A","N/A",IF(F14="Returned","Returned: resubmit",IF(K14="TPOC / Req Owner only","Awaiting TPOC / Req Owner",IF(K14="AAS COR only","Awaiting AAS COR",IF(F14="Submitted","Awaiting AAS COR + TPOC / Req Owner",IF(A14<TodayD,"OVERDUE",IF(A14-TodayD<=7,"Due within 7 days","")))))))) -> OVERDUE
A15: =DATE(2025,4,1) -> 45748 | B15: =TEXT(A15,"ddd") -> Tue | C15: M03 | D15: M03 – Project Initiation and all service initiations (O/A 1 Apr 2025) | E15: One-time | K15: =IF(AND(H15<>"",J15<>""),"Fully accepted",IF(H15<>"","AAS COR only",IF(J15<>"","TPOC / Req Owner only",""))) | L15: =A15-TodayD -> -560 | M15: =IF(K15="Fully accepted","Done",IF(F15="N/A","N/A",IF(F15="Returned","Returned: resubmit",IF(K15="TPOC / Req Owner only","Awaiting TPOC / Req Owner",IF(K15="AAS COR only","Awaiting AAS COR",IF(F15="Submitted","Awaiting AAS COR + TPOC / Req Owner",IF(A15<TodayD,"OVERDUE",IF(A15-TodayD<=7,"Due within 7 days","")))))))) -> OVERDUE | N15: M03–M09 share this date.
A16: =Monthly!J5 -> 45778 | B16: =TEXT(A16,"ddd") -> Thu | C16: F01 | D16: Monthly Status Report – Apr 2025 | E16: Monthly | F16: =IF(Monthly!J6="","",Monthly!J6) | G16: =IF(Monthly!J7="","",Monthly!J7) | H16: =IF(Monthly!J8="","",Monthly!J8) | I16: =IF(Monthly!J9="","",Monthly!J9) | J16: =IF(Monthly!J10="","",Monthly!J10) | K16: =IF(AND(H16<>"",J16<>""),"Fully accepted",IF(H16<>"","AAS COR only",IF(J16<>"","TPOC / Req Owner only",""))) | L16: =A16-TodayD -> -530 | M16: =IF(K16="Fully accepted","Done",IF(F16="N/A","N/A",IF(F16="Returned","Returned: resubmit",IF(K16="TPOC / Req Owner only","Awaiting TPOC / Req Owner",IF(K16="AAS COR only","Awaiting AAS COR",IF(F16="Submitted","Awaiting AAS COR + TPOC / Req Owner",IF(A16<TodayD,"OVERDUE",IF(A16-TodayD<=7,"Due within 7 days","")))))))) -> OVERDUE
A17: =Monthly!J12 -> 45778 | B17: =TEXT(A17,"ddd") -> Thu | C17: F09 | D17: C6ISR Operations Deliverables – Apr 2025 | E17: Monthly | F17: =IF(Monthly!J13="","",Monthly!J13) | G17: =IF(Monthly!J14="","",Monthly!J14) | H17: =IF(Monthly!J15="","",Monthly!J15) | I17: =IF(Monthly!J16="","",Monthly!J16) | J17: =IF(Monthly!J17="","",Monthly!J17) | K17: =IF(AND(H17<>"",J17<>""),"Fully accepted",IF(H17<>"","AAS COR only",IF(J17<>"","TPOC / Req Owner only",""))) | L17: =A17-TodayD -> -530 | M17: =IF(K17="Fully accepted","Done",IF(F17="N/A","N/A",IF(F17="Returned","Returned: resubmit",IF(K17="TPOC / Req Owner only","Awaiting TPOC / Req Owner",IF(K17="AAS COR only","Awaiting AAS COR",IF(F17="Submitted","Awaiting AAS COR + TPOC / Req Owner",IF(A17<TodayD,"OVERDUE",IF(A17-TodayD<=7,"Due within 7 days","")))))))) -> OVERDUE
A18: =Monthly!J19 -> 45778 | B18: =TEXT(A18,"ddd") -> Thu | C18: F10 | D18: C6ISR Solutions Deliverables – Apr 2025 | E18: Monthly | F18: =IF(Monthly!J20="","",Monthly!J20) | G18: =IF(Monthly!J21="","",Monthly!J21) | H18: =IF(Monthly!J22="","",Monthly!J22) | I18: =IF(Monthly!J23="","",Monthly!J23) | J18: =IF(Monthly!J24="","",Monthly!J24) | K18: =IF(AND(H18<>"",J18<>""),"Fully accepted",IF(H18<>"","AAS COR only",IF(J18<>"","TPOC / Req Owner only",""))) | L18: =A18-TodayD -> -530 | M18: =IF(K18="Fully accepted","Done",IF(F18="N/A","N/A",IF(F18="Returned","Returned: resubmit",IF(K18="TPOC / Req Owner only","Awaiting TPOC / Req Owner",IF(K18="AAS COR only","Awaiting AAS COR",IF(F18="Submitted","Awaiting AAS COR + TPOC / Req Owner",IF(A18<TodayD,"OVERDUE",IF(A18-TodayD<=7,"Due within 7 days","")))))))) -> OVERDUE
A19: =Monthly!J26 -> 45778 | B19: =TEXT(A19,"ddd") -> Thu | C19: F11 | D19: Intelligence Operations Deliverables – Apr 2025 | E19: Monthly | F19: =IF(Monthly!J27="","",Monthly!J27) | G19: =IF(Monthly!J28="","",Monthly!J28) | H19: =IF(Monthly!J29="","",Monthly!J29) | I19: =IF(Monthly!J30="","",Monthly!J30) | J19: =IF(Monthly!J31="","",Monthly!J31) | K19: =IF(AND(H19<>"",J19<>""),"Fully accepted",IF(H19<>"","AAS COR only",IF(J19<>"","TPOC / Req Owner only",""))) | L19: =A19-TodayD -> -530 | M19: =IF(K19="Fully accepted","Done",IF(F19="N/A","N/A",IF(F19="Returned","Returned: resubmit",IF(K19="TPOC / Req Owner only","Awaiting TPOC / Req Owner",IF(K19="AAS COR only","Awaiting AAS COR",IF(F19="Submitted","Awaiting AAS COR + TPOC / Req Owner",IF(A19<TodayD,"OVERDUE",IF(A19-TodayD<=7,"Due within 7 days","")))))))) -> OVERDUE
A20: =Monthly!J33 -> 45778 | B20: =TEXT(A20,"ddd") -> Thu | C20: F12 | D20: Training Deliverables – Apr 2025 | E20: Monthly | F20: =IF(Monthly!J34="","",Monthly!J34) | G20: =IF(Monthly!J35="","",Monthly!J35) | H20: =IF(Monthly!J36="","",Monthly!J36) | I20: =IF(Monthly!J37="","",Monthly!J37) | J20: =IF(Monthly!J38="","",Monthly!J38) | K20: =IF(AND(H20<>"",J20<>""),"Fully accepted",IF(H20<>"","AAS COR only",IF(J20<>"","TPOC / Req Owner only",""))) | L20: =A20-TodayD -> -530 | M20: =IF(K20="Fully accepted","Done",IF(F20="N/A","N/A",IF(F20="Returned","Returned: resubmit",IF(K20="TPOC / Req Owner only","Awaiting TPOC / Req Owner",IF(K20="AAS COR only","Awaiting AAS COR",IF(F20="Submitted","Awaiting AAS COR + TPOC / Req Owner",IF(A20<TodayD,"OVERDUE",IF(A20-TodayD<=7,"Due within 7 days","")))))))) -> OVERDUE
A21: =Monthly!J40 -> 45778 | B21: =TEXT(A21,"ddd") -> Thu | C21: F13 | D21: Cybersecurity and Information Assurance Deliverables – Apr 2025 | E21: Monthly | F21: =IF(Monthly!J41="","",Monthly!J41) | G21: =IF(Monthly!J42="","",Monthly!J42) | H21: =IF(Monthly!J43="","",Monthly!J43) | I21: =IF(Monthly!J44="","",Monthly!J44) | J21: =IF(Monthly!J45="","",Monthly!J45) | K21: =IF(AND(H21<>"",J21<>""),"Fully accepted",IF(H21<>"","AAS COR only",IF(J21<>"","TPOC / Req Owner only",""))) | L21: =A21-TodayD -> -530 | M21: =IF(K21="Fully accepted","Done",IF(F21="N/A","N/A",IF(F21="Returned","Returned: resubmit",IF(K21="TPOC / Req Owner only","Awaiting TPOC / Req Owner",IF(K21="AAS COR only","Awaiting AAS COR",IF(F21="Submitted","Awaiting AAS COR + TPOC / Req Owner",IF(A21<TodayD,"OVERDUE",IF(A21-TodayD<=7,"Due within 7 days","")))))))) -> OVERDUE
A22: =Monthly!J47 -> 45778 | B22: =TEXT(A22,"ddd") -> Thu | C22: F14 | D22: Logistics Deliverables – Apr 2025 | E22: Monthly | F22: =IF(Monthly!J48="","",Monthly!J48) | G22: =IF(Monthly!J49="","",Monthly!J49) | H22: =IF(Monthly!J50="","",Monthly!J50) | I22: =IF(Monthly!J51="","",Monthly!J51) | J22: =IF(Monthly!J52="","",Monthly!J52) | K22: =IF(AND(H22<>"",J22<>""),"Fully accepted",IF(H22<>"","AAS COR only",IF(J22<>"","TPOC / Req Owner only",""))) | L22: =A22-TodayD -> -530 | M22: =IF(K22="Fully accepted","Done",IF(F22="N/A","N/A",IF(F22="Returned","Returned: resubmit",IF(K22="TPOC / Req Owner only","Awaiting TPOC / Req Owner",IF(K22="AAS COR only","Awaiting AAS COR",IF(F22="Submitted","Awaiting AAS COR + TPOC / Req Owner",IF(A22<TodayD,"OVERDUE",IF(A22-TodayD<=7,"Due within 7 days","")))))))) -> OVERDUE
A23: =Monthly!K5 -> 45810 | B23: =TEXT(A23,"ddd") -> Mon | C23: F01 | D23: Monthly Status Report – May 2025 | E23: Monthly | F23: =IF(Monthly!K6="","",Monthly!K6) | G23: =IF(Monthly!K7="","",Monthly!K7) | H23: =IF(Monthly!K8="","",Monthly!K8) | I23: =IF(Monthly!K9="","",Monthly!K9) | J23: =IF(Monthly!K10="","",Monthly!K10) | K23: =IF(AND(H23<>"",J23<>""),"Fully accepted",IF(H23<>"","AAS COR only",IF(J23<>"","TPOC / Req Owner only",""))) | L23: =A23-TodayD -> -498 | M23: =IF(K23="Fully accepted","Done",IF(F23="N/A","N/A",IF(F23="Returned","Returned: resubmit",IF(K23="TPOC / Req Owner only","Awaiting TPOC / Req Owner",IF(K23="AAS COR only","Awaiting AAS COR",IF(F23="Submitted","Awaiting AAS COR + TPOC / Req Owner",IF(A23<TodayD,"OVERDUE",IF(A23-TodayD<=7,"Due within 7 days","")))))))) -> OVERDUE
A24: =Monthly!K12 -> 45810 | B24: =TEXT(A24,"ddd") -> Mon | C24: F09 | D24: C6ISR Operations Deliverables – May 2025 | E24: Monthly | F24: =IF(Monthly!K13="","",Monthly!K13) | G24: =IF(Monthly!K14="","",Monthly!K14) | H24: =IF(Monthly!K15="","",Monthly!K15) | I24: =IF(Monthly!K16="","",Monthly!K16) | J24: =IF(Monthly!K17="","",Monthly!K17) | K24: =IF(AND(H24<>"",J24<>""),"Fully accepted",IF(H24<>"","AAS COR only",IF(J24<>"","TPOC / Req Owner only",""))) | L24: =A24-TodayD -> -498 | M24: =IF(K24="Fully accepted","Done",IF(F24="N/A","N/A",IF(F24="Returned","Returned: resubmit",IF(K24="TPOC / Req Owner only","Awaiting TPOC / Req Owner",IF(K24="AAS COR only","Awaiting AAS COR",IF(F24="Submitted","Awaiting AAS COR + TPOC / Req Owner",IF(A24<TodayD,"OVERDUE",IF(A24-TodayD<=7,"Due within 7 days","")))))))) -> OVERDUE
A25: =Monthly!K19 -> 45810 | B25: =TEXT(A25,"ddd") -> Mon | C25: F10 | D25: C6ISR Solutions Deliverables – May 2025 | E25: Monthly | F25: =IF(Monthly!K20="","",Monthly!K20) | G25: =IF(Monthly!K21="","",Monthly!K21) | H25: =IF(Monthly!K22="","",Monthly!K22) | I25: =IF(Monthly!K23="","",Monthly!K23) | J25: =IF(Monthly!K24="","",Monthly!K24) | K25: =IF(AND(H25<>"",J25<>""),"Fully accepted",IF(H25<>"","AAS COR only",IF(J25<>"","TPOC / Req Owner only",""))) | L25: =A25-TodayD -> -498 | M25: =IF(K25="Fully accepted","Done",IF(F25="N/A","N/A",IF(F25="Returned","Returned: resubmit",IF(K25="TPOC / Req Owner only","Awaiting TPOC / Req Owner",IF(K25="AAS COR only","Awaiting AAS COR",IF(F25="Submitted","Awaiting AAS COR + TPOC / Req Owner",IF(A25<TodayD,"OVERDUE",IF(A25-TodayD<=7,"Due within 7 days","")))))))) -> OVERDUE
A26: =Monthly!K26 -> 45810 | B26: =TEXT(A26,"ddd") -> Mon | C26: F11 | D26: Intelligence Operations Deliverables – May 2025 | E26: Monthly | F26: =IF(Monthly!K27="","",Monthly!K27) | G26: =IF(Monthly!K28="","",Monthly!K28) | H26: =IF(Monthly!K29="","",Monthly!K29) | I26: =IF(Monthly!K30="","",Monthly!K30) | J26: =IF(Monthly!K31="","",Monthly!K31) | K26: =IF(AND(H26<>"",J26<>""),"Fully accepted",IF(H26<>"","AAS COR only",IF(J26<>"","TPOC / Req Owner only",""))) | L26: =A26-TodayD -> -498 | M26: =IF(K26="Fully accepted","Done",IF(F26="N/A","N/A",IF(F26="Returned","Returned: resubmit",IF(K26="TPOC / Req Owner only","Awaiting TPOC / Req Owner",IF(K26="AAS COR only","Awaiting AAS COR",IF(F26="Submitted","Awaiting AAS COR + TPOC / Req Owner",IF(A26<TodayD,"OVERDUE",IF(A26-TodayD<=7,"Due within 7 days","")))))))) -> OVERDUE
A27: =Monthly!K33 -> 45810 | B27: =TEXT(A27,"ddd") -> Mon | C27: F12 | D27: Training Deliverables – May 2025 | E27: Monthly | F27: =IF(Monthly!K34="","",Monthly!K34) | G27: =IF(Monthly!K35="","",Monthly!K35) | H27: =IF(Monthly!K36="","",Monthly!K36) | I27: =IF(Monthly!K37="","",Monthly!K37) | J27: =IF(Monthly!K38="","",Monthly!K38) | K27: =IF(AND(H27<>"",J27<>""),"Fully accepted",IF(H27<>"","AAS COR only",IF(J27<>"","TPOC / Req Owner only",""))) | L27: =A27-TodayD -> -498 | M27: =IF(K27="Fully accepted","Done",IF(F27="N/A","N/A",IF(F27="Returned","Returned: resubmit",IF(K27="TPOC / Req Owner only","Awaiting TPOC / Req Owner",IF(K27="AAS COR only","Awaiting AAS COR",IF(F27="Submitted","Awaiting AAS COR + TPOC / Req Owner",IF(A27<TodayD,"OVERDUE",IF(A27-TodayD<=7,"Due within 7 days","")))))))) -> OVERDUE
A28: =Monthly!K40 -> 45810 | B28: =TEXT(A28,"ddd") -> Mon | C28: F13 | D28: Cybersecurity and Information Assurance Deliverables – May 2025 | E28: Monthly | F28: =IF(Monthly!K41="","",Monthly!K41) | G28: =IF(Monthly!K42="","",Monthly!K42) | H28: =IF(Monthly!K43="","",Monthly!K43) | I28: =IF(Monthly!K44="","",Monthly!K44) | J28: =IF(Monthly!K45="","",Monthly!K45) | K28: =IF(AND(H28<>"",J28<>""),"Fully accepted",IF(H28<>"","AAS COR only",IF(J28<>"","TPOC / Req Owner only",""))) | L28: =A28-TodayD -> -498 | M28: =IF(K28="Fully accepted","Done",IF(F28="N/A","N/A",IF(F28="Returned","Returned: resubmit",IF(K28="TPOC / Req Owner only","Awaiting TPOC / Req Owner",IF(K28="AAS COR only","Awaiting AAS COR",IF(F28="Submitted","Awaiting AAS COR + TPOC / Req Owner",IF(A28<TodayD,"OVERDUE",IF(A28-TodayD<=7,"Due within 7 days","")))))))) -> OVERDUE
A29: =Monthly!K47 -> 45810 | B29: =TEXT(A29,"ddd") -> Mon | C29: F14 | D29: Logistics Deliverables – May 2025 | E29: Monthly | F29: =IF(Monthly!K48="","",Monthly!K48) | G29: =IF(Monthly!K49="","",Monthly!K49) | H29: =IF(Monthly!K50="","",Monthly!K50) | I29: =IF(Monthly!K51="","",Monthly!K51) | J29: =IF(Monthly!K52="","",Monthly!K52) | K29: =IF(AND(H29<>"",J29<>""),"Fully accepted",IF(H29<>"","AAS COR only",IF(J29<>"","TPOC / Req Owner only",""))) | L29: =A29-TodayD -> -498 | M29: =IF(K29="Fully accepted","Done",IF(F29="N/A","N/A",IF(F29="Returned","Returned: resubmit",IF(K29="TPOC / Req Owner only","Awaiting TPOC / Req Owner",IF(K29="AAS COR only","Awaiting AAS COR",IF(F29="Submitted","Awaiting AAS COR + TPOC / Req Owner",IF(A29<TodayD,"OVERDUE",IF(A29-TodayD<=7,"Due within 7 days","")))))))) -> OVERDUE
A30: =Monthly!L5 -> 45839 | B30: =TEXT(A30,"ddd") -> Tue | C30: F01 | D30: Monthly Status Report – Jun 2025 | E30: Monthly | F30: =IF(Monthly!L6="","",Monthly!L6) | G30: =IF(Monthly!L7="","",Monthly!L7) | H30: =IF(Monthly!L8="","",Monthly!L8) | I30: =IF(Monthly!L9="","",Monthly!L9) | J30: =IF(Monthly!L10="","",Monthly!L10) | K30: =IF(AND(H30<>"",J30<>""),"Fully accepted",IF(H30<>"","AAS COR only",IF(J30<>"","TPOC / Req Owner only",""))) | L30: =A30-TodayD -> -469 | M30: =IF(K30="Fully accepted","Done",IF(F30="N/A","N/A",IF(F30="Returned","Returned: resubmit",IF(K30="TPOC / Req Owner only","Awaiting TPOC / Req Owner",IF(K30="AAS COR only","Awaiting AAS COR",IF(F30="Submitted","Awaiting AAS COR + TPOC / Req Owner",IF(A30<TodayD,"OVERDUE",IF(A30-TodayD<=7,"Due within 7 days","")))))))) -> OVERDUE
A31: =Monthly!L12 -> 45839 | B31: =TEXT(A31,"ddd") -> Tue | C31: F09 | D31: C6ISR Operations Deliverables – Jun 2025 | E31: Monthly | F31: =IF(Monthly!L13="","",Monthly!L13) | G31: =IF(Monthly!L14="","",Monthly!L14) | H31: =IF(Monthly!L15="","",Monthly!L15) | I31: =IF(Monthly!L16="","",Monthly!L16) | J31: =IF(Monthly!L17="","",Monthly!L17) | K31: =IF(AND(H31<>"",J31<>""),"Fully accepted",IF(H31<>"","AAS COR only",IF(J31<>"","TPOC / Req Owner only",""))) | L31: =A31-TodayD -> -469 | M31: =IF(K31="Fully accepted","Done",IF(F31="N/A","N/A",IF(F31="Returned","Returned: resubmit",IF(K31="TPOC / Req Owner only","Awaiting TPOC / Req Owner",IF(K31="AAS COR only","Awaiting AAS COR",IF(F31="Submitted","Awaiting AAS COR + TPOC / Req Owner",IF(A31<TodayD,"OVERDUE",IF(A31-TodayD<=7,"Due within 7 days","")))))))) -> OVERDUE
A32: =Monthly!L19 -> 45839 | B32: =TEXT(A32,"ddd") -> Tue | C32: F10 | D32: C6ISR Solutions Deliverables – Jun 2025 | E32: Monthly | F32: =IF(Monthly!L20="","",Monthly!L20) | G32: =IF(Monthly!L21="","",Monthly!L21) | H32: =IF(Monthly!L22="","",Monthly!L22) | I32: =IF(Monthly!L23="","",Monthly!L23) | J32: =IF(Monthly!L24="","",Monthly!L24) | K32: =IF(AND(H32<>"",J32<>""),"Fully accepted",IF(H32<>"","AAS COR only",IF(J32<>"","TPOC / Req Owner only",""))) | L32: =A32-TodayD -> -469 | M32: =IF(K32="Fully accepted","Done",IF(F32="N/A","N/A",IF(F32="Returned","Returned: resubmit",IF(K32="TPOC / Req Owner only","Awaiting TPOC / Req Owner",IF(K32="AAS COR only","Awaiting AAS COR",IF(F32="Submitted","Awaiting AAS COR + TPOC / Req Owner",IF(A32<TodayD,"OVERDUE",IF(A32-TodayD<=7,"Due within 7 days","")))))))) -> OVERDUE
A33: =Monthly!L26 -> 45839 | B33: =TEXT(A33,"ddd") -> Tue | C33: F11 | D33: Intelligence Operations Deliverables – Jun 2025 | E33: Monthly | F33: =IF(Monthly!L27="","",Monthly!L27) | G33: =IF(Monthly!L28="","",Monthly!L28) | H33: =IF(Monthly!L29="","",Monthly!L29) | I33: =IF(Monthly!L30="","",Monthly!L30) | J33: =IF(Monthly!L31="","",Monthly!L31) | K33: =IF(AND(H33<>"",J33<>""),"Fully accepted",IF(H33<>"","AAS COR only",IF(J33<>"","TPOC / Req Owner only",""))) | L33: =A33-TodayD -> -469 | M33: =IF(K33="Fully accepted","Done",IF(F33="N/A","N/A",IF(F33="Returned","Returned: resubmit",IF(K33="TPOC / Req Owner only","Awaiting TPOC / Req Owner",IF(K33="AAS COR only","Awaiting AAS COR",IF(F33="Submitted","Awaiting AAS COR + TPOC / Req Owner",IF(A33<TodayD,"OVERDUE",IF(A33-TodayD<=7,"Due within 7 days","")))))))) -> OVERDUE
A34: =Monthly!L33 -> 45839 | B34: =TEXT(A34,"ddd") -> Tue | C34: F12 | D34: Training Deliverables – Jun 2025 | E34: Monthly | F34: =IF(Monthly!L34="","",Monthly!L34) | G34: =IF(Monthly!L35="","",Monthly!L35) | H34: =IF(Monthly!L36="","",Monthly!L36) | I34: =IF(Monthly!L37="","",Monthly!L37) | J34: =IF(Monthly!L38="","",Monthly!L38) | K34: =IF(AND(H34<>"",J34<>""),"Fully accepted",IF(H34<>"","AAS COR only",IF(J34<>"","TPOC / Req Owner only",""))) | L34: =A34-TodayD -> -469 | M34: =IF(K34="Fully accepted","Done",IF(F34="N/A","N/A",IF(F34="Returned","Returned: resubmit",IF(K34="TPOC / Req Owner only","Awaiting TPOC / Req Owner",IF(K34="AAS COR only","Awaiting AAS COR",IF(F34="Submitted","Awaiting AAS COR + TPOC / Req Owner",IF(A34<TodayD,"OVERDUE",IF(A34-TodayD<=7,"Due within 7 days","")))))))) -> OVERDUE
A35: =Monthly!L40 -> 45839 | B35: =TEXT(A35,"ddd") -> Tue | C35: F13 | D35: Cybersecurity and Information Assurance Deliverables – Jun 2025 | E35: Monthly | F35: =IF(Monthly!L41="","",Monthly!L41) | G35: =IF(Monthly!L42="","",Monthly!L42) | H35: =IF(Monthly!L43="","",Monthly!L43) | I35: =IF(Monthly!L44="","",Monthly!L44) | J35: =IF(Monthly!L45="","",Monthly!L45) | K35: =IF(AND(H35<>"",J35<>""),"Fully accepted",IF(H35<>"","AAS COR only",IF(J35<>"","TPOC / Req Owner only",""))) | L35: =A35-TodayD -> -469 | M35: =IF(K35="Fully accepted","Done",IF(F35="N/A","N/A",IF(F35="Returned","Returned: resubmit",IF(K35="TPOC / Req Owner only","Awaiting TPOC / Req Owner",IF(K35="AAS COR only","Awaiting AAS COR",IF(F35="Submitted","Awaiting AAS COR + TPOC / Req Owner",IF(A35<TodayD,"OVERDUE",IF(A35-TodayD<=7,"Due within 7 days","")))))))) -> OVERDUE
A36: =Monthly!L47 -> 45839 | B36: =TEXT(A36,"ddd") -> Tue | C36: F14 | D36: Logistics Deliverables – Jun 2025 | E36: Monthly | F36: =IF(Monthly!L48="","",Monthly!L48) | G36: =IF(Monthly!L49="","",Monthly!L49) | H36: =IF(Monthly!L50="","",Monthly!L50) | I36: =IF(Monthly!L51="","",Monthly!L51) | J36: =IF(Monthly!L52="","",Monthly!L52) | K36: =IF(AND(H36<>"",J36<>""),"Fully accepted",IF(H36<>"","AAS COR only",IF(J36<>"","TPOC / Req Owner only",""))) | L36: =A36-TodayD -> -469 | M36: =IF(K36="Fully accepted","Done",IF(F36="N/A","N/A",IF(F36="Returned","Returned: resubmit",IF(K36="TPOC / Req Owner only","Awaiting TPOC / Req Owner",IF(K36="AAS COR only","Awaiting AAS COR",IF(F36="Submitted","Awaiting AAS COR + TPOC / Req Owner",IF(A36<TodayD,"OVERDUE",IF(A36-TodayD<=7,"Due within 7 days","")))))))) -> OVERDUE
A37: =Monthly!M5 -> 45870 | B37: =TEXT(A37,"ddd") -> Fri | C37: F01 | D37: Monthly Status Report – Jul 2025 | E37: Monthly | F37: =IF(Monthly!M6="","",Monthly!M6) | G37: =IF(Monthly!M7="","",Monthly!M7) | H37: =IF(Monthly!M8="","",Monthly!M8) | I37: =IF(Monthly!M9="","",Monthly!M9) | J37: =IF(Monthly!M10="","",Monthly!M10) | K37: =IF(AND(H37<>"",J37<>""),"Fully accepted",IF(H37<>"","AAS COR only",IF(J37<>"","TPOC / Req Owner only",""))) | L37: =A37-TodayD -> -438 | M37: =IF(K37="Fully accepted","Done",IF(F37="N/A","N/A",IF(F37="Returned","Returned: resubmit",IF(K37="TPOC / Req Owner only","Awaiting TPOC / Req Owner",IF(K37="AAS COR only","Awaiting AAS COR",IF(F37="Submitted","Awaiting AAS COR + TPOC / Req Owner",IF(A37<TodayD,"OVERDUE",IF(A37-TodayD<=7,"Due within 7 days","")))))))) -> OVERDUE
A38: =Monthly!M12 -> 45870 | B38: =TEXT(A38,"ddd") -> Fri | C38: F09 | D38: C6ISR Operations Deliverables – Jul 2025 | E38: Monthly | F38: =IF(Monthly!M13="","",Monthly!M13) | G38: =IF(Monthly!M14="","",Monthly!M14) | H38: =IF(Monthly!M15="","",Monthly!M15) | I38: =IF(Monthly!M16="","",Monthly!M16) | J38: =IF(Monthly!M17="","",Monthly!M17) | K38: =IF(AND(H38<>"",J38<>""),"Fully accepted",IF(H38<>"","AAS COR only",IF(J38<>"","TPOC / Req Owner only",""))) | L38: =A38-TodayD -> -438 | M38: =IF(K38="Fully accepted","Done",IF(F38="N/A","N/A",IF(F38="Returned","Returned: resubmit",IF(K38="TPOC / Req Owner only","Awaiting TPOC / Req Owner",IF(K38="AAS COR only","Awaiting AAS COR",IF(F38="Submitted","Awaiting AAS COR + TPOC / Req Owner",IF(A38<TodayD,"OVERDUE",IF(A38-TodayD<=7,"Due within 7 days","")))))))) -> OVERDUE
A39: =Monthly!M19 -> 45870 | B39: =TEXT(A39,"ddd") -> Fri | C39: F10 | D39: C6ISR Solutions Deliverables – Jul 2025 | E39: Monthly | F39: =IF(Monthly!M20="","",Monthly!M20) | G39: =IF(Monthly!M21="","",Monthly!M21) | H39: =IF(Monthly!M22="","",Monthly!M22) | I39: =IF(Monthly!M23="","",Monthly!M23) | J39: =IF(Monthly!M24="","",Monthly!M24) | K39: =IF(AND(H39<>"",J39<>""),"Fully accepted",IF(H39<>"","AAS COR only",IF(J39<>"","TPOC / Req Owner only",""))) | L39: =A39-TodayD -> -438 | M39: =IF(K39="Fully accepted","Done",IF(F39="N/A","N/A",IF(F39="Returned","Returned: resubmit",IF(K39="TPOC / Req Owner only","Awaiting TPOC / Req Owner",IF(K39="AAS COR only","Awaiting AAS COR",IF(F39="Submitted","Awaiting AAS COR + TPOC / Req Owner",IF(A39<TodayD,"OVERDUE",IF(A39-TodayD<=7,"Due within 7 days","")))))))) -> OVERDUE
A40: =Monthly!M26 -> 45870 | B40: =TEXT(A40,"ddd") -> Fri | C40: F11 | D40: Intelligence Operations Deliverables – Jul 2025 | E40: Monthly | F40: =IF(Monthly!M27="","",Monthly!M27) | G40: =IF(Monthly!M28="","",Monthly!M28) | H40: =IF(Monthly!M29="","",Monthly!M29) | I40: =IF(Monthly!M30="","",Monthly!M30) | J40: =IF(Monthly!M31="","",Monthly!M31) | K40: =IF(AND(H40<>"",J40<>""),"Fully accepted",IF(H40<>"","AAS COR only",IF(J40<>"","TPOC / Req Owner only",""))) | L40: =A40-TodayD -> -438 | M40: =IF(K40="Fully accepted","Done",IF(F40="N/A","N/A",IF(F40="Returned","Returned: resubmit",IF(K40="TPOC / Req Owner only","Awaiting TPOC / Req Owner",IF(K40="AAS COR only","Awaiting AAS COR",IF(F40="Submitted","Awaiting AAS COR + TPOC / Req Owner",IF(A40<TodayD,"OVERDUE",IF(A40-TodayD<=7,"Due within 7 days","")))))))) -> OVERDUE
...
