Workbook

Sheet Tracker
A1: Thunderdome ZT Production OTA – Deliverable Tracker
A2: Agreement HC1084-26-9-2023 | Vendor: Booz Allen Hamilton | PWS as of 02 Sep 2026 | Clock start 02 Sep 2026
A3: Government POCs | C3: COR / Primary: Christine Y. Shigeta (christine.y.shigeta.civ@us.navy.mil) | Secondary: Brian Abrigo, AOR (brian.k.abrigo.civ@us.navy.mil) | Second acceptor: J698
A5: At a glance | C5: Overdue | D5: Due within 7 days | E5: Awaiting COR / J698 | F5: Fully accepted | G5: Returned: resubmit | H5: PWS paragraphs with no deliverable
C6: =COUNTIF(Daily!$M$5:$M$129,"OVERDUE") -> 23 | D6: =COUNTIF(Daily!$M$5:$M$129,"Due within 7 days") -> 2 | E6: =COUNTIF(Daily!$M$5:$M$129,"Awaiting*") -> 0 | F6: =COUNTIF(Daily!$M$5:$M$129,"Done") -> 0 | G6: =COUNTIF(Daily!$M$5:$M$129,"Returned: resubmit") -> 0 | H6: =COUNTIF($I$9:$M$78,"None named in PWS") -> 8
AB7: Lists (dropdown sources). Add names below the last entry, then widen the range if needed.
A8: Month | B8: Sub Task Number | C8: Paragraph / Section | D8: Frequency | E8: Category | F8: Primary POC | G8: Secondary POC | H8: Format of Deliverable | I8: Deliverable 1 | J8: Deliverable 2 | K8: Deliverable 3 | L8: Deliverable 4 | M8: Deliverable 5 | N8: Status Flow 1 | O8: Status Flow 2 | P8: Status Flow 3 | Q8: COR Accepted By | R8: COR Date Accepted | S8: J698 Accepted By | T8: J698 Date Accepted | AB8: Category | AC8: Status Flow 1 | AD8: Status Flow 2 | AE8: Status Flow 3 | AF8: Frequency | AG8: Month | AH8: COR Acceptors | AI8: J698 Acceptors
A9: Oct | B9: 6.1 | C9: Zero Trust AI Implementation (1 of 2) | D9: Mixed (see due row) | E9: Engineering | F9: Christine Y. Shigeta | G9: Brian Abrigo | H9: Government format | I9: A001 Implementation Approach and Architecture | J9: A002 ZT Governance Plan | K9: A004 ATO Documentation/ Artifacts | L9: A005 POA&Ms including risk acceptance POA&Ms for vulnerabilities that cannot be mitigated and STIGs that cannot be applied. | M9: A006 STIG/SRG Checklists | N9: Not Received | O9: Not Reviewed | AB9: Program Mgmt | AC9: Received | AD9: Reviewed | AE9: Accepted | AF9: Weekly | AG9: Jan | AH9: Christine Y. Shigeta | AI9: J698
H10: Due / Frequency (per PWS) | I10: Due: IAW IMS Freq: One-Time, update as needed Flag: Due "IAW IMS"; IMS must exist first | J10: Due: IAW IMS Freq: One-Time, update as needed Flag: Due "IAW IMS" | K10: Due: IAW IMS Freq: One-Time, update as needed Flag: Due "IAW IMS" | L10: Due: 30 days post vulnerability identification (if vulnerability cannot be mitigated) Freq: As Needed Flag: Body: CAT I POA&M if no fix in 1 week | M10: Due: Routine Updates Freq: Quarterly Dates: see Quarterly tab | AB10: Engineering | AC10: Not Received | AD10: Not Reviewed | AE10: Returned | AF10: Monthly | AG10: Feb | AH10: Brian Abrigo
A11: Oct | B11: 6.1 | C11: Zero Trust AI Implementation (2 of 2) | D11: Mixed (see due row) | E11: Engineering | F11: Christine Y. Shigeta | G11: Brian Abrigo | H11: Mixed (see deliverables) | I11: A007 ACAS Scans | J11: A016 Briefings Slides | K11: A024 DoDAF Artifacts/Diagrams (e.g., OV, SV) | L11: A025 Engineering Artifacts (e.g., Network/System Diagrams) | M11: A026 Concept of Operations (CONOPS) | N11: Not Received | O11: Not Reviewed | AB11: Operations | AD11: Demonstrated | AE11: Returned, but Fixed | AF11: Quarterly | AG11: Mar
H12: Due / Frequency (per PWS) | I12: Due: As Needed Freq: Weekly Dates: see Weekly tab | J12: Due: As determined by the Government Freq: As required | K12: Due: As determined by the Government Freq: As needed | L12: Due: Within 10 business days after assignment Freq: As needed Flag: Near-duplicate of A032 | M12: Due: 60 days post deployment Freq: Once, updated yearly or with major change | AD12: Not Demonstrated | AF12: One-Time | AG12: Apr
A13: Oct | B13: 6.2.1 | C13: Cybersecurity Engineering / A&A (1 of 3) | D13: Mixed (see due row) | E13: Engineering | F13: Christine Y. Shigeta | G13: Brian Abrigo | H13: Mixed (see deliverables) | I13: A003 eMASS Data Entry | J13: A004 ATO Documentation/ Artifacts | K13: A005 POA&Ms including risk acceptance POA&Ms for vulnerabilities that cannot be mitigated and STIGs that cannot be applied. | L13: A006 STIG/SRG Checklists | M13: A007 ACAS Scans | N13: Not Received | O13: Not Reviewed | AF13: One-Time + Updates | AG13: May
H14: Due / Frequency (per PWS) | I14: Due: IAW IMS Freq: As Needed | J14: Due: IAW IMS Freq: One-Time, update as needed | K14: Due: 30 days post vulnerability identification (if vulnerability cannot be mitigated) Freq: As Needed | L14: Due: Routine Updates Freq: Quarterly Dates: see Quarterly tab | M14: Due: As Needed Freq: Weekly Dates: see Weekly tab | AF14: Per Package | AG14: Jun
A15: Oct | B15: 6.2.1 | C15: Cybersecurity Engineering / A&A (2 of 3) | D15: Mixed (see due row) | E15: Engineering | F15: Christine Y. Shigeta | G15: Brian Abrigo | H15: Mixed (see deliverables) | I15: A008 System Change Requests Form/ Configuration Change Request | J15: A009 eMASS Package | K15: A010 Status updates on Security patches/hot fixes, OPORD, TASK ORDER, FISMA, PPSM, IAVM and STIGs | L15: A011 Incident Response Plan | M15: A012 Security Monitoring Reports | N15: Not Received | O15: Not Reviewed | AF15: As Needed | AG15: Jul
H16: Due / Frequency (per PWS) | I16: Due: As needed Freq: As required | J16: Due: As needed Freq: One-Time per package, update as needed | K16: Due: As needed Freq: As required | L16: Due: IAW IMS Freq: One-Time, update as needed Flag: Due "IAW IMS" | M16: Due: Routine Updates Freq: Quarterly Dates: see Quarterly tab Flag: Same title as A040 | AF16: Mixed (see due row) | AG16: Aug
A17: Oct | B17: 6.2.1 | C17: Cybersecurity Engineering / A&A (3 of 3) | D17: Mixed (see due row) | E17: Engineering | F17: Christine Y. Shigeta | G17: Brian Abrigo | H17: Mixed (see deliverables) | I17: A013 Vulnerability Scan Reports | J17: A014 Compliance Documentation | K17: A015 Security Assessment Report | N17: Not Received | O17: Not Reviewed | AF17: None named | AG17: Sep
H18: Due / Frequency (per PWS) | I18: Due: Routine Updates Freq: Quarterly Dates: see Quarterly tab | J18: Due: 90 Days after award Freq: One per accreditation package Date: Tue 1 Dec 2026 | K18: Due: ICW Accreditation Freq: One per accreditation package | AG18: Oct
A19: Oct | B19: 6.2.2 | C19: Partner Nation Coordination / Country Desk Officer Support | D19: As Needed | E19: Program Mgmt | F19: Christine Y. Shigeta | G19: Brian Abrigo | H19: Vendor format | I19: A016 Briefings Slides | N19: Not Received | O19: Not Reviewed | AG19: Nov
H20: Due / Frequency (per PWS) | I20: Due: As determined by the Government Freq: As required | AG20: Dec
A21: Oct | B21: 6.3.1 | C21: Task Order Mgmt / PMO Support for PMN | D21: Monthly | E21: Program Mgmt | F21: Christine Y. Shigeta | G21: Brian Abrigo | H21: Vendor format | I21: A017 Integrated Master Schedule | N21: Not Received | O21: Not Reviewed
H22: Due / Frequency (per PWS) | I22: Due: As determined by the Government Freq: One per month Dates: see Monthly tab
A23: Oct | B23: 6.3.1.1 | C23: Monthly Progress Report | D23: Monthly | E23: Program Mgmt | F23: Christine Y. Shigeta | G23: Brian Abrigo | H23: Vendor format | I23: A018 Monthly Progress Report (MPR) (including Invoice Data, ODC Data, Travel Data) | N23: Not Received | O23: Not Reviewed
H24: Due / Frequency (per PWS) | I24: Due: As determined by the Government Freq: One per month Dates: see Monthly tab
A25: Oct | B25: 6.3.1.2 | C25: Weekly Activity Report | D25: Weekly | E25: Program Mgmt | F25: Christine Y. Shigeta | G25: Brian Abrigo | H25: Vendor format | I25: A019 Weekly Activity Report (WAR) | N25: Not Received | O25: Not Reviewed
H26: Due / Frequency (per PWS) | I26: Due: Every Friday Freq: Weekly Dates: see Weekly tab
A27: Oct | B27: 6.3.1.3 | C27: Transition Planning | D27: One-Time | E27: Program Mgmt | F27: Christine Y. Shigeta | G27: Brian Abrigo | H27: Vendor format | I27: A041 Transition-In Plan | J27: A042 Transition-Out Plan | K27: A043 Task Order Closeout | N27: Not Received | O27: Not Reviewed
H28: Due / Frequency (per PWS) | I28: Due: Initial Draft at Project Kickoff Meeting Final Draft 5 business days after contract award Freq: One-Time Date: draft Wed 2 Sep, final Wed 9 Sep 2026 Flag: Body: 30 days after kickoff | J28: Due: T-30 Days (30 Days Prior to Contract End) Freq: One-Time Date: Sun 3 Jan 2027 (base year only) or Fri 1 Jun 2029 Flag: Body: 120 days before end; table: T-30 | K28: Due: End of Contract Freq: One-Time Date: Mon 3 May 2027 (base year only) or Sat 29 Sep 2029
A29: Oct | B29: 6.3.1.4 | C29: HW / SW Maintenance Support (Logistics) | D29: Mixed (see due row) | E29: Operations | F29: Christine Y. Shigeta | G29: Brian Abrigo | H29: Vendor format | I29: A019 Weekly Activity Report (WAR) | J29: A044 Logistics Deliverables | N29: Not Received | O29: Not Reviewed
H30: Due / Frequency (per PWS) | I30: Due: Every Friday Freq: Weekly Dates: see Weekly tab | J30: Due: ICW MSR Freq: Updated as needed Flag: ICW MSR = Monthly Status Report; confirm it equals the MPR
A31: Oct | B31: 6.3.1.5 | C31: Communications | D31: None named | E31: Program Mgmt | F31: Christine Y. Shigeta | G31: Brian Abrigo | H31: n/a | I31: None named in PWS
H32: Due / Frequency (per PWS) | I32: PWS requires: Marketing material, engagement strategy. No deliverable ID or due date.
A33: Oct | B33: 6.3.1.6 | C33: Cyber Capacity | D33: None named | E33: Program Mgmt | F33: Christine Y. Shigeta | G33: Brian Abrigo | H33: n/a | I33: None named in PWS
H34: Due / Frequency (per PWS) | I34: PWS requires: Capacity-building objectives and engagements. No deliverable ID or due date.
A35: Oct | B35: 6.3.1.7 | C35: Knowledge Mgmt, Technical Documentation and Meeting Support | D35: Mixed (see due row) | E35: Program Mgmt | F35: Christine Y. Shigeta | G35: Brian Abrigo | H35: Vendor format | I35: A020 Technical Library Documentation Report | J35: A021 Technical Briefing/ Presentation | K35: A022 Knowledge Management Site | N35: Not Received | O35: Not Reviewed
H36: Due / Frequency (per PWS) | I36: Due: ICW MSR Freq: Once per month Dates: see Monthly tab Flag: ICW MSR = Monthly Status Report; confirm it equals the MPR | J36: Due: ICW MSR Freq: One per month Dates: see Monthly tab Flag: ICW MSR = Monthly Status Report; confirm it equals the MPR | K36: Due: ICW MSR Freq: Updated, as needed Flag: ICW MSR = Monthly Status Report; confirm it equals the MPR
A37: Oct | B37: 6.3.2.1 | C37: Analysis of Alternatives | D37: As Needed | E37: Engineering | F37: Christine Y. Shigeta | G37: Brian Abrigo | H37: Vendor format | I37: A016 Briefings Slides | J37: A023 Whitepapers | N37: Not Received | O37: Not Reviewed
H38: Due / Frequency (per PWS) | I38: Due: As determined by the Government Freq: As required | J38: Due: ICW MSR Freq: As needed
A39: Oct | B39: 6.3.2.2 | C39: Network Transformation and Modernization Support | D39: One-Time + Updates | E39: Engineering | F39: Christine Y. Shigeta | G39: Brian Abrigo | H39: Vendor format | I39: A027 Network Modernization Plan | N39: Not Received | O39: Not Reviewed
H40: Due / Frequency (per PWS) | I40: Due: 90 Days after contract award Freq: One-Time, updated yearly or with major change Date: Tue 1 Dec 2026
A41: Oct | B41: 6.3.2.3 | C41: Zero Trust Policy Assessment | D41: Mixed (see due row) | E41: Engineering | F41: Christine Y. Shigeta | G41: Brian Abrigo | H41: Vendor format | I41: A023 Whitepapers | J41: A028 ZT Traceability Matrix | K41: A029 ZT Gap Analysis | L41: A030 Zero Trust Architecture Design Document | N41: Not Received | O41: Not Reviewed
...

Sheet Weekly
A1: Weekly Deliverables – due every Friday
A2: Agreement HC1084-26-9-2023 | Vendor: Booz Allen Hamilton | PWS as of 02 Sep 2026 | Clock start 02 Sep 2026
A4: ID | B4: Deliverable | C4: PWS ¶ | D4: Primary POC | E4: Secondary POC | F4: Record | G4: Fully accepted | H4: Overdue | I4: Wk 1 | J4: Wk 2 | K4: Wk 3 | L4: Wk 4 | M4: Wk 5 | N4: Wk 6 | O4: Wk 7 | P4: Wk 8 | Q4: Wk 9 | R4: Wk 10 | S4: Wk 11 | T4: Wk 12 | U4: Wk 13 | V4: Wk 14 | W4: Wk 15 | X4: Wk 16 | Y4: Wk 17 | Z4: Wk 18 | AA4: Wk 19 | AB4: Wk 20 | AC4: Wk 21 | AD4: Wk 22 | AE4: Wk 23 | AF4: Wk 24 | AG4: Wk 25 | AH4: Wk 26 | AI4: Wk 27 | AJ4: Wk 28 | AK4: Wk 29 | AL4: Wk 30 | AM4: Wk 31 | AN4: Wk 32 | AO4: Wk 33 | AP4: Wk 34 | AQ4: Wk 35
B5: Due (Friday) | I5: =ClockStart+MOD(6-WEEKDAY(ClockStart),7)+0 -> 46269 | J5: =ClockStart+MOD(6-WEEKDAY(ClockStart),7)+7 -> 46276 | K5: =ClockStart+MOD(6-WEEKDAY(ClockStart),7)+14 -> 46283 | L5: =ClockStart+MOD(6-WEEKDAY(ClockStart),7)+21 -> 46290 | M5: =ClockStart+MOD(6-WEEKDAY(ClockStart),7)+28 -> 46297 | N5: =ClockStart+MOD(6-WEEKDAY(ClockStart),7)+35 -> 46304 | O5: =ClockStart+MOD(6-WEEKDAY(ClockStart),7)+42 -> 46311 | P5: =ClockStart+MOD(6-WEEKDAY(ClockStart),7)+49 -> 46318 | Q5: =ClockStart+MOD(6-WEEKDAY(ClockStart),7)+56 -> 46325 | R5: =ClockStart+MOD(6-WEEKDAY(ClockStart),7)+63 -> 46332 | S5: =ClockStart+MOD(6-WEEKDAY(ClockStart),7)+70 -> 46339 | T5: =ClockStart+MOD(6-WEEKDAY(ClockStart),7)+77 -> 46346 | U5: =ClockStart+MOD(6-WEEKDAY(ClockStart),7)+84 -> 46353 | V5: =ClockStart+MOD(6-WEEKDAY(ClockStart),7)+91 -> 46360 | W5: =ClockStart+MOD(6-WEEKDAY(ClockStart),7)+98 -> 46367 | X5: =ClockStart+MOD(6-WEEKDAY(ClockStart),7)+105 -> 46374 | Y5: =ClockStart+MOD(6-WEEKDAY(ClockStart),7)+112 -> 46381 | Z5: =ClockStart+MOD(6-WEEKDAY(ClockStart),7)+119 -> 46388 | AA5: =ClockStart+MOD(6-WEEKDAY(ClockStart),7)+126 -> 46395 | AB5: =ClockStart+MOD(6-WEEKDAY(ClockStart),7)+133 -> 46402 | AC5: =ClockStart+MOD(6-WEEKDAY(ClockStart),7)+140 -> 46409 | AD5: =ClockStart+MOD(6-WEEKDAY(ClockStart),7)+147 -> 46416 | AE5: =ClockStart+MOD(6-WEEKDAY(ClockStart),7)+154 -> 46423 | AF5: =ClockStart+MOD(6-WEEKDAY(ClockStart),7)+161 -> 46430 | AG5: =ClockStart+MOD(6-WEEKDAY(ClockStart),7)+168 -> 46437 | AH5: =ClockStart+MOD(6-WEEKDAY(ClockStart),7)+175 -> 46444 | AI5: =ClockStart+MOD(6-WEEKDAY(ClockStart),7)+182 -> 46451 | AJ5: =ClockStart+MOD(6-WEEKDAY(ClockStart),7)+189 -> 46458 | AK5: =ClockStart+MOD(6-WEEKDAY(ClockStart),7)+196 -> 46465 | AL5: =ClockStart+MOD(6-WEEKDAY(ClockStart),7)+203 -> 46472 | AM5: =ClockStart+MOD(6-WEEKDAY(ClockStart),7)+210 -> 46479 | AN5: =ClockStart+MOD(6-WEEKDAY(ClockStart),7)+217 -> 46486 | AO5: =ClockStart+MOD(6-WEEKDAY(ClockStart),7)+224 -> 46493 | AP5: =ClockStart+MOD(6-WEEKDAY(ClockStart),7)+231 -> 46500 | AQ5: =ClockStart+MOD(6-WEEKDAY(ClockStart),7)+238 -> 46507
A6: A019 | B6: Weekly Activity Report (WAR) | C6: 6.3.1.2, 6.3.1.4 | D6: Christine Y. Shigeta | E6: Brian Abrigo | F6: Status | G6: =SUMPRODUCT((I8:AQ8<>"")*(I10:AQ10<>"")) -> 0 | H6: =SUMPRODUCT((I$5:AQ$5<TODAY())*(((I6:AQ6="")+(I6:AQ6="In Progress"))>0)*(((I8:AQ8="")+(I10:AQ10=""))>0)) -> 6
F7: COR accepted by
F8: COR date accepted
F9: J698 accepted by
F10: J698 date accepted
F11: Result | I11: =IF(AND(I8<>"",I10<>""),"Fully accepted",IF(I8<>"","COR only",IF(I10<>"","J698 only",""))) | J11: =IF(AND(J8<>"",J10<>""),"Fully accepted",IF(J8<>"","COR only",IF(J10<>"","J698 only",""))) | K11: =IF(AND(K8<>"",K10<>""),"Fully accepted",IF(K8<>"","COR only",IF(K10<>"","J698 only",""))) | L11: =IF(AND(L8<>"",L10<>""),"Fully accepted",IF(L8<>"","COR only",IF(L10<>"","J698 only",""))) | M11: =IF(AND(M8<>"",M10<>""),"Fully accepted",IF(M8<>"","COR only",IF(M10<>"","J698 only",""))) | N11: =IF(AND(N8<>"",N10<>""),"Fully accepted",IF(N8<>"","COR only",IF(N10<>"","J698 only",""))) | O11: =IF(AND(O8<>"",O10<>""),"Fully accepted",IF(O8<>"","COR only",IF(O10<>"","J698 only",""))) | P11: =IF(AND(P8<>"",P10<>""),"Fully accepted",IF(P8<>"","COR only",IF(P10<>"","J698 only",""))) | ... AQ11: =IF(AND(AQ8<>"",AQ10<>""),"Fully accepted",IF(AQ8<>"","COR only",IF(AQ10<>"","J698 only","")))
A12: A007 | B12: ACAS Scans | C12: 6.1, 6.2.1 | D12: Christine Y. Shigeta | E12: Brian Abrigo | F12: Status | G12: =SUMPRODUCT((I14:AQ14<>"")*(I16:AQ16<>"")) -> 0 | H12: =SUMPRODUCT((I$5:AQ$5<TODAY())*(((I12:AQ12="")+(I12:AQ12="In Progress"))>0)*(((I14:AQ14="")+(I16:AQ16=""))>0)) -> 6
F13: COR accepted by
F14: COR date accepted
F15: J698 accepted by
F16: J698 date accepted
F17: Result | I17: =IF(AND(I14<>"",I16<>""),"Fully accepted",IF(I14<>"","COR only",IF(I16<>"","J698 only",""))) | J17: =IF(AND(J14<>"",J16<>""),"Fully accepted",IF(J14<>"","COR only",IF(J16<>"","J698 only",""))) | K17: =IF(AND(K14<>"",K16<>""),"Fully accepted",IF(K14<>"","COR only",IF(K16<>"","J698 only",""))) | L17: =IF(AND(L14<>"",L16<>""),"Fully accepted",IF(L14<>"","COR only",IF(L16<>"","J698 only",""))) | M17: =IF(AND(M14<>"",M16<>""),"Fully accepted",IF(M14<>"","COR only",IF(M16<>"","J698 only",""))) | N17: =IF(AND(N14<>"",N16<>""),"Fully accepted",IF(N14<>"","COR only",IF(N16<>"","J698 only",""))) | O17: =IF(AND(O14<>"",O16<>""),"Fully accepted",IF(O14<>"","COR only",IF(O16<>"","J698 only",""))) | P17: =IF(AND(P14<>"",P16<>""),"Fully accepted",IF(P14<>"","COR only",IF(P16<>"","J698 only",""))) | ... AQ17: =IF(AND(AQ14<>"",AQ16<>""),"Fully accepted",IF(AQ14<>"","COR only",IF(AQ16<>"","J698 only","")))
B19: How to fill a period: click the cell next to Status and pick from the dropdown (arrow appears on click). Click COR accepted by to pick Christine or Brian (or type a name), then enter the date. Do the same for J698. When both dates are in, the column turns green and Result reads "Fully accepted". A name without a date (or the reverse) turns yellow. A019 is explicit in the PWS; Friday for A007 is assumed.

Sheet Monthly
A1: Monthly Deliverables – due 5 business days after month end
A2: Agreement HC1084-26-9-2023 | Vendor: Booz Allen Hamilton | PWS as of 02 Sep 2026 | Clock start 02 Sep 2026
A4: ID | B4: Deliverable | C4: PWS ¶ | D4: Primary POC | E4: Secondary POC | F4: Record | G4: Fully accepted | H4: Overdue | I4: =EDATE(DATE(YEAR(ClockStart),MONTH(ClockStart),1),0) -> 46266 | J4: =EDATE(DATE(YEAR(ClockStart),MONTH(ClockStart),1),1) -> 46296 | K4: =EDATE(DATE(YEAR(ClockStart),MONTH(ClockStart),1),2) -> 46327 | L4: =EDATE(DATE(YEAR(ClockStart),MONTH(ClockStart),1),3) -> 46357 | M4: =EDATE(DATE(YEAR(ClockStart),MONTH(ClockStart),1),4) -> 46388 | N4: =EDATE(DATE(YEAR(ClockStart),MONTH(ClockStart),1),5) -> 46419 | O4: =EDATE(DATE(YEAR(ClockStart),MONTH(ClockStart),1),6) -> 46447 | P4: =EDATE(DATE(YEAR(ClockStart),MONTH(ClockStart),1),7) -> 46478
B5: Due | I5: =WORKDAY(EOMONTH(I4,0),DueOffset) -> 46302 | J5: =WORKDAY(EOMONTH(J4,0),DueOffset) -> 46332 | K5: =WORKDAY(EOMONTH(K4,0),DueOffset) -> 46363 | L5: =WORKDAY(EOMONTH(L4,0),DueOffset) -> 46394 | M5: =WORKDAY(EOMONTH(M4,0),DueOffset) -> 46423 | N5: =WORKDAY(EOMONTH(N4,0),DueOffset) -> 46451 | O5: =WORKDAY(EOMONTH(O4,0),DueOffset) -> 46484 | P5: =WORKDAY(EOMONTH(P4,0),DueOffset) -> 46514
A6: A017 | B6: Integrated Master Schedule | C6: 6.3.1 | D6: Christine Y. Shigeta | E6: Brian Abrigo | F6: Status | G6: =SUMPRODUCT((I8:P8<>"")*(I10:P10<>"")) -> 0 | H6: =SUMPRODUCT((I$5:P$5<TODAY())*(((I6:P6="")+(I6:P6="In Progress"))>0)*(((I8:P8="")+(I10:P10=""))>0)) -> 1
F7: COR accepted by
F8: COR date accepted
F9: J698 accepted by
F10: J698 date accepted
F11: Result | I11: =IF(AND(I8<>"",I10<>""),"Fully accepted",IF(I8<>"","COR only",IF(I10<>"","J698 only",""))) | J11: =IF(AND(J8<>"",J10<>""),"Fully accepted",IF(J8<>"","COR only",IF(J10<>"","J698 only",""))) | K11: =IF(AND(K8<>"",K10<>""),"Fully accepted",IF(K8<>"","COR only",IF(K10<>"","J698 only",""))) | L11: =IF(AND(L8<>"",L10<>""),"Fully accepted",IF(L8<>"","COR only",IF(L10<>"","J698 only",""))) | M11: =IF(AND(M8<>"",M10<>""),"Fully accepted",IF(M8<>"","COR only",IF(M10<>"","J698 only",""))) | N11: =IF(AND(N8<>"",N10<>""),"Fully accepted",IF(N8<>"","COR only",IF(N10<>"","J698 only",""))) | O11: =IF(AND(O8<>"",O10<>""),"Fully accepted",IF(O8<>"","COR only",IF(O10<>"","J698 only",""))) | P11: =IF(AND(P8<>"",P10<>""),"Fully accepted",IF(P8<>"","COR only",IF(P10<>"","J698 only","")))
A12: A018 | B12: Monthly Progress Report (MPR) (including Invoice Data, ODC Data, Travel Data) | C12: 6.3.1.1 | D12: Christine Y. Shigeta | E12: Brian Abrigo | F12: Status | G12: =SUMPRODUCT((I14:P14<>"")*(I16:P16<>"")) -> 0 | H12: =SUMPRODUCT((I$5:P$5<TODAY())*(((I12:P12="")+(I12:P12="In Progress"))>0)*(((I14:P14="")+(I16:P16=""))>0)) -> 1
F13: COR accepted by
F14: COR date accepted
F15: J698 accepted by
F16: J698 date accepted
F17: Result | I17: =IF(AND(I14<>"",I16<>""),"Fully accepted",IF(I14<>"","COR only",IF(I16<>"","J698 only",""))) | J17: =IF(AND(J14<>"",J16<>""),"Fully accepted",IF(J14<>"","COR only",IF(J16<>"","J698 only",""))) | K17: =IF(AND(K14<>"",K16<>""),"Fully accepted",IF(K14<>"","COR only",IF(K16<>"","J698 only",""))) | L17: =IF(AND(L14<>"",L16<>""),"Fully accepted",IF(L14<>"","COR only",IF(L16<>"","J698 only",""))) | M17: =IF(AND(M14<>"",M16<>""),"Fully accepted",IF(M14<>"","COR only",IF(M16<>"","J698 only",""))) | N17: =IF(AND(N14<>"",N16<>""),"Fully accepted",IF(N14<>"","COR only",IF(N16<>"","J698 only",""))) | O17: =IF(AND(O14<>"",O16<>""),"Fully accepted",IF(O14<>"","COR only",IF(O16<>"","J698 only",""))) | P17: =IF(AND(P14<>"",P16<>""),"Fully accepted",IF(P14<>"","COR only",IF(P16<>"","J698 only","")))
A18: A020 | B18: Technical Library Documentation Report | C18: 6.3.1.7 | D18: Christine Y. Shigeta | E18: Brian Abrigo | F18: Status | G18: =SUMPRODUCT((I20:P20<>"")*(I22:P22<>"")) -> 0 | H18: =SUMPRODUCT((I$5:P$5<TODAY())*(((I18:P18="")+(I18:P18="In Progress"))>0)*(((I20:P20="")+(I22:P22=""))>0)) -> 1
F19: COR accepted by
F20: COR date accepted
F21: J698 accepted by
F22: J698 date accepted
F23: Result | I23: =IF(AND(I20<>"",I22<>""),"Fully accepted",IF(I20<>"","COR only",IF(I22<>"","J698 only",""))) | J23: =IF(AND(J20<>"",J22<>""),"Fully accepted",IF(J20<>"","COR only",IF(J22<>"","J698 only",""))) | K23: =IF(AND(K20<>"",K22<>""),"Fully accepted",IF(K20<>"","COR only",IF(K22<>"","J698 only",""))) | L23: =IF(AND(L20<>"",L22<>""),"Fully accepted",IF(L20<>"","COR only",IF(L22<>"","J698 only",""))) | M23: =IF(AND(M20<>"",M22<>""),"Fully accepted",IF(M20<>"","COR only",IF(M22<>"","J698 only",""))) | N23: =IF(AND(N20<>"",N22<>""),"Fully accepted",IF(N20<>"","COR only",IF(N22<>"","J698 only",""))) | O23: =IF(AND(O20<>"",O22<>""),"Fully accepted",IF(O20<>"","COR only",IF(O22<>"","J698 only",""))) | P23: =IF(AND(P20<>"",P22<>""),"Fully accepted",IF(P20<>"","COR only",IF(P22<>"","J698 only","")))
A24: A021 | B24: Technical Briefing/ Presentation | C24: 6.3.1.7 | D24: Christine Y. Shigeta | E24: Brian Abrigo | F24: Status | G24: =SUMPRODUCT((I26:P26<>"")*(I28:P28<>"")) -> 0 | H24: =SUMPRODUCT((I$5:P$5<TODAY())*(((I24:P24="")+(I24:P24="In Progress"))>0)*(((I26:P26="")+(I28:P28=""))>0)) -> 1
F25: COR accepted by
F26: COR date accepted
F27: J698 accepted by
F28: J698 date accepted
F29: Result | I29: =IF(AND(I26<>"",I28<>""),"Fully accepted",IF(I26<>"","COR only",IF(I28<>"","J698 only",""))) | J29: =IF(AND(J26<>"",J28<>""),"Fully accepted",IF(J26<>"","COR only",IF(J28<>"","J698 only",""))) | K29: =IF(AND(K26<>"",K28<>""),"Fully accepted",IF(K26<>"","COR only",IF(K28<>"","J698 only",""))) | L29: =IF(AND(L26<>"",L28<>""),"Fully accepted",IF(L26<>"","COR only",IF(L28<>"","J698 only",""))) | M29: =IF(AND(M26<>"",M28<>""),"Fully accepted",IF(M26<>"","COR only",IF(M28<>"","J698 only",""))) | N29: =IF(AND(N26<>"",N28<>""),"Fully accepted",IF(N26<>"","COR only",IF(N28<>"","J698 only",""))) | O29: =IF(AND(O26<>"",O28<>""),"Fully accepted",IF(O26<>"","COR only",IF(O28<>"","J698 only",""))) | P29: =IF(AND(P26<>"",P28<>""),"Fully accepted",IF(P26<>"","COR only",IF(P28<>"","J698 only","")))
B31: How to fill a period: click the cell next to Status and pick from the dropdown (arrow appears on click). Click COR accepted by to pick Christine or Brian (or type a name), then enter the date. Do the same for J698. When both dates are in, the column turns green and Result reads "Fully accepted". A name without a date (or the reverse) turns yellow. The 5-business-day offset is an assumption (Daily tab settings); the PWS says "as determined by the Government" or "with the Monthly Status Report".

Sheet Quarterly
A1: Quarterly Deliverables – federal fiscal quarters, due 5 business days after quarter end
A2: Agreement HC1084-26-9-2023 | Vendor: Booz Allen Hamilton | PWS as of 02 Sep 2026 | Clock start 02 Sep 2026
A4: ID | B4: Deliverable | C4: PWS ¶ | D4: Primary POC | E4: Secondary POC | F4: Record | G4: Fully accepted | H4: Overdue | I4: =EOMONTH(EOMONTH(ClockStart,MOD(9-MONTH(ClockStart),3)),0) -> 46295 | J4: =EOMONTH(EOMONTH(ClockStart,MOD(9-MONTH(ClockStart),3)),3) -> 46387 | K4: =EOMONTH(EOMONTH(ClockStart,MOD(9-MONTH(ClockStart),3)),6) -> 46477 | L4: =EOMONTH(EOMONTH(ClockStart,MOD(9-MONTH(ClockStart),3)),9) -> 46568
B5: Due | I5: =WORKDAY(I4,DueOffset) -> 46302 | J5: =WORKDAY(J4,DueOffset) -> 46394 | K5: =WORKDAY(K4,DueOffset) -> 46484 | L5: =WORKDAY(L4,DueOffset) -> 46575
A6: A006 | B6: STIG/SRG Checklists | C6: 6.1, 6.2.1 | D6: Christine Y. Shigeta | E6: Brian Abrigo | F6: Status | G6: =SUMPRODUCT((I8:L8<>"")*(I10:L10<>"")) -> 0 | H6: =SUMPRODUCT((I$5:L$5<TODAY())*(((I6:L6="")+(I6:L6="In Progress"))>0)*(((I8:L8="")+(I10:L10=""))>0)) -> 1
F7: COR accepted by
F8: COR date accepted
F9: J698 accepted by
F10: J698 date accepted
F11: Result | I11: =IF(AND(I8<>"",I10<>""),"Fully accepted",IF(I8<>"","COR only",IF(I10<>"","J698 only",""))) | J11: =IF(AND(J8<>"",J10<>""),"Fully accepted",IF(J8<>"","COR only",IF(J10<>"","J698 only",""))) | K11: =IF(AND(K8<>"",K10<>""),"Fully accepted",IF(K8<>"","COR only",IF(K10<>"","J698 only",""))) | L11: =IF(AND(L8<>"",L10<>""),"Fully accepted",IF(L8<>"","COR only",IF(L10<>"","J698 only","")))
A12: A012 | B12: Security Monitoring Reports | C12: 6.2.1 | D12: Christine Y. Shigeta | E12: Brian Abrigo | F12: Status | G12: =SUMPRODUCT((I14:L14<>"")*(I16:L16<>"")) -> 0 | H12: =SUMPRODUCT((I$5:L$5<TODAY())*(((I12:L12="")+(I12:L12="In Progress"))>0)*(((I14:L14="")+(I16:L16=""))>0)) -> 1
F13: COR accepted by
F14: COR date accepted
F15: J698 accepted by
F16: J698 date accepted
F17: Result | I17: =IF(AND(I14<>"",I16<>""),"Fully accepted",IF(I14<>"","COR only",IF(I16<>"","J698 only",""))) | J17: =IF(AND(J14<>"",J16<>""),"Fully accepted",IF(J14<>"","COR only",IF(J16<>"","J698 only",""))) | K17: =IF(AND(K14<>"",K16<>""),"Fully accepted",IF(K14<>"","COR only",IF(K16<>"","J698 only",""))) | L17: =IF(AND(L14<>"",L16<>""),"Fully accepted",IF(L14<>"","COR only",IF(L16<>"","J698 only","")))
A18: A013 | B18: Vulnerability Scan Reports | C18: 6.2.1 | D18: Christine Y. Shigeta | E18: Brian Abrigo | F18: Status | G18: =SUMPRODUCT((I20:L20<>"")*(I22:L22<>"")) -> 0 | H18: =SUMPRODUCT((I$5:L$5<TODAY())*(((I18:L18="")+(I18:L18="In Progress"))>0)*(((I20:L20="")+(I22:L22=""))>0)) -> 1
F19: COR accepted by
F20: COR date accepted
F21: J698 accepted by
F22: J698 date accepted
F23: Result | I23: =IF(AND(I20<>"",I22<>""),"Fully accepted",IF(I20<>"","COR only",IF(I22<>"","J698 only",""))) | J23: =IF(AND(J20<>"",J22<>""),"Fully accepted",IF(J20<>"","COR only",IF(J22<>"","J698 only",""))) | K23: =IF(AND(K20<>"",K22<>""),"Fully accepted",IF(K20<>"","COR only",IF(K22<>"","J698 only",""))) | L23: =IF(AND(L20<>"",L22<>""),"Fully accepted",IF(L20<>"","COR only",IF(L22<>"","J698 only","")))
B25: How to fill a period: click the cell next to Status and pick from the dropdown (arrow appears on click). Click COR accepted by to pick Christine or Brian (or type a name), then enter the date. Do the same for J698. When both dates are in, the column turns green and Result reads "Fully accepted". A name without a date (or the reverse) turns yellow. Federal fiscal quarters are assumed; confirm with the COR.

Sheet Daily
A1: Daily Agenda – what is due, in date order
A2: Agreement HC1084-26-9-2023 | Vendor: Booz Allen Hamilton | PWS as of 02 Sep 2026 | Clock start 02 Sep 2026
P3: Settings (edit the yellow cells)
A4: Due Date | B4: Day | C4: ID | D4: Deliverable | E4: Source | F4: Status | G4: COR Accepted By | H4: COR Date Accepted | I4: J698 Accepted By | J4: J698 Date Accepted | K4: Result | L4: Days Until Due | M4: Flag | N4: Notes | P4: Clock start (PWS date) | Q4: 46267
A5: =ClockStart -> 46267 | B5: =TEXT(A5,"ddd") -> Wed | C5: A041 | D5: Transition-In Plan – initial draft | E5: One-time | K5: =IF(AND(H5<>"",J5<>""),"Fully accepted",IF(H5<>"","COR only",IF(J5<>"","J698 only",""))) | L5: =A5-TodayD -> -41 | M5: =IF(K5="Fully accepted","Done",IF(F5="N/A","N/A",IF(F5="Returned","Returned: resubmit",IF(K5="COR only","Awaiting J698",IF(K5="J698 only","Awaiting COR",IF(F5="Submitted","Awaiting COR + J698",IF(A5<TodayD,"OVERDUE",IF(A5-TodayD<=7,"Due within 7 days","")))))))) -> OVERDUE | N5: At kickoff (table). Body says 30 days after kickoff = 2 Oct 2026. | P5: Monthly / quarterly due offset (business days) | Q5: 5
A6: =Weekly!I5 -> 46269 | B6: =TEXT(A6,"ddd") -> Fri | C6: A007 | D6: ACAS Scans – Wk 1 | E6: Weekly | F6: =IF(Weekly!I12="","",Weekly!I12) | G6: =IF(Weekly!I13="","",Weekly!I13) | H6: =IF(Weekly!I14="","",Weekly!I14) | I6: =IF(Weekly!I15="","",Weekly!I15) | J6: =IF(Weekly!I16="","",Weekly!I16) | K6: =IF(AND(H6<>"",J6<>""),"Fully accepted",IF(H6<>"","COR only",IF(J6<>"","J698 only",""))) | L6: =A6-TodayD -> -39 | M6: =IF(K6="Fully accepted","Done",IF(F6="N/A","N/A",IF(F6="Returned","Returned: resubmit",IF(K6="COR only","Awaiting J698",IF(K6="J698 only","Awaiting COR",IF(F6="Submitted","Awaiting COR + J698",IF(A6<TodayD,"OVERDUE",IF(A6-TodayD<=7,"Due within 7 days","")))))))) -> OVERDUE | P6: Gov inspection window (business days) | Q6: 5
A7: =Weekly!I5 -> 46269 | B7: =TEXT(A7,"ddd") -> Fri | C7: A019 | D7: Weekly Activity Report (WAR) – Wk 1 | E7: Weekly | F7: =IF(Weekly!I6="","",Weekly!I6) | G7: =IF(Weekly!I7="","",Weekly!I7) | H7: =IF(Weekly!I8="","",Weekly!I8) | I7: =IF(Weekly!I9="","",Weekly!I9) | J7: =IF(Weekly!I10="","",Weekly!I10) | K7: =IF(AND(H7<>"",J7<>""),"Fully accepted",IF(H7<>"","COR only",IF(J7<>"","J698 only",""))) | L7: =A7-TodayD -> -39 | M7: =IF(K7="Fully accepted","Done",IF(F7="N/A","N/A",IF(F7="Returned","Returned: resubmit",IF(K7="COR only","Awaiting J698",IF(K7="J698 only","Awaiting COR",IF(F7="Submitted","Awaiting COR + J698",IF(A7<TodayD,"OVERDUE",IF(A7-TodayD<=7,"Due within 7 days","")))))))) -> OVERDUE | P7: Resubmission window (business days) | Q7: 10
A8: =WORKDAY(ClockStart,5) -> 46274 | B8: =TEXT(A8,"ddd") -> Wed | C8: A041 | D8: Transition-In Plan – final draft | E8: One-time | K8: =IF(AND(H8<>"",J8<>""),"Fully accepted",IF(H8<>"","COR only",IF(J8<>"","J698 only",""))) | L8: =A8-TodayD -> -34 | M8: =IF(K8="Fully accepted","Done",IF(F8="N/A","N/A",IF(F8="Returned","Returned: resubmit",IF(K8="COR only","Awaiting J698",IF(K8="J698 only","Awaiting COR",IF(F8="Submitted","Awaiting COR + J698",IF(A8<TodayD,"OVERDUE",IF(A8-TodayD<=7,"Due within 7 days","")))))))) -> OVERDUE | N8: 5 business days after award (table). Labor Day not excluded. | P8: End of base period | Q8: 46510
A9: =Weekly!J5 -> 46276 | B9: =TEXT(A9,"ddd") -> Fri | C9: A007 | D9: ACAS Scans – Wk 2 | E9: Weekly | F9: =IF(Weekly!J12="","",Weekly!J12) | G9: =IF(Weekly!J13="","",Weekly!J13) | H9: =IF(Weekly!J14="","",Weekly!J14) | I9: =IF(Weekly!J15="","",Weekly!J15) | J9: =IF(Weekly!J16="","",Weekly!J16) | K9: =IF(AND(H9<>"",J9<>""),"Fully accepted",IF(H9<>"","COR only",IF(J9<>"","J698 only",""))) | L9: =A9-TodayD -> -32 | M9: =IF(K9="Fully accepted","Done",IF(F9="N/A","N/A",IF(F9="Returned","Returned: resubmit",IF(K9="COR only","Awaiting J698",IF(K9="J698 only","Awaiting COR",IF(F9="Submitted","Awaiting COR + J698",IF(A9<TodayD,"OVERDUE",IF(A9-TodayD<=7,"Due within 7 days","")))))))) -> OVERDUE | P9: End of final option year | Q9: 47390
A10: =Weekly!J5 -> 46276 | B10: =TEXT(A10,"ddd") -> Fri | C10: A019 | D10: Weekly Activity Report (WAR) – Wk 2 | E10: Weekly | F10: =IF(Weekly!J6="","",Weekly!J6) | G10: =IF(Weekly!J7="","",Weekly!J7) | H10: =IF(Weekly!J8="","",Weekly!J8) | I10: =IF(Weekly!J9="","",Weekly!J9) | J10: =IF(Weekly!J10="","",Weekly!J10) | K10: =IF(AND(H10<>"",J10<>""),"Fully accepted",IF(H10<>"","COR only",IF(J10<>"","J698 only",""))) | L10: =A10-TodayD -> -32 | M10: =IF(K10="Fully accepted","Done",IF(F10="N/A","N/A",IF(F10="Returned","Returned: resubmit",IF(K10="COR only","Awaiting J698",IF(K10="J698 only","Awaiting COR",IF(F10="Submitted","Awaiting COR + J698",IF(A10<TodayD,"OVERDUE",IF(A10-TodayD<=7,"Due within 7 days","")))))))) -> OVERDUE | P10: Today | Q10: =TODAY() -> 46308
A11: =Weekly!K5 -> 46283 | B11: =TEXT(A11,"ddd") -> Fri | C11: A007 | D11: ACAS Scans – Wk 3 | E11: Weekly | F11: =IF(Weekly!K12="","",Weekly!K12) | G11: =IF(Weekly!K13="","",Weekly!K13) | H11: =IF(Weekly!K14="","",Weekly!K14) | I11: =IF(Weekly!K15="","",Weekly!K15) | J11: =IF(Weekly!K16="","",Weekly!K16) | K11: =IF(AND(H11<>"",J11<>""),"Fully accepted",IF(H11<>"","COR only",IF(J11<>"","J698 only",""))) | L11: =A11-TodayD -> -25 | M11: =IF(K11="Fully accepted","Done",IF(F11="N/A","N/A",IF(F11="Returned","Returned: resubmit",IF(K11="COR only","Awaiting J698",IF(K11="J698 only","Awaiting COR",IF(F11="Submitted","Awaiting COR + J698",IF(A11<TodayD,"OVERDUE",IF(A11-TodayD<=7,"Due within 7 days","")))))))) -> OVERDUE
A12: =Weekly!K5 -> 46283 | B12: =TEXT(A12,"ddd") -> Fri | C12: A019 | D12: Weekly Activity Report (WAR) – Wk 3 | E12: Weekly | F12: =IF(Weekly!K6="","",Weekly!K6) | G12: =IF(Weekly!K7="","",Weekly!K7) | H12: =IF(Weekly!K8="","",Weekly!K8) | I12: =IF(Weekly!K9="","",Weekly!K9) | J12: =IF(Weekly!K10="","",Weekly!K10) | K12: =IF(AND(H12<>"",J12<>""),"Fully accepted",IF(H12<>"","COR only",IF(J12<>"","J698 only",""))) | L12: =A12-TodayD -> -25 | M12: =IF(K12="Fully accepted","Done",IF(F12="N/A","N/A",IF(F12="Returned","Returned: resubmit",IF(K12="COR only","Awaiting J698",IF(K12="J698 only","Awaiting COR",IF(F12="Submitted","Awaiting COR + J698",IF(A12<TodayD,"OVERDUE",IF(A12-TodayD<=7,"Due within 7 days","")))))))) -> OVERDUE | P12: Dates on the other tabs recalculate from these cells. Holidays are not excluded.
A13: =Weekly!L5 -> 46290 | B13: =TEXT(A13,"ddd") -> Fri | C13: A007 | D13: ACAS Scans – Wk 4 | E13: Weekly | F13: =IF(Weekly!L12="","",Weekly!L12) | G13: =IF(Weekly!L13="","",Weekly!L13) | H13: =IF(Weekly!L14="","",Weekly!L14) | I13: =IF(Weekly!L15="","",Weekly!L15) | J13: =IF(Weekly!L16="","",Weekly!L16) | K13: =IF(AND(H13<>"",J13<>""),"Fully accepted",IF(H13<>"","COR only",IF(J13<>"","J698 only",""))) | L13: =A13-TodayD -> -18 | M13: =IF(K13="Fully accepted","Done",IF(F13="N/A","N/A",IF(F13="Returned","Returned: resubmit",IF(K13="COR only","Awaiting J698",IF(K13="J698 only","Awaiting COR",IF(F13="Submitted","Awaiting COR + J698",IF(A13<TodayD,"OVERDUE",IF(A13-TodayD<=7,"Due within 7 days","")))))))) -> OVERDUE
A14: =Weekly!L5 -> 46290 | B14: =TEXT(A14,"ddd") -> Fri | C14: A019 | D14: Weekly Activity Report (WAR) – Wk 4 | E14: Weekly | F14: =IF(Weekly!L6="","",Weekly!L6) | G14: =IF(Weekly!L7="","",Weekly!L7) | H14: =IF(Weekly!L8="","",Weekly!L8) | I14: =IF(Weekly!L9="","",Weekly!L9) | J14: =IF(Weekly!L10="","",Weekly!L10) | K14: =IF(AND(H14<>"",J14<>""),"Fully accepted",IF(H14<>"","COR only",IF(J14<>"","J698 only",""))) | L14: =A14-TodayD -> -18 | M14: =IF(K14="Fully accepted","Done",IF(F14="N/A","N/A",IF(F14="Returned","Returned: resubmit",IF(K14="COR only","Awaiting J698",IF(K14="J698 only","Awaiting COR",IF(F14="Submitted","Awaiting COR + J698",IF(A14<TodayD,"OVERDUE",IF(A14-TodayD<=7,"Due within 7 days","")))))))) -> OVERDUE
A15: =Weekly!M5 -> 46297 | B15: =TEXT(A15,"ddd") -> Fri | C15: A007 | D15: ACAS Scans – Wk 5 | E15: Weekly | F15: =IF(Weekly!M12="","",Weekly!M12) | G15: =IF(Weekly!M13="","",Weekly!M13) | H15: =IF(Weekly!M14="","",Weekly!M14) | I15: =IF(Weekly!M15="","",Weekly!M15) | J15: =IF(Weekly!M16="","",Weekly!M16) | K15: =IF(AND(H15<>"",J15<>""),"Fully accepted",IF(H15<>"","COR only",IF(J15<>"","J698 only",""))) | L15: =A15-TodayD -> -11 | M15: =IF(K15="Fully accepted","Done",IF(F15="N/A","N/A",IF(F15="Returned","Returned: resubmit",IF(K15="COR only","Awaiting J698",IF(K15="J698 only","Awaiting COR",IF(F15="Submitted","Awaiting COR + J698",IF(A15<TodayD,"OVERDUE",IF(A15-TodayD<=7,"Due within 7 days","")))))))) -> OVERDUE
A16: =Weekly!M5 -> 46297 | B16: =TEXT(A16,"ddd") -> Fri | C16: A019 | D16: Weekly Activity Report (WAR) – Wk 5 | E16: Weekly | F16: =IF(Weekly!M6="","",Weekly!M6) | G16: =IF(Weekly!M7="","",Weekly!M7) | H16: =IF(Weekly!M8="","",Weekly!M8) | I16: =IF(Weekly!M9="","",Weekly!M9) | J16: =IF(Weekly!M10="","",Weekly!M10) | K16: =IF(AND(H16<>"",J16<>""),"Fully accepted",IF(H16<>"","COR only",IF(J16<>"","J698 only",""))) | L16: =A16-TodayD -> -11 | M16: =IF(K16="Fully accepted","Done",IF(F16="N/A","N/A",IF(F16="Returned","Returned: resubmit",IF(K16="COR only","Awaiting J698",IF(K16="J698 only","Awaiting COR",IF(F16="Submitted","Awaiting COR + J698",IF(A16<TodayD,"OVERDUE",IF(A16-TodayD<=7,"Due within 7 days","")))))))) -> OVERDUE
A17: =ClockStart+30 -> 46297 | B17: =TEXT(A17,"ddd") -> Fri | C17: A038 | D17: Test Plans | E17: One-time | K17: =IF(AND(H17<>"",J17<>""),"Fully accepted",IF(H17<>"","COR only",IF(J17<>"","J698 only",""))) | L17: =A17-TodayD -> -11 | M17: =IF(K17="Fully accepted","Done",IF(F17="N/A","N/A",IF(F17="Returned","Returned: resubmit",IF(K17="COR only","Awaiting J698",IF(K17="J698 only","Awaiting COR",IF(F17="Submitted","Awaiting COR + J698",IF(A17<TodayD,"OVERDUE",IF(A17-TodayD<=7,"Due within 7 days","")))))))) -> OVERDUE | N17: 30 days after award
A18: =ClockStart+30 -> 46297 | B18: =TEXT(A18,"ddd") -> Fri | C18: A039 | D18: Test Reports | E18: One-time | K18: =IF(AND(H18<>"",J18<>""),"Fully accepted",IF(H18<>"","COR only",IF(J18<>"","J698 only",""))) | L18: =A18-TodayD -> -11 | M18: =IF(K18="Fully accepted","Done",IF(F18="N/A","N/A",IF(F18="Returned","Returned: resubmit",IF(K18="COR only","Awaiting J698",IF(K18="J698 only","Awaiting COR",IF(F18="Submitted","Awaiting COR + J698",IF(A18<TodayD,"OVERDUE",IF(A18-TodayD<=7,"Due within 7 days","")))))))) -> OVERDUE | N18: 30 days after award
A19: =Quarterly!I5 -> 46302 | B19: =TEXT(A19,"ddd") -> Wed | C19: A006 | D19: STIG/SRG Checklists – Qtr ending 30 Sep 2026 | E19: Quarterly | F19: =IF(Quarterly!I6="","",Quarterly!I6) | G19: =IF(Quarterly!I7="","",Quarterly!I7) | H19: =IF(Quarterly!I8="","",Quarterly!I8) | I19: =IF(Quarterly!I9="","",Quarterly!I9) | J19: =IF(Quarterly!I10="","",Quarterly!I10) | K19: =IF(AND(H19<>"",J19<>""),"Fully accepted",IF(H19<>"","COR only",IF(J19<>"","J698 only",""))) | L19: =A19-TodayD -> -6 | M19: =IF(K19="Fully accepted","Done",IF(F19="N/A","N/A",IF(F19="Returned","Returned: resubmit",IF(K19="COR only","Awaiting J698",IF(K19="J698 only","Awaiting COR",IF(F19="Submitted","Awaiting COR + J698",IF(A19<TodayD,"OVERDUE",IF(A19-TodayD<=7,"Due within 7 days","")))))))) -> OVERDUE
A20: =Quarterly!I5 -> 46302 | B20: =TEXT(A20,"ddd") -> Wed | C20: A012 | D20: Security Monitoring Reports – Qtr ending 30 Sep 2026 | E20: Quarterly | F20: =IF(Quarterly!I12="","",Quarterly!I12) | G20: =IF(Quarterly!I13="","",Quarterly!I13) | H20: =IF(Quarterly!I14="","",Quarterly!I14) | I20: =IF(Quarterly!I15="","",Quarterly!I15) | J20: =IF(Quarterly!I16="","",Quarterly!I16) | K20: =IF(AND(H20<>"",J20<>""),"Fully accepted",IF(H20<>"","COR only",IF(J20<>"","J698 only",""))) | L20: =A20-TodayD -> -6 | M20: =IF(K20="Fully accepted","Done",IF(F20="N/A","N/A",IF(F20="Returned","Returned: resubmit",IF(K20="COR only","Awaiting J698",IF(K20="J698 only","Awaiting COR",IF(F20="Submitted","Awaiting COR + J698",IF(A20<TodayD,"OVERDUE",IF(A20-TodayD<=7,"Due within 7 days","")))))))) -> OVERDUE
A21: =Quarterly!I5 -> 46302 | B21: =TEXT(A21,"ddd") -> Wed | C21: A013 | D21: Vulnerability Scan Reports – Qtr ending 30 Sep 2026 | E21: Quarterly | F21: =IF(Quarterly!I18="","",Quarterly!I18) | G21: =IF(Quarterly!I19="","",Quarterly!I19) | H21: =IF(Quarterly!I20="","",Quarterly!I20) | I21: =IF(Quarterly!I21="","",Quarterly!I21) | J21: =IF(Quarterly!I22="","",Quarterly!I22) | K21: =IF(AND(H21<>"",J21<>""),"Fully accepted",IF(H21<>"","COR only",IF(J21<>"","J698 only",""))) | L21: =A21-TodayD -> -6 | M21: =IF(K21="Fully accepted","Done",IF(F21="N/A","N/A",IF(F21="Returned","Returned: resubmit",IF(K21="COR only","Awaiting J698",IF(K21="J698 only","Awaiting COR",IF(F21="Submitted","Awaiting COR + J698",IF(A21<TodayD,"OVERDUE",IF(A21-TodayD<=7,"Due within 7 days","")))))))) -> OVERDUE
A22: =Monthly!I5 -> 46302 | B22: =TEXT(A22,"ddd") -> Wed | C22: A017 | D22: Integrated Master Schedule – Sep 2026 | E22: Monthly | F22: =IF(Monthly!I6="","",Monthly!I6) | G22: =IF(Monthly!I7="","",Monthly!I7) | H22: =IF(Monthly!I8="","",Monthly!I8) | I22: =IF(Monthly!I9="","",Monthly!I9) | J22: =IF(Monthly!I10="","",Monthly!I10) | K22: =IF(AND(H22<>"",J22<>""),"Fully accepted",IF(H22<>"","COR only",IF(J22<>"","J698 only",""))) | L22: =A22-TodayD -> -6 | M22: =IF(K22="Fully accepted","Done",IF(F22="N/A","N/A",IF(F22="Returned","Returned: resubmit",IF(K22="COR only","Awaiting J698",IF(K22="J698 only","Awaiting COR",IF(F22="Submitted","Awaiting COR + J698",IF(A22<TodayD,"OVERDUE",IF(A22-TodayD<=7,"Due within 7 days","")))))))) -> OVERDUE
A23: =Monthly!I5 -> 46302 | B23: =TEXT(A23,"ddd") -> Wed | C23: A018 | D23: Monthly Progress Report (MPR) (including Invoice Data, ODC Data, Travel Data) – Sep 2026 | E23: Monthly | F23: =IF(Monthly!I12="","",Monthly!I12) | G23: =IF(Monthly!I13="","",Monthly!I13) | H23: =IF(Monthly!I14="","",Monthly!I14) | I23: =IF(Monthly!I15="","",Monthly!I15) | J23: =IF(Monthly!I16="","",Monthly!I16) | K23: =IF(AND(H23<>"",J23<>""),"Fully accepted",IF(H23<>"","COR only",IF(J23<>"","J698 only",""))) | L23: =A23-TodayD -> -6 | M23: =IF(K23="Fully accepted","Done",IF(F23="N/A","N/A",IF(F23="Returned","Returned: resubmit",IF(K23="COR only","Awaiting J698",IF(K23="J698 only","Awaiting COR",IF(F23="Submitted","Awaiting COR + J698",IF(A23<TodayD,"OVERDUE",IF(A23-TodayD<=7,"Due within 7 days","")))))))) -> OVERDUE
A24: =Monthly!I5 -> 46302 | B24: =TEXT(A24,"ddd") -> Wed | C24: A020 | D24: Technical Library Documentation Report – Sep 2026 | E24: Monthly | F24: =IF(Monthly!I18="","",Monthly!I18) | G24: =IF(Monthly!I19="","",Monthly!I19) | H24: =IF(Monthly!I20="","",Monthly!I20) | I24: =IF(Monthly!I21="","",Monthly!I21) | J24: =IF(Monthly!I22="","",Monthly!I22) | K24: =IF(AND(H24<>"",J24<>""),"Fully accepted",IF(H24<>"","COR only",IF(J24<>"","J698 only",""))) | L24: =A24-TodayD -> -6 | M24: =IF(K24="Fully accepted","Done",IF(F24="N/A","N/A",IF(F24="Returned","Returned: resubmit",IF(K24="COR only","Awaiting J698",IF(K24="J698 only","Awaiting COR",IF(F24="Submitted","Awaiting COR + J698",IF(A24<TodayD,"OVERDUE",IF(A24-TodayD<=7,"Due within 7 days","")))))))) -> OVERDUE
A25: =Monthly!I5 -> 46302 | B25: =TEXT(A25,"ddd") -> Wed | C25: A021 | D25: Technical Briefing/ Presentation – Sep 2026 | E25: Monthly | F25: =IF(Monthly!I24="","",Monthly!I24) | G25: =IF(Monthly!I25="","",Monthly!I25) | H25: =IF(Monthly!I26="","",Monthly!I26) | I25: =IF(Monthly!I27="","",Monthly!I27) | J25: =IF(Monthly!I28="","",Monthly!I28) | K25: =IF(AND(H25<>"",J25<>""),"Fully accepted",IF(H25<>"","COR only",IF(J25<>"","J698 only",""))) | L25: =A25-TodayD -> -6 | M25: =IF(K25="Fully accepted","Done",IF(F25="N/A","N/A",IF(F25="Returned","Returned: resubmit",IF(K25="COR only","Awaiting J698",IF(K25="J698 only","Awaiting COR",IF(F25="Submitted","Awaiting COR + J698",IF(A25<TodayD,"OVERDUE",IF(A25-TodayD<=7,"Due within 7 days","")))))))) -> OVERDUE
A26: =Weekly!N5 -> 46304 | B26: =TEXT(A26,"ddd") -> Fri | C26: A007 | D26: ACAS Scans – Wk 6 | E26: Weekly | F26: =IF(Weekly!N12="","",Weekly!N12) | G26: =IF(Weekly!N13="","",Weekly!N13) | H26: =IF(Weekly!N14="","",Weekly!N14) | I26: =IF(Weekly!N15="","",Weekly!N15) | J26: =IF(Weekly!N16="","",Weekly!N16) | K26: =IF(AND(H26<>"",J26<>""),"Fully accepted",IF(H26<>"","COR only",IF(J26<>"","J698 only",""))) | L26: =A26-TodayD -> -4 | M26: =IF(K26="Fully accepted","Done",IF(F26="N/A","N/A",IF(F26="Returned","Returned: resubmit",IF(K26="COR only","Awaiting J698",IF(K26="J698 only","Awaiting COR",IF(F26="Submitted","Awaiting COR + J698",IF(A26<TodayD,"OVERDUE",IF(A26-TodayD<=7,"Due within 7 days","")))))))) -> OVERDUE
A27: =Weekly!N5 -> 46304 | B27: =TEXT(A27,"ddd") -> Fri | C27: A019 | D27: Weekly Activity Report (WAR) – Wk 6 | E27: Weekly | F27: =IF(Weekly!N6="","",Weekly!N6) | G27: =IF(Weekly!N7="","",Weekly!N7) | H27: =IF(Weekly!N8="","",Weekly!N8) | I27: =IF(Weekly!N9="","",Weekly!N9) | J27: =IF(Weekly!N10="","",Weekly!N10) | K27: =IF(AND(H27<>"",J27<>""),"Fully accepted",IF(H27<>"","COR only",IF(J27<>"","J698 only",""))) | L27: =A27-TodayD -> -4 | M27: =IF(K27="Fully accepted","Done",IF(F27="N/A","N/A",IF(F27="Returned","Returned: resubmit",IF(K27="COR only","Awaiting J698",IF(K27="J698 only","Awaiting COR",IF(F27="Submitted","Awaiting COR + J698",IF(A27<TodayD,"OVERDUE",IF(A27-TodayD<=7,"Due within 7 days","")))))))) -> OVERDUE
A28: =Weekly!O5 -> 46311 | B28: =TEXT(A28,"ddd") -> Fri | C28: A007 | D28: ACAS Scans – Wk 7 | E28: Weekly | F28: =IF(Weekly!O12="","",Weekly!O12) | G28: =IF(Weekly!O13="","",Weekly!O13) | H28: =IF(Weekly!O14="","",Weekly!O14) | I28: =IF(Weekly!O15="","",Weekly!O15) | J28: =IF(Weekly!O16="","",Weekly!O16) | K28: =IF(AND(H28<>"",J28<>""),"Fully accepted",IF(H28<>"","COR only",IF(J28<>"","J698 only",""))) | L28: =A28-TodayD -> 3 | M28: =IF(K28="Fully accepted","Done",IF(F28="N/A","N/A",IF(F28="Returned","Returned: resubmit",IF(K28="COR only","Awaiting J698",IF(K28="J698 only","Awaiting COR",IF(F28="Submitted","Awaiting COR + J698",IF(A28<TodayD,"OVERDUE",IF(A28-TodayD<=7,"Due within 7 days","")))))))) -> Due within 7 days
A29: =Weekly!O5 -> 46311 | B29: =TEXT(A29,"ddd") -> Fri | C29: A019 | D29: Weekly Activity Report (WAR) – Wk 7 | E29: Weekly | F29: =IF(Weekly!O6="","",Weekly!O6) | G29: =IF(Weekly!O7="","",Weekly!O7) | H29: =IF(Weekly!O8="","",Weekly!O8) | I29: =IF(Weekly!O9="","",Weekly!O9) | J29: =IF(Weekly!O10="","",Weekly!O10) | K29: =IF(AND(H29<>"",J29<>""),"Fully accepted",IF(H29<>"","COR only",IF(J29<>"","J698 only",""))) | L29: =A29-TodayD -> 3 | M29: =IF(K29="Fully accepted","Done",IF(F29="N/A","N/A",IF(F29="Returned","Returned: resubmit",IF(K29="COR only","Awaiting J698",IF(K29="J698 only","Awaiting COR",IF(F29="Submitted","Awaiting COR + J698",IF(A29<TodayD,"OVERDUE",IF(A29-TodayD<=7,"Due within 7 days","")))))))) -> Due within 7 days
A30: =Weekly!P5 -> 46318 | B30: =TEXT(A30,"ddd") -> Fri | C30: A007 | D30: ACAS Scans – Wk 8 | E30: Weekly | F30: =IF(Weekly!P12="","",Weekly!P12) | G30: =IF(Weekly!P13="","",Weekly!P13) | H30: =IF(Weekly!P14="","",Weekly!P14) | I30: =IF(Weekly!P15="","",Weekly!P15) | J30: =IF(Weekly!P16="","",Weekly!P16) | K30: =IF(AND(H30<>"",J30<>""),"Fully accepted",IF(H30<>"","COR only",IF(J30<>"","J698 only",""))) | L30: =A30-TodayD -> 10 | M30: =IF(K30="Fully accepted","Done",IF(F30="N/A","N/A",IF(F30="Returned","Returned: resubmit",IF(K30="COR only","Awaiting J698",IF(K30="J698 only","Awaiting COR",IF(F30="Submitted","Awaiting COR + J698",IF(A30<TodayD,"OVERDUE",IF(A30-TodayD<=7,"Due within 7 days",""))))))))
A31: =Weekly!P5 -> 46318 | B31: =TEXT(A31,"ddd") -> Fri | C31: A019 | D31: Weekly Activity Report (WAR) – Wk 8 | E31: Weekly | F31: =IF(Weekly!P6="","",Weekly!P6) | G31: =IF(Weekly!P7="","",Weekly!P7) | H31: =IF(Weekly!P8="","",Weekly!P8) | I31: =IF(Weekly!P9="","",Weekly!P9) | J31: =IF(Weekly!P10="","",Weekly!P10) | K31: =IF(AND(H31<>"",J31<>""),"Fully accepted",IF(H31<>"","COR only",IF(J31<>"","J698 only",""))) | L31: =A31-TodayD -> 10 | M31: =IF(K31="Fully accepted","Done",IF(F31="N/A","N/A",IF(F31="Returned","Returned: resubmit",IF(K31="COR only","Awaiting J698",IF(K31="J698 only","Awaiting COR",IF(F31="Submitted","Awaiting COR + J698",IF(A31<TodayD,"OVERDUE",IF(A31-TodayD<=7,"Due within 7 days",""))))))))
A32: =Weekly!Q5 -> 46325 | B32: =TEXT(A32,"ddd") -> Fri | C32: A007 | D32: ACAS Scans – Wk 9 | E32: Weekly | F32: =IF(Weekly!Q12="","",Weekly!Q12) | G32: =IF(Weekly!Q13="","",Weekly!Q13) | H32: =IF(Weekly!Q14="","",Weekly!Q14) | I32: =IF(Weekly!Q15="","",Weekly!Q15) | J32: =IF(Weekly!Q16="","",Weekly!Q16) | K32: =IF(AND(H32<>"",J32<>""),"Fully accepted",IF(H32<>"","COR only",IF(J32<>"","J698 only",""))) | L32: =A32-TodayD -> 17 | M32: =IF(K32="Fully accepted","Done",IF(F32="N/A","N/A",IF(F32="Returned","Returned: resubmit",IF(K32="COR only","Awaiting J698",IF(K32="J698 only","Awaiting COR",IF(F32="Submitted","Awaiting COR + J698",IF(A32<TodayD,"OVERDUE",IF(A32-TodayD<=7,"Due within 7 days",""))))))))
A33: =Weekly!Q5 -> 46325 | B33: =TEXT(A33,"ddd") -> Fri | C33: A019 | D33: Weekly Activity Report (WAR) – Wk 9 | E33: Weekly | F33: =IF(Weekly!Q6="","",Weekly!Q6) | G33: =IF(Weekly!Q7="","",Weekly!Q7) | H33: =IF(Weekly!Q8="","",Weekly!Q8) | I33: =IF(Weekly!Q9="","",Weekly!Q9) | J33: =IF(Weekly!Q10="","",Weekly!Q10) | K33: =IF(AND(H33<>"",J33<>""),"Fully accepted",IF(H33<>"","COR only",IF(J33<>"","J698 only",""))) | L33: =A33-TodayD -> 17 | M33: =IF(K33="Fully accepted","Done",IF(F33="N/A","N/A",IF(F33="Returned","Returned: resubmit",IF(K33="COR only","Awaiting J698",IF(K33="J698 only","Awaiting COR",IF(F33="Submitted","Awaiting COR + J698",IF(A33<TodayD,"OVERDUE",IF(A33-TodayD<=7,"Due within 7 days",""))))))))
A34: =Weekly!R5 -> 46332 | B34: =TEXT(A34,"ddd") -> Fri | C34: A007 | D34: ACAS Scans – Wk 10 | E34: Weekly | F34: =IF(Weekly!R12="","",Weekly!R12) | G34: =IF(Weekly!R13="","",Weekly!R13) | H34: =IF(Weekly!R14="","",Weekly!R14) | I34: =IF(Weekly!R15="","",Weekly!R15) | J34: =IF(Weekly!R16="","",Weekly!R16) | K34: =IF(AND(H34<>"",J34<>""),"Fully accepted",IF(H34<>"","COR only",IF(J34<>"","J698 only",""))) | L34: =A34-TodayD -> 24 | M34: =IF(K34="Fully accepted","Done",IF(F34="N/A","N/A",IF(F34="Returned","Returned: resubmit",IF(K34="COR only","Awaiting J698",IF(K34="J698 only","Awaiting COR",IF(F34="Submitted","Awaiting COR + J698",IF(A34<TodayD,"OVERDUE",IF(A34-TodayD<=7,"Due within 7 days",""))))))))
A35: =Monthly!J5 -> 46332 | B35: =TEXT(A35,"ddd") -> Fri | C35: A017 | D35: Integrated Master Schedule – Oct 2026 | E35: Monthly | F35: =IF(Monthly!J6="","",Monthly!J6) | G35: =IF(Monthly!J7="","",Monthly!J7) | H35: =IF(Monthly!J8="","",Monthly!J8) | I35: =IF(Monthly!J9="","",Monthly!J9) | J35: =IF(Monthly!J10="","",Monthly!J10) | K35: =IF(AND(H35<>"",J35<>""),"Fully accepted",IF(H35<>"","COR only",IF(J35<>"","J698 only",""))) | L35: =A35-TodayD -> 24 | M35: =IF(K35="Fully accepted","Done",IF(F35="N/A","N/A",IF(F35="Returned","Returned: resubmit",IF(K35="COR only","Awaiting J698",IF(K35="J698 only","Awaiting COR",IF(F35="Submitted","Awaiting COR + J698",IF(A35<TodayD,"OVERDUE",IF(A35-TodayD<=7,"Due within 7 days",""))))))))
A36: =Monthly!J5 -> 46332 | B36: =TEXT(A36,"ddd") -> Fri | C36: A018 | D36: Monthly Progress Report (MPR) (including Invoice Data, ODC Data, Travel Data) – Oct 2026 | E36: Monthly | F36: =IF(Monthly!J12="","",Monthly!J12) | G36: =IF(Monthly!J13="","",Monthly!J13) | H36: =IF(Monthly!J14="","",Monthly!J14) | I36: =IF(Monthly!J15="","",Monthly!J15) | J36: =IF(Monthly!J16="","",Monthly!J16) | K36: =IF(AND(H36<>"",J36<>""),"Fully accepted",IF(H36<>"","COR only",IF(J36<>"","J698 only",""))) | L36: =A36-TodayD -> 24 | M36: =IF(K36="Fully accepted","Done",IF(F36="N/A","N/A",IF(F36="Returned","Returned: resubmit",IF(K36="COR only","Awaiting J698",IF(K36="J698 only","Awaiting COR",IF(F36="Submitted","Awaiting COR + J698",IF(A36<TodayD,"OVERDUE",IF(A36-TodayD<=7,"Due within 7 days",""))))))))
A37: =Weekly!R5 -> 46332 | B37: =TEXT(A37,"ddd") -> Fri | C37: A019 | D37: Weekly Activity Report (WAR) – Wk 10 | E37: Weekly | F37: =IF(Weekly!R6="","",Weekly!R6) | G37: =IF(Weekly!R7="","",Weekly!R7) | H37: =IF(Weekly!R8="","",Weekly!R8) | I37: =IF(Weekly!R9="","",Weekly!R9) | J37: =IF(Weekly!R10="","",Weekly!R10) | K37: =IF(AND(H37<>"",J37<>""),"Fully accepted",IF(H37<>"","COR only",IF(J37<>"","J698 only",""))) | L37: =A37-TodayD -> 24 | M37: =IF(K37="Fully accepted","Done",IF(F37="N/A","N/A",IF(F37="Returned","Returned: resubmit",IF(K37="COR only","Awaiting J698",IF(K37="J698 only","Awaiting COR",IF(F37="Submitted","Awaiting COR + J698",IF(A37<TodayD,"OVERDUE",IF(A37-TodayD<=7,"Due within 7 days",""))))))))
A38: =Monthly!J5 -> 46332 | B38: =TEXT(A38,"ddd") -> Fri | C38: A020 | D38: Technical Library Documentation Report – Oct 2026 | E38: Monthly | F38: =IF(Monthly!J18="","",Monthly!J18) | G38: =IF(Monthly!J19="","",Monthly!J19) | H38: =IF(Monthly!J20="","",Monthly!J20) | I38: =IF(Monthly!J21="","",Monthly!J21) | J38: =IF(Monthly!J22="","",Monthly!J22) | K38: =IF(AND(H38<>"",J38<>""),"Fully accepted",IF(H38<>"","COR only",IF(J38<>"","J698 only",""))) | L38: =A38-TodayD -> 24 | M38: =IF(K38="Fully accepted","Done",IF(F38="N/A","N/A",IF(F38="Returned","Returned: resubmit",IF(K38="COR only","Awaiting J698",IF(K38="J698 only","Awaiting COR",IF(F38="Submitted","Awaiting COR + J698",IF(A38<TodayD,"OVERDUE",IF(A38-TodayD<=7,"Due within 7 days",""))))))))
A39: =Monthly!J5 -> 46332 | B39: =TEXT(A39,"ddd") -> Fri | C39: A021 | D39: Technical Briefing/ Presentation – Oct 2026 | E39: Monthly | F39: =IF(Monthly!J24="","",Monthly!J24) | G39: =IF(Monthly!J25="","",Monthly!J25) | H39: =IF(Monthly!J26="","",Monthly!J26) | I39: =IF(Monthly!J27="","",Monthly!J27) | J39: =IF(Monthly!J28="","",Monthly!J28) | K39: =IF(AND(H39<>"",J39<>""),"Fully accepted",IF(H39<>"","COR only",IF(J39<>"","J698 only",""))) | L39: =A39-TodayD -> 24 | M39: =IF(K39="Fully accepted","Done",IF(F39="N/A","N/A",IF(F39="Returned","Returned: resubmit",IF(K39="COR only","Awaiting J698",IF(K39="J698 only","Awaiting COR",IF(F39="Submitted","Awaiting COR + J698",IF(A39<TodayD,"OVERDUE",IF(A39-TodayD<=7,"Due within 7 days",""))))))))
A40: =Weekly!S5 -> 46339 | B40: =TEXT(A40,"ddd") -> Fri | C40: A007 | D40: ACAS Scans – Wk 11 | E40: Weekly | F40: =IF(Weekly!S12="","",Weekly!S12) | G40: =IF(Weekly!S13="","",Weekly!S13) | H40: =IF(Weekly!S14="","",Weekly!S14) | I40: =IF(Weekly!S15="","",Weekly!S15) | J40: =IF(Weekly!S16="","",Weekly!S16) | K40: =IF(AND(H40<>"",J40<>""),"Fully accepted",IF(H40<>"","COR only",IF(J40<>"","J698 only",""))) | L40: =A40-TodayD -> 31 | M40: =IF(K40="Fully accepted","Done",IF(F40="N/A","N/A",IF(F40="Returned","Returned: resubmit",IF(K40="COR only","Awaiting J698",IF(K40="J698 only","Awaiting COR",IF(F40="Submitted","Awaiting COR + J698",IF(A40<TodayD,"OVERDUE",IF(A40-TodayD<=7,"Due within 7 days",""))))))))
...
