Workbook

Sheet PWS Deliverables Tracker
D1: THUNDERDOME
A2: Month | B2: Performance Req Section | C2: Sub Task Number | D2: Paragraph / Section | E2: Frequency | F2: Category | G2: Primary Accountable POC | H2: Secondary Accountable POC | I2: Format of Deliverable | J2: Deliverable 1 | K2: Deliverable 2 | L2: Deliverable 3 | M2: Deliverable 4 | N2: Deliverable 5 | O2: Status Flow 1 | P2: Status Flow 2 | Q2: Status Flow 3 | AA2: Category | AB2: Status Flow 1 | AC2: Status Flow 2 | AD2: Status Flow 3 | AE2: Frequency | AF2: Month
A3: Oct | B3: 6.1 | C3: 6.1 | D3: Zero Trust AI Implementation (1 of 2) | E3: Mixed (see due row) | F3: Engineering | G3: Chris Kuznicki | H3: CW4 Michael Butler | I3: Government format | J3: A001 Implementation Approach and Architecture | K3: A002 ZT Governance Plan | L3: A004 ATO Documentation/ Artifacts | M3: A005 POA&Ms including risk acceptance POA&Ms for vulnerabilities that cannot be mitigated and STIGs that cannot be applied. | N3: A006 STIG/SRG Checklists | O3: Not Received | P3: Not Reviewed | AA3: Program Mgmt | AB3: Received | AC3: Reviewed | AD3: Accepted | AE3: Weekly | AF3: Jan
I4: PWS Due Date / Frequency | J4: Due: IAW IMS Freq: One-Time, update as needed Flag: Due "IAW IMS"; IMS must exist first | K4: Due: IAW IMS Freq: One-Time, update as needed Flag: Due "IAW IMS" | L4: Due: IAW IMS Freq: One-Time, update as needed Flag: Due "IAW IMS" | M4: Due: 30 days post vulnerability identification (if vulnerability cannot be mitigated) Freq: As Needed Flag: Body: CAT I POA&M if no fix in 1 week | N4: Due: Routine Updates Freq: Quarterly Dates: see Quarterly tab | AA4: Engineering | AB4: Not Received | AC4: Not Reviewed | AD4: Returned | AE4: Monthly | AF4: Feb
A5: Oct | B5: 6.1 | C5: 6.1 | D5: Zero Trust AI Implementation (2 of 2) | E5: Mixed (see due row) | F5: Engineering | G5: Chris Kuznicki | H5: CW4 Michael Butler | I5: Mixed (see deliverables) | J5: A007 ACAS Scans | K5: A016 Briefings Slides | L5: A024 DoDAF Artifacts/Diagrams (e.g., OV, SV) | M5: A025 Engineering Artifacts (e.g., Network/System Diagrams) | N5: A026 Concept of Operations (CONOPS) | O5: Not Received | P5: Not Reviewed | AA5: Operations | AC5: Demonstrated | AD5: Returned, but Fixed | AE5: Quarterly | AF5: Mar
I6: PWS Due Date / Frequency | J6: Due: As Needed Freq: Weekly Dates: see Weekly tab | K6: Due: As determined by the Government Freq: As required | L6: Due: As determined by the Government Freq: As needed | M6: Due: Within 10 business days after assignment Freq: As needed Flag: Near-duplicate of A032 | N6: Due: 60 days post deployment Freq: Once, updated yearly or with major change | AC6: Not Demonstrated | AE6: One-Time | AF6: Apr
A7: Oct | B7: 6.2 | C7: 6.2.1 | D7: Cybersecurity Engineering / A&A (1 of 3) | E7: Mixed (see due row) | F7: Engineering | G7: Chris Kuznicki | H7: CW4 Michael Butler | I7: Mixed (see deliverables) | J7: A003 eMASS Data Entry | K7: A004 ATO Documentation/ Artifacts | L7: A005 POA&Ms including risk acceptance POA&Ms for vulnerabilities that cannot be mitigated and STIGs that cannot be applied. | M7: A006 STIG/SRG Checklists | N7: A007 ACAS Scans | O7: Not Received | P7: Not Reviewed | AE7: One-Time + Updates | AF7: May
I8: PWS Due Date / Frequency | J8: Due: IAW IMS Freq: As Needed | K8: Due: IAW IMS Freq: One-Time, update as needed | L8: Due: 30 days post vulnerability identification (if vulnerability cannot be mitigated) Freq: As Needed | M8: Due: Routine Updates Freq: Quarterly Dates: see Quarterly tab | N8: Due: As Needed Freq: Weekly Dates: see Weekly tab | AE8: Per Package | AF8: Jun
A9: Oct | B9: 6.2 | C9: 6.2.1 | D9: Cybersecurity Engineering / A&A (2 of 3) | E9: Mixed (see due row) | F9: Engineering | G9: Chris Kuznicki | H9: CW4 Michael Butler | I9: Mixed (see deliverables) | J9: A008 System Change Requests Form/ Configuration Change Request | K9: A009 eMASS Package | L9: A010 Status updates on Security patches/hot fixes, OPORD, TASK ORDER, FISMA, PPSM, IAVM and STIGs | M9: A011 Incident Response Plan | N9: A012 Security Monitoring Reports | O9: Not Received | P9: Not Reviewed | AE9: As Needed | AF9: Jul
I10: PWS Due Date / Frequency | J10: Due: As needed Freq: As required | K10: Due: As needed Freq: One-Time per package, update as needed | L10: Due: As needed Freq: As required | M10: Due: IAW IMS Freq: One-Time, update as needed Flag: Due "IAW IMS" | N10: Due: Routine Updates Freq: Quarterly Dates: see Quarterly tab Flag: Same title as A040 | AE10: Mixed (see due row) | AF10: Aug
A11: Oct | B11: 6.2 | C11: 6.2.1 | D11: Cybersecurity Engineering / A&A (3 of 3) | E11: Mixed (see due row) | F11: Engineering | G11: Chris Kuznicki | H11: CW4 Michael Butler | I11: Mixed (see deliverables) | J11: A013 Vulnerability Scan Reports | K11: A014 Compliance Documentation | L11: A015 Security Assessment Report | O11: Not Received | P11: Not Reviewed | AE11: None named | AF11: Sep
I12: PWS Due Date / Frequency | J12: Due: Routine Updates Freq: Quarterly Dates: see Quarterly tab | K12: Due: 90 Days after award Freq: One per accreditation package Date: Tue 1 Dec 2026 | L12: Due: ICW Accreditation Freq: One per accreditation package | AF12: Oct
A13: Oct | B13: 6.2 | C13: 6.2.2 | D13: Partner Nation Coordination / Country Desk Officer Support | E13: As Needed | F13: Program Mgmt | G13: Dr Marvina Harring | H13: Donovan Cozzens | I13: Vendor format | J13: A016 Briefings Slides | O13: Not Received | P13: Not Reviewed | AF13: Nov
I14: PWS Due Date / Frequency | J14: Due: As determined by the Government Freq: As required | AF14: Dec
A15: Oct | B15: 6.3 | C15: 6.3.1 | D15: Task Order Mgmt / PMO Support for PMN | E15: Monthly | F15: Program Mgmt | G15: Dr Marvina Harring | H15: Donovan Cozzens | I15: Vendor format | J15: A017 Integrated Master Schedule | O15: Not Received | P15: Not Reviewed
I16: PWS Due Date / Frequency | J16: Due: As determined by the Government Freq: One per month Dates: see Monthly tab
A17: Oct | B17: 6.3 | C17: 6.3.1.1 | D17: Monthly Progress Report | E17: Monthly | F17: Program Mgmt | G17: Dr Marvina Harring | H17: Donovan Cozzens | I17: Vendor format | J17: A018 Monthly Progress Report (MPR) (including Invoice Data, ODC Data, Travel Data) | O17: Not Received | P17: Not Reviewed
I18: PWS Due Date / Frequency | J18: Due: As determined by the Government Freq: One per month Dates: see Monthly tab
A19: Oct | B19: 6.3 | C19: 6.3.1.2 | D19: Weekly Activity Report | E19: Weekly | F19: Program Mgmt | G19: Dr Marvina Harring | H19: Donovan Cozzens | I19: Vendor format | J19: A019 Weekly Activity Report (WAR) | O19: Not Received | P19: Not Reviewed
I20: PWS Due Date / Frequency | J20: Due: Every Friday Freq: Weekly Dates: see Weekly tab
A21: Oct | B21: 6.3 | C21: 6.3.1.3 | D21: Transition Planning | E21: One-Time | F21: Program Mgmt | G21: Dr Marvina Harring | H21: Donovan Cozzens | I21: Vendor format | J21: A041 Transition-In Plan | K21: A042 Transition-Out Plan | L21: A043 Task Order Closeout | O21: Not Received | P21: Not Reviewed
I22: PWS Due Date / Frequency | J22: Due: Initial Draft at Project Kickoff Meeting Final Draft 5 business days after contract award Freq: One-Time Date: draft Wed 2 Sep, final Wed 9 Sep 2026 Flag: Body: 30 days after kickoff | K22: Due: T-30 Days (30 Days Prior to Contract End) Freq: One-Time Date: Sun 3 Jan 2027 (base year only) or Fri 1 Jun 2029 Flag: Body: 120 days before end; table: T-30 | L22: Due: End of Contract Freq: One-Time Date: Mon 3 May 2027 (base year only) or Sat 29 Sep 2029
A23: Oct | B23: 6.3 | C23: 6.3.1.4 | D23: HW / SW Maintenance Support (Logistics) | E23: Mixed (see due row) | F23: Operations | G23: Brian Abrigo | H23: Chris Kuznicki | I23: Vendor format | J23: A019 Weekly Activity Report (WAR) | K23: A044 Logistics Deliverables | O23: Not Received | P23: Not Reviewed
I24: PWS Due Date / Frequency | J24: Due: Every Friday Freq: Weekly Dates: see Weekly tab | K24: Due: ICW MSR Freq: Updated as needed Flag: ICW MSR = Monthly Status Report; confirm it equals the MPR
A25: Oct | B25: 6.3 | C25: 6.3.1.5 | D25: Communications | E25: None named | F25: Program Mgmt | G25: Dr Marvina Harring | H25: Donovan Cozzens | I25: n/a | J25: None named in PWS
I26: PWS Due Date / Frequency | J26: PWS requires: Marketing material, engagement strategy. No deliverable ID or due date.
A27: Oct | B27: 6.3 | C27: 6.3.1.6 | D27: Cyber Capacity | E27: None named | F27: Program Mgmt | G27: Dr Marvina Harring | H27: Donovan Cozzens | I27: n/a | J27: None named in PWS
I28: PWS Due Date / Frequency | J28: PWS requires: Capacity-building objectives and engagements. No deliverable ID or due date.
A29: Oct | B29: 6.3 | C29: 6.3.1.7 | D29: Knowledge Mgmt, Technical Documentation and Meeting Support | E29: Mixed (see due row) | F29: Program Mgmt | G29: Dr Marvina Harring | H29: Donovan Cozzens | I29: Vendor format | J29: A020 Technical Library Documentation Report | K29: A021 Technical Briefing/ Presentation | L29: A022 Knowledge Management Site | O29: Not Received | P29: Not Reviewed
I30: PWS Due Date / Frequency | J30: Due: ICW MSR Freq: Once per month Dates: see Monthly tab Flag: ICW MSR = Monthly Status Report; confirm it equals the MPR | K30: Due: ICW MSR Freq: One per month Dates: see Monthly tab Flag: ICW MSR = Monthly Status Report; confirm it equals the MPR | L30: Due: ICW MSR Freq: Updated, as needed Flag: ICW MSR = Monthly Status Report; confirm it equals the MPR
A31: Oct | B31: 6.3 | C31: 6.3.2.1 | D31: Analysis of Alternatives | E31: As Needed | F31: Engineering | G31: Chris Kuznicki | H31: CW4 Michael Butler | I31: Vendor format | J31: A016 Briefings Slides | K31: A023 Whitepapers | O31: Not Received | P31: Not Reviewed
I32: PWS Due Date / Frequency | J32: Due: As determined by the Government Freq: As required | K32: Due: ICW MSR Freq: As needed
A33: Oct | B33: 6.3 | C33: 6.3.2.2 | D33: Network Transformation and Modernization Support | E33: One-Time + Updates | F33: Engineering | G33: Chris Kuznicki | H33: CW4 Michael Butler | I33: Vendor format | J33: A027 Network Modernization Plan | O33: Not Received | P33: Not Reviewed
I34: PWS Due Date / Frequency | J34: Due: 90 Days after contract award Freq: One-Time, updated yearly or with major change Date: Tue 1 Dec 2026
A35: Oct | B35: 6.3 | C35: 6.3.2.3 | D35: Zero Trust Policy Assessment | E35: Mixed (see due row) | F35: Engineering | G35: Chris Kuznicki | H35: CW4 Michael Butler | I35: Vendor format | J35: A023 Whitepapers | K35: A028 ZT Traceability Matrix | L35: A029 ZT Gap Analysis | M35: A030 Zero Trust Architecture Design Document | O35: Not Received | P35: Not Reviewed
I36: PWS Due Date / Frequency | J36: Due: ICW MSR Freq: As needed | K36: Due: ICW MSR Freq: One-Time, updated yearly or with major change Flag: ICW MSR = Monthly Status Report; confirm it equals the MPR | L36: Due: As determined by the Government Freq: One-Time, updated yearly or with major change | M36: Due: As determined by the Government Freq: One-Time, updated yearly or with major change
A37: Oct | B37: 6.3 | C37: 6.3.2.4 | D37: Architecture, Design and Engineering | E37: As Needed | F37: Engineering | G37: Chris Kuznicki | H37: CW4 Michael Butler | I37: Mixed (see deliverables) | J37: A016 Briefings Slides | K37: A023 Whitepapers | L37: A024 DoDAF Artifacts/Diagrams (e.g., OV, SV) | M37: A025 Engineering Artifacts (e.g., Network/System Diagrams) | O37: Not Received | P37: Not Reviewed
I38: PWS Due Date / Frequency | J38: Due: As determined by the Government Freq: As required | K38: Due: ICW MSR Freq: As needed Flag: Table omits this paragraph (6.3.2.4) | L38: Due: As determined by the Government Freq: As needed | M38: Due: Within 10 business days after assignment Freq: As needed
A39: Oct | B39: 6.3 | C39: 6.3.2.5 | D39: AppSS Integration, Implementation and Cutover | E39: Mixed (see due row) | F39: Engineering | G39: Chris Kuznicki | H39: CW4 Michael Butler | I39: Mixed (see deliverables) | J39: A031 Implementation Plan | K39: A032 Engineering Artifacts (e.g., Network/System Diagrams) | L39: A033 ASIs | O39: Not Received | P39: Not Reviewed
I40: PWS Due Date / Frequency | J40: Due: 30 days before Implementation Freq: As needed | K40: Due: Within 10 business days after assignment Freq: As needed Flag: Near-duplicate of A025 | L40: Due: 10 days upon expected outage unless otherwise noted by the Government (must receive Gov’t approval) Freq: One-Time
...

Sheet Weekly
A1: WEEKLY – due every Friday
A2: ID | B2: Deliverable | C2: PWS ¶ | D2: Primary POC | E2: Secondary POC | F2: Accepted | G2: Overdue | H2: Wk 1 | I2: Wk 2 | J2: Wk 3 | K2: Wk 4 | L2: Wk 5 | M2: Wk 6 | N2: Wk 7 | O2: Wk 8 | P2: Wk 9 | Q2: Wk 10 | R2: Wk 11 | S2: Wk 12 | T2: Wk 13 | U2: Wk 14 | V2: Wk 15 | W2: Wk 16 | X2: Wk 17 | Y2: Wk 18 | Z2: Wk 19 | AA2: Wk 20 | AB2: Wk 21 | AC2: Wk 22 | AD2: Wk 23 | AE2: Wk 24 | AF2: Wk 25 | AG2: Wk 26 | AH2: Wk 27 | AI2: Wk 28 | AJ2: Wk 29 | AK2: Wk 30 | AL2: Wk 31 | AM2: Wk 32 | AN2: Wk 33 | AO2: Wk 34 | AP2: Wk 35
B3: Due (Friday) → | H3: =ClockStart+MOD(6-WEEKDAY(ClockStart),7)+0 -> 46269 | I3: =ClockStart+MOD(6-WEEKDAY(ClockStart),7)+7 -> 46276 | J3: =ClockStart+MOD(6-WEEKDAY(ClockStart),7)+14 -> 46283 | K3: =ClockStart+MOD(6-WEEKDAY(ClockStart),7)+21 -> 46290 | L3: =ClockStart+MOD(6-WEEKDAY(ClockStart),7)+28 -> 46297 | M3: =ClockStart+MOD(6-WEEKDAY(ClockStart),7)+35 -> 46304 | N3: =ClockStart+MOD(6-WEEKDAY(ClockStart),7)+42 -> 46311 | O3: =ClockStart+MOD(6-WEEKDAY(ClockStart),7)+49 -> 46318 | P3: =ClockStart+MOD(6-WEEKDAY(ClockStart),7)+56 -> 46325 | Q3: =ClockStart+MOD(6-WEEKDAY(ClockStart),7)+63 -> 46332 | R3: =ClockStart+MOD(6-WEEKDAY(ClockStart),7)+70 -> 46339 | S3: =ClockStart+MOD(6-WEEKDAY(ClockStart),7)+77 -> 46346 | T3: =ClockStart+MOD(6-WEEKDAY(ClockStart),7)+84 -> 46353 | U3: =ClockStart+MOD(6-WEEKDAY(ClockStart),7)+91 -> 46360 | V3: =ClockStart+MOD(6-WEEKDAY(ClockStart),7)+98 -> 46367 | W3: =ClockStart+MOD(6-WEEKDAY(ClockStart),7)+105 -> 46374 | X3: =ClockStart+MOD(6-WEEKDAY(ClockStart),7)+112 -> 46381 | Y3: =ClockStart+MOD(6-WEEKDAY(ClockStart),7)+119 -> 46388 | Z3: =ClockStart+MOD(6-WEEKDAY(ClockStart),7)+126 -> 46395 | AA3: =ClockStart+MOD(6-WEEKDAY(ClockStart),7)+133 -> 46402 | AB3: =ClockStart+MOD(6-WEEKDAY(ClockStart),7)+140 -> 46409 | AC3: =ClockStart+MOD(6-WEEKDAY(ClockStart),7)+147 -> 46416 | AD3: =ClockStart+MOD(6-WEEKDAY(ClockStart),7)+154 -> 46423 | AE3: =ClockStart+MOD(6-WEEKDAY(ClockStart),7)+161 -> 46430 | AF3: =ClockStart+MOD(6-WEEKDAY(ClockStart),7)+168 -> 46437 | AG3: =ClockStart+MOD(6-WEEKDAY(ClockStart),7)+175 -> 46444 | AH3: =ClockStart+MOD(6-WEEKDAY(ClockStart),7)+182 -> 46451 | AI3: =ClockStart+MOD(6-WEEKDAY(ClockStart),7)+189 -> 46458 | AJ3: =ClockStart+MOD(6-WEEKDAY(ClockStart),7)+196 -> 46465 | AK3: =ClockStart+MOD(6-WEEKDAY(ClockStart),7)+203 -> 46472 | AL3: =ClockStart+MOD(6-WEEKDAY(ClockStart),7)+210 -> 46479 | AM3: =ClockStart+MOD(6-WEEKDAY(ClockStart),7)+217 -> 46486 | AN3: =ClockStart+MOD(6-WEEKDAY(ClockStart),7)+224 -> 46493 | AO3: =ClockStart+MOD(6-WEEKDAY(ClockStart),7)+231 -> 46500 | AP3: =ClockStart+MOD(6-WEEKDAY(ClockStart),7)+238 -> 46507
A4: A019 | B4: Weekly Activity Report (WAR) | C4: 6.3.1.2, 6.3.1.4 | D4: Dr Marvina Harring | E4: Donovan Cozzens | F4: =COUNTIF(H4:AP4,"Accepted") -> 0 | G4: =SUMPRODUCT((H$3:AP$3<TODAY())*(H4:AP4="")) -> 6
A5: A007 | B5: ACAS Scans | C5: 6.1, 6.2.1 | D5: Chris Kuznicki | E5: CW4 Michael Butler | F5: =COUNTIF(H5:AP5,"Accepted") -> 0 | G5: =SUMPRODUCT((H$3:AP$3<TODAY())*(H5:AP5="")) -> 6
B7: Pick Submitted, Accepted, Returned or N/A. A blank cell turns red once its Friday has passed. A019 is explicit in the PWS ("every Friday"); A007 Friday is assumed.

Sheet Monthly
A1: MONTHLY – report month, due 5 business days after month end
A2: ID | B2: Deliverable | C2: PWS ¶ | D2: Primary POC | E2: Secondary POC | F2: Accepted | G2: Overdue | H2: =EDATE(DATE(YEAR(ClockStart),MONTH(ClockStart),1),0) -> 46266 | I2: =EDATE(DATE(YEAR(ClockStart),MONTH(ClockStart),1),1) -> 46296 | J2: =EDATE(DATE(YEAR(ClockStart),MONTH(ClockStart),1),2) -> 46327 | K2: =EDATE(DATE(YEAR(ClockStart),MONTH(ClockStart),1),3) -> 46357 | L2: =EDATE(DATE(YEAR(ClockStart),MONTH(ClockStart),1),4) -> 46388 | M2: =EDATE(DATE(YEAR(ClockStart),MONTH(ClockStart),1),5) -> 46419 | N2: =EDATE(DATE(YEAR(ClockStart),MONTH(ClockStart),1),6) -> 46447 | O2: =EDATE(DATE(YEAR(ClockStart),MONTH(ClockStart),1),7) -> 46478
B3: Due → | H3: =WORKDAY(EOMONTH(H2,0),DueOffset) -> 46302 | I3: =WORKDAY(EOMONTH(I2,0),DueOffset) -> 46332 | J3: =WORKDAY(EOMONTH(J2,0),DueOffset) -> 46363 | K3: =WORKDAY(EOMONTH(K2,0),DueOffset) -> 46394 | L3: =WORKDAY(EOMONTH(L2,0),DueOffset) -> 46423 | M3: =WORKDAY(EOMONTH(M2,0),DueOffset) -> 46451 | N3: =WORKDAY(EOMONTH(N2,0),DueOffset) -> 46484 | O3: =WORKDAY(EOMONTH(O2,0),DueOffset) -> 46514
A4: A017 | B4: Integrated Master Schedule | C4: 6.3.1 | D4: Dr Marvina Harring | E4: Donovan Cozzens | F4: =COUNTIF(H4:O4,"Accepted") -> 0 | G4: =SUMPRODUCT((H$3:O$3<TODAY())*(H4:O4="")) -> 1
A5: A018 | B5: Monthly Progress Report (MPR) (including Invoice Data, ODC Data, Travel Data) | C5: 6.3.1.1 | D5: Dr Marvina Harring | E5: Donovan Cozzens | F5: =COUNTIF(H5:O5,"Accepted") -> 0 | G5: =SUMPRODUCT((H$3:O$3<TODAY())*(H5:O5="")) -> 1
A6: A020 | B6: Technical Library Documentation Report | C6: 6.3.1.7 | D6: Dr Marvina Harring | E6: Donovan Cozzens | F6: =COUNTIF(H6:O6,"Accepted") -> 0 | G6: =SUMPRODUCT((H$3:O$3<TODAY())*(H6:O6="")) -> 1
A7: A021 | B7: Technical Briefing/ Presentation | C7: 6.3.1.7 | D7: Dr Marvina Harring | E7: Donovan Cozzens | F7: =COUNTIF(H7:O7,"Accepted") -> 0 | G7: =SUMPRODUCT((H$3:O$3<TODAY())*(H7:O7="")) -> 1
B9: Pick Submitted, Accepted, Returned or N/A. The PWS says "as determined by the Government" or "with the Monthly Status Report"; the 5-business-day offset is an assumption (Daily tab, cell B4). Holidays are not excluded.

Sheet Quarterly
A1: QUARTERLY – fiscal quarters, due 5 business days after quarter end
A2: ID | B2: Deliverable | C2: PWS ¶ | D2: Primary POC | E2: Secondary POC | F2: Accepted | G2: Overdue | H2: =EOMONTH(EOMONTH(ClockStart,MOD(9-MONTH(ClockStart),3)),0) -> 46295 | I2: =EOMONTH(EOMONTH(ClockStart,MOD(9-MONTH(ClockStart),3)),3) -> 46387 | J2: =EOMONTH(EOMONTH(ClockStart,MOD(9-MONTH(ClockStart),3)),6) -> 46477 | K2: =EOMONTH(EOMONTH(ClockStart,MOD(9-MONTH(ClockStart),3)),9) -> 46568
B3: Due → | H3: =WORKDAY(H2,DueOffset) -> 46302 | I3: =WORKDAY(I2,DueOffset) -> 46394 | J3: =WORKDAY(J2,DueOffset) -> 46484 | K3: =WORKDAY(K2,DueOffset) -> 46575
A4: A006 | B4: STIG/SRG Checklists | C4: 6.1, 6.2.1 | D4: Chris Kuznicki | E4: CW4 Michael Butler | F4: =COUNTIF(H4:K4,"Accepted") -> 0 | G4: =SUMPRODUCT((H$3:K$3<TODAY())*(H4:K4="")) -> 1
A5: A012 | B5: Security Monitoring Reports | C5: 6.2.1 | D5: Chris Kuznicki | E5: CW4 Michael Butler | F5: =COUNTIF(H5:K5,"Accepted") -> 0 | G5: =SUMPRODUCT((H$3:K$3<TODAY())*(H5:K5="")) -> 1
A6: A013 | B6: Vulnerability Scan Reports | C6: 6.2.1 | D6: Chris Kuznicki | E6: CW4 Michael Butler | F6: =COUNTIF(H6:K6,"Accepted") -> 0 | G6: =SUMPRODUCT((H$3:K$3<TODAY())*(H6:K6="")) -> 1
B8: Pick Submitted, Accepted, Returned or N/A. The PWS says "Quarterly / routine updates" and does not define the quarter; federal fiscal quarters are assumed (confirm with the COR). The last column falls after the base year ends.

Sheet Daily
A1: DAILY – what is due, in date order
A2: Settings (yellow = edit)
A3: Clock start (PWS date, Scenario B) | B3: 46267 | D3: Dates on the Weekly, Monthly and Quarterly tabs and the one-time items below all recalculate from these cells.
A4: Monthly / quarterly due offset (business days) | B4: 5 | D4: Recurring rows read their status from the source tab (gray). One-time rows are edited here (yellow).
A5: Gov inspection window (business days) | B5: 5 | D5: Days until due: negative means past. Holidays are not excluded from business-day math.
A6: Resubmission window (business days) | B6: 10
A7: End of base period | B7: 46510
A8: End of final option year | B8: 47390
A9: Today | B9: =TODAY() -> 46308
A11: Due date | B11: Day | C11: ID | D11: Deliverable | E11: Source | F11: Status | G11: Days until due | H11: Flag | I11: Notes
A12: =ClockStart -> 46267 | B12: =TEXT(A12,"ddd") -> Wed | C12: A041 | D12: Transition-In Plan – initial draft | E12: One-time | G12: =A12-TodayD -> -41 | H12: =IF(F12="Accepted","Done",IF(F12="Submitted","Awaiting Gov",IF(F12="N/A","N/A",IF(F12="Returned","Returned: resubmit",IF(A12<TodayD,"OVERDUE",IF(A12-TodayD<=7,"Due within 7 days","")))))) -> OVERDUE | I12: At kickoff (table). Body: 30 days after kickoff = 2 Oct 2026
A13: =Weekly!H3 -> 46269 | B13: =TEXT(A13,"ddd") -> Fri | C13: A007 | D13: ACAS Scans – Wk 1 | E13: Weekly | F13: =IF(Weekly!H5="","",Weekly!H5) | G13: =A13-TodayD -> -39 | H13: =IF(F13="Accepted","Done",IF(F13="Submitted","Awaiting Gov",IF(F13="N/A","N/A",IF(F13="Returned","Returned: resubmit",IF(A13<TodayD,"OVERDUE",IF(A13-TodayD<=7,"Due within 7 days","")))))) -> OVERDUE
A14: =Weekly!H3 -> 46269 | B14: =TEXT(A14,"ddd") -> Fri | C14: A019 | D14: Weekly Activity Report (WAR) – Wk 1 | E14: Weekly | F14: =IF(Weekly!H4="","",Weekly!H4) | G14: =A14-TodayD -> -39 | H14: =IF(F14="Accepted","Done",IF(F14="Submitted","Awaiting Gov",IF(F14="N/A","N/A",IF(F14="Returned","Returned: resubmit",IF(A14<TodayD,"OVERDUE",IF(A14-TodayD<=7,"Due within 7 days","")))))) -> OVERDUE
A15: =WORKDAY(ClockStart,5) -> 46274 | B15: =TEXT(A15,"ddd") -> Wed | C15: A041 | D15: Transition-In Plan – final draft | E15: One-time | G15: =A15-TodayD -> -34 | H15: =IF(F15="Accepted","Done",IF(F15="Submitted","Awaiting Gov",IF(F15="N/A","N/A",IF(F15="Returned","Returned: resubmit",IF(A15<TodayD,"OVERDUE",IF(A15-TodayD<=7,"Due within 7 days","")))))) -> OVERDUE | I15: 5 business days after award (table); Labor Day not excluded
A16: =Weekly!I3 -> 46276 | B16: =TEXT(A16,"ddd") -> Fri | C16: A007 | D16: ACAS Scans – Wk 2 | E16: Weekly | F16: =IF(Weekly!I5="","",Weekly!I5) | G16: =A16-TodayD -> -32 | H16: =IF(F16="Accepted","Done",IF(F16="Submitted","Awaiting Gov",IF(F16="N/A","N/A",IF(F16="Returned","Returned: resubmit",IF(A16<TodayD,"OVERDUE",IF(A16-TodayD<=7,"Due within 7 days","")))))) -> OVERDUE
A17: =Weekly!I3 -> 46276 | B17: =TEXT(A17,"ddd") -> Fri | C17: A019 | D17: Weekly Activity Report (WAR) – Wk 2 | E17: Weekly | F17: =IF(Weekly!I4="","",Weekly!I4) | G17: =A17-TodayD -> -32 | H17: =IF(F17="Accepted","Done",IF(F17="Submitted","Awaiting Gov",IF(F17="N/A","N/A",IF(F17="Returned","Returned: resubmit",IF(A17<TodayD,"OVERDUE",IF(A17-TodayD<=7,"Due within 7 days","")))))) -> OVERDUE
A18: =Weekly!J3 -> 46283 | B18: =TEXT(A18,"ddd") -> Fri | C18: A007 | D18: ACAS Scans – Wk 3 | E18: Weekly | F18: =IF(Weekly!J5="","",Weekly!J5) | G18: =A18-TodayD -> -25 | H18: =IF(F18="Accepted","Done",IF(F18="Submitted","Awaiting Gov",IF(F18="N/A","N/A",IF(F18="Returned","Returned: resubmit",IF(A18<TodayD,"OVERDUE",IF(A18-TodayD<=7,"Due within 7 days","")))))) -> OVERDUE
A19: =Weekly!J3 -> 46283 | B19: =TEXT(A19,"ddd") -> Fri | C19: A019 | D19: Weekly Activity Report (WAR) – Wk 3 | E19: Weekly | F19: =IF(Weekly!J4="","",Weekly!J4) | G19: =A19-TodayD -> -25 | H19: =IF(F19="Accepted","Done",IF(F19="Submitted","Awaiting Gov",IF(F19="N/A","N/A",IF(F19="Returned","Returned: resubmit",IF(A19<TodayD,"OVERDUE",IF(A19-TodayD<=7,"Due within 7 days","")))))) -> OVERDUE
A20: =Weekly!K3 -> 46290 | B20: =TEXT(A20,"ddd") -> Fri | C20: A007 | D20: ACAS Scans – Wk 4 | E20: Weekly | F20: =IF(Weekly!K5="","",Weekly!K5) | G20: =A20-TodayD -> -18 | H20: =IF(F20="Accepted","Done",IF(F20="Submitted","Awaiting Gov",IF(F20="N/A","N/A",IF(F20="Returned","Returned: resubmit",IF(A20<TodayD,"OVERDUE",IF(A20-TodayD<=7,"Due within 7 days","")))))) -> OVERDUE
A21: =Weekly!K3 -> 46290 | B21: =TEXT(A21,"ddd") -> Fri | C21: A019 | D21: Weekly Activity Report (WAR) – Wk 4 | E21: Weekly | F21: =IF(Weekly!K4="","",Weekly!K4) | G21: =A21-TodayD -> -18 | H21: =IF(F21="Accepted","Done",IF(F21="Submitted","Awaiting Gov",IF(F21="N/A","N/A",IF(F21="Returned","Returned: resubmit",IF(A21<TodayD,"OVERDUE",IF(A21-TodayD<=7,"Due within 7 days","")))))) -> OVERDUE
A22: =Weekly!L3 -> 46297 | B22: =TEXT(A22,"ddd") -> Fri | C22: A007 | D22: ACAS Scans – Wk 5 | E22: Weekly | F22: =IF(Weekly!L5="","",Weekly!L5) | G22: =A22-TodayD -> -11 | H22: =IF(F22="Accepted","Done",IF(F22="Submitted","Awaiting Gov",IF(F22="N/A","N/A",IF(F22="Returned","Returned: resubmit",IF(A22<TodayD,"OVERDUE",IF(A22-TodayD<=7,"Due within 7 days","")))))) -> OVERDUE
A23: =Weekly!L3 -> 46297 | B23: =TEXT(A23,"ddd") -> Fri | C23: A019 | D23: Weekly Activity Report (WAR) – Wk 5 | E23: Weekly | F23: =IF(Weekly!L4="","",Weekly!L4) | G23: =A23-TodayD -> -11 | H23: =IF(F23="Accepted","Done",IF(F23="Submitted","Awaiting Gov",IF(F23="N/A","N/A",IF(F23="Returned","Returned: resubmit",IF(A23<TodayD,"OVERDUE",IF(A23-TodayD<=7,"Due within 7 days","")))))) -> OVERDUE
A24: =ClockStart+30 -> 46297 | B24: =TEXT(A24,"ddd") -> Fri | C24: A038 | D24: Test Plans | E24: One-time | G24: =A24-TodayD -> -11 | H24: =IF(F24="Accepted","Done",IF(F24="Submitted","Awaiting Gov",IF(F24="N/A","N/A",IF(F24="Returned","Returned: resubmit",IF(A24<TodayD,"OVERDUE",IF(A24-TodayD<=7,"Due within 7 days","")))))) -> OVERDUE | I24: 30 days after award
A25: =ClockStart+30 -> 46297 | B25: =TEXT(A25,"ddd") -> Fri | C25: A039 | D25: Test Reports | E25: One-time | G25: =A25-TodayD -> -11 | H25: =IF(F25="Accepted","Done",IF(F25="Submitted","Awaiting Gov",IF(F25="N/A","N/A",IF(F25="Returned","Returned: resubmit",IF(A25<TodayD,"OVERDUE",IF(A25-TodayD<=7,"Due within 7 days","")))))) -> OVERDUE | I25: 30 days after award
A26: =Quarterly!H3 -> 46302 | B26: =TEXT(A26,"ddd") -> Wed | C26: A006 | D26: STIG/SRG Checklists – Qtr ending 30 Sep 2026 | E26: Quarterly | F26: =IF(Quarterly!H4="","",Quarterly!H4) | G26: =A26-TodayD -> -6 | H26: =IF(F26="Accepted","Done",IF(F26="Submitted","Awaiting Gov",IF(F26="N/A","N/A",IF(F26="Returned","Returned: resubmit",IF(A26<TodayD,"OVERDUE",IF(A26-TodayD<=7,"Due within 7 days","")))))) -> OVERDUE
A27: =Quarterly!H3 -> 46302 | B27: =TEXT(A27,"ddd") -> Wed | C27: A012 | D27: Security Monitoring Reports – Qtr ending 30 Sep 2026 | E27: Quarterly | F27: =IF(Quarterly!H5="","",Quarterly!H5) | G27: =A27-TodayD -> -6 | H27: =IF(F27="Accepted","Done",IF(F27="Submitted","Awaiting Gov",IF(F27="N/A","N/A",IF(F27="Returned","Returned: resubmit",IF(A27<TodayD,"OVERDUE",IF(A27-TodayD<=7,"Due within 7 days","")))))) -> OVERDUE
A28: =Quarterly!H3 -> 46302 | B28: =TEXT(A28,"ddd") -> Wed | C28: A013 | D28: Vulnerability Scan Reports – Qtr ending 30 Sep 2026 | E28: Quarterly | F28: =IF(Quarterly!H6="","",Quarterly!H6) | G28: =A28-TodayD -> -6 | H28: =IF(F28="Accepted","Done",IF(F28="Submitted","Awaiting Gov",IF(F28="N/A","N/A",IF(F28="Returned","Returned: resubmit",IF(A28<TodayD,"OVERDUE",IF(A28-TodayD<=7,"Due within 7 days","")))))) -> OVERDUE
A29: =Monthly!H3 -> 46302 | B29: =TEXT(A29,"ddd") -> Wed | C29: A017 | D29: Integrated Master Schedule – Sep 2026 | E29: Monthly | F29: =IF(Monthly!H4="","",Monthly!H4) | G29: =A29-TodayD -> -6 | H29: =IF(F29="Accepted","Done",IF(F29="Submitted","Awaiting Gov",IF(F29="N/A","N/A",IF(F29="Returned","Returned: resubmit",IF(A29<TodayD,"OVERDUE",IF(A29-TodayD<=7,"Due within 7 days","")))))) -> OVERDUE
A30: =Monthly!H3 -> 46302 | B30: =TEXT(A30,"ddd") -> Wed | C30: A018 | D30: Monthly Progress Report (MPR) (including Invoice Data, ODC Data, Travel Data) – Sep 2026 | E30: Monthly | F30: =IF(Monthly!H5="","",Monthly!H5) | G30: =A30-TodayD -> -6 | H30: =IF(F30="Accepted","Done",IF(F30="Submitted","Awaiting Gov",IF(F30="N/A","N/A",IF(F30="Returned","Returned: resubmit",IF(A30<TodayD,"OVERDUE",IF(A30-TodayD<=7,"Due within 7 days","")))))) -> OVERDUE
A31: =Monthly!H3 -> 46302 | B31: =TEXT(A31,"ddd") -> Wed | C31: A020 | D31: Technical Library Documentation Report – Sep 2026 | E31: Monthly | F31: =IF(Monthly!H6="","",Monthly!H6) | G31: =A31-TodayD -> -6 | H31: =IF(F31="Accepted","Done",IF(F31="Submitted","Awaiting Gov",IF(F31="N/A","N/A",IF(F31="Returned","Returned: resubmit",IF(A31<TodayD,"OVERDUE",IF(A31-TodayD<=7,"Due within 7 days","")))))) -> OVERDUE
A32: =Monthly!H3 -> 46302 | B32: =TEXT(A32,"ddd") -> Wed | C32: A021 | D32: Technical Briefing/ Presentation – Sep 2026 | E32: Monthly | F32: =IF(Monthly!H7="","",Monthly!H7) | G32: =A32-TodayD -> -6 | H32: =IF(F32="Accepted","Done",IF(F32="Submitted","Awaiting Gov",IF(F32="N/A","N/A",IF(F32="Returned","Returned: resubmit",IF(A32<TodayD,"OVERDUE",IF(A32-TodayD<=7,"Due within 7 days","")))))) -> OVERDUE
A33: =Weekly!M3 -> 46304 | B33: =TEXT(A33,"ddd") -> Fri | C33: A007 | D33: ACAS Scans – Wk 6 | E33: Weekly | F33: =IF(Weekly!M5="","",Weekly!M5) | G33: =A33-TodayD -> -4 | H33: =IF(F33="Accepted","Done",IF(F33="Submitted","Awaiting Gov",IF(F33="N/A","N/A",IF(F33="Returned","Returned: resubmit",IF(A33<TodayD,"OVERDUE",IF(A33-TodayD<=7,"Due within 7 days","")))))) -> OVERDUE
A34: =Weekly!M3 -> 46304 | B34: =TEXT(A34,"ddd") -> Fri | C34: A019 | D34: Weekly Activity Report (WAR) – Wk 6 | E34: Weekly | F34: =IF(Weekly!M4="","",Weekly!M4) | G34: =A34-TodayD -> -4 | H34: =IF(F34="Accepted","Done",IF(F34="Submitted","Awaiting Gov",IF(F34="N/A","N/A",IF(F34="Returned","Returned: resubmit",IF(A34<TodayD,"OVERDUE",IF(A34-TodayD<=7,"Due within 7 days","")))))) -> OVERDUE
A35: =Weekly!N3 -> 46311 | B35: =TEXT(A35,"ddd") -> Fri | C35: A007 | D35: ACAS Scans – Wk 7 | E35: Weekly | F35: =IF(Weekly!N5="","",Weekly!N5) | G35: =A35-TodayD -> 3 | H35: =IF(F35="Accepted","Done",IF(F35="Submitted","Awaiting Gov",IF(F35="N/A","N/A",IF(F35="Returned","Returned: resubmit",IF(A35<TodayD,"OVERDUE",IF(A35-TodayD<=7,"Due within 7 days","")))))) -> Due within 7 days
A36: =Weekly!N3 -> 46311 | B36: =TEXT(A36,"ddd") -> Fri | C36: A019 | D36: Weekly Activity Report (WAR) – Wk 7 | E36: Weekly | F36: =IF(Weekly!N4="","",Weekly!N4) | G36: =A36-TodayD -> 3 | H36: =IF(F36="Accepted","Done",IF(F36="Submitted","Awaiting Gov",IF(F36="N/A","N/A",IF(F36="Returned","Returned: resubmit",IF(A36<TodayD,"OVERDUE",IF(A36-TodayD<=7,"Due within 7 days","")))))) -> Due within 7 days
A37: =Weekly!O3 -> 46318 | B37: =TEXT(A37,"ddd") -> Fri | C37: A007 | D37: ACAS Scans – Wk 8 | E37: Weekly | F37: =IF(Weekly!O5="","",Weekly!O5) | G37: =A37-TodayD -> 10 | H37: =IF(F37="Accepted","Done",IF(F37="Submitted","Awaiting Gov",IF(F37="N/A","N/A",IF(F37="Returned","Returned: resubmit",IF(A37<TodayD,"OVERDUE",IF(A37-TodayD<=7,"Due within 7 days",""))))))
A38: =Weekly!O3 -> 46318 | B38: =TEXT(A38,"ddd") -> Fri | C38: A019 | D38: Weekly Activity Report (WAR) – Wk 8 | E38: Weekly | F38: =IF(Weekly!O4="","",Weekly!O4) | G38: =A38-TodayD -> 10 | H38: =IF(F38="Accepted","Done",IF(F38="Submitted","Awaiting Gov",IF(F38="N/A","N/A",IF(F38="Returned","Returned: resubmit",IF(A38<TodayD,"OVERDUE",IF(A38-TodayD<=7,"Due within 7 days",""))))))
A39: =Weekly!P3 -> 46325 | B39: =TEXT(A39,"ddd") -> Fri | C39: A007 | D39: ACAS Scans – Wk 9 | E39: Weekly | F39: =IF(Weekly!P5="","",Weekly!P5) | G39: =A39-TodayD -> 17 | H39: =IF(F39="Accepted","Done",IF(F39="Submitted","Awaiting Gov",IF(F39="N/A","N/A",IF(F39="Returned","Returned: resubmit",IF(A39<TodayD,"OVERDUE",IF(A39-TodayD<=7,"Due within 7 days",""))))))
A40: =Weekly!P3 -> 46325 | B40: =TEXT(A40,"ddd") -> Fri | C40: A019 | D40: Weekly Activity Report (WAR) – Wk 9 | E40: Weekly | F40: =IF(Weekly!P4="","",Weekly!P4) | G40: =A40-TodayD -> 17 | H40: =IF(F40="Accepted","Done",IF(F40="Submitted","Awaiting Gov",IF(F40="N/A","N/A",IF(F40="Returned","Returned: resubmit",IF(A40<TodayD,"OVERDUE",IF(A40-TodayD<=7,"Due within 7 days",""))))))
A41: =Weekly!Q3 -> 46332 | B41: =TEXT(A41,"ddd") -> Fri | C41: A007 | D41: ACAS Scans – Wk 10 | E41: Weekly | F41: =IF(Weekly!Q5="","",Weekly!Q5) | G41: =A41-TodayD -> 24 | H41: =IF(F41="Accepted","Done",IF(F41="Submitted","Awaiting Gov",IF(F41="N/A","N/A",IF(F41="Returned","Returned: resubmit",IF(A41<TodayD,"OVERDUE",IF(A41-TodayD<=7,"Due within 7 days",""))))))
...
