Workbook

Sheet Start Here
A1: Thunderdome ZT Production OTA – PWS Requirements & Deliverable Matrix
A2: Built from the PWS "as of 02 SEP 2026" (Agreement Order HC1084-26-9-2023). Replace the yellow cells; everything else calculates.
A4: Key facts (from PWS)
A5: Agreement Number | B5: HC1084-23-9-2000
A6: Agreement Order | B6: HC1084-26-9-2023
A7: Vendor | B7: Booz Allen Hamilton (BAH)
A8: Primary AOR | B8: Brian Abrigo, U.S. Pacific Command (N00038)
A9: Alternate AOR / Property Administrator | B9: Blank in the PWS contact tables – fill in when named
A10: Period of performance | B10: Base 4 May 2026–3 May 2027 · OY1 to 3 May 2028 · OY2 to 3 May 2029 · OY3 to 29 Sep 2029
A12: Settings (drive every date and metric in the workbook)
A13: Award / kickoff date | B13: 46146 | C13: ASSUMED = base period start (4 May 2026). The PWS says "after award" without a date. Enter the real award or kickoff date.
A14: End of period of performance | B14: 47390 | C14: From PWS Period of Performance (OY3 end).
A15: Gov inspection window (business days) | B15: 5 | C15: PWS Deliverables: Government has up to 5 business days; silence = deemed acceptance.
A16: Vendor resubmission window (business days) | B16: 10 | C16: PWS Deliverables: resubmit within 10 business days of a rejection notice.
A17: CAR response (business days) | B17: 5 | C17: PWS Incentives: written reply to a Corrective Action Report within 5 business days.
A18: Monthly/quarterly due offset (business days after period end) | B18: 5 | C18: ASSUMED. The PWS says "as determined by the Government" / "ICW MSR". Change when the COR sets a date.
A19: Target: on-time submissions | B19: 0.95 | C19: PWS Performance Standards, example: 95% of submissions on time.
A20: Target: max deliverables needing rework | B20: 0.05 | C20: PWS Performance Standards, example: fewer than 5% require rework.
A21: AQL: per-task quality level | B21: 0.9 | C21: PWS AQL table for 6.1, 6.2 and 6.3: 90%.
A22: Today (auto) | B22: =TODAY() -> 46306 | C22: Updates when the file opens. Overwrite with a fixed date to freeze a status snapshot.
A24: How the tabs fit together
A25: Deliverables | B25: Master list of A001–A044 straight from the PWS deliverables table. Rollups count what you log.
A26: Submission Log | B26: One row per due date. Pre-filled for the base year (weekly, monthly, quarterly, one-time). Enter submitted date and Government decision; timeliness and deadlines calculate.
A27: PWS Requirements | B27: One row per PWS paragraph: what the Vendor shall do, which deliverables the PWS names, and a gap flag. Owner and status are yours to fill.
A28: Timed Obligations | B28: Every day-count the PWS imposes (1 week, 30/120 days, 5/10 business days, 2 hours, and so on).
A29: Traceability Check | B29: Deliverables table vs. deliverable lists inside the PWS body, paragraph by paragraph.
A30: PWS Issues | B30: Conflicts, gaps and undefined terms found in the PWS that need a Government ruling.
A31: Performance | B31: On-time and rework rates against the PWS targets, plus open-item counts.
A32: Lists | B32: Dropdown sources.
A34: Color key
A35: Blue text on yellow = you enter it
A36: Black on gray = formula, do not overwrite
A38: Read this first
A39: The file ships with no actuals. Every pre-filled due date earlier than Today shows "Overdue" until you enter its submitted date, so the Performance tab reads poorly on day one. Back-fill the Submission Log, or set the award date to the real one, before trusting any rate.
A41: Example row (Submission Log)
A42: WAR wk 1: due Fri 8 May 2026, submitted 8 May, Gov decision "Accepted" → Timeliness = On time.

Sheet Deliverables
A1: Deliverables (PWS A001–A044)
A2: Columns A–J copy the PWS deliverables table. Yellow = yours. Rollups (P–U) read the Submission Log.
A4: ID | B4: Deliverable | C4: PWS ref (per PWS table) | D4: Task group | E4: Data rights | F4: Format | G4: Due (PWS wording) | H4: Distribution | I4: Frequency (PWS wording) | J4: Cadence | K4: Base / Optional | L4: Primary owner | M4: Alternate owner | N4: Gov reviewer (COR/AOR) | O4: Status | P4: Scheduled in log | Q4: Submitted | R4: Accepted | S4: Returned | T4: Overdue | U4: Next open due date | V4: Flags from PWS review
A5: A001 | B5: Implementation Approach and Architecture | C5: 6.1 | D5: 6.1 | E5: OTA Technical Data | F5: Government format | G5: Due Date IAW IMS | H5: Standard Distribution | I5: One-Time, update as needed | J5: One-time + updates | K5: Base | O5: Not Started | P5: =COUNTIF('Submission Log'!$B$5:$B$400,A5) -> 1 | Q5: =COUNTIFS('Submission Log'!$B$5:$B$400,A5,'Submission Log'!$G$5:$G$400,"<>") -> 0 | R5: =COUNTIFS('Submission Log'!$B$5:$B$400,A5,'Submission Log'!$H$5:$H$400,"Accepted")+COUNTIFS('Submission Log'!$B$5:$B$400,A5,'Submission Log'!$H$5:$H$400,"Deemed Accepted") -> 0 | S5: =COUNTIFS('Submission Log'!$B$5:$B$400,A5,'Submission Log'!$H$5:$H$400,"Returned") -> 0 | T5: =COUNTIFS('Submission Log'!$B$5:$B$400,A5,'Submission Log'!$M$5:$M$400,"Overdue") -> 0 | U5: =IFERROR(IF(_xlfn.MINIFS('Submission Log'!$F$5:$F$400,'Submission Log'!$B$5:$B$400,A5,'Submission Log'!$G$5:$G$400,"=",'Submission Log'!$F$5:$F$400,">="&Today)=0,"",_xlfn.MINIFS('Submission Log'!$F$5:$F$400,'Submission Log'!$B$5:$B$400,A5,'Submission Log'!$G$5:$G$400,"=",'Submission Log'!$F$5:$F$400,">="&Today)),"") | V5: Due "IAW IMS" – A017 must exist first (Issue 8).
A6: A002 | B6: ZT Governance Plan | C6: 6.1 | D6: 6.1 | E6: OTA Technical Data | F6: Government format | G6: Due Date IAW IMS | H6: Standard Distribution | I6: One-Time, update as needed | J6: One-time + updates | K6: Base | O6: Not Started | P6: =COUNTIF('Submission Log'!$B$5:$B$400,A6) -> 1 | Q6: =COUNTIFS('Submission Log'!$B$5:$B$400,A6,'Submission Log'!$G$5:$G$400,"<>") -> 0 | R6: =COUNTIFS('Submission Log'!$B$5:$B$400,A6,'Submission Log'!$H$5:$H$400,"Accepted")+COUNTIFS('Submission Log'!$B$5:$B$400,A6,'Submission Log'!$H$5:$H$400,"Deemed Accepted") -> 0 | S6: =COUNTIFS('Submission Log'!$B$5:$B$400,A6,'Submission Log'!$H$5:$H$400,"Returned") -> 0 | T6: =COUNTIFS('Submission Log'!$B$5:$B$400,A6,'Submission Log'!$M$5:$M$400,"Overdue") -> 0 | U6: =IFERROR(IF(_xlfn.MINIFS('Submission Log'!$F$5:$F$400,'Submission Log'!$B$5:$B$400,A6,'Submission Log'!$G$5:$G$400,"=",'Submission Log'!$F$5:$F$400,">="&Today)=0,"",_xlfn.MINIFS('Submission Log'!$F$5:$F$400,'Submission Log'!$B$5:$B$400,A6,'Submission Log'!$G$5:$G$400,"=",'Submission Log'!$F$5:$F$400,">="&Today)),"") | V6: Due "IAW IMS" (Issue 8).
A7: A003 | B7: eMASS Data Entry | C7: 6.2.1 | D7: 6.2 | E7: OTA Technical Data | F7: Government format | G7: Due Date IAW IMS | H7: Standard Distribution | I7: As Needed | J7: As needed | K7: Base | O7: Not Started | P7: =COUNTIF('Submission Log'!$B$5:$B$400,A7) -> 0 | Q7: =COUNTIFS('Submission Log'!$B$5:$B$400,A7,'Submission Log'!$G$5:$G$400,"<>") -> 0 | R7: =COUNTIFS('Submission Log'!$B$5:$B$400,A7,'Submission Log'!$H$5:$H$400,"Accepted")+COUNTIFS('Submission Log'!$B$5:$B$400,A7,'Submission Log'!$H$5:$H$400,"Deemed Accepted") -> 0 | S7: =COUNTIFS('Submission Log'!$B$5:$B$400,A7,'Submission Log'!$H$5:$H$400,"Returned") -> 0 | T7: =COUNTIFS('Submission Log'!$B$5:$B$400,A7,'Submission Log'!$M$5:$M$400,"Overdue") -> 0 | U7: =IFERROR(IF(_xlfn.MINIFS('Submission Log'!$F$5:$F$400,'Submission Log'!$B$5:$B$400,A7,'Submission Log'!$G$5:$G$400,"=",'Submission Log'!$F$5:$F$400,">="&Today)=0,"",_xlfn.MINIFS('Submission Log'!$F$5:$F$400,'Submission Log'!$B$5:$B$400,A7,'Submission Log'!$G$5:$G$400,"=",'Submission Log'!$F$5:$F$400,">="&Today)),"")
A8: A004 | B8: ATO Documentation/ Artifacts | C8: 6.1, 6.2.1 | D8: 6.1 | E8: OTA Technical Data | F8: Government format | G8: Due Date IAW IMS | H8: Standard Distribution | I8: One-Time, update as needed | J8: One-time + updates | K8: Base | O8: Not Started | P8: =COUNTIF('Submission Log'!$B$5:$B$400,A8) -> 1 | Q8: =COUNTIFS('Submission Log'!$B$5:$B$400,A8,'Submission Log'!$G$5:$G$400,"<>") -> 0 | R8: =COUNTIFS('Submission Log'!$B$5:$B$400,A8,'Submission Log'!$H$5:$H$400,"Accepted")+COUNTIFS('Submission Log'!$B$5:$B$400,A8,'Submission Log'!$H$5:$H$400,"Deemed Accepted") -> 0 | S8: =COUNTIFS('Submission Log'!$B$5:$B$400,A8,'Submission Log'!$H$5:$H$400,"Returned") -> 0 | T8: =COUNTIFS('Submission Log'!$B$5:$B$400,A8,'Submission Log'!$M$5:$M$400,"Overdue") -> 0 | U8: =IFERROR(IF(_xlfn.MINIFS('Submission Log'!$F$5:$F$400,'Submission Log'!$B$5:$B$400,A8,'Submission Log'!$G$5:$G$400,"=",'Submission Log'!$F$5:$F$400,">="&Today)=0,"",_xlfn.MINIFS('Submission Log'!$F$5:$F$400,'Submission Log'!$B$5:$B$400,A8,'Submission Log'!$G$5:$G$400,"=",'Submission Log'!$F$5:$F$400,">="&Today)),"") | V8: Due "IAW IMS" (Issue 8).
A9: A005 | B9: POA&Ms including risk acceptance POA&Ms for vulnerabilities that cannot be mitigated and STIGs that cannot be applied. | C9: 6.1, 6.2.1 | D9: 6.1 | E9: OTA Technical Data | F9: Government format | G9: 30 days post vulnerability identification (if vulnerability cannot be mitigated). To be reviewed every 30 days from initial finding. | H9: Standard Distribution | I9: As Needed | J9: As needed | K9: Base | O9: Not Started | P9: =COUNTIF('Submission Log'!$B$5:$B$400,A9) -> 0 | Q9: =COUNTIFS('Submission Log'!$B$5:$B$400,A9,'Submission Log'!$G$5:$G$400,"<>") -> 0 | R9: =COUNTIFS('Submission Log'!$B$5:$B$400,A9,'Submission Log'!$H$5:$H$400,"Accepted")+COUNTIFS('Submission Log'!$B$5:$B$400,A9,'Submission Log'!$H$5:$H$400,"Deemed Accepted") -> 0 | S9: =COUNTIFS('Submission Log'!$B$5:$B$400,A9,'Submission Log'!$H$5:$H$400,"Returned") -> 0 | T9: =COUNTIFS('Submission Log'!$B$5:$B$400,A9,'Submission Log'!$M$5:$M$400,"Overdue") -> 0 | U9: =IFERROR(IF(_xlfn.MINIFS('Submission Log'!$F$5:$F$400,'Submission Log'!$B$5:$B$400,A9,'Submission Log'!$G$5:$G$400,"=",'Submission Log'!$F$5:$F$400,">="&Today)=0,"",_xlfn.MINIFS('Submission Log'!$F$5:$F$400,'Submission Log'!$B$5:$B$400,A9,'Submission Log'!$G$5:$G$400,"=",'Submission Log'!$F$5:$F$400,">="&Today)),"") | V9: Body says CAT I POA&M if no fix in 1 week; table says 30 days (Issue 3).
A10: A006 | B10: STIG/SRG Checklists | C10: 6.1, 6.2.1 | D10: 6.1 | E10: OTA Technical Data | F10: Government format | G10: Routine Updates | H10: Standard Distribution | I10: Quarterly | J10: Quarterly | K10: Base | O10: Not Started | P10: =COUNTIF('Submission Log'!$B$5:$B$400,A10) -> 4 | Q10: =COUNTIFS('Submission Log'!$B$5:$B$400,A10,'Submission Log'!$G$5:$G$400,"<>") -> 0 | R10: =COUNTIFS('Submission Log'!$B$5:$B$400,A10,'Submission Log'!$H$5:$H$400,"Accepted")+COUNTIFS('Submission Log'!$B$5:$B$400,A10,'Submission Log'!$H$5:$H$400,"Deemed Accepted") -> 0 | S10: =COUNTIFS('Submission Log'!$B$5:$B$400,A10,'Submission Log'!$H$5:$H$400,"Returned") -> 0 | T10: =COUNTIFS('Submission Log'!$B$5:$B$400,A10,'Submission Log'!$M$5:$M$400,"Overdue") -> 1 | U10: =IFERROR(IF(_xlfn.MINIFS('Submission Log'!$F$5:$F$400,'Submission Log'!$B$5:$B$400,A10,'Submission Log'!$G$5:$G$400,"=",'Submission Log'!$F$5:$F$400,">="&Today)=0,"",_xlfn.MINIFS('Submission Log'!$F$5:$F$400,'Submission Log'!$B$5:$B$400,A10,'Submission Log'!$G$5:$G$400,"=",'Submission Log'!$F$5:$F$400,">="&Today)),"") -> 46332
A11: A007 | B11: ACAS Scans | C11: 6.1, 6.2.1 | D11: 6.1 | E11: OTA Technical Data | F11: Vendor format/ Government Approved | G11: As Needed | H11: Standard Distribution | I11: Weekly | J11: Weekly | K11: Base | O11: Not Started | P11: =COUNTIF('Submission Log'!$B$5:$B$400,A11) -> 52 | Q11: =COUNTIFS('Submission Log'!$B$5:$B$400,A11,'Submission Log'!$G$5:$G$400,"<>") -> 0 | R11: =COUNTIFS('Submission Log'!$B$5:$B$400,A11,'Submission Log'!$H$5:$H$400,"Accepted")+COUNTIFS('Submission Log'!$B$5:$B$400,A11,'Submission Log'!$H$5:$H$400,"Deemed Accepted") -> 0 | S11: =COUNTIFS('Submission Log'!$B$5:$B$400,A11,'Submission Log'!$H$5:$H$400,"Returned") -> 0 | T11: =COUNTIFS('Submission Log'!$B$5:$B$400,A11,'Submission Log'!$M$5:$M$400,"Overdue") -> 23 | U11: =IFERROR(IF(_xlfn.MINIFS('Submission Log'!$F$5:$F$400,'Submission Log'!$B$5:$B$400,A11,'Submission Log'!$G$5:$G$400,"=",'Submission Log'!$F$5:$F$400,">="&Today)=0,"",_xlfn.MINIFS('Submission Log'!$F$5:$F$400,'Submission Log'!$B$5:$B$400,A11,'Submission Log'!$G$5:$G$400,"=",'Submission Log'!$F$5:$F$400,">="&Today)),"") -> 46311
A12: A008 | B12: System Change Requests Form/ Configuration Change Request | C12: 6.2.1 | D12: 6.2 | E12: OTA Technical Data | F12: Government Format | G12: As needed | H12: Standard Distribution | I12: As required | J12: As needed | K12: Base | O12: Not Started | P12: =COUNTIF('Submission Log'!$B$5:$B$400,A12) -> 0 | Q12: =COUNTIFS('Submission Log'!$B$5:$B$400,A12,'Submission Log'!$G$5:$G$400,"<>") -> 0 | R12: =COUNTIFS('Submission Log'!$B$5:$B$400,A12,'Submission Log'!$H$5:$H$400,"Accepted")+COUNTIFS('Submission Log'!$B$5:$B$400,A12,'Submission Log'!$H$5:$H$400,"Deemed Accepted") -> 0 | S12: =COUNTIFS('Submission Log'!$B$5:$B$400,A12,'Submission Log'!$H$5:$H$400,"Returned") -> 0 | T12: =COUNTIFS('Submission Log'!$B$5:$B$400,A12,'Submission Log'!$M$5:$M$400,"Overdue") -> 0 | U12: =IFERROR(IF(_xlfn.MINIFS('Submission Log'!$F$5:$F$400,'Submission Log'!$B$5:$B$400,A12,'Submission Log'!$G$5:$G$400,"=",'Submission Log'!$F$5:$F$400,">="&Today)=0,"",_xlfn.MINIFS('Submission Log'!$F$5:$F$400,'Submission Log'!$B$5:$B$400,A12,'Submission Log'!$G$5:$G$400,"=",'Submission Log'!$F$5:$F$400,">="&Today)),"")
A13: A009 | B13: eMASS Package | C13: 6.2.1 | D13: 6.2 | E13: OTA Technical Data | F13: Government Format | G13: As needed | H13: Standard Distribution | I13: One-Time per package, update as needed | J13: One-time + updates | K13: Base | O13: Not Started | P13: =COUNTIF('Submission Log'!$B$5:$B$400,A13) -> 0 | Q13: =COUNTIFS('Submission Log'!$B$5:$B$400,A13,'Submission Log'!$G$5:$G$400,"<>") -> 0 | R13: =COUNTIFS('Submission Log'!$B$5:$B$400,A13,'Submission Log'!$H$5:$H$400,"Accepted")+COUNTIFS('Submission Log'!$B$5:$B$400,A13,'Submission Log'!$H$5:$H$400,"Deemed Accepted") -> 0 | S13: =COUNTIFS('Submission Log'!$B$5:$B$400,A13,'Submission Log'!$H$5:$H$400,"Returned") -> 0 | T13: =COUNTIFS('Submission Log'!$B$5:$B$400,A13,'Submission Log'!$M$5:$M$400,"Overdue") -> 0 | U13: =IFERROR(IF(_xlfn.MINIFS('Submission Log'!$F$5:$F$400,'Submission Log'!$B$5:$B$400,A13,'Submission Log'!$G$5:$G$400,"=",'Submission Log'!$F$5:$F$400,">="&Today)=0,"",_xlfn.MINIFS('Submission Log'!$F$5:$F$400,'Submission Log'!$B$5:$B$400,A13,'Submission Log'!$G$5:$G$400,"=",'Submission Log'!$F$5:$F$400,">="&Today)),"")
A14: A010 | B14: Status updates on Security patches/hot fixes, OPORD, TASK ORDER, FISMA, PPSM, IAVM and STIGs | C14: 6.2.1 | D14: 6.2 | E14: OTA Technical Data | F14: Vendor format/ Government Approved | G14: As needed | H14: Standard Distribution | I14: As required | J14: As needed | K14: Base | O14: Not Started | P14: =COUNTIF('Submission Log'!$B$5:$B$400,A14) -> 0 | Q14: =COUNTIFS('Submission Log'!$B$5:$B$400,A14,'Submission Log'!$G$5:$G$400,"<>") -> 0 | R14: =COUNTIFS('Submission Log'!$B$5:$B$400,A14,'Submission Log'!$H$5:$H$400,"Accepted")+COUNTIFS('Submission Log'!$B$5:$B$400,A14,'Submission Log'!$H$5:$H$400,"Deemed Accepted") -> 0 | S14: =COUNTIFS('Submission Log'!$B$5:$B$400,A14,'Submission Log'!$H$5:$H$400,"Returned") -> 0 | T14: =COUNTIFS('Submission Log'!$B$5:$B$400,A14,'Submission Log'!$M$5:$M$400,"Overdue") -> 0 | U14: =IFERROR(IF(_xlfn.MINIFS('Submission Log'!$F$5:$F$400,'Submission Log'!$B$5:$B$400,A14,'Submission Log'!$G$5:$G$400,"=",'Submission Log'!$F$5:$F$400,">="&Today)=0,"",_xlfn.MINIFS('Submission Log'!$F$5:$F$400,'Submission Log'!$B$5:$B$400,A14,'Submission Log'!$G$5:$G$400,"=",'Submission Log'!$F$5:$F$400,">="&Today)),"")
A15: A011 | B15: Incident Response Plan | C15: 6.2.1 | D15: 6.2 | E15: OTA Technical Data | F15: Government format | G15: Due Date IAW IMS | H15: Standard Distribution | I15: One-Time, update as needed | J15: One-time + updates | K15: Base | O15: Not Started | P15: =COUNTIF('Submission Log'!$B$5:$B$400,A15) -> 1 | Q15: =COUNTIFS('Submission Log'!$B$5:$B$400,A15,'Submission Log'!$G$5:$G$400,"<>") -> 0 | R15: =COUNTIFS('Submission Log'!$B$5:$B$400,A15,'Submission Log'!$H$5:$H$400,"Accepted")+COUNTIFS('Submission Log'!$B$5:$B$400,A15,'Submission Log'!$H$5:$H$400,"Deemed Accepted") -> 0 | S15: =COUNTIFS('Submission Log'!$B$5:$B$400,A15,'Submission Log'!$H$5:$H$400,"Returned") -> 0 | T15: =COUNTIFS('Submission Log'!$B$5:$B$400,A15,'Submission Log'!$M$5:$M$400,"Overdue") -> 0 | U15: =IFERROR(IF(_xlfn.MINIFS('Submission Log'!$F$5:$F$400,'Submission Log'!$B$5:$B$400,A15,'Submission Log'!$G$5:$G$400,"=",'Submission Log'!$F$5:$F$400,">="&Today)=0,"",_xlfn.MINIFS('Submission Log'!$F$5:$F$400,'Submission Log'!$B$5:$B$400,A15,'Submission Log'!$G$5:$G$400,"=",'Submission Log'!$F$5:$F$400,">="&Today)),"") | V15: Due "IAW IMS" (Issue 8).
A16: A012 | B16: Security Monitoring Reports | C16: 6.2.1 | D16: 6.2 | E16: OTA Technical Data | F16: Government format | G16: Routine Updates | H16: Standard Distribution | I16: Quarterly | J16: Quarterly | K16: Base | O16: Not Started | P16: =COUNTIF('Submission Log'!$B$5:$B$400,A16) -> 4 | Q16: =COUNTIFS('Submission Log'!$B$5:$B$400,A16,'Submission Log'!$G$5:$G$400,"<>") -> 0 | R16: =COUNTIFS('Submission Log'!$B$5:$B$400,A16,'Submission Log'!$H$5:$H$400,"Accepted")+COUNTIFS('Submission Log'!$B$5:$B$400,A16,'Submission Log'!$H$5:$H$400,"Deemed Accepted") -> 0 | S16: =COUNTIFS('Submission Log'!$B$5:$B$400,A16,'Submission Log'!$H$5:$H$400,"Returned") -> 0 | T16: =COUNTIFS('Submission Log'!$B$5:$B$400,A16,'Submission Log'!$M$5:$M$400,"Overdue") -> 1 | U16: =IFERROR(IF(_xlfn.MINIFS('Submission Log'!$F$5:$F$400,'Submission Log'!$B$5:$B$400,A16,'Submission Log'!$G$5:$G$400,"=",'Submission Log'!$F$5:$F$400,">="&Today)=0,"",_xlfn.MINIFS('Submission Log'!$F$5:$F$400,'Submission Log'!$B$5:$B$400,A16,'Submission Log'!$G$5:$G$400,"=",'Submission Log'!$F$5:$F$400,">="&Today)),"") -> 46332 | V16: Same title as A040 (Issue 20).
A17: A013 | B17: Vulnerability Scan Reports | C17: 6.2.1 | D17: 6.2 | E17: OTA Technical Data | F17: Government format | G17: Routine Updates | H17: Standard Distribution | I17: Quarterly | J17: Quarterly | K17: Base | O17: Not Started | P17: =COUNTIF('Submission Log'!$B$5:$B$400,A17) -> 4 | Q17: =COUNTIFS('Submission Log'!$B$5:$B$400,A17,'Submission Log'!$G$5:$G$400,"<>") -> 0 | R17: =COUNTIFS('Submission Log'!$B$5:$B$400,A17,'Submission Log'!$H$5:$H$400,"Accepted")+COUNTIFS('Submission Log'!$B$5:$B$400,A17,'Submission Log'!$H$5:$H$400,"Deemed Accepted") -> 0 | S17: =COUNTIFS('Submission Log'!$B$5:$B$400,A17,'Submission Log'!$H$5:$H$400,"Returned") -> 0 | T17: =COUNTIFS('Submission Log'!$B$5:$B$400,A17,'Submission Log'!$M$5:$M$400,"Overdue") -> 1 | U17: =IFERROR(IF(_xlfn.MINIFS('Submission Log'!$F$5:$F$400,'Submission Log'!$B$5:$B$400,A17,'Submission Log'!$G$5:$G$400,"=",'Submission Log'!$F$5:$F$400,">="&Today)=0,"",_xlfn.MINIFS('Submission Log'!$F$5:$F$400,'Submission Log'!$B$5:$B$400,A17,'Submission Log'!$G$5:$G$400,"=",'Submission Log'!$F$5:$F$400,">="&Today)),"") -> 46332
A18: A014 | B18: Compliance Documentation | C18: 6.2.1 | D18: 6.2 | E18: OTA Work | F18: Vendor Determined Format | G18: 90 Days after award | H18: Standard Distribution | I18: One per accreditation package | J18: Per package | K18: Base | O18: Not Started | P18: =COUNTIF('Submission Log'!$B$5:$B$400,A18) -> 1 | Q18: =COUNTIFS('Submission Log'!$B$5:$B$400,A18,'Submission Log'!$G$5:$G$400,"<>") -> 0 | R18: =COUNTIFS('Submission Log'!$B$5:$B$400,A18,'Submission Log'!$H$5:$H$400,"Accepted")+COUNTIFS('Submission Log'!$B$5:$B$400,A18,'Submission Log'!$H$5:$H$400,"Deemed Accepted") -> 0 | S18: =COUNTIFS('Submission Log'!$B$5:$B$400,A18,'Submission Log'!$H$5:$H$400,"Returned") -> 0 | T18: =COUNTIFS('Submission Log'!$B$5:$B$400,A18,'Submission Log'!$M$5:$M$400,"Overdue") -> 1 | U18: =IFERROR(IF(_xlfn.MINIFS('Submission Log'!$F$5:$F$400,'Submission Log'!$B$5:$B$400,A18,'Submission Log'!$G$5:$G$400,"=",'Submission Log'!$F$5:$F$400,">="&Today)=0,"",_xlfn.MINIFS('Submission Log'!$F$5:$F$400,'Submission Log'!$B$5:$B$400,A18,'Submission Log'!$G$5:$G$400,"=",'Submission Log'!$F$5:$F$400,">="&Today)),"")
A19: A015 | B19: Security Assessment Report | C19: 6.2.1 | D19: 6.2 | E19: OTA Work | F19: Vendor Determined Format | G19: ICW Accreditation | H19: Standard Distribution | I19: One per accreditation package | J19: Per package | K19: Base | O19: Not Started | P19: =COUNTIF('Submission Log'!$B$5:$B$400,A19) -> 1 | Q19: =COUNTIFS('Submission Log'!$B$5:$B$400,A19,'Submission Log'!$G$5:$G$400,"<>") -> 0 | R19: =COUNTIFS('Submission Log'!$B$5:$B$400,A19,'Submission Log'!$H$5:$H$400,"Accepted")+COUNTIFS('Submission Log'!$B$5:$B$400,A19,'Submission Log'!$H$5:$H$400,"Deemed Accepted") -> 0 | S19: =COUNTIFS('Submission Log'!$B$5:$B$400,A19,'Submission Log'!$H$5:$H$400,"Returned") -> 0 | T19: =COUNTIFS('Submission Log'!$B$5:$B$400,A19,'Submission Log'!$M$5:$M$400,"Overdue") -> 0 | U19: =IFERROR(IF(_xlfn.MINIFS('Submission Log'!$F$5:$F$400,'Submission Log'!$B$5:$B$400,A19,'Submission Log'!$G$5:$G$400,"=",'Submission Log'!$F$5:$F$400,">="&Today)=0,"",_xlfn.MINIFS('Submission Log'!$F$5:$F$400,'Submission Log'!$B$5:$B$400,A19,'Submission Log'!$G$5:$G$400,"=",'Submission Log'!$F$5:$F$400,">="&Today)),"")
A20: A016 | B20: Briefings Slides | C20: 6.1, 6.2.2, 6.3.2.1, 6.3.2.4, 6.3.3.1 | D20: 6.1 | E20: OTA Technical Data | F20: Vendor Determined Format | G20: As determined by the Government | H20: Standard Distribution | I20: As required | J20: As needed | K20: Base | O20: Not Started | P20: =COUNTIF('Submission Log'!$B$5:$B$400,A20) -> 0 | Q20: =COUNTIFS('Submission Log'!$B$5:$B$400,A20,'Submission Log'!$G$5:$G$400,"<>") -> 0 | R20: =COUNTIFS('Submission Log'!$B$5:$B$400,A20,'Submission Log'!$H$5:$H$400,"Accepted")+COUNTIFS('Submission Log'!$B$5:$B$400,A20,'Submission Log'!$H$5:$H$400,"Deemed Accepted") -> 0 | S20: =COUNTIFS('Submission Log'!$B$5:$B$400,A20,'Submission Log'!$H$5:$H$400,"Returned") -> 0 | T20: =COUNTIFS('Submission Log'!$B$5:$B$400,A20,'Submission Log'!$M$5:$M$400,"Overdue") -> 0 | U20: =IFERROR(IF(_xlfn.MINIFS('Submission Log'!$F$5:$F$400,'Submission Log'!$B$5:$B$400,A20,'Submission Log'!$G$5:$G$400,"=",'Submission Log'!$F$5:$F$400,">="&Today)=0,"",_xlfn.MINIFS('Submission Log'!$F$5:$F$400,'Submission Log'!$B$5:$B$400,A20,'Submission Log'!$G$5:$G$400,"=",'Submission Log'!$F$5:$F$400,">="&Today)),"")
A21: A017 | B21: Integrated Master Schedule | C21: 6.3.1 | D21: 6.3 | E21: OTA Work | F21: Vendor Determined Format | G21: As determined by the Government | H21: Standard Distribution | I21: One per month | J21: Monthly | K21: Base | O21: Not Started | P21: =COUNTIF('Submission Log'!$B$5:$B$400,A21) -> 12 | Q21: =COUNTIFS('Submission Log'!$B$5:$B$400,A21,'Submission Log'!$G$5:$G$400,"<>") -> 0 | R21: =COUNTIFS('Submission Log'!$B$5:$B$400,A21,'Submission Log'!$H$5:$H$400,"Accepted")+COUNTIFS('Submission Log'!$B$5:$B$400,A21,'Submission Log'!$H$5:$H$400,"Deemed Accepted") -> 0 | S21: =COUNTIFS('Submission Log'!$B$5:$B$400,A21,'Submission Log'!$H$5:$H$400,"Returned") -> 0 | T21: =COUNTIFS('Submission Log'!$B$5:$B$400,A21,'Submission Log'!$M$5:$M$400,"Overdue") -> 5 | U21: =IFERROR(IF(_xlfn.MINIFS('Submission Log'!$F$5:$F$400,'Submission Log'!$B$5:$B$400,A21,'Submission Log'!$G$5:$G$400,"=",'Submission Log'!$F$5:$F$400,">="&Today)=0,"",_xlfn.MINIFS('Submission Log'!$F$5:$F$400,'Submission Log'!$B$5:$B$400,A21,'Submission Log'!$G$5:$G$400,"=",'Submission Log'!$F$5:$F$400,">="&Today)),"") -> 46332
A22: A018 | B22: Monthly Progress Report (MPR) (including Invoice Data, ODC Data, Travel Data) | C22: 6.3.1.1 | D22: 6.3 | E22: OTA Work | F22: Vendor Determined Format | G22: As determined by the Government | H22: Standard Distribution | I22: One per month | J22: Monthly | K22: Base | O22: Not Started | P22: =COUNTIF('Submission Log'!$B$5:$B$400,A22) -> 12 | Q22: =COUNTIFS('Submission Log'!$B$5:$B$400,A22,'Submission Log'!$G$5:$G$400,"<>") -> 0 | R22: =COUNTIFS('Submission Log'!$B$5:$B$400,A22,'Submission Log'!$H$5:$H$400,"Accepted")+COUNTIFS('Submission Log'!$B$5:$B$400,A22,'Submission Log'!$H$5:$H$400,"Deemed Accepted") -> 0 | S22: =COUNTIFS('Submission Log'!$B$5:$B$400,A22,'Submission Log'!$H$5:$H$400,"Returned") -> 0 | T22: =COUNTIFS('Submission Log'!$B$5:$B$400,A22,'Submission Log'!$M$5:$M$400,"Overdue") -> 5 | U22: =IFERROR(IF(_xlfn.MINIFS('Submission Log'!$F$5:$F$400,'Submission Log'!$B$5:$B$400,A22,'Submission Log'!$G$5:$G$400,"=",'Submission Log'!$F$5:$F$400,">="&Today)=0,"",_xlfn.MINIFS('Submission Log'!$F$5:$F$400,'Submission Log'!$B$5:$B$400,A22,'Submission Log'!$G$5:$G$400,"=",'Submission Log'!$F$5:$F$400,">="&Today)),"") -> 46332
A23: A019 | B23: Weekly Activity Report (WAR) | C23: 6.3.1.2, 6.3.1.4 | D23: 6.3 | E23: OTA Work | F23: Vendor Determined Format | G23: Every Friday | H23: Standard Distribution | I23: Weekly | J23: Weekly | K23: Base | O23: Not Started | P23: =COUNTIF('Submission Log'!$B$5:$B$400,A23) -> 52 | Q23: =COUNTIFS('Submission Log'!$B$5:$B$400,A23,'Submission Log'!$G$5:$G$400,"<>") -> 0 | R23: =COUNTIFS('Submission Log'!$B$5:$B$400,A23,'Submission Log'!$H$5:$H$400,"Accepted")+COUNTIFS('Submission Log'!$B$5:$B$400,A23,'Submission Log'!$H$5:$H$400,"Deemed Accepted") -> 0 | S23: =COUNTIFS('Submission Log'!$B$5:$B$400,A23,'Submission Log'!$H$5:$H$400,"Returned") -> 0 | T23: =COUNTIFS('Submission Log'!$B$5:$B$400,A23,'Submission Log'!$M$5:$M$400,"Overdue") -> 23 | U23: =IFERROR(IF(_xlfn.MINIFS('Submission Log'!$F$5:$F$400,'Submission Log'!$B$5:$B$400,A23,'Submission Log'!$G$5:$G$400,"=",'Submission Log'!$F$5:$F$400,">="&Today)=0,"",_xlfn.MINIFS('Submission Log'!$F$5:$F$400,'Submission Log'!$B$5:$B$400,A23,'Submission Log'!$G$5:$G$400,"=",'Submission Log'!$F$5:$F$400,">="&Today)),"") -> 46311
A24: A020 | B24: Technical Library Documentation Report | C24: 6.3.1.7 | D24: 6.3 | E24: OTA Work | F24: Vendor Determined Format | G24: ICW MSR | H24: Standard Distribution | I24: Once per month | J24: Monthly | K24: Base | O24: Not Started | P24: =COUNTIF('Submission Log'!$B$5:$B$400,A24) -> 12 | Q24: =COUNTIFS('Submission Log'!$B$5:$B$400,A24,'Submission Log'!$G$5:$G$400,"<>") -> 0 | R24: =COUNTIFS('Submission Log'!$B$5:$B$400,A24,'Submission Log'!$H$5:$H$400,"Accepted")+COUNTIFS('Submission Log'!$B$5:$B$400,A24,'Submission Log'!$H$5:$H$400,"Deemed Accepted") -> 0 | S24: =COUNTIFS('Submission Log'!$B$5:$B$400,A24,'Submission Log'!$H$5:$H$400,"Returned") -> 0 | T24: =COUNTIFS('Submission Log'!$B$5:$B$400,A24,'Submission Log'!$M$5:$M$400,"Overdue") -> 5 | U24: =IFERROR(IF(_xlfn.MINIFS('Submission Log'!$F$5:$F$400,'Submission Log'!$B$5:$B$400,A24,'Submission Log'!$G$5:$G$400,"=",'Submission Log'!$F$5:$F$400,">="&Today)=0,"",_xlfn.MINIFS('Submission Log'!$F$5:$F$400,'Submission Log'!$B$5:$B$400,A24,'Submission Log'!$G$5:$G$400,"=",'Submission Log'!$F$5:$F$400,">="&Today)),"") -> 46332 | V24: "ICW MSR" is undefined (Issue 7).
A25: A021 | B25: Technical Briefing/ Presentation | C25: 6.3.1.7 | D25: 6.3 | E25: OTA Work | F25: Vendor Determined Format | G25: ICW MSR | H25: Standard Distribution | I25: One per month | J25: Monthly | K25: Base | O25: Not Started | P25: =COUNTIF('Submission Log'!$B$5:$B$400,A25) -> 12 | Q25: =COUNTIFS('Submission Log'!$B$5:$B$400,A25,'Submission Log'!$G$5:$G$400,"<>") -> 0 | R25: =COUNTIFS('Submission Log'!$B$5:$B$400,A25,'Submission Log'!$H$5:$H$400,"Accepted")+COUNTIFS('Submission Log'!$B$5:$B$400,A25,'Submission Log'!$H$5:$H$400,"Deemed Accepted") -> 0 | S25: =COUNTIFS('Submission Log'!$B$5:$B$400,A25,'Submission Log'!$H$5:$H$400,"Returned") -> 0 | T25: =COUNTIFS('Submission Log'!$B$5:$B$400,A25,'Submission Log'!$M$5:$M$400,"Overdue") -> 5 | U25: =IFERROR(IF(_xlfn.MINIFS('Submission Log'!$F$5:$F$400,'Submission Log'!$B$5:$B$400,A25,'Submission Log'!$G$5:$G$400,"=",'Submission Log'!$F$5:$F$400,">="&Today)=0,"",_xlfn.MINIFS('Submission Log'!$F$5:$F$400,'Submission Log'!$B$5:$B$400,A25,'Submission Log'!$G$5:$G$400,"=",'Submission Log'!$F$5:$F$400,">="&Today)),"") -> 46332 | V25: "ICW MSR" is undefined (Issue 7).
A26: A022 | B26: Knowledge Management Site | C26: 6.3.1.7 | D26: 6.3 | E26: OTA Work | F26: Vendor Determined Format | G26: ICW MSR | H26: Standard Distribution | I26: Updated, as needed | J26: As needed | K26: Base | O26: Not Started | P26: =COUNTIF('Submission Log'!$B$5:$B$400,A26) -> 0 | Q26: =COUNTIFS('Submission Log'!$B$5:$B$400,A26,'Submission Log'!$G$5:$G$400,"<>") -> 0 | R26: =COUNTIFS('Submission Log'!$B$5:$B$400,A26,'Submission Log'!$H$5:$H$400,"Accepted")+COUNTIFS('Submission Log'!$B$5:$B$400,A26,'Submission Log'!$H$5:$H$400,"Deemed Accepted") -> 0 | S26: =COUNTIFS('Submission Log'!$B$5:$B$400,A26,'Submission Log'!$H$5:$H$400,"Returned") -> 0 | T26: =COUNTIFS('Submission Log'!$B$5:$B$400,A26,'Submission Log'!$M$5:$M$400,"Overdue") -> 0 | U26: =IFERROR(IF(_xlfn.MINIFS('Submission Log'!$F$5:$F$400,'Submission Log'!$B$5:$B$400,A26,'Submission Log'!$G$5:$G$400,"=",'Submission Log'!$F$5:$F$400,">="&Today)=0,"",_xlfn.MINIFS('Submission Log'!$F$5:$F$400,'Submission Log'!$B$5:$B$400,A26,'Submission Log'!$G$5:$G$400,"=",'Submission Log'!$F$5:$F$400,">="&Today)),"") | V26: "ICW MSR" is undefined (Issue 7).
A27: A023 | B27: Whitepapers | C27: 6.3.2.1, 6.3.2.3, 6.3.3.1 | D27: 6.3 | E27: OTA Work | F27: Vendor Determined Format | G27: ICW MSR | H27: Standard Distribution | I27: As needed | J27: As needed | K27: Base | O27: Not Started | P27: =COUNTIF('Submission Log'!$B$5:$B$400,A27) -> 0 | Q27: =COUNTIFS('Submission Log'!$B$5:$B$400,A27,'Submission Log'!$G$5:$G$400,"<>") -> 0 | R27: =COUNTIFS('Submission Log'!$B$5:$B$400,A27,'Submission Log'!$H$5:$H$400,"Accepted")+COUNTIFS('Submission Log'!$B$5:$B$400,A27,'Submission Log'!$H$5:$H$400,"Deemed Accepted") -> 0 | S27: =COUNTIFS('Submission Log'!$B$5:$B$400,A27,'Submission Log'!$H$5:$H$400,"Returned") -> 0 | T27: =COUNTIFS('Submission Log'!$B$5:$B$400,A27,'Submission Log'!$M$5:$M$400,"Overdue") -> 0 | U27: =IFERROR(IF(_xlfn.MINIFS('Submission Log'!$F$5:$F$400,'Submission Log'!$B$5:$B$400,A27,'Submission Log'!$G$5:$G$400,"=",'Submission Log'!$F$5:$F$400,">="&Today)=0,"",_xlfn.MINIFS('Submission Log'!$F$5:$F$400,'Submission Log'!$B$5:$B$400,A27,'Submission Log'!$G$5:$G$400,"=",'Submission Log'!$F$5:$F$400,">="&Today)),"") | V27: Table omits 6.3.2.4, where the body lists it (Issue 5).
A28: A024 | B28: DoDAF Artifacts/Diagrams (e.g., OV, SV) | C28: 6.1, 6.3.2.4, 6.3.3.1 | D28: 6.1 | E28: OTA Technical Data | F28: Vendor Determined Format | G28: As determined by the Government | H28: Standard Distribution | I28: As needed | J28: As needed | K28: Base | O28: Not Started | P28: =COUNTIF('Submission Log'!$B$5:$B$400,A28) -> 0 | Q28: =COUNTIFS('Submission Log'!$B$5:$B$400,A28,'Submission Log'!$G$5:$G$400,"<>") -> 0 | R28: =COUNTIFS('Submission Log'!$B$5:$B$400,A28,'Submission Log'!$H$5:$H$400,"Accepted")+COUNTIFS('Submission Log'!$B$5:$B$400,A28,'Submission Log'!$H$5:$H$400,"Deemed Accepted") -> 0 | S28: =COUNTIFS('Submission Log'!$B$5:$B$400,A28,'Submission Log'!$H$5:$H$400,"Returned") -> 0 | T28: =COUNTIFS('Submission Log'!$B$5:$B$400,A28,'Submission Log'!$M$5:$M$400,"Overdue") -> 0 | U28: =IFERROR(IF(_xlfn.MINIFS('Submission Log'!$F$5:$F$400,'Submission Log'!$B$5:$B$400,A28,'Submission Log'!$G$5:$G$400,"=",'Submission Log'!$F$5:$F$400,">="&Today)=0,"",_xlfn.MINIFS('Submission Log'!$F$5:$F$400,'Submission Log'!$B$5:$B$400,A28,'Submission Log'!$G$5:$G$400,"=",'Submission Log'!$F$5:$F$400,">="&Today)),"")
A29: A025 | B29: Engineering Artifacts (e.g., Network/System Diagrams) | C29: 6.1, 6.3.2.4, 6.3.4.1.3, 6.3.4.1.4, 6.3.4.1.5 | D29: 6.1 | E29: OTA Technical Data | F29: Government format | G29: Within 10 business days after assignment | H29: Standard Distribution | I29: As needed | J29: As needed | K29: Base | O29: Not Started | P29: =COUNTIF('Submission Log'!$B$5:$B$400,A29) -> 0 | Q29: =COUNTIFS('Submission Log'!$B$5:$B$400,A29,'Submission Log'!$G$5:$G$400,"<>") -> 0 | R29: =COUNTIFS('Submission Log'!$B$5:$B$400,A29,'Submission Log'!$H$5:$H$400,"Accepted")+COUNTIFS('Submission Log'!$B$5:$B$400,A29,'Submission Log'!$H$5:$H$400,"Deemed Accepted") -> 0 | S29: =COUNTIFS('Submission Log'!$B$5:$B$400,A29,'Submission Log'!$H$5:$H$400,"Returned") -> 0 | T29: =COUNTIFS('Submission Log'!$B$5:$B$400,A29,'Submission Log'!$M$5:$M$400,"Overdue") -> 0 | U29: =IFERROR(IF(_xlfn.MINIFS('Submission Log'!$F$5:$F$400,'Submission Log'!$B$5:$B$400,A29,'Submission Log'!$G$5:$G$400,"=",'Submission Log'!$F$5:$F$400,">="&Today)=0,"",_xlfn.MINIFS('Submission Log'!$F$5:$F$400,'Submission Log'!$B$5:$B$400,A29,'Submission Log'!$G$5:$G$400,"=",'Submission Log'!$F$5:$F$400,">="&Today)),"") | V29: Near-duplicate of A032 (Issue 20).
A30: A026 | B30: Concept of Operations (CONOPS) | C30: 6.1 | D30: 6.1 | E30: OTA Technical Data | F30: Vendor Determined/ Govt Approved Format | G30: 60 days post deployment | H30: Standard Distribution | I30: Once, updated yearly or with major change | J30: One-time + updates | K30: Base | O30: Not Started | P30: =COUNTIF('Submission Log'!$B$5:$B$400,A30) -> 1 | Q30: =COUNTIFS('Submission Log'!$B$5:$B$400,A30,'Submission Log'!$G$5:$G$400,"<>") -> 0 | R30: =COUNTIFS('Submission Log'!$B$5:$B$400,A30,'Submission Log'!$H$5:$H$400,"Accepted")+COUNTIFS('Submission Log'!$B$5:$B$400,A30,'Submission Log'!$H$5:$H$400,"Deemed Accepted") -> 0 | S30: =COUNTIFS('Submission Log'!$B$5:$B$400,A30,'Submission Log'!$H$5:$H$400,"Returned") -> 0 | T30: =COUNTIFS('Submission Log'!$B$5:$B$400,A30,'Submission Log'!$M$5:$M$400,"Overdue") -> 0 | U30: =IFERROR(IF(_xlfn.MINIFS('Submission Log'!$F$5:$F$400,'Submission Log'!$B$5:$B$400,A30,'Submission Log'!$G$5:$G$400,"=",'Submission Log'!$F$5:$F$400,">="&Today)=0,"",_xlfn.MINIFS('Submission Log'!$F$5:$F$400,'Submission Log'!$B$5:$B$400,A30,'Submission Log'!$G$5:$G$400,"=",'Submission Log'!$F$5:$F$400,">="&Today)),"")
A31: A027 | B31: Network Modernization Plan | C31: 6.3.2.2 | D31: 6.3 | E31: OTA Technical Data | F31: Vendor Determined Format | G31: 90 Days after contract award | H31: Standard Distribution | I31: One-Time, updated yearly or with major change | J31: One-time + updates | K31: Base | O31: Not Started | P31: =COUNTIF('Submission Log'!$B$5:$B$400,A31) -> 1 | Q31: =COUNTIFS('Submission Log'!$B$5:$B$400,A31,'Submission Log'!$G$5:$G$400,"<>") -> 0 | R31: =COUNTIFS('Submission Log'!$B$5:$B$400,A31,'Submission Log'!$H$5:$H$400,"Accepted")+COUNTIFS('Submission Log'!$B$5:$B$400,A31,'Submission Log'!$H$5:$H$400,"Deemed Accepted") -> 0 | S31: =COUNTIFS('Submission Log'!$B$5:$B$400,A31,'Submission Log'!$H$5:$H$400,"Returned") -> 0 | T31: =COUNTIFS('Submission Log'!$B$5:$B$400,A31,'Submission Log'!$M$5:$M$400,"Overdue") -> 1 | U31: =IFERROR(IF(_xlfn.MINIFS('Submission Log'!$F$5:$F$400,'Submission Log'!$B$5:$B$400,A31,'Submission Log'!$G$5:$G$400,"=",'Submission Log'!$F$5:$F$400,">="&Today)=0,"",_xlfn.MINIFS('Submission Log'!$F$5:$F$400,'Submission Log'!$B$5:$B$400,A31,'Submission Log'!$G$5:$G$400,"=",'Submission Log'!$F$5:$F$400,">="&Today)),"")
A32: A028 | B32: ZT Traceability Matrix | C32: 6.3.2.3 | D32: 6.3 | E32: OTA Technical Data | F32: Vendor Determined Format | G32: ICW MSR | H32: Standard Distribution | I32: One-Time, updated yearly or with major change | J32: One-time + updates | K32: Base | O32: Not Started | P32: =COUNTIF('Submission Log'!$B$5:$B$400,A32) -> 1 | Q32: =COUNTIFS('Submission Log'!$B$5:$B$400,A32,'Submission Log'!$G$5:$G$400,"<>") -> 0 | R32: =COUNTIFS('Submission Log'!$B$5:$B$400,A32,'Submission Log'!$H$5:$H$400,"Accepted")+COUNTIFS('Submission Log'!$B$5:$B$400,A32,'Submission Log'!$H$5:$H$400,"Deemed Accepted") -> 0 | S32: =COUNTIFS('Submission Log'!$B$5:$B$400,A32,'Submission Log'!$H$5:$H$400,"Returned") -> 0 | T32: =COUNTIFS('Submission Log'!$B$5:$B$400,A32,'Submission Log'!$M$5:$M$400,"Overdue") -> 0 | U32: =IFERROR(IF(_xlfn.MINIFS('Submission Log'!$F$5:$F$400,'Submission Log'!$B$5:$B$400,A32,'Submission Log'!$G$5:$G$400,"=",'Submission Log'!$F$5:$F$400,">="&Today)=0,"",_xlfn.MINIFS('Submission Log'!$F$5:$F$400,'Submission Log'!$B$5:$B$400,A32,'Submission Log'!$G$5:$G$400,"=",'Submission Log'!$F$5:$F$400,">="&Today)),"") | V32: "ICW MSR" is undefined (Issue 7).
A33: A029 | B33: ZT Gap Analysis | C33: 6.3.2.3 | D33: 6.3 | E33: OTA Technical Data | F33: Vendor Determined Format | G33: As determined by the Government | H33: Standard Distribution | I33: One-Time, updated yearly or with major change | J33: One-time + updates | K33: Base | O33: Not Started | P33: =COUNTIF('Submission Log'!$B$5:$B$400,A33) -> 1 | Q33: =COUNTIFS('Submission Log'!$B$5:$B$400,A33,'Submission Log'!$G$5:$G$400,"<>") -> 0 | R33: =COUNTIFS('Submission Log'!$B$5:$B$400,A33,'Submission Log'!$H$5:$H$400,"Accepted")+COUNTIFS('Submission Log'!$B$5:$B$400,A33,'Submission Log'!$H$5:$H$400,"Deemed Accepted") -> 0 | S33: =COUNTIFS('Submission Log'!$B$5:$B$400,A33,'Submission Log'!$H$5:$H$400,"Returned") -> 0 | T33: =COUNTIFS('Submission Log'!$B$5:$B$400,A33,'Submission Log'!$M$5:$M$400,"Overdue") -> 0 | U33: =IFERROR(IF(_xlfn.MINIFS('Submission Log'!$F$5:$F$400,'Submission Log'!$B$5:$B$400,A33,'Submission Log'!$G$5:$G$400,"=",'Submission Log'!$F$5:$F$400,">="&Today)=0,"",_xlfn.MINIFS('Submission Log'!$F$5:$F$400,'Submission Log'!$B$5:$B$400,A33,'Submission Log'!$G$5:$G$400,"=",'Submission Log'!$F$5:$F$400,">="&Today)),"")
A34: A030 | B34: Zero Trust Architecture Design Document | C34: 6.3.2.3 | D34: 6.3 | E34: OTA Technical Data | F34: Vendor Determined Format | G34: As determined by the Government | H34: Standard Distribution | I34: One-Time, updated yearly or with major change | J34: One-time + updates | K34: Base | O34: Not Started | P34: =COUNTIF('Submission Log'!$B$5:$B$400,A34) -> 1 | Q34: =COUNTIFS('Submission Log'!$B$5:$B$400,A34,'Submission Log'!$G$5:$G$400,"<>") -> 0 | R34: =COUNTIFS('Submission Log'!$B$5:$B$400,A34,'Submission Log'!$H$5:$H$400,"Accepted")+COUNTIFS('Submission Log'!$B$5:$B$400,A34,'Submission Log'!$H$5:$H$400,"Deemed Accepted") -> 0 | S34: =COUNTIFS('Submission Log'!$B$5:$B$400,A34,'Submission Log'!$H$5:$H$400,"Returned") -> 0 | T34: =COUNTIFS('Submission Log'!$B$5:$B$400,A34,'Submission Log'!$M$5:$M$400,"Overdue") -> 0 | U34: =IFERROR(IF(_xlfn.MINIFS('Submission Log'!$F$5:$F$400,'Submission Log'!$B$5:$B$400,A34,'Submission Log'!$G$5:$G$400,"=",'Submission Log'!$F$5:$F$400,">="&Today)=0,"",_xlfn.MINIFS('Submission Log'!$F$5:$F$400,'Submission Log'!$B$5:$B$400,A34,'Submission Log'!$G$5:$G$400,"=",'Submission Log'!$F$5:$F$400,">="&Today)),"")
A35: A031 | B35: Implementation Plan | C35: 6.3.2.5, 6.3.3.2, 6.3.3.3 | D35: 6.3 | E35: OTA Technical Data | F35: Vendor format | G35: 30 days before Implementation | H35: Standard Distribution | I35: As needed | J35: As needed | K35: Base | O35: Not Started | P35: =COUNTIF('Submission Log'!$B$5:$B$400,A35) -> 0 | Q35: =COUNTIFS('Submission Log'!$B$5:$B$400,A35,'Submission Log'!$G$5:$G$400,"<>") -> 0 | R35: =COUNTIFS('Submission Log'!$B$5:$B$400,A35,'Submission Log'!$H$5:$H$400,"Accepted")+COUNTIFS('Submission Log'!$B$5:$B$400,A35,'Submission Log'!$H$5:$H$400,"Deemed Accepted") -> 0 | S35: =COUNTIFS('Submission Log'!$B$5:$B$400,A35,'Submission Log'!$H$5:$H$400,"Returned") -> 0 | T35: =COUNTIFS('Submission Log'!$B$5:$B$400,A35,'Submission Log'!$M$5:$M$400,"Overdue") -> 0 | U35: =IFERROR(IF(_xlfn.MINIFS('Submission Log'!$F$5:$F$400,'Submission Log'!$B$5:$B$400,A35,'Submission Log'!$G$5:$G$400,"=",'Submission Log'!$F$5:$F$400,">="&Today)=0,"",_xlfn.MINIFS('Submission Log'!$F$5:$F$400,'Submission Log'!$B$5:$B$400,A35,'Submission Log'!$G$5:$G$400,"=",'Submission Log'!$F$5:$F$400,">="&Today)),"")
A36: A032 | B36: Engineering Artifacts (e.g., Network/System Diagrams) | C36: 6.3.2.5, 6.3.3.1, 6.3.3.2, 6.3.3.3 | D36: 6.3 | E36: OTA Technical Data | F36: Government format | G36: Within 10 business days after assignment | H36: Standard Distribution | I36: As needed | J36: As needed | K36: Base | O36: Not Started | P36: =COUNTIF('Submission Log'!$B$5:$B$400,A36) -> 0 | Q36: =COUNTIFS('Submission Log'!$B$5:$B$400,A36,'Submission Log'!$G$5:$G$400,"<>") -> 0 | R36: =COUNTIFS('Submission Log'!$B$5:$B$400,A36,'Submission Log'!$H$5:$H$400,"Accepted")+COUNTIFS('Submission Log'!$B$5:$B$400,A36,'Submission Log'!$H$5:$H$400,"Deemed Accepted") -> 0 | S36: =COUNTIFS('Submission Log'!$B$5:$B$400,A36,'Submission Log'!$H$5:$H$400,"Returned") -> 0 | T36: =COUNTIFS('Submission Log'!$B$5:$B$400,A36,'Submission Log'!$M$5:$M$400,"Overdue") -> 0 | U36: =IFERROR(IF(_xlfn.MINIFS('Submission Log'!$F$5:$F$400,'Submission Log'!$B$5:$B$400,A36,'Submission Log'!$G$5:$G$400,"=",'Submission Log'!$F$5:$F$400,">="&Today)=0,"",_xlfn.MINIFS('Submission Log'!$F$5:$F$400,'Submission Log'!$B$5:$B$400,A36,'Submission Log'!$G$5:$G$400,"=",'Submission Log'!$F$5:$F$400,">="&Today)),"") | V36: Near-duplicate of A025 (Issue 20).
A37: A033 | B37: ASIs | C37: 6.3.2.5, 6.3.3.2, 6.3.3.3 | D37: 6.3 | E37: OTA Technical Data | F37: Government format | G37: 10 days upon expected outage unless otherwise noted by the Government (must receive Gov’t approval) | H37: Standard Distribution | I37: One-Time | J37: One-time | K37: Base | O37: Not Started | P37: =COUNTIF('Submission Log'!$B$5:$B$400,A37) -> 0 | Q37: =COUNTIFS('Submission Log'!$B$5:$B$400,A37,'Submission Log'!$G$5:$G$400,"<>") -> 0 | R37: =COUNTIFS('Submission Log'!$B$5:$B$400,A37,'Submission Log'!$H$5:$H$400,"Accepted")+COUNTIFS('Submission Log'!$B$5:$B$400,A37,'Submission Log'!$H$5:$H$400,"Deemed Accepted") -> 0 | S37: =COUNTIFS('Submission Log'!$B$5:$B$400,A37,'Submission Log'!$H$5:$H$400,"Returned") -> 0 | T37: =COUNTIFS('Submission Log'!$B$5:$B$400,A37,'Submission Log'!$M$5:$M$400,"Overdue") -> 0 | U37: =IFERROR(IF(_xlfn.MINIFS('Submission Log'!$F$5:$F$400,'Submission Log'!$B$5:$B$400,A37,'Submission Log'!$G$5:$G$400,"=",'Submission Log'!$F$5:$F$400,">="&Today)=0,"",_xlfn.MINIFS('Submission Log'!$F$5:$F$400,'Submission Log'!$B$5:$B$400,A37,'Submission Log'!$G$5:$G$400,"=",'Submission Log'!$F$5:$F$400,">="&Today)),"")
A38: A034 | B38: Site Survey Reports | C38: 6.3.2.6, 6.3.3.1 | D38: 6.3 | E38: OTA Technical Data | F38: Vendor format/ Government Approved | G38: IAW IMS | H38: Standard Distribution | I38: One-Time | J38: One-time | K38: Base | O38: Not Started | P38: =COUNTIF('Submission Log'!$B$5:$B$400,A38) -> 1 | Q38: =COUNTIFS('Submission Log'!$B$5:$B$400,A38,'Submission Log'!$G$5:$G$400,"<>") -> 0 | R38: =COUNTIFS('Submission Log'!$B$5:$B$400,A38,'Submission Log'!$H$5:$H$400,"Accepted")+COUNTIFS('Submission Log'!$B$5:$B$400,A38,'Submission Log'!$H$5:$H$400,"Deemed Accepted") -> 0 | S38: =COUNTIFS('Submission Log'!$B$5:$B$400,A38,'Submission Log'!$H$5:$H$400,"Returned") -> 0 | T38: =COUNTIFS('Submission Log'!$B$5:$B$400,A38,'Submission Log'!$M$5:$M$400,"Overdue") -> 0 | U38: =IFERROR(IF(_xlfn.MINIFS('Submission Log'!$F$5:$F$400,'Submission Log'!$B$5:$B$400,A38,'Submission Log'!$G$5:$G$400,"=",'Submission Log'!$F$5:$F$400,">="&Today)=0,"",_xlfn.MINIFS('Submission Log'!$F$5:$F$400,'Submission Log'!$B$5:$B$400,A38,'Submission Log'!$G$5:$G$400,"=",'Submission Log'!$F$5:$F$400,">="&Today)),"") | V38: Table cites 6.3.2.6, which names no deliverables (Issue 4).
A39: A035 | B39: ITSM/ Change Tickets | C39: 6.3.4.1.1, 6.3.4.1.2 | D39: 6.3 | E39: OTA Technical Data | F39: Government format | G39: 10 days prior to necessary change | H39: Standard Distribution | I39: One-Time, updated as needed | J39: One-time + updates | K39: Base + Optional | O39: Not Started | P39: =COUNTIF('Submission Log'!$B$5:$B$400,A39) -> 0 | Q39: =COUNTIFS('Submission Log'!$B$5:$B$400,A39,'Submission Log'!$G$5:$G$400,"<>") -> 0 | R39: =COUNTIFS('Submission Log'!$B$5:$B$400,A39,'Submission Log'!$H$5:$H$400,"Accepted")+COUNTIFS('Submission Log'!$B$5:$B$400,A39,'Submission Log'!$H$5:$H$400,"Deemed Accepted") -> 0 | S39: =COUNTIFS('Submission Log'!$B$5:$B$400,A39,'Submission Log'!$H$5:$H$400,"Returned") -> 0 | T39: =COUNTIFS('Submission Log'!$B$5:$B$400,A39,'Submission Log'!$M$5:$M$400,"Overdue") -> 0 | U39: =IFERROR(IF(_xlfn.MINIFS('Submission Log'!$F$5:$F$400,'Submission Log'!$B$5:$B$400,A39,'Submission Log'!$G$5:$G$400,"=",'Submission Log'!$F$5:$F$400,">="&Today)=0,"",_xlfn.MINIFS('Submission Log'!$F$5:$F$400,'Submission Log'!$B$5:$B$400,A39,'Submission Log'!$G$5:$G$400,"=",'Submission Log'!$F$5:$F$400,">="&Today)),"") | V39: Table omits the 24x7 paragraph (Issue 6).
A40: A036 | B40: Metrics Report | C40: 6.3.4.1.2 | D40: 6.3 | E40: OTA Technical Data | F40: Vendor Determined/ Govt Approved format | G40: 30 Days after Implementation | H40: Standard Distribution | I40: One-Time | J40: One-time | K40: Optional Priced | O40: Not Started | P40: =COUNTIF('Submission Log'!$B$5:$B$400,A40) -> 0 | Q40: =COUNTIFS('Submission Log'!$B$5:$B$400,A40,'Submission Log'!$G$5:$G$400,"<>") -> 0 | R40: =COUNTIFS('Submission Log'!$B$5:$B$400,A40,'Submission Log'!$H$5:$H$400,"Accepted")+COUNTIFS('Submission Log'!$B$5:$B$400,A40,'Submission Log'!$H$5:$H$400,"Deemed Accepted") -> 0 | S40: =COUNTIFS('Submission Log'!$B$5:$B$400,A40,'Submission Log'!$H$5:$H$400,"Returned") -> 0 | T40: =COUNTIFS('Submission Log'!$B$5:$B$400,A40,'Submission Log'!$M$5:$M$400,"Overdue") -> 0 | U40: =IFERROR(IF(_xlfn.MINIFS('Submission Log'!$F$5:$F$400,'Submission Log'!$B$5:$B$400,A40,'Submission Log'!$G$5:$G$400,"=",'Submission Log'!$F$5:$F$400,">="&Today)=0,"",_xlfn.MINIFS('Submission Log'!$F$5:$F$400,'Submission Log'!$B$5:$B$400,A40,'Submission Log'!$G$5:$G$400,"=",'Submission Log'!$F$5:$F$400,">="&Today)),"") | V40: Table omits the 24x7 paragraph (Issue 6).
A41: A037 | B41: Help Desk Report | C41: 6.3.4.1.2 | D41: 6.3 | E41: OTA Technical Data | F41: Vendor Determined/ Govt Approved format | G41: 24 hours upon request | H41: Standard Distribution | I41: One-Time, updated as needed | J41: One-time + updates | K41: Optional Priced | O41: Not Started | P41: =COUNTIF('Submission Log'!$B$5:$B$400,A41) -> 0 | Q41: =COUNTIFS('Submission Log'!$B$5:$B$400,A41,'Submission Log'!$G$5:$G$400,"<>") -> 0 | R41: =COUNTIFS('Submission Log'!$B$5:$B$400,A41,'Submission Log'!$H$5:$H$400,"Accepted")+COUNTIFS('Submission Log'!$B$5:$B$400,A41,'Submission Log'!$H$5:$H$400,"Deemed Accepted") -> 0 | S41: =COUNTIFS('Submission Log'!$B$5:$B$400,A41,'Submission Log'!$H$5:$H$400,"Returned") -> 0 | T41: =COUNTIFS('Submission Log'!$B$5:$B$400,A41,'Submission Log'!$M$5:$M$400,"Overdue") -> 0 | U41: =IFERROR(IF(_xlfn.MINIFS('Submission Log'!$F$5:$F$400,'Submission Log'!$B$5:$B$400,A41,'Submission Log'!$G$5:$G$400,"=",'Submission Log'!$F$5:$F$400,">="&Today)=0,"",_xlfn.MINIFS('Submission Log'!$F$5:$F$400,'Submission Log'!$B$5:$B$400,A41,'Submission Log'!$G$5:$G$400,"=",'Submission Log'!$F$5:$F$400,">="&Today)),"") | V41: Table omits the 24x7 paragraph (Issue 6).
...

Sheet Submission Log
A1: Submission Log
A2: One row per due date. Enter the yellow cells; the gray cells calculate. Add rows for as-needed deliverables in the blank rows below.
A4: Log # | B4: Deliverable ID | C4: Deliverable | D4: Task group | E4: Period / event | F4: Due date | G4: Date submitted | H4: Gov decision | I4: Decision date | J4: Gov inspection deadline | K4: Deemed-acceptance flag | L4: Resubmission due | M4: Timeliness | N4: Days late | O4: Rework (1/0) | P4: Link / location | Q4: Notes
A5: 1 | B5: A001 | C5: =IF(B5="","",IFERROR(INDEX(Deliverables!$B$5:$B$48,MATCH(B5,Deliverables!$A$5:$A$48,0)),"ID not found")) -> Implementation Approach and Architecture | D5: =IF(B5="","",IFERROR(INDEX(Deliverables!$D$5:$D$48,MATCH(B5,Deliverables!$A$5:$A$48,0)),"")) -> 6.1 | E5: Initial delivery | J5: =IF(G5="","",WORKDAY(G5,ReviewDays)) | K5: =IF(AND(G5<>"",OR(H5="",H5="Pending"),Today>J5),"Past inspection window – deemed accepted","") | L5: =IF(AND(H5="Returned",I5<>""),WORKDAY(I5,ResubDays),"") | M5: =IF(OR(B5="",F5=""),"",IF(G5<>"",IF(G5<=F5,"On time","Late"),IF(Today>F5,"Overdue",IF(F5-Today<=7,"Due within 7 days","Not yet due")))) | N5: =IF(OR(M5="Late",M5="Overdue"),IF(G5<>"",G5-F5,Today-F5),"") | O5: =IF(H5="Returned",1,0) -> 0 | Q5: Due per the IMS (A017): enter the date.
A6: 2 | B6: A002 | C6: =IF(B6="","",IFERROR(INDEX(Deliverables!$B$5:$B$48,MATCH(B6,Deliverables!$A$5:$A$48,0)),"ID not found")) -> ZT Governance Plan | D6: =IF(B6="","",IFERROR(INDEX(Deliverables!$D$5:$D$48,MATCH(B6,Deliverables!$A$5:$A$48,0)),"")) -> 6.1 | E6: Initial delivery | J6: =IF(G6="","",WORKDAY(G6,ReviewDays)) | K6: =IF(AND(G6<>"",OR(H6="",H6="Pending"),Today>J6),"Past inspection window – deemed accepted","") | L6: =IF(AND(H6="Returned",I6<>""),WORKDAY(I6,ResubDays),"") | M6: =IF(OR(B6="",F6=""),"",IF(G6<>"",IF(G6<=F6,"On time","Late"),IF(Today>F6,"Overdue",IF(F6-Today<=7,"Due within 7 days","Not yet due")))) | N6: =IF(OR(M6="Late",M6="Overdue"),IF(G6<>"",G6-F6,Today-F6),"") | O6: =IF(H6="Returned",1,0) -> 0 | Q6: Due per the IMS (A017): enter the date.
A7: 3 | B7: A004 | C7: =IF(B7="","",IFERROR(INDEX(Deliverables!$B$5:$B$48,MATCH(B7,Deliverables!$A$5:$A$48,0)),"ID not found")) -> ATO Documentation/ Artifacts | D7: =IF(B7="","",IFERROR(INDEX(Deliverables!$D$5:$D$48,MATCH(B7,Deliverables!$A$5:$A$48,0)),"")) -> 6.1 | E7: Initial delivery | J7: =IF(G7="","",WORKDAY(G7,ReviewDays)) | K7: =IF(AND(G7<>"",OR(H7="",H7="Pending"),Today>J7),"Past inspection window – deemed accepted","") | L7: =IF(AND(H7="Returned",I7<>""),WORKDAY(I7,ResubDays),"") | M7: =IF(OR(B7="",F7=""),"",IF(G7<>"",IF(G7<=F7,"On time","Late"),IF(Today>F7,"Overdue",IF(F7-Today<=7,"Due within 7 days","Not yet due")))) | N7: =IF(OR(M7="Late",M7="Overdue"),IF(G7<>"",G7-F7,Today-F7),"") | O7: =IF(H7="Returned",1,0) -> 0 | Q7: Due per the IMS (A017): enter the date.
A8: 4 | B8: A006 | C8: =IF(B8="","",IFERROR(INDEX(Deliverables!$B$5:$B$48,MATCH(B8,Deliverables!$A$5:$A$48,0)),"ID not found")) -> STIG/SRG Checklists | D8: =IF(B8="","",IFERROR(INDEX(Deliverables!$D$5:$D$48,MATCH(B8,Deliverables!$A$5:$A$48,0)),"")) -> 6.1 | E8: ="Quarter 1 (months 1-3)" -> Quarter 1 (months 1-3) | F8: =WORKDAY(EOMONTH(Award,2),DueOffset) -> 46241 | J8: =IF(G8="","",WORKDAY(G8,ReviewDays)) | K8: =IF(AND(G8<>"",OR(H8="",H8="Pending"),Today>J8),"Past inspection window – deemed accepted","") | L8: =IF(AND(H8="Returned",I8<>""),WORKDAY(I8,ResubDays),"") | M8: =IF(OR(B8="",F8=""),"",IF(G8<>"",IF(G8<=F8,"On time","Late"),IF(Today>F8,"Overdue",IF(F8-Today<=7,"Due within 7 days","Not yet due")))) -> Overdue | N8: =IF(OR(M8="Late",M8="Overdue"),IF(G8<>"",G8-F8,Today-F8),"") -> 65 | O8: =IF(H8="Returned",1,0) -> 0 | Q8: Due date uses the DueOffset assumption.
A9: 5 | B9: A006 | C9: =IF(B9="","",IFERROR(INDEX(Deliverables!$B$5:$B$48,MATCH(B9,Deliverables!$A$5:$A$48,0)),"ID not found")) -> STIG/SRG Checklists | D9: =IF(B9="","",IFERROR(INDEX(Deliverables!$D$5:$D$48,MATCH(B9,Deliverables!$A$5:$A$48,0)),"")) -> 6.1 | E9: ="Quarter 2 (months 4-6)" -> Quarter 2 (months 4-6) | F9: =WORKDAY(EOMONTH(Award,5),DueOffset) -> 46332 | J9: =IF(G9="","",WORKDAY(G9,ReviewDays)) | K9: =IF(AND(G9<>"",OR(H9="",H9="Pending"),Today>J9),"Past inspection window – deemed accepted","") | L9: =IF(AND(H9="Returned",I9<>""),WORKDAY(I9,ResubDays),"") | M9: =IF(OR(B9="",F9=""),"",IF(G9<>"",IF(G9<=F9,"On time","Late"),IF(Today>F9,"Overdue",IF(F9-Today<=7,"Due within 7 days","Not yet due")))) -> Not yet due | N9: =IF(OR(M9="Late",M9="Overdue"),IF(G9<>"",G9-F9,Today-F9),"") | O9: =IF(H9="Returned",1,0) -> 0 | Q9: Due date uses the DueOffset assumption.
A10: 6 | B10: A006 | C10: =IF(B10="","",IFERROR(INDEX(Deliverables!$B$5:$B$48,MATCH(B10,Deliverables!$A$5:$A$48,0)),"ID not found")) -> STIG/SRG Checklists | D10: =IF(B10="","",IFERROR(INDEX(Deliverables!$D$5:$D$48,MATCH(B10,Deliverables!$A$5:$A$48,0)),"")) -> 6.1 | E10: ="Quarter 3 (months 7-9)" -> Quarter 3 (months 7-9) | F10: =WORKDAY(EOMONTH(Award,8),DueOffset) -> 46423 | J10: =IF(G10="","",WORKDAY(G10,ReviewDays)) | K10: =IF(AND(G10<>"",OR(H10="",H10="Pending"),Today>J10),"Past inspection window – deemed accepted","") | L10: =IF(AND(H10="Returned",I10<>""),WORKDAY(I10,ResubDays),"") | M10: =IF(OR(B10="",F10=""),"",IF(G10<>"",IF(G10<=F10,"On time","Late"),IF(Today>F10,"Overdue",IF(F10-Today<=7,"Due within 7 days","Not yet due")))) -> Not yet due | N10: =IF(OR(M10="Late",M10="Overdue"),IF(G10<>"",G10-F10,Today-F10),"") | O10: =IF(H10="Returned",1,0) -> 0 | Q10: Due date uses the DueOffset assumption.
A11: 7 | B11: A006 | C11: =IF(B11="","",IFERROR(INDEX(Deliverables!$B$5:$B$48,MATCH(B11,Deliverables!$A$5:$A$48,0)),"ID not found")) -> STIG/SRG Checklists | D11: =IF(B11="","",IFERROR(INDEX(Deliverables!$D$5:$D$48,MATCH(B11,Deliverables!$A$5:$A$48,0)),"")) -> 6.1 | E11: ="Quarter 4 (months 10-12)" -> Quarter 4 (months 10-12) | F11: =WORKDAY(EOMONTH(Award,11),DueOffset) -> 46514 | J11: =IF(G11="","",WORKDAY(G11,ReviewDays)) | K11: =IF(AND(G11<>"",OR(H11="",H11="Pending"),Today>J11),"Past inspection window – deemed accepted","") | L11: =IF(AND(H11="Returned",I11<>""),WORKDAY(I11,ResubDays),"") | M11: =IF(OR(B11="",F11=""),"",IF(G11<>"",IF(G11<=F11,"On time","Late"),IF(Today>F11,"Overdue",IF(F11-Today<=7,"Due within 7 days","Not yet due")))) -> Not yet due | N11: =IF(OR(M11="Late",M11="Overdue"),IF(G11<>"",G11-F11,Today-F11),"") | O11: =IF(H11="Returned",1,0) -> 0 | Q11: Due date uses the DueOffset assumption.
A12: 8 | B12: A007 | C12: =IF(B12="","",IFERROR(INDEX(Deliverables!$B$5:$B$48,MATCH(B12,Deliverables!$A$5:$A$48,0)),"ID not found")) -> ACAS Scans | D12: =IF(B12="","",IFERROR(INDEX(Deliverables!$D$5:$D$48,MATCH(B12,Deliverables!$A$5:$A$48,0)),"")) -> 6.1 | E12: ="ACAS scan wk 1" -> ACAS scan wk 1 | F12: =Award+MOD(6-WEEKDAY(Award),7)+0 -> 46150 | J12: =IF(G12="","",WORKDAY(G12,ReviewDays)) | K12: =IF(AND(G12<>"",OR(H12="",H12="Pending"),Today>J12),"Past inspection window – deemed accepted","") | L12: =IF(AND(H12="Returned",I12<>""),WORKDAY(I12,ResubDays),"") | M12: =IF(OR(B12="",F12=""),"",IF(G12<>"",IF(G12<=F12,"On time","Late"),IF(Today>F12,"Overdue",IF(F12-Today<=7,"Due within 7 days","Not yet due")))) -> Overdue | N12: =IF(OR(M12="Late",M12="Overdue"),IF(G12<>"",G12-F12,Today-F12),"") -> 156 | O12: =IF(H12="Returned",1,0) -> 0 | Q12: Friday assumed; PWS says weekly only.
A13: 9 | B13: A007 | C13: =IF(B13="","",IFERROR(INDEX(Deliverables!$B$5:$B$48,MATCH(B13,Deliverables!$A$5:$A$48,0)),"ID not found")) -> ACAS Scans | D13: =IF(B13="","",IFERROR(INDEX(Deliverables!$D$5:$D$48,MATCH(B13,Deliverables!$A$5:$A$48,0)),"")) -> 6.1 | E13: ="ACAS scan wk 2" -> ACAS scan wk 2 | F13: =Award+MOD(6-WEEKDAY(Award),7)+7 -> 46157 | J13: =IF(G13="","",WORKDAY(G13,ReviewDays)) | K13: =IF(AND(G13<>"",OR(H13="",H13="Pending"),Today>J13),"Past inspection window – deemed accepted","") | L13: =IF(AND(H13="Returned",I13<>""),WORKDAY(I13,ResubDays),"") | M13: =IF(OR(B13="",F13=""),"",IF(G13<>"",IF(G13<=F13,"On time","Late"),IF(Today>F13,"Overdue",IF(F13-Today<=7,"Due within 7 days","Not yet due")))) -> Overdue | N13: =IF(OR(M13="Late",M13="Overdue"),IF(G13<>"",G13-F13,Today-F13),"") -> 149 | O13: =IF(H13="Returned",1,0) -> 0 | Q13: Friday assumed; PWS says weekly only.
A14: 10 | B14: A007 | C14: =IF(B14="","",IFERROR(INDEX(Deliverables!$B$5:$B$48,MATCH(B14,Deliverables!$A$5:$A$48,0)),"ID not found")) -> ACAS Scans | D14: =IF(B14="","",IFERROR(INDEX(Deliverables!$D$5:$D$48,MATCH(B14,Deliverables!$A$5:$A$48,0)),"")) -> 6.1 | E14: ="ACAS scan wk 3" -> ACAS scan wk 3 | F14: =Award+MOD(6-WEEKDAY(Award),7)+14 -> 46164 | J14: =IF(G14="","",WORKDAY(G14,ReviewDays)) | K14: =IF(AND(G14<>"",OR(H14="",H14="Pending"),Today>J14),"Past inspection window – deemed accepted","") | L14: =IF(AND(H14="Returned",I14<>""),WORKDAY(I14,ResubDays),"") | M14: =IF(OR(B14="",F14=""),"",IF(G14<>"",IF(G14<=F14,"On time","Late"),IF(Today>F14,"Overdue",IF(F14-Today<=7,"Due within 7 days","Not yet due")))) -> Overdue | N14: =IF(OR(M14="Late",M14="Overdue"),IF(G14<>"",G14-F14,Today-F14),"") -> 142 | O14: =IF(H14="Returned",1,0) -> 0 | Q14: Friday assumed; PWS says weekly only.
A15: 11 | B15: A007 | C15: =IF(B15="","",IFERROR(INDEX(Deliverables!$B$5:$B$48,MATCH(B15,Deliverables!$A$5:$A$48,0)),"ID not found")) -> ACAS Scans | D15: =IF(B15="","",IFERROR(INDEX(Deliverables!$D$5:$D$48,MATCH(B15,Deliverables!$A$5:$A$48,0)),"")) -> 6.1 | E15: ="ACAS scan wk 4" -> ACAS scan wk 4 | F15: =Award+MOD(6-WEEKDAY(Award),7)+21 -> 46171 | J15: =IF(G15="","",WORKDAY(G15,ReviewDays)) | K15: =IF(AND(G15<>"",OR(H15="",H15="Pending"),Today>J15),"Past inspection window – deemed accepted","") | L15: =IF(AND(H15="Returned",I15<>""),WORKDAY(I15,ResubDays),"") | M15: =IF(OR(B15="",F15=""),"",IF(G15<>"",IF(G15<=F15,"On time","Late"),IF(Today>F15,"Overdue",IF(F15-Today<=7,"Due within 7 days","Not yet due")))) -> Overdue | N15: =IF(OR(M15="Late",M15="Overdue"),IF(G15<>"",G15-F15,Today-F15),"") -> 135 | O15: =IF(H15="Returned",1,0) -> 0 | Q15: Friday assumed; PWS says weekly only.
A16: 12 | B16: A007 | C16: =IF(B16="","",IFERROR(INDEX(Deliverables!$B$5:$B$48,MATCH(B16,Deliverables!$A$5:$A$48,0)),"ID not found")) -> ACAS Scans | D16: =IF(B16="","",IFERROR(INDEX(Deliverables!$D$5:$D$48,MATCH(B16,Deliverables!$A$5:$A$48,0)),"")) -> 6.1 | E16: ="ACAS scan wk 5" -> ACAS scan wk 5 | F16: =Award+MOD(6-WEEKDAY(Award),7)+28 -> 46178 | J16: =IF(G16="","",WORKDAY(G16,ReviewDays)) | K16: =IF(AND(G16<>"",OR(H16="",H16="Pending"),Today>J16),"Past inspection window – deemed accepted","") | L16: =IF(AND(H16="Returned",I16<>""),WORKDAY(I16,ResubDays),"") | M16: =IF(OR(B16="",F16=""),"",IF(G16<>"",IF(G16<=F16,"On time","Late"),IF(Today>F16,"Overdue",IF(F16-Today<=7,"Due within 7 days","Not yet due")))) -> Overdue | N16: =IF(OR(M16="Late",M16="Overdue"),IF(G16<>"",G16-F16,Today-F16),"") -> 128 | O16: =IF(H16="Returned",1,0) -> 0 | Q16: Friday assumed; PWS says weekly only.
A17: 13 | B17: A007 | C17: =IF(B17="","",IFERROR(INDEX(Deliverables!$B$5:$B$48,MATCH(B17,Deliverables!$A$5:$A$48,0)),"ID not found")) -> ACAS Scans | D17: =IF(B17="","",IFERROR(INDEX(Deliverables!$D$5:$D$48,MATCH(B17,Deliverables!$A$5:$A$48,0)),"")) -> 6.1 | E17: ="ACAS scan wk 6" -> ACAS scan wk 6 | F17: =Award+MOD(6-WEEKDAY(Award),7)+35 -> 46185 | J17: =IF(G17="","",WORKDAY(G17,ReviewDays)) | K17: =IF(AND(G17<>"",OR(H17="",H17="Pending"),Today>J17),"Past inspection window – deemed accepted","") | L17: =IF(AND(H17="Returned",I17<>""),WORKDAY(I17,ResubDays),"") | M17: =IF(OR(B17="",F17=""),"",IF(G17<>"",IF(G17<=F17,"On time","Late"),IF(Today>F17,"Overdue",IF(F17-Today<=7,"Due within 7 days","Not yet due")))) -> Overdue | N17: =IF(OR(M17="Late",M17="Overdue"),IF(G17<>"",G17-F17,Today-F17),"") -> 121 | O17: =IF(H17="Returned",1,0) -> 0 | Q17: Friday assumed; PWS says weekly only.
A18: 14 | B18: A007 | C18: =IF(B18="","",IFERROR(INDEX(Deliverables!$B$5:$B$48,MATCH(B18,Deliverables!$A$5:$A$48,0)),"ID not found")) -> ACAS Scans | D18: =IF(B18="","",IFERROR(INDEX(Deliverables!$D$5:$D$48,MATCH(B18,Deliverables!$A$5:$A$48,0)),"")) -> 6.1 | E18: ="ACAS scan wk 7" -> ACAS scan wk 7 | F18: =Award+MOD(6-WEEKDAY(Award),7)+42 -> 46192 | J18: =IF(G18="","",WORKDAY(G18,ReviewDays)) | K18: =IF(AND(G18<>"",OR(H18="",H18="Pending"),Today>J18),"Past inspection window – deemed accepted","") | L18: =IF(AND(H18="Returned",I18<>""),WORKDAY(I18,ResubDays),"") | M18: =IF(OR(B18="",F18=""),"",IF(G18<>"",IF(G18<=F18,"On time","Late"),IF(Today>F18,"Overdue",IF(F18-Today<=7,"Due within 7 days","Not yet due")))) -> Overdue | N18: =IF(OR(M18="Late",M18="Overdue"),IF(G18<>"",G18-F18,Today-F18),"") -> 114 | O18: =IF(H18="Returned",1,0) -> 0 | Q18: Friday assumed; PWS says weekly only.
